Workbook

Sheet Zomba
A1: SOUTHERN REGION WATER BOARD
A3: MONTHLY REPORTS - 2024/2025
A4: ZOMBA ZONE
A5: ZOMBA SCHEME
A7: PARAMETERS | C7: UNITS | D7: APRIL | E7: MAY | F7: JUNE | G7: JULY | H7: AUGUST | I7: SEPTEMBER | J7: OCTOBER | K7: NOVEMBER | L7: DECEMBER | M7: JANUARY | N7: FEBRUARY | O7: MARCH | P7: TOTALS
A8: PRODUCTION
A9: Volume Produced | C9: m3 | D9: 455725 | E9: 543720 | F9: 487019 | G9: 480949 | H9: 517415 | I9: 515483 | J9: 566721 | K9: 417636 | L9: 542479 | M9: 557661 | N9: 426923 | O9: 492032 | P9: =SUM(D9:O9) -> 6003763
A10: REVENUE WATER - POSTPAID
A11: Volume Billed Individuals | C11: m3 | D11: 162543 | E11: 158741 | F11: 154972 | G11: 153563 | H11: 160397 | I11: 174718 | J11: 179319 | K11: 153670 | L11: 187353 | M11: 149349 | N11: 142130 | O11: 131764 | P11: =SUM(D11:O11) -> 1908519
A12: Volume Billed CWPs | C12: m3 | D12: 11486 | E12: 10668 | F12: 11600 | G12: 12154 | H12: 14133 | I12: 14387 | J12: 13064 | K12: 11512 | L12: 16077 | M12: 12266 | N12: 11668 | O12: 10740 | P12: =SUM(D12:O12) -> 149755
A13: Volume Billed Institutions | C13: m3 | D13: 26963 | E13: 55060 | F13: 44468 | G13: 35028 | H13: 37753 | I13: 34783 | J13: 42220 | K13: 32146 | L13: 32817 | M13: 28516 | N13: 30666 | O13: 30647 | P13: =SUM(D13:O13) -> 431067
A14: Volume Billed Commercial/Industrial | C14: m3 | D14: 2408 | E14: 2851 | F14: 3114 | G14: 2570 | H14: 3190 | I14: 1950 | J14: 1965 | K14: 1635 | L14: 960 | M14: 746 | N14: 220 | O14: 145 | P14: =SUM(D14:O14) -> 21754
A15: Total Volume Billed Post Paid | C15: m3 | D15: =SUM(D11:D14) -> 203400 | E15: =SUM(E11:E14) -> 227320 | F15: =SUM(F11:F14) -> 214154 | G15: =SUM(G11:G14) -> 203315 | H15: =SUM(H11:H14) -> 215473 | I15: =SUM(I11:I14) -> 225838 | J15: =SUM(J11:J14) -> 236568 | K15: =SUM(K11:K14) -> 198963 | ... P15: =SUM(P11:P14) -> 2511095
A16: REVENUE WATER - PREPAID
A17: Individuals | C17: m3 | D17: 55086.6 | E17: 53695.8 | F17: 109740.2 | G17: 49046 | H17: 54795.3 | I17: 51640.6 | J17: 63486.9 | K17: 51019.5 | L17: 55681.2 | M17: 86444.3 | N17: 45750 | O17: 60117.4 | P17: =SUM(D17:O17) -> 736503.8
A18: CWPs | C18: m3 | D18: 7766.6 | E18: 7409.1 | F18: 7280.7 | G18: 9019.7 | H18: 7792.6 | I18: 8136.5 | J18: 8176.3 | K18: 8249.2 | L18: 8786.1 | M18: 8231.2 | N18: 7388.1 | O18: 7526 | P18: =SUM(D18:O18) -> 95762.1
A19: Institutions | C19: m3 | D19: 23551.2 | E19: 76944.5 | F19: 29554.7 | G19: 39065.9 | H19: 37994.7 | I19: 29341.2 | J19: 48888 | K19: 29976.4 | L19: 38909.9 | M19: 77548.6 | N19: 29875.2 | O19: 48910.5 | P19: =SUM(D19:O19) -> 510560.8
A20: Commercial/Industrial | C20: m3 | D20: 4077.7 | E20: 3927.7 | F20: 3548.7 | G20: 4275.8 | H20: 4337.4 | I20: 5500.1 | J20: 5443.4 | K20: 6352.8 | L20: 5991.2 | M20: 5003.3 | N20: 5117.6 | O20: 6048.6 | P20: =SUM(D20:O20) -> 59624.3
A21: Total Volume Prepaid | C21: m3 | D21: =SUM(D17:D20) -> 90482.1 | E21: =SUM(E17:E20) -> 141977.1 | F21: =SUM(F17:F20) -> 150124.3 | G21: =SUM(G17:G20) -> 101407.4 | H21: =SUM(H17:H20) -> 104920 | I21: =SUM(I17:I20) -> 94618.4 | J21: =SUM(J17:J20) -> 125994.6 | K21: =SUM(K17:K20) -> 95597.9 | ... P21: =SUM(P17:P20) -> 1402451
A22: TOTAL REVENUE WATER | C22: m3 | D22: =D21+D15 -> 293882.1 | E22: =E21+E15 -> 369297.1 | F22: =F21+F15 -> 364278.3 | G22: =G21+G15 -> 304722.4 | H22: =H21+H15 -> 320393 | I22: =I21+I15 -> 320456.4 | J22: =J21+J15 -> 362562.6 | K22: =K21+K15 -> 294560.9 | ... P22: =P21+P15 -> 3913546
A24: Non-Revenue Water (NRW) | B24: Volume | C24: m3 | D24: =D9-D22 -> 161842.9 | E24: =E9-E22 -> 174422.9 | F24: =F9-F22 -> 122740.7 | G24: =G9-G22 -> 176226.6 | H24: =H9-H22 -> 197022 | I24: =I9-I22 -> 195026.6 | J24: =J9-J22 -> 204158.4 | K24: =K9-K22 -> 123075.1 | ... P24: =P9-P22 -> 2090217
B25: Percentage | C25: % | D25: =IFERROR(D24/D9,0) -> 0.35513281 | E25: =IFERROR(E24/E9,0) -> 0.32079545 | F25: =IFERROR(F24/F9,0) -> 0.25202446 | G25: =IFERROR(G24/G9,0) -> 0.36641432 | H25: =IFERROR(H24/H9,0) -> 0.38078138 | I25: =IFERROR(I24/I9,0) -> 0.3783376 | J25: =IFERROR(J24/J9,0) -> 0.36024499 | K25: =IFERROR(K24/K9,0) -> 0.29469466 | ... O25: =IFERROR(O24/O9,0) -> 0.3986194 | P25: =IF(P9,P24/P9,"") -> 0.34815115
A26: OPERATING EXPENSES
A27: Chemicals
A28: Chemical | B28: Rate(MK/kg)
A29: Chlorine | B29: 7400 | C29: kg | D29: 1234.4 | E29: 1183.2 | F29: 1237.6 | G29: 1309.4 | H29: 1225 | I29: 1179 | J29: 1281 | K29: 1181 | L29: 1368.9 | M29: 1179 | N29: 1322 | O29: 1422 | P29: =SUM(D29:O29) -> 15122.5
C30: kg/mg litre | D30: =IFERROR(D29/(D9/1000),0) -> 2.7086511 | E30: =IFERROR(E29/(E9/1000),0) -> 2.1761201 | F30: =IFERROR(F29/(F9/1000),0) -> 2.541174 | G30: =IFERROR(G29/(G9/1000),0) -> 2.722534 | H30: =IFERROR(H29/(H9/1000),0) -> 2.3675386 | I30: =IFERROR(I29/(I9/1000),0) -> 2.2871753 | J30: =IFERROR(J29/(J9/1000),0) -> 2.2603715 | K30: =IFERROR(K29/(K9/1000),0) -> 2.8278214 | ... P30: =IFERROR(P29/(P9/1000),0) -> 2.5188369
A31: Aluminium sulphate | B31: 1900 | C31: kg | D31: 4542.8 | E31: 2613 | F31: 2106.4 | G31: 1941.4 | H31: 2058 | I31: 1966 | J31: 3300 | K31: 3284 | L31: 5769.1 | M31: 6924 | N31: 6071 | O31: 5489 | P31: =SUM(D31:O31) -> 46064.7
C32: kg/mg litre | D32: =IFERROR(D31/(D9/1000),0) -> 9.9682923 | E32: =IFERROR(E31/(E9/1000),0) -> 4.8057824 | F32: =IFERROR(F31/(F9/1000),0) -> 4.3250879 | G32: =IFERROR(G31/(G9/1000),0) -> 4.0366026 | H32: =IFERROR(H31/(H9/1000),0) -> 3.9774649 | I32: =IFERROR(I31/(I9/1000),0) -> 3.8138988 | J32: =IFERROR(J31/(J9/1000),0) -> 5.8229711 | K32: =IFERROR(K31/(K9/1000),0) -> 7.8633068 | ... P32: =IFERROR(P31/(P9/1000),0) -> 7.672638
A33: Soda | B33: 1900 | C33: kg | D33: 1580.1 | E33: 936.7 | F33: 986.2 | G33: 984.5 | H33: 1275 | I33: 688 | J33: 887 | K33: 933 | L33: 2102.3 | M33: 1915 | N33: 1493 | O33: 2352 | P33: =SUM(D33:O33) -> 16132.8
C34: kg/mg litre | D34: =IFERROR(D33/(D9/1000),0) -> 3.4672226 | E34: =IFERROR(E33/(E9/1000),0) -> 1.7227617 | F34: =IFERROR(F33/(F9/1000),0) -> 2.0249723 | G34: =IFERROR(G33/(G9/1000),0) -> 2.0469946 | H34: =IFERROR(H33/(H9/1000),0) -> 2.4641729 | I34: =IFERROR(I33/(I9/1000),0) -> 1.3346706 | J34: =IFERROR(J33/(J9/1000),0) -> 1.565144 | K34: =IFERROR(K33/(K9/1000),0) -> 2.2340028 | ... P34: =IFERROR(P33/(P9/1000),0) -> 2.6871147
A35: Algae floc | B35: =745345.16/200 -> 3726.7258 | C35: litres | D35: 0 | E35: 0 | F35: 0 | G35: 0 | H35: 0 | I35: 0 | J35: 0 | K35: 0 | L35: 0 | M35: 0 | N35: 0 | O35: 0
C36: litres/mg litre
A37: Sud floc | B37: =790318.72/200 -> 3951.5936 | C37: litres | D37: 0 | E37: 0 | F37: 0 | G37: 0 | H37: 0 | I37: 0 | J37: 0 | K37: 0 | L37: 0 | M37: 0 | N37: 0 | O37: 0 | P37: =SUM(D37:O37) -> 0
C38: litres/mg litre | D38: =IFERROR(D37/(D9/1000),0) -> 0 | E38: =IFERROR(E37/(E9/1000),0) -> 0 | F38: =IFERROR(F37/(F9/1000),0) -> 0 | G38: =IFERROR(G37/(G9/1000),0) -> 0 | H38: =IFERROR(H37/(H9/1000),0) -> 0 | I38: =IFERROR(I37/(I9/1000),0) -> 0 | J38: =IFERROR(J37/(J9/1000),0) -> 0 | K38: =IFERROR(K37/(K9/1000),0) -> 0 | ... P38: =IFERROR(P37/(P9/1000),0) -> 0
A39: Potasium permanganate | B39: 1950 | C39: kg | D39: 0 | E39: 0 | F39: 0 | G39: 0 | H39: 0 | I39: 0 | J39: 0 | K39: 0 | L39: 0 | M39: 0 | N39: 0 | O39: 0 | P39: =SUM(D39:O39) -> 0
C40: kg/mg litre | D40: =IFERROR(D39/(D9/1000),0) -> 0 | E40: =IFERROR(E39/(E9/1000),0) -> 0 | F40: =IFERROR(F39/(F9/1000),0) -> 0 | G40: =IFERROR(G39/(G9/1000),0) -> 0 | H40: =IFERROR(H39/(H9/1000),0) -> 0 | I40: =IFERROR(I39/(I9/1000),0) -> 0 | J40: =IFERROR(J39/(J9/1000),0) -> 0 | K40: =IFERROR(K39/(K9/1000),0) -> 0 | ... P40: =IFERROR(P39/(P9/1000),0) -> 0
A41: Cost of Chemicals | C41: Mk | D41: =(D29*$B29)+(D31*$B31)+(D33*$B33)+(D35*$B35)+(D37*$B37)+(D39*$B39) -> 20768070 | E41: =(E29*$B29)+(E31*$B31)+(E33*$B33)+(E35*$B35)+(E37*$B37)+(E39*$B39) -> 15500110 | F41: =(F29*$B29)+(F31*$B31)+(F33*$B33)+(F35*$B35)+(F37*$B37)+(F39*$B39) -> 15034180 | G41: =(G29*$B29)+(G31*$B31)+(G33*$B33)+(G35*$B35)+(G37*$B37)+(G39*$B39) -> 15248770 | H41: =(H29*$B29)+(H31*$B31)+(H33*$B33)+(H35*$B35)+(H37*$B37)+(H39*$B39) -> 15397700 | I41: =(I29*$B29)+(I31*$B31)+(I33*$B33)+(I35*$B35)+(I37*$B37)+(I39*$B39) -> 13767200 | J41: =(J29*$B29)+(J31*$B31)+(J33*$B33)+(J35*$B35)+(J37*$B37)+(J39*$B39) -> 17434700 | K41: =(K29*$B29)+(K31*$B31)+(K33*$B33)+(K35*$B35)+(K37*$B37)+(K39*$B39) -> 16751700 | ... O41: =(O29*$B29)+(O31*$B31)+(O33*$B33)+(O35*$B35)+(O37*$B37)+(O39*$B39) -> 25420700 | P41: =SUM(D41:O41) -> 230081750
A42: Cost/vol. Produced (chemicals) | C42: Mk/m3 | D42: =IFERROR(D41/D9,0) -> 45.571496 | E42: =IFERROR(E41/E9,0) -> 28.507522 | F42: =IFERROR(F41/F9,0) -> 30.869802 | G42: =IFERROR(G41/G9,0) -> 31.705586 | H42: =IFERROR(H41/H9,0) -> 29.758898 | I42: =IFERROR(I41/I9,0) -> 26.707379 | J42: =IFERROR(J41/J9,0) -> 30.764168 | K42: =IFERROR(K41/K9,0) -> 40.110766 | ... P42: =IFERROR(P41/P9,0) -> 38.322923
A43: Power
...

Sheet Mwanza
A1: SOUTHERN REGION WATER BOARD
A3: MONTHLY REPORTS - 2024/2025
A4: ZOMBA ZONE
A5: MWANZA SCHEME
A7: PARAMETERS | C7: UNITS | D7: APRIL | E7: MAY | F7: JUNE | G7: JULY | H7: AUGUST | I7: SEPTEMBER | J7: OCTOBER | K7: NOVEMBER | L7: DECEMBER | M7: JANUARY | N7: FEBRUARY | O7: MARCH | P7: TOTALS
A8: PRODUCTION
A9: Volume Produced | C9: m3 | D9: 34688 | E9: 36835 | F9: 35077 | G9: 35440 | H9: 43486 | I9: 40218 | J9: 42060 | K9: 35466 | L9: 38896 | M9: 39483 | N9: 36021 | O9: 35021 | P9: =SUM(D9:O9) -> 452691
A10: REVENUE WATER - POSTPAID
A11: Volume Billed Individuals | C11: m3 | D11: 19824 | E11: 19875 | F11: 19563 | G11: 20026 | H11: 20749 | I11: 21429 | J11: 21266 | K11: 20525 | L11: 21819 | M11: 20508 | N11: 19613 | O11: 18671 | P11: =SUM(D11:O11) -> 243868
A12: Volume Billed CWPs | C12: m3 | D12: 907 | E12: 1224 | F12: 921 | G12: 967 | H12: 839 | I12: 852 | J12: 791 | K12: 782 | L12: 826 | M12: 744 | N12: 690 | O12: 766 | P12: =SUM(D12:O12) -> 10309
A13: Volume Billed Institutions | C13: m3 | D13: 156 | E13: 212 | F13: 336 | G13: 497 | H13: 361 | I13: 462 | J13: 441 | K13: 564 | L13: 626 | M13: 552 | N13: 427 | O13: 360 | P13: =SUM(D13:O13) -> 4994
A14: Volume Billed Commercial/Industrial | C14: m3 | D14: 1120 | E14: 1266 | F14: 918 | G14: 947 | H14: 809 | I14: 801 | J14: 811 | K14: 734 | L14: 666 | M14: 439 | N14: 261 | O14: 189 | P14: =SUM(D14:O14) -> 8961
A15: Total Volume Billed Post Paid | C15: m3 | D15: =SUM(D11:D14) -> 22007 | E15: =SUM(E11:E14) -> 22577 | F15: =SUM(F11:F14) -> 21738 | G15: =SUM(G11:G14) -> 22437 | H15: =SUM(H11:H14) -> 22758 | I15: =SUM(I11:I14) -> 23544 | J15: =SUM(J11:J14) -> 23309 | K15: =SUM(K11:K14) -> 22605 | ... P15: =SUM(P11:P14) -> 268132
A16: REVENUE WATER - PREPAID
A17: Individuals | C17: m3 | D17: 1727.1 | E17: 1886.4 | F17: 3796.2 | G17: 2070.3 | H17: 1889.2 | I17: 1798.2 | J17: 2023.8 | K17: 1888.8 | L17: 2005.7 | M17: 2276.7 | N17: 1569.8 | O17: 1968 | P17: =SUM(D17:O17) -> 24900.2
A18: CWPs | C18: m3 | D18: 148.9 | E18: 213.4 | F18: 201.9 | G18: 240.9 | H18: 237.4 | I18: 271.7 | J18: 197.7 | K18: 225.5 | L18: 470.2 | M18: 183.6 | N18: 94.1 | O18: 209.5 | P18: =SUM(D18:O18) -> 2694.8
A19: Institutions | C19: m3 | D19: 351.4 | E19: 1289.2 | F19: 2636.3 | G19: 4525.5 | H19: 1609.3 | I19: 2383.5 | J19: 3001.2 | K19: 3139.3 | L19: 2672.5 | M19: 4996.4 | N19: 1406.9 | O19: 630.8 | P19: =SUM(D19:O19) -> 28642.3
A20: Commercial/Industrial | C20: m3 | D20: 250.4 | E20: 252.1 | F20: 189.5 | G20: 203.7 | H20: 213.9 | I20: 344.2 | J20: 290.4 | K20: 194 | L20: 348 | M20: 342.1 | N20: 478.2 | O20: 478.4 | P20: =SUM(D20:O20) -> 3584.9
A21: Total Volume Prepaid | C21: m3 | D21: =SUM(D17:D20) -> 2477.8 | E21: =SUM(E17:E20) -> 3641.1 | F21: =SUM(F17:F20) -> 6823.9 | G21: =SUM(G17:G20) -> 7040.4 | H21: =SUM(H17:H20) -> 3949.8 | I21: =SUM(I17:I20) -> 4797.6 | J21: =SUM(J17:J20) -> 5513.1 | K21: =SUM(K17:K20) -> 5447.6 | ... P21: =SUM(P17:P20) -> 59822.2
A22: TOTAL REVENUE WATER | C22: m3 | D22: =D21+D15 -> 24484.8 | E22: =E21+E15 -> 26218.1 | F22: =F21+F15 -> 28561.9 | G22: =G21+G15 -> 29477.4 | H22: =H21+H15 -> 26707.8 | I22: =I21+I15 -> 28341.6 | J22: =J21+J15 -> 28822.1 | K22: =K21+K15 -> 28052.6 | ... P22: =P21+P15 -> 327954.2
A24: Non-Revenue Water (NRW) | B24: Volume | C24: m3 | D24: =D9-D22 -> 10203.2 | E24: =E9-E22 -> 10616.9 | F24: =F9-F22 -> 6515.1 | G24: =G9-G22 -> 5962.6 | H24: =H9-H22 -> 16778.2 | I24: =I9-I22 -> 11876.4 | J24: =J9-J22 -> 13237.9 | K24: =K9-K22 -> 7413.4 | ... P24: =P9-P22 -> 124736.8
B25: Percentage | C25: % | D25: =IFERROR(D24/D9,0) -> 0.29414207 | E25: =E24/E9 -> 0.28822859 | F25: =F24/F9 -> 0.18573709 | G25: =IFERROR(G24/G9,0) -> 0.16824492 | H25: =IFERROR(H24/H9,0) -> 0.38582992 | I25: =IFERROR(I24/I9,0) -> 0.29530061 | J25: =IFERROR(J24/J9,0) -> 0.31473847 | K25: =IFERROR(K24/K9,0) -> 0.20902837 | L25: =IFERROR(L24/L9,0) -> 0.24327951 | M25: =IFERROR(M24/M9,0) -> 0.23912063 | N25: =IFERROR(N24/N9,0) -> 0.31873074 | O25: =IFERROR(O24/O9,0) -> 0.33546444 | P25: =IF(P9,P24/P9,"") -> 0.27554513
A26: OPERATING EXPENSES
A27: Chemicals
A28: Chemical | B28: Rate(MK/kg)
A29: Chlorine | B29: 7400 | C29: kg | D29: 45 | E29: 28 | F29: 21 | G29: 23 | H29: 24 | I29: 24 | J29: 21 | K29: 17 | L29: 15.5 | M29: 17 | N29: 16.5 | O29: 10.5 | P29: =SUM(D29:O29) -> 262.5
C30: kg/mg litre | D30: =IFERROR(D29/(D9/1000),0) -> 1.2972786 | E30: =IFERROR(E29/(E9/1000),0) -> 0.7601466 | F30: =IFERROR(F29/(F9/1000),0) -> 0.5986829 | G30: =IFERROR(G29/(G9/1000),0) -> 0.6489842 | H30: =IFERROR(H29/(H9/1000),0) -> 0.55190176 | I30: =IFERROR(I29/(I9/1000),0) -> 0.59674772 | J30: =IFERROR(J29/(J9/1000),0) -> 0.49928673 | K30: =IFERROR(K29/(K9/1000),0) -> 0.47933232 | ... P30: =IFERROR(P29/(P9/1000),0) -> 0.57986574
A31: Aluminium sulphate | B31: 1900 | C31: kg | D31: 0 | E31: 0 | F31: 0 | G31: 0 | H31: 0 | I31: 0 | J31: 0 | K31: 0 | L31: 0 | M31: 0 | N31: 0 | O31: 0 | P31: =SUM(D31:O31) -> 0
C32: kg/mg litre | D32: =IFERROR(D31/(D9/1000),0) -> 0 | E32: =IFERROR(E31/(E9/1000),0) -> 0 | F32: =IFERROR(F31/(F9/1000),0) -> 0 | G32: =IFERROR(G31/(G9/1000),0) -> 0 | H32: =IFERROR(H31/(H9/1000),0) -> 0 | I32: =IFERROR(I31/(I9/1000),0) -> 0 | J32: =IFERROR(J31/(J9/1000),0) -> 0 | K32: =IFERROR(K31/(K9/1000),0) -> 0 | ... P32: =IFERROR(P31/(P9/1000),0) -> 0
A33: Soda | B33: 1900 | C33: kg | D33: 0 | E33: 0 | F33: 0 | G33: 0 | H33: 0 | I33: 0 | J33: 0 | K33: 0 | L33: 0 | M33: 0 | N33: 0 | O33: 0 | P33: =SUM(D33:O33) -> 0
C34: kg/mg litre | D34: =IFERROR(D33/(D9/1000),0) -> 0 | E34: =IFERROR(E33/(E9/1000),0) -> 0 | F34: =IFERROR(F33/(F9/1000),0) -> 0 | G34: =IFERROR(G33/(G9/1000),0) -> 0 | H34: =IFERROR(H33/(H9/1000),0) -> 0 | I34: =IFERROR(I33/(I9/1000),0) -> 0 | J34: =IFERROR(J33/(J9/1000),0) -> 0 | K34: =IFERROR(K33/(K9/1000),0) -> 0 | ... P34: =IFERROR(P33/(P9/1000),0) -> 0
A35: Algae floc | B35: =745345.16/200 -> 3726.7258 | C35: litres | D35: 0 | E35: 0 | F35: 0 | G35: 0 | H35: 0 | I35: 0 | J35: 0 | K35: 0 | L35: 0 | M35: 0 | N35: 0 | O35: 0
C36: litres/mg litre
A37: Sud floc | B37: =790318.72/200 -> 3951.5936 | C37: litres | D37: 0 | E37: 0 | F37: 0 | G37: 0 | H37: 0 | I37: 0 | J37: 0 | K37: 0 | L37: 0 | M37: 0 | N37: 0 | O37: 0 | P37: =SUM(D37:O37) -> 0
C38: litres/mg litre | D38: =IFERROR(D37/(D9/1000),0) -> 0 | E38: =IFERROR(E37/(E9/1000),0) -> 0 | F38: =IFERROR(F37/(F9/1000),0) -> 0 | G38: =IFERROR(G37/(G9/1000),0) -> 0 | H38: =IFERROR(H37/(H9/1000),0) -> 0 | I38: =IFERROR(I37/(I9/1000),0) -> 0 | J38: =IFERROR(J37/(J9/1000),0) -> 0 | K38: =IFERROR(K37/(K9/1000),0) -> 0 | ... P38: =IFERROR(P37/(P9/1000),0) -> 0
A39: Potasium permanganate | B39: 1950 | C39: kg | D39: 0 | E39: 0 | F39: 0 | G39: 0 | H39: 0 | I39: 0 | J39: 0 | K39: 0 | L39: 0 | M39: 0 | N39: 0 | O39: 0 | P39: =SUM(D39:O39) -> 0
C40: kg/mg litre | D40: =IFERROR(D39/(D9/1000),0) -> 0 | E40: =IFERROR(E39/(E9/1000),0) -> 0 | F40: =IFERROR(F39/(F9/1000),0) -> 0 | G40: =IFERROR(G39/(G9/1000),0) -> 0 | H40: =IFERROR(H39/(H9/1000),0) -> 0 | I40: =IFERROR(I39/(I9/1000),0) -> 0 | J40: =IFERROR(J39/(J9/1000),0) -> 0 | K40: =IFERROR(K39/(K9/1000),0) -> 0 | ... P40: =IFERROR(P39/(P9/1000),0) -> 0
A41: Cost of Chemicals | C41: Mk | D41: =(D29*$B29)+(D31*$B31)+(D33*$B33)+(D35*$B35)+(D37*$B37)+(D39*$B39) -> 333000 | E41: =(E29*$B29)+(E31*$B31)+(E33*$B33)+(E35*$B35)+(E37*$B37)+(E39*$B39) -> 207200 | F41: =(F29*$B29)+(F31*$B31)+(F33*$B33)+(F35*$B35)+(F37*$B37)+(F39*$B39) -> 155400 | G41: =(G29*$B29)+(G31*$B31)+(G33*$B33)+(G35*$B35)+(G37*$B37)+(G39*$B39) -> 170200 | H41: =(H29*$B29)+(H31*$B31)+(H33*$B33)+(H35*$B35)+(H37*$B37)+(H39*$B39) -> 177600 | I41: =(I29*$B29)+(I31*$B31)+(I33*$B33)+(I35*$B35)+(I37*$B37)+(I39*$B39) -> 177600 | J41: =(J29*$B29)+(J31*$B31)+(J33*$B33)+(J35*$B35)+(J37*$B37)+(J39*$B39) -> 155400 | K41: =(K29*$B29)+(K31*$B31)+(K33*$B33)+(K35*$B35)+(K37*$B37)+(K39*$B39) -> 125800 | ... O41: =(O29*$B29)+(O31*$B31)+(O33*$B33)+(O35*$B35)+(O37*$B37)+(O39*$B39) -> 77700 | P41: =SUM(D41:O41) -> 1942500
A42: Cost/vol. Produced (chemicals) | C42: Mk/m3 | D42: =IFERROR(D41/D9,0) -> 9.5998616 | E42: =IFERROR(E41/E9,0) -> 5.6250848 | F42: =IFERROR(F41/F9,0) -> 4.4302534 | G42: =IFERROR(G41/G9,0) -> 4.8024831 | H42: =IFERROR(H41/H9,0) -> 4.084073 | I42: =IFERROR(I41/I9,0) -> 4.4159332 | J42: =IFERROR(J41/J9,0) -> 3.6947218 | K42: =IFERROR(K41/K9,0) -> 3.5470592 | ... P42: =IFERROR(P41/P9,0) -> 4.2910064
A43: Power
...

Sheet Domasi
A1: SOUTHERN REGION WATER BOARD
A3: MONTHLY REPORTS - 2024/2025
A4: ZOMBA ZONE
A5: DOMASI SCHEME
A7: PARAMETERS | C7: UNITS | D7: APRIL | E7: MAY | F7: JUNE | G7: JULY | H7: AUGUST | I7: SEPTEMBER | J7: OCTOBER | K7: NOVEMBER | L7: DECEMBER | M7: JANUARY | N7: FEBRUARY | O7: MARCH | P7: TOTALS
A8: PRODUCTION
A9: Volume Produced | C9: m3 | D9: 22093 | E9: 19087 | F9: 16884 | G9: 29538 | H9: 29005 | I9: 25801 | J9: 17517 | K9: 20821 | L9: 18258 | M9: 17242 | N9: 24090 | O9: 23231 | P9: =SUM(D9:O9) -> 263567
A10: REVENUE WATER - POSTPAID
A11: Volume Billed Individuals | C11: m3 | D11: 6622 | E11: 7449 | F11: 7945 | G11: 7101 | H11: 8635 | I11: 11214 | J11: 9566 | K11: 9460 | L11: 8521 | M11: 6055 | N11: 8500 | O11: 8337 | P11: =SUM(D11:O11) -> 99405
A12: Volume Billed CWPs | C12: m3 | D12: 46 | E12: 46 | F12: 27 | G12: 0 | H12: 0 | I12: 0 | J12: 0 | K12: 0 | L12: 0 | M12: 0 | N12: 0 | O12: 0 | P12: =SUM(D12:O12) -> 119
A13: Volume Billed Institutions | C13: m3 | D13: 79 | E13: 92 | F13: 83 | G13: 66 | H13: 70 | I13: 80 | J13: 116 | K13: 103 | L13: 145 | M13: 49 | N13: 49 | O13: 54 | P13: =SUM(D13:O13) -> 986
A14: Volume Billed Commercial/Industrial | C14: m3 | D14: 173 | E14: 58 | F14: 44 | G14: 20 | H14: 54 | I14: 386 | J14: 125 | K14: 42 | L14: 25 | M14: 6 | N14: 15 | O14: 9 | P14: =SUM(D14:O14) -> 957
A15: Total Volume Billed Post Paid | C15: m3 | D15: =SUM(D11:D14) -> 6920 | E15: =SUM(E11:E14) -> 7645 | F15: =SUM(F11:F14) -> 8099 | G15: =SUM(G11:G14) -> 7187 | H15: =SUM(H11:H14) -> 8759 | I15: =SUM(I11:I14) -> 11680 | J15: =SUM(J11:J14) -> 9807 | K15: =SUM(K11:K14) -> 9605 | ... P15: =SUM(P11:P14) -> 101467
A16: REVENUE WATER - PREPAID
A17: Individuals | C17: m3 | D17: 3109 | E17: 4053 | F17: 3169.7 | G17: 3636 | H17: 4347.6 | I17: 5453.6 | J17: 4241.7 | K17: 4742 | L17: 3605.9 | M17: 3763.1 | N17: 6030 | O17: 5663 | P17: =SUM(D17:O17) -> 51814.6
A18: CWPs | C18: m3 | D18: 25.9 | E18: 90.6 | F18: 125.9 | G18: 249.1 | H18: 129 | I18: 154.5 | J18: 155.5 | K18: 108.7 | L18: 149.7 | M18: 82.7 | N18: 92.3 | O18: 100.2 | P18: =SUM(D18:O18) -> 1464.1
A19: Institutions | C19: m3 | D19: 8677 | E19: 2884.8 | F19: 1759.4 | G19: 6627.5 | H19: 6922.5 | I19: 5064.9 | J19: 2780.1 | K19: 3429.6 | L19: 1620.8 | M19: 2422.7 | N19: 1842.5 | O19: 5164.1 | P19: =SUM(D19:O19) -> 49195.9
A20: Commercial/Industrial | C20: m3 | D20: 134.1 | E20: 64.8 | F20: 147.5 | G20: 524.3 | H20: 555.2 | I20: 543 | J20: 125.9 | K20: 107.5 | L20: 79.3 | M20: 145.1 | N20: 120.9 | O20: 2215.8 | P20: =SUM(D20:O20) -> 4763.4
A21: Total Volume Prepaid | C21: m3 | D21: =SUM(D17:D20) -> 11946 | E21: =SUM(E17:E20) -> 7093.2 | F21: =SUM(F17:F20) -> 5202.5 | G21: =SUM(G17:G20) -> 11036.9 | H21: =SUM(H17:H20) -> 11954.3 | I21: =SUM(I17:I20) -> 11216 | J21: =SUM(J17:J20) -> 7303.2 | K21: =SUM(K17:K20) -> 8387.8 | ... P21: =SUM(P17:P20) -> 107238
A22: TOTAL REVENUE WATER | C22: m3 | D22: =D21+D15 -> 18866 | E22: =E21+E15 -> 14738.2 | F22: =F21+F15 -> 13301.5 | G22: =G21+G15 -> 18223.9 | H22: =H21+H15 -> 20713.3 | I22: =I21+I15 -> 22896 | J22: =J21+J15 -> 17110.2 | K22: =K21+K15 -> 17992.8 | ... P22: =P21+P15 -> 208705
A24: Non-Revenue Water (NRW) | B24: Volume | C24: m3 | D24: =D9-D22 -> 3227 | E24: =E9-E22 -> 4348.8 | F24: =F9-F22 -> 3582.5 | G24: =G9-G22 -> 11314.1 | H24: =H9-H22 -> 8291.7 | I24: =I9-I22 -> 2905 | J24: =J9-J22 -> 406.8 | K24: =K9-K22 -> 2828.2 | ... P24: =P9-P22 -> 54862
B25: Percentage | C25: % | D25: =IFERROR(D24/D9,0) -> 0.14606436 | E25: =E24/E9 -> 0.22784094 | F25: =F24/F9 -> 0.21218313 | G25: =IFERROR(G24/G9,0) -> 0.38303541 | H25: =IFERROR(H24/H9,0) -> 0.2858714 | I25: =IFERROR(I24/I9,0) -> 0.11259254 | J25: =IFERROR(J24/J9,0) -> 0.023223155 | K25: =IFERROR(K24/K9,0) -> 0.13583401 | L25: =IFERROR(L24/L9,0) -> 0.225178 | M25: =IFERROR(M24/M9,0) -> 0.27365735 | N25: =IFERROR(N24/N9,0) -> 0.3088543 | O25: =IFERROR(O24/O9,0) -> 0.072657225 | P25: =IF(P9,P24/P9,"") -> 0.20815201
A26: OPERATING EXPENSES
A27: Chemicals
A28: Chemical | B28: Rate(MK/kg)
A29: Chlorine | B29: 7400 | C29: kg | D29: 48 | E29: 46 | F29: 50 | G29: 87.5 | H29: 75 | I29: 50 | J29: 50 | K29: 50 | L29: 50 | M29: 50 | N29: 52 | O29: 50 | P29: =SUM(D29:O29) -> 658.5
C30: kg/mg litre | D30: =IFERROR(D29/(D9/1000),0) -> 2.1726339 | E30: =IFERROR(E29/(E9/1000),0) -> 2.4100173 | F30: =IFERROR(F29/(F9/1000),0) -> 2.9613836 | G30: =IFERROR(G29/(G9/1000),0) -> 2.9622859 | H30: =IFERROR(H29/(H9/1000),0) -> 2.5857611 | I30: =IFERROR(I29/(I9/1000),0) -> 1.9379094 | J30: =IFERROR(J29/(J9/1000),0) -> 2.85437 | K30: =IFERROR(K29/(K9/1000),0) -> 2.4014216 | ... P30: =IFERROR(P29/(P9/1000),0) -> 2.498416
A31: Aluminium sulphate | B31: 1900 | C31: kg | D31: 0 | E31: 0 | F31: 0 | G31: 0 | H31: 0 | I31: 0 | J31: 0 | K31: 0 | L31: 100 | M31: 200 | N31: 300 | O31: 50 | P31: =SUM(D31:O31) -> 650
C32: kg/mg litre | D32: =IFERROR(D31/(D9/1000),0) -> 0 | E32: =IFERROR(E31/(E9/1000),0) -> 0 | F32: =IFERROR(F31/(F9/1000),0) -> 0 | G32: =IFERROR(G31/(G9/1000),0) -> 0 | H32: =IFERROR(H31/(H9/1000),0) -> 0 | I32: =IFERROR(I31/(I9/1000),0) -> 0 | J32: =IFERROR(J31/(J9/1000),0) -> 0 | K32: =IFERROR(K31/(K9/1000),0) -> 0 | ... P32: =IFERROR(P31/(P9/1000),0) -> 2.4661661
A33: Soda | B33: 1900 | C33: kg | D33: 0 | E33: 0 | F33: 0 | G33: 0 | H33: 0 | I33: 0 | J33: 0 | K33: 0 | L33: 37.5 | M33: 87.5 | N33: 150 | O33: 25 | P33: =SUM(D33:O33) -> 300
C34: kg/mg litre | D34: =IFERROR(D33/(D9/1000),0) -> 0 | E34: =IFERROR(E33/(E9/1000),0) -> 0 | F34: =IFERROR(F33/(F9/1000),0) -> 0 | G34: =IFERROR(G33/(G9/1000),0) -> 0 | H34: =IFERROR(H33/(H9/1000),0) -> 0 | I34: =IFERROR(I33/(I9/1000),0) -> 0 | J34: =IFERROR(J33/(J9/1000),0) -> 0 | K34: =IFERROR(K33/(K9/1000),0) -> 0 | ... P34: =IFERROR(P33/(P9/1000),0) -> 1.1382305
A35: Algae floc | B35: =745345.16/200 -> 3726.7258 | C35: litres | D35: 0 | E35: 0 | F35: 0 | G35: 0 | H35: 0 | I35: 0 | J35: 0 | K35: 0 | L35: 0 | M35: 0 | N35: 0 | O35: 0
C36: litres/mg litre
A37: Sud floc | B37: =790318.72/200 -> 3951.5936 | C37: litres | D37: 0 | E37: 0 | F37: 0 | G37: 0 | H37: 0 | I37: 0 | J37: 0 | K37: 0 | L37: 0 | M37: 0 | N37: 0 | O37: 0 | P37: =SUM(D37:O37) -> 0
C38: litres/mg litre | D38: =IFERROR(D37/(D9/1000),0) -> 0 | E38: =IFERROR(E37/(E9/1000),0) -> 0 | F38: =IFERROR(F37/(F9/1000),0) -> 0 | G38: =IFERROR(G37/(G9/1000),0) -> 0 | H38: =IFERROR(H37/(H9/1000),0) -> 0 | I38: =IFERROR(I37/(I9/1000),0) -> 0 | J38: =IFERROR(J37/(J9/1000),0) -> 0 | K38: =IFERROR(K37/(K9/1000),0) -> 0 | ... P38: =IFERROR(P37/(P9/1000),0) -> 0
A39: Potasium permanganate | B39: 1950 | C39: kg | D39: 0 | E39: 0 | F39: 0 | G39: 0 | H39: 0 | I39: 0 | J39: 0 | K39: 0 | L39: 0 | M39: 0 | N39: 0 | O39: 0 | P39: =SUM(D39:O39) -> 0
C40: kg/mg litre | D40: =IFERROR(D39/(D9/1000),0) -> 0 | E40: =IFERROR(E39/(E9/1000),0) -> 0 | F40: =IFERROR(F39/(F9/1000),0) -> 0 | G40: =IFERROR(G39/(G9/1000),0) -> 0 | H40: =IFERROR(H39/(H9/1000),0) -> 0 | I40: =IFERROR(I39/(I9/1000),0) -> 0 | J40: =IFERROR(J39/(J9/1000),0) -> 0 | K40: =IFERROR(K39/(K9/1000),0) -> 0 | ... P40: =IFERROR(P39/(P9/1000),0) -> 0
A41: Cost of Chemicals | C41: Mk | D41: =(D29*$B29)+(D31*$B31)+(D33*$B33)+(D35*$B35)+(D37*$B37)+(D39*$B39) -> 355200 | E41: =(E29*$B29)+(E31*$B31)+(E33*$B33)+(E35*$B35)+(E37*$B37)+(E39*$B39) -> 340400 | F41: =(F29*$B29)+(F31*$B31)+(F33*$B33)+(F35*$B35)+(F37*$B37)+(F39*$B39) -> 370000 | G41: =(G29*$B29)+(G31*$B31)+(G33*$B33)+(G35*$B35)+(G37*$B37)+(G39*$B39) -> 647500 | H41: =(H29*$B29)+(H31*$B31)+(H33*$B33)+(H35*$B35)+(H37*$B37)+(H39*$B39) -> 555000 | I41: =(I29*$B29)+(I31*$B31)+(I33*$B33)+(I35*$B35)+(I37*$B37)+(I39*$B39) -> 370000 | J41: =(J29*$B29)+(J31*$B31)+(J33*$B33)+(J35*$B35)+(J37*$B37)+(J39*$B39) -> 370000 | K41: =(K29*$B29)+(K31*$B31)+(K33*$B33)+(K35*$B35)+(K37*$B37)+(K39*$B39) -> 370000 | ... O41: =(O29*$B29)+(O31*$B31)+(O33*$B33)+(O35*$B35)+(O37*$B37)+(O39*$B39) -> 512500 | P41: =SUM(D41:O41) -> 6677900
A42: Cost/vol. Produced (chemicals) | C42: Mk/m3 | D42: =IFERROR(D41/D9,0) -> 16.077491 | E42: =IFERROR(E41/E9,0) -> 17.834128 | F42: =IFERROR(F41/F9,0) -> 21.914238 | G42: =IFERROR(G41/G9,0) -> 21.920915 | H42: =IFERROR(H41/H9,0) -> 19.134632 | I42: =IFERROR(I41/I9,0) -> 14.340529 | J42: =IFERROR(J41/J9,0) -> 21.122338 | K42: =IFERROR(K41/K9,0) -> 17.77052 | ... P42: =IFERROR(P41/P9,0) -> 25.336632
A43: Power
...

Sheet Namadzi
A1: SOUTHERN REGION WATER BOARD
A3: MONTHLY REPORTS - 2024/2025
A4: ZOMBA ZONE
A5: NAMADZI SCHEME
A7: PARAMETERS | C7: UNITS | D7: APRIL | E7: MAY | F7: JUNE | G7: JULY | H7: AUGUST | I7: SEPTEMBER | J7: OCTOBER | K7: NOVEMBER | L7: DECEMBER | M7: JANUARY | N7: FEBRUARY | O7: MARCH | P7: TOTALS
A8: PRODUCTION
A9: Volume Produced | C9: m3 | D9: 4801 | E9: 5121 | F9: 13858 | G9: 5365 | H9: 10578 | I9: 5471 | J9: 5574 | K9: 10290 | L9: 4872 | M9: 9496 | N9: 4237 | O9: 3933 | P9: =SUM(D9:O9) -> 83596
A10: REVENUE WATER - POSTPAID
A11: Volume Billed Individuals | C11: m3 | D11: 1794 | E11: 2354 | F11: 2259 | G11: 2595 | H11: 2604 | I11: 2718 | J11: 2577 | K11: 2489 | L11: 2630 | M11: 1878 | N11: 1922 | O11: 1828 | P11: =SUM(D11:O11) -> 27648
A12: Volume Billed CWPs | C12: m3 | D12: 51 | E12: 59 | F12: 53 | G12: 52 | H12: 100 | I12: 80 | J12: 71 | K12: 63 | L12: 4 | M12: 4 | N12: 4 | O12: 4 | P12: =SUM(D12:O12) -> 545
A13: Volume Billed Institutions | C13: m3 | D13: 68 | E13: 56 | F13: 56 | G13: 514 | H13: 505 | I13: 454 | J13: 445 | K13: 445 | L13: 337 | M13: 190 | N13: 122 | O13: 172 | P13: =SUM(D13:O13) -> 3364
A14: Volume Billed Commercial/Industrial | C14: m3 | D14: 7 | E14: 11 | F14: 9 | G14: 10 | H14: 8 | I14: 12 | J14: 9 | K14: 16 | L14: 36 | M14: 31 | N14: 25 | O14: 8 | P14: =SUM(D14:O14) -> 182
A15: Total Volume Billed Post Paid | C15: m3 | D15: =SUM(D11:D14) -> 1920 | E15: =SUM(E11:E14) -> 2480 | F15: =SUM(F11:F14) -> 2377 | G15: =SUM(G11:G14) -> 3171 | H15: =SUM(H11:H14) -> 3217 | I15: =SUM(I11:I14) -> 3264 | J15: =SUM(J11:J14) -> 3102 | K15: =SUM(K11:K14) -> 3013 | ... P15: =SUM(P11:P14) -> 31739
A16: REVENUE WATER - PREPAID
A17: Individuals | C17: m3 | D17: 1230.7 | E17: 791 | F17: 3082.7 | G17: 797.4 | H17: 633.7 | I17: 743.7 | J17: 630.7 | K17: 595.5 | L17: 781.3 | M17: 1303.6 | N17: 561.4 | O17: 642.3 | P17: =SUM(D17:O17) -> 11794
A18: CWPs | C18: m3 | D18: 0 | E18: 0 | F18: 0 | G18: 0 | H18: 0 | I18: 0 | J18: 0 | K18: 0 | L18: 36.2 | M18: 18.8 | N18: 18.8 | O18: 3.8 | P18: =SUM(D18:O18) -> 77.6
A19: Institutions | C19: m3 | D19: 289.1 | E19: 441.3 | F19: 6081.4 | G19: 416.1 | H19: 5824.2 | I19: 987.1 | J19: 1391.1 | K19: 5536.4 | L19: 542.9 | M19: 5707.4 | N19: 520 | O19: 839.8 | P19: =SUM(D19:O19) -> 28576.8
A20: Commercial/Industrial | C20: m3 | D20: 32.9 | E20: 30.3 | F20: 43.9 | G20: 18.3 | H20: 26.9 | I20: 25.1 | J20: 35 | K20: 23.9 | L20: 24.2 | M20: 27.7 | N20: 23.1 | O20: 34.5 | P20: =SUM(D20:O20) -> 345.8
A21: Total Volume Prepaid | C21: m3 | D21: =SUM(D17:D20) -> 1552.7 | E21: =SUM(E17:E20) -> 1262.6 | F21: =SUM(F17:F20) -> 9208 | G21: =SUM(G17:G20) -> 1231.8 | H21: =SUM(H17:H20) -> 6484.8 | I21: =SUM(I17:I20) -> 1755.9 | J21: =SUM(J17:J20) -> 2056.8 | K21: =SUM(K17:K20) -> 6155.8 | ... P21: =SUM(P17:P20) -> 40794.2
A22: TOTAL REVENUE WATER | C22: m3 | D22: =D21+D15 -> 3472.7 | E22: =E21+E15 -> 3742.6 | F22: =F21+F15 -> 11585 | G22: =G21+G15 -> 4402.8 | H22: =H21+H15 -> 9701.8 | I22: =I21+I15 -> 5019.9 | J22: =J21+J15 -> 5158.8 | K22: =K21+K15 -> 9168.8 | ... P22: =P21+P15 -> 72533.2
A24: Non-Revenue Water (NRW) | B24: Volume | C24: m3 | D24: =D9-D22 -> 1328.3 | E24: =E9-E22 -> 1378.4 | F24: =F9-F22 -> 2273 | G24: =G9-G22 -> 962.2 | H24: =H9-H22 -> 876.2 | I24: =I9-I22 -> 451.1 | J24: =J9-J22 -> 415.2 | K24: =K9-K22 -> 1121.2 | ... P24: =P9-P22 -> 11062.8
B25: Percentage | C25: % | D25: =IFERROR(D24/D9,0) -> 0.27667153 | E25: =E24/E9 -> 0.26916618 | F25: =F24/F9 -> 0.16402078 | G25: =IFERROR(G24/G9,0) -> 0.17934762 | H25: =IFERROR(H24/H9,0) -> 0.082832293 | I25: =IFERROR(I24/I9,0) -> 0.082452934 | J25: =IFERROR(J24/J9,0) -> 0.074488698 | K25: =IFERROR(K24/K9,0) -> 0.10896016 | L25: =IFERROR(L24/L9,0) -> 0.098604269 | M25: =IFERROR(M24/M9,0) -> 0.035330666 | N25: =IFERROR(N24/N9,0) -> 0.2456219 | O25: =IFERROR(O24/O9,0) -> 0.10185609 | P25: =IF(P9,P24/P9,"") -> 0.13233648
A26: OPERATING EXPENSES
A27: Chemicals
A28: Chemical | B28: Rate(MK/kg)
A29: Chlorine | B29: 7400 | C29: kg | D29: 4 | E29: 4 | F29: 5 | G29: 3.25 | H29: 3.5 | I29: 4.25 | J29: 3.25 | K29: 5 | L29: 5 | M29: 5 | N29: 5 | O29: 5 | P29: =SUM(D29:O29) -> 52.25
C30: kg/mg litre | D30: =IFERROR(D29/(D9/1000),0) -> 0.83315976 | E30: =IFERROR(E29/(E9/1000),0) -> 0.78109744 | F30: =IFERROR(F29/(F9/1000),0) -> 0.36080242 | G30: =IFERROR(G29/(G9/1000),0) -> 0.60577819 | H30: =IFERROR(H29/(H9/1000),0) -> 0.3308754 | I30: =IFERROR(I29/(I9/1000),0) -> 0.77682325 | J30: =IFERROR(J29/(J9/1000),0) -> 0.58306423 | K30: =IFERROR(K29/(K9/1000),0) -> 0.48590865 | ... P30: =IFERROR(P29/(P9/1000),0) -> 0.62502991
A31: Aluminium sulphate | B31: 1900 | C31: kg | D31: 0 | E31: 0 | F31: 0 | G31: 0 | H31: 0 | I31: 0 | J31: 0 | K31: 0 | L31: 0 | M31: 0 | N31: 0 | O31: 0 | P31: =SUM(D31:O31) -> 0
C32: kg/mg litre | D32: =IFERROR(D31/(D9/1000),0) -> 0 | E32: =IFERROR(E31/(E9/1000),0) -> 0 | F32: =IFERROR(F31/(F9/1000),0) -> 0 | G32: =IFERROR(G31/(G9/1000),0) -> 0 | H32: =IFERROR(H31/(H9/1000),0) -> 0 | I32: =IFERROR(I31/(I9/1000),0) -> 0 | J32: =IFERROR(J31/(J9/1000),0) -> 0 | K32: =IFERROR(K31/(K9/1000),0) -> 0 | ... P32: =IFERROR(P31/(P9/1000),0) -> 0
A33: Soda | B33: 1900 | C33: kg | D33: 0 | E33: 0 | F33: 0 | G33: 0 | H33: 0 | I33: 0 | J33: 0 | K33: 0 | L33: 0 | M33: 0 | N33: 0 | O33: 0 | P33: =SUM(D33:O33) -> 0
C34: kg/mg litre | D34: =IFERROR(D33/(D9/1000),0) -> 0 | E34: =IFERROR(E33/(E9/1000),0) -> 0 | F34: =IFERROR(F33/(F9/1000),0) -> 0 | G34: =IFERROR(G33/(G9/1000),0) -> 0 | H34: =IFERROR(H33/(H9/1000),0) -> 0 | I34: =IFERROR(I33/(I9/1000),0) -> 0 | J34: =IFERROR(J33/(J9/1000),0) -> 0 | K34: =IFERROR(K33/(K9/1000),0) -> 0 | ... P34: =IFERROR(P33/(P9/1000),0) -> 0
A35: Algae floc | B35: =745345.16/200 -> 3726.7258 | C35: litres | D35: 0 | E35: 0 | F35: 0 | G35: 0 | H35: 0 | I35: 0 | J35: 0 | K35: 0 | L35: 0 | M35: 0 | N35: 0 | O35: 0
C36: litres/mg litre
A37: Sud floc | B37: =790318.72/200 -> 3951.5936 | C37: litres | D37: 0 | E37: 0 | F37: 0 | G37: 0 | H37: 0 | I37: 0 | J37: 0 | K37: 0 | L37: 0 | M37: 0 | N37: 0 | O37: 0 | P37: =SUM(D37:O37) -> 0
C38: litres/mg litre | D38: =IFERROR(D37/(D9/1000),0) -> 0 | E38: =IFERROR(E37/(E9/1000),0) -> 0 | F38: =IFERROR(F37/(F9/1000),0) -> 0 | G38: =IFERROR(G37/(G9/1000),0) -> 0 | H38: =IFERROR(H37/(H9/1000),0) -> 0 | I38: =IFERROR(I37/(I9/1000),0) -> 0 | J38: =IFERROR(J37/(J9/1000),0) -> 0 | K38: =IFERROR(K37/(K9/1000),0) -> 0 | ... P38: =IFERROR(P37/(P9/1000),0) -> 0
A39: Potasium permanganate | B39: 1950 | C39: kg | D39: 0 | E39: 0 | F39: 0 | G39: 0 | H39: 0 | I39: 0 | J39: 0 | K39: 0 | L39: 0 | M39: 0 | N39: 0 | O39: 0 | P39: =SUM(D39:O39) -> 0
C40: kg/mg litre | D40: =IFERROR(D39/(D9/1000),0) -> 0 | E40: =IFERROR(E39/(E9/1000),0) -> 0 | F40: =IFERROR(F39/(F9/1000),0) -> 0 | G40: =IFERROR(G39/(G9/1000),0) -> 0 | H40: =IFERROR(H39/(H9/1000),0) -> 0 | I40: =IFERROR(I39/(I9/1000),0) -> 0 | J40: =IFERROR(J39/(J9/1000),0) -> 0 | K40: =IFERROR(K39/(K9/1000),0) -> 0 | ... P40: =IFERROR(P39/(P9/1000),0) -> 0
A41: Cost of Chemicals | C41: Mk | D41: =(D29*$B29)+(D31*$B31)+(D33*$B33)+(D35*$B35)+(D37*$B37)+(D39*$B39) -> 29600 | E41: =(E29*$B29)+(E31*$B31)+(E33*$B33)+(E35*$B35)+(E37*$B37)+(E39*$B39) -> 29600 | F41: =(F29*$B29)+(F31*$B31)+(F33*$B33)+(F35*$B35)+(F37*$B37)+(F39*$B39) -> 37000 | G41: =(G29*$B29)+(G31*$B31)+(G33*$B33)+(G35*$B35)+(G37*$B37)+(G39*$B39) -> 24050 | H41: =(H29*$B29)+(H31*$B31)+(H33*$B33)+(H35*$B35)+(H37*$B37)+(H39*$B39) -> 25900 | I41: =(I29*$B29)+(I31*$B31)+(I33*$B33)+(I35*$B35)+(I37*$B37)+(I39*$B39) -> 31450 | J41: =(J29*$B29)+(J31*$B31)+(J33*$B33)+(J35*$B35)+(J37*$B37)+(J39*$B39) -> 24050 | K41: =(K29*$B29)+(K31*$B31)+(K33*$B33)+(K35*$B35)+(K37*$B37)+(K39*$B39) -> 37000 | ... O41: =(O29*$B29)+(O31*$B31)+(O33*$B33)+(O35*$B35)+(O37*$B37)+(O39*$B39) -> 37000 | P41: =SUM(D41:O41) -> 386650
A42: Cost/vol. Produced (chemicals) | C42: Mk/m3 | D42: =IFERROR(D41/D9,0) -> 6.1653822 | E42: =IFERROR(E41/E9,0) -> 5.7801211 | F42: =IFERROR(F41/F9,0) -> 2.6699379 | G42: =IFERROR(G41/G9,0) -> 4.4827586 | H42: =IFERROR(H41/H9,0) -> 2.448478 | I42: =IFERROR(I41/I9,0) -> 5.748492 | J42: =IFERROR(J41/J9,0) -> 4.3146753 | K42: =IFERROR(K41/K9,0) -> 3.595724 | ... P42: =IFERROR(P41/P9,0) -> 4.6252213
A43: Power
...

Sheet Neno
A1: SOUTHERN REGION WATER BOARD
A3: MONTHLY REPORTS - 2024/2025
A4: ZOMBA ZONE
A5: NENO SCHEME
A7: PARAMETERS | C7: UNITS | D7: APRIL | E7: MAY | F7: JUNE | G7: JULY | H7: AUGUST | I7: SEPTEMBER | J7: OCTOBER | K7: NOVEMBER | L7: DECEMBER | M7: JANUARY | N7: FEBRUARY | O7: MARCH | P7: TOTALS
A8: PRODUCTION
A9: Volume Produced | C9: m3 | D9: 7850 | E9: 7498 | F9: 6853 | G9: 8661 | H9: 6451 | I9: 4841 | J9: 5051 | K9: 4845 | L9: 4765 | M9: 9861 | N9: 5335 | O9: 4682 | P9: =SUM(D9:O9) -> 76693
A10: REVENUE WATER - POSTPAID
A11: Volume Billed Individuals | C11: m3 | D11: 3973 | E11: 4298 | F11: 4278 | G11: 4672 | H11: 4633 | I11: 3337 | J11: 2884 | K11: 3209 | L11: 3360 | M11: 3725 | N11: 3938 | O11: 3242 | P11: =SUM(D11:O11) -> 45549
A12: Volume Billed CWPs | C12: m3 | D12: 30 | E12: 78 | F12: 41 | G12: 40 | H12: 34 | I12: 23 | J12: 23 | K12: 16 | L12: 29 | M12: 27 | N12: 20 | O12: 5 | P12: =SUM(D12:O12) -> 366
A13: Volume Billed Institutions | C13: m3 | D13: 87 | E13: 72 | F13: 55 | G13: 76 | H13: 102 | I13: 77 | J13: 62 | K13: 81 | L13: 105 | M13: 86 | N13: 91 | O13: 64 | P13: =SUM(D13:O13) -> 958
A14: Volume Billed Commercial/Industrial | C14: m3 | D14: 136 | E14: 182 | F14: 117 | G14: 112 | H14: 84 | I14: 71 | J14: 48 | K14: 65 | L14: 70 | M14: 67 | N14: 126 | O14: 105 | P14: =SUM(D14:O14) -> 1183
A15: Total Volume Billed Post Paid | C15: m3 | D15: =SUM(D11:D14) -> 4226 | E15: =SUM(E11:E14) -> 4630 | F15: =SUM(F11:F14) -> 4491 | G15: =SUM(G11:G14) -> 4900 | H15: =SUM(H11:H14) -> 4853 | I15: =SUM(I11:I14) -> 3508 | J15: =SUM(J11:J14) -> 3017 | K15: =SUM(K11:K14) -> 3371 | ... P15: =SUM(P11:P14) -> 48056
A16: REVENUE WATER - PREPAID
A17: Individuals | C17: m3 | D17: 895.7 | E17: 770.9 | F17: 658.9 | G17: 1942.2 | H17: 734.4 | I17: 501.6 | J17: 321.3 | K17: 526 | L17: 730.4 | M17: 648.3 | N17: 636.5 | O17: 579.1 | P17: =SUM(D17:O17) -> 8945.3
A18: CWPs | C18: m3 | D18: 0 | E18: 0 | F18: 0 | G18: 0 | H18: 0 | I18: 0 | J18: 0 | K18: 0 | L18: 0 | M18: 0 | N18: 0 | O18: 0 | P18: =SUM(D18:O18) -> 0
A19: Institutions | C19: m3 | D19: 297.7 | E19: 127.7 | F19: 921.9 | G19: 888 | H19: 367.6 | I19: 98 | J19: 723.8 | K19: 69.7 | L19: 72.1 | M19: 4676 | N19: 93.1 | O19: 316.7 | P19: =SUM(D19:O19) -> 8652.3
A20: Commercial/Industrial | C20: m3 | D20: 51.2 | E20: 100.8 | F20: 65 | G20: 264.9 | H20: 53.3 | I20: 56.6 | J20: 68.2 | K20: 87.9 | L20: 76.6 | M20: 73.2 | N20: 76.7 | O20: 59.6 | P20: =SUM(D20:O20) -> 1034
A21: Total Volume Prepaid | C21: m3 | D21: =SUM(D17:D20) -> 1244.6 | E21: =SUM(E17:E20) -> 999.4 | F21: =SUM(F17:F20) -> 1645.8 | G21: =SUM(G17:G20) -> 3095.1 | H21: =SUM(H17:H20) -> 1155.3 | I21: =SUM(I17:I20) -> 656.2 | J21: =SUM(J17:J20) -> 1113.3 | K21: =SUM(K17:K20) -> 683.6 | ... P21: =SUM(P17:P20) -> 18631.6
A22: TOTAL REVENUE WATER | C22: m3 | D22: =D21+D15 -> 5470.6 | E22: =E21+E15 -> 5629.4 | F22: =F21+F15 -> 6136.8 | G22: =G21+G15 -> 7995.1 | H22: =H21+H15 -> 6008.3 | I22: =I21+I15 -> 4164.2 | J22: =J21+J15 -> 4130.3 | K22: =K21+K15 -> 4054.6 | ... P22: =P21+P15 -> 66687.6
A24: Non-Revenue Water (NRW) | B24: Volume | C24: m3 | D24: =D9-D22 -> 2379.4 | E24: =E9-E22 -> 1868.6 | F24: =F9-F22 -> 716.2 | G24: =G9-G22 -> 665.9 | H24: =H9-H22 -> 442.7 | I24: =I9-I22 -> 676.8 | J24: =J9-J22 -> 920.7 | K24: =K9-K22 -> 790.4 | ... P24: =P9-P22 -> 10005.4
B25: Percentage | C25: % | D25: =IFERROR(D24/D9,0) -> 0.30310828 | E25: =E24/E9 -> 0.24921312 | F25: =F24/F9 -> 0.10450897 | G25: =IFERROR(G24/G9,0) -> 0.076884886 | H25: =IFERROR(H24/H9,0) -> 0.068625019 | I25: =IFERROR(I24/I9,0) -> 0.13980583 | J25: =IFERROR(J24/J9,0) -> 0.18228074 | K25: =IFERROR(K24/K9,0) -> 0.16313725 | L25: =IFERROR(L24/L9,0) -> 0.067555089 | M25: =IFERROR(M24/M9,0) -> 0.056637258 | N25: =IFERROR(N24/N9,0) -> 0.066298032 | O25: =IFERROR(O24/O9,0) -> 0.066339171 | P25: =IF(P9,P24/P9,"") -> 0.13046041
A26: OPERATING EXPENSES
A27: Chemicals
A28: Chemical | B28: Rate(MK/kg)
A29: Chlorine | B29: 7400 | C29: kg | D29: 10 | E29: 10 | F29: 9 | G29: 15 | H29: 15 | I29: 12 | J29: 15 | K29: 8 | L29: 10 | M29: 11 | N29: 13 | O29: 10 | P29: =SUM(D29:O29) -> 138
C30: kg/mg litre | D30: =IFERROR(D29/(D9/1000),0) -> 1.2738854 | E30: =IFERROR(E29/(E9/1000),0) -> 1.333689 | F30: =IFERROR(F29/(F9/1000),0) -> 1.3132934 | G30: =IFERROR(G29/(G9/1000),0) -> 1.7319016 | H30: =IFERROR(H29/(H9/1000),0) -> 2.3252209 | I30: =IFERROR(I29/(I9/1000),0) -> 2.4788267 | J30: =IFERROR(J29/(J9/1000),0) -> 2.969709 | K30: =IFERROR(K29/(K9/1000),0) -> 1.6511868 | ... P30: =IFERROR(P29/(P9/1000),0) -> 1.799382
A31: Aluminium sulphate | B31: 1900 | C31: kg | D31: 0 | E31: 0 | F31: 0 | G31: 0 | H31: 0 | I31: 0 | J31: 0 | K31: 0 | L31: 0 | M31: 0 | N31: 0 | O31: 0 | P31: =SUM(D31:O31) -> 0
C32: kg/mg litre | D32: =IFERROR(D31/(D9/1000),0) -> 0 | E32: =IFERROR(E31/(E9/1000),0) -> 0 | F32: =IFERROR(F31/(F9/1000),0) -> 0 | G32: =IFERROR(G31/(G9/1000),0) -> 0 | H32: =IFERROR(H31/(H9/1000),0) -> 0 | I32: =IFERROR(I31/(I9/1000),0) -> 0 | J32: =IFERROR(J31/(J9/1000),0) -> 0 | K32: =IFERROR(K31/(K9/1000),0) -> 0 | ... P32: =IFERROR(P31/(P9/1000),0) -> 0
A33: Soda | B33: 1900 | C33: kg | D33: 0 | E33: 0 | F33: 0 | G33: 0 | H33: 0 | I33: 0 | J33: 0 | K33: 0 | L33: 0 | M33: 0 | N33: 0 | O33: 0 | P33: =SUM(D33:O33) -> 0
C34: kg/mg litre | D34: =IFERROR(D33/(D9/1000),0) -> 0 | E34: =IFERROR(E33/(E9/1000),0) -> 0 | F34: =IFERROR(F33/(F9/1000),0) -> 0 | G34: =IFERROR(G33/(G9/1000),0) -> 0 | H34: =IFERROR(H33/(H9/1000),0) -> 0 | I34: =IFERROR(I33/(I9/1000),0) -> 0 | J34: =IFERROR(J33/(J9/1000),0) -> 0 | K34: =IFERROR(K33/(K9/1000),0) -> 0 | ... P34: =IFERROR(P33/(P9/1000),0) -> 0
A35: Algae floc | B35: =745345.16/200 -> 3726.7258 | C35: litres | D35: 0 | E35: 0 | F35: 0 | G35: 0 | H35: 0 | I35: 0 | J35: 0 | K35: 0 | L35: 0 | M35: 0 | N35: 0 | O35: 0
C36: litres/mg litre
A37: Sud floc | B37: =790318.72/200 -> 3951.5936 | C37: litres | D37: 0 | E37: 0 | F37: 0 | G37: 0 | H37: 0 | I37: 0 | J37: 0 | K37: 0 | L37: 0 | M37: 0 | N37: 0 | O37: 0 | P37: =SUM(D37:O37) -> 0
C38: litres/mg litre | D38: =IFERROR(D37/(D9/1000),0) -> 0 | E38: =IFERROR(E37/(E9/1000),0) -> 0 | F38: =IFERROR(F37/(F9/1000),0) -> 0 | G38: =IFERROR(G37/(G9/1000),0) -> 0 | H38: =IFERROR(H37/(H9/1000),0) -> 0 | I38: =IFERROR(I37/(I9/1000),0) -> 0 | J38: =IFERROR(J37/(J9/1000),0) -> 0 | K38: =IFERROR(K37/(K9/1000),0) -> 0 | ... P38: =IFERROR(P37/(P9/1000),0) -> 0
A39: Potasium permanganate | B39: 1950 | C39: kg | D39: 0 | E39: 0 | F39: 0 | G39: 0 | H39: 0 | I39: 0 | J39: 0 | K39: 0 | L39: 0 | M39: 0 | N39: 0 | O39: 0 | P39: =SUM(D39:O39) -> 0
C40: kg/mg litre | D40: =IFERROR(D39/(D9/1000),0) -> 0 | E40: =IFERROR(E39/(E9/1000),0) -> 0 | F40: =IFERROR(F39/(F9/1000),0) -> 0 | G40: =IFERROR(G39/(G9/1000),0) -> 0 | H40: =IFERROR(H39/(H9/1000),0) -> 0 | I40: =IFERROR(I39/(I9/1000),0) -> 0 | J40: =IFERROR(J39/(J9/1000),0) -> 0 | K40: =IFERROR(K39/(K9/1000),0) -> 0 | ... P40: =IFERROR(P39/(P9/1000),0) -> 0
A41: Cost of Chemicals | C41: Mk | D41: =(D29*$B29)+(D31*$B31)+(D33*$B33)+(D35*$B35)+(D37*$B37)+(D39*$B39) -> 74000 | E41: =(E29*$B29)+(E31*$B31)+(E33*$B33)+(E35*$B35)+(E37*$B37)+(E39*$B39) -> 74000 | F41: =(F29*$B29)+(F31*$B31)+(F33*$B33)+(F35*$B35)+(F37*$B37)+(F39*$B39) -> 66600 | G41: =(G29*$B29)+(G31*$B31)+(G33*$B33)+(G35*$B35)+(G37*$B37)+(G39*$B39) -> 111000 | H41: =(H29*$B29)+(H31*$B31)+(H33*$B33)+(H35*$B35)+(H37*$B37)+(H39*$B39) -> 111000 | I41: =(I29*$B29)+(I31*$B31)+(I33*$B33)+(I35*$B35)+(I37*$B37)+(I39*$B39) -> 88800 | J41: =(J29*$B29)+(J31*$B31)+(J33*$B33)+(J35*$B35)+(J37*$B37)+(J39*$B39) -> 111000 | K41: =(K29*$B29)+(K31*$B31)+(K33*$B33)+(K35*$B35)+(K37*$B37)+(K39*$B39) -> 59200 | ... O41: =(O29*$B29)+(O31*$B31)+(O33*$B33)+(O35*$B35)+(O37*$B37)+(O39*$B39) -> 74000 | P41: =SUM(D41:O41) -> 1021200
A42: Cost/vol. Produced (chemicals) | C42: Mk/m3 | D42: =IFERROR(D41/D9,0) -> 9.4267516 | E42: =IFERROR(E41/E9,0) -> 9.8692985 | F42: =IFERROR(F41/F9,0) -> 9.7183715 | G42: =IFERROR(G41/G9,0) -> 12.816072 | H42: =IFERROR(H41/H9,0) -> 17.206635 | I42: =IFERROR(I41/I9,0) -> 18.343317 | J42: =IFERROR(J41/J9,0) -> 21.975846 | K42: =IFERROR(K41/K9,0) -> 12.218782 | ... P42: =IFERROR(P41/P9,0) -> 13.315426
A43: Power
...

Sheet Kuchawe
A1: SOUTHERN REGION WATER BOARD
A3: MONTHLY REPORTS - 2024/2025
A4: ZOMBA ZONE
A5: KUCHAWE SCHEME
A7: PARAMETERS | C7: UNITS | D7: APRIL | E7: MAY | F7: JUNE | G7: JULY | H7: AUGUST | I7: SEPTEMBER | J7: OCTOBER | K7: NOVEMBER | L7: DECEMBER | M7: JANUARY | N7: FEBRUARY | O7: MARCH | P7: TOTALS
A8: PRODUCTION
A9: Volume Produced | C9: m3 | D9: 3228 | E9: 4810 | F9: 4002 | G9: 4710 | H9: 4969 | I9: 5109 | J9: 4481 | K9: 3635 | L9: 4202 | M9: 3180 | N9: 3216 | O9: 4041 | P9: =SUM(D9:O9) -> 49583
A10: REVENUE WATER - POSTPAID
A11: Volume Billed Individuals | C11: m3 | D11: 546 | E11: 559 | F11: 616 | G11: 589 | H11: 823 | I11: 712 | J11: 555 | K11: 416 | L11: 485 | M11: 358 | N11: 391 | O11: 432 | P11: =SUM(D11:O11) -> 6482
A12: Volume Billed CWPs | C12: m3 | D12: 26 | E12: 18 | F12: 18 | G12: 13 | H12: 16 | I12: 3 | J12: 3 | K12: 4 | L12: 0 | M12: 0 | N12: 0 | O12: 0 | P12: =SUM(D12:O12) -> 101
A13: Volume Billed Institutions | C13: m3 | D13: 368 | E13: 787 | F13: 394 | G13: 503 | H13: 265 | I13: 432 | J13: 497 | K13: 157 | L13: 151 | M13: 149 | N13: 112 | O13: 119 | P13: =SUM(D13:O13) -> 3934
A14: Volume Billed Commercial/Industrial | C14: m3 | D14: 1 | E14: 108 | F14: 60 | G14: 53 | H14: 64 | I14: 72 | J14: 30 | K14: 9 | L14: 18 | M14: 8 | N14: 7 | O14: 11 | P14: =SUM(D14:O14) -> 441
A15: Total Volume Billed Post Paid | C15: m3 | D15: =SUM(D11:D14) -> 941 | E15: =SUM(E11:E14) -> 1472 | F15: =SUM(F11:F14) -> 1088 | G15: =SUM(G11:G14) -> 1158 | H15: =SUM(H11:H14) -> 1168 | I15: =SUM(I11:I14) -> 1219 | J15: =SUM(J11:J14) -> 1085 | K15: =SUM(K11:K14) -> 586 | ... P15: =SUM(P11:P14) -> 10958
A16: REVENUE WATER - PREPAID
A17: Individuals | C17: m3 | D17: 234.3 | E17: 324.4 | F17: 204.8 | G17: 439.1 | H17: 479.1 | I17: 311.7 | J17: 399.6 | K17: 314.9 | L17: 180.6 | M17: 232.2 | N17: 94.4 | O17: 161.5 | P17: =SUM(D17:O17) -> 3376.6
A18: CWPs | C18: m3 | D18: 259 | E18: 319.6 | F18: 265.1 | G18: 397.3 | H18: 436.1 | I18: 206.5 | J18: 110.6 | K18: 187.9 | L18: 306.1 | M18: 142.4 | N18: 81.9 | O18: 188.4 | P18: =SUM(D18:O18) -> 2900.9
A19: Institutions | C19: m3 | D19: 0.5 | E19: 39.4 | F19: 18.9 | G19: 943.2 | H19: 92 | I19: 136.6 | J19: 25.5 | K19: 27.9 | L19: 62.7 | M19: 21.8 | N19: 32.7 | O19: 23.2 | P19: =SUM(D19:O19) -> 1424.4
A20: Commercial/Industrial | C20: m3 | D20: 748 | E20: 1210 | F20: 863.3 | G20: 1221.7 | H20: 1422.3 | I20: 2827.6 | J20: 1340.8 | K20: 2200.2 | L20: 1767.2 | M20: 1959.5 | N20: 1911.6 | O20: 1559.3 | P20: =SUM(D20:O20) -> 19031.5
A21: Total Volume Prepaid | C21: m3 | D21: =SUM(D17:D20) -> 1241.8 | E21: =SUM(E17:E20) -> 1893.4 | F21: =SUM(F17:F20) -> 1352.1 | G21: =SUM(G17:G20) -> 3001.3 | H21: =SUM(H17:H20) -> 2429.5 | I21: =SUM(I17:I20) -> 3482.4 | J21: =SUM(J17:J20) -> 1876.5 | K21: =SUM(K17:K20) -> 2730.9 | ... P21: =SUM(P17:P20) -> 26733.4
A22: TOTAL REVENUE WATER | C22: m3 | D22: =D21+D15 -> 2182.8 | E22: =E21+E15 -> 3365.4 | F22: =F21+F15 -> 2440.1 | G22: =G21+G15 -> 4159.3 | H22: =H21+H15 -> 3597.5 | I22: =I21+I15 -> 4701.4 | J22: =J21+J15 -> 2961.5 | K22: =K21+K15 -> 3316.9 | ... P22: =P21+P15 -> 37691.4
A24: Non-Revenue Water (NRW) | B24: Volume | C24: m3 | D24: =D9-D22 -> 1045.2 | E24: =E9-E22 -> 1444.6 | F24: =F9-F22 -> 1561.9 | G24: =G9-G22 -> 550.7 | H24: =H9-H22 -> 1371.5 | I24: =I9-I22 -> 407.6 | J24: =J9-J22 -> 1519.5 | K24: =K9-K22 -> 318.1 | ... P24: =P9-P22 -> 11891.6
B25: Percentage | C25: % | D25: =IFERROR(D24/D9,0) -> 0.32379182 | E25: =E24/E9 -> 0.30033264 | F25: =F24/F9 -> 0.39027986 | G25: =IFERROR(G24/G9,0) -> 0.11692144 | H25: =IFERROR(H24/H9,0) -> 0.27601127 | I25: =IFERROR(I24/I9,0) -> 0.079780779 | J25: =IFERROR(J24/J9,0) -> 0.33909842 | K25: =IFERROR(K24/K9,0) -> 0.087510316 | L25: =IFERROR(L24/L9,0) -> 0.29305093 | M25: =IFERROR(M24/M9,0) -> 0.097201258 | N25: =IFERROR(N24/N9,0) -> 0.18202736 | O25: =IFERROR(O24/O9,0) -> 0.38272705 | P25: =IF(P9,P24/P9,"") -> 0.2398322
A26: OPERATING EXPENSES
A27: Chemicals
A28: Chemical | B28: Rate(MK/kg)
A29: Chlorine | B29: 7400 | C29: kg | D29: 18 | E29: 16 | F29: 15 | G29: 17 | H29: 18 | I29: 15 | J29: 18 | K29: 15 | L29: 16 | M29: 15 | N29: 12 | O29: 16 | P29: =SUM(D29:O29) -> 191
C30: kg/mg litre | D30: =IFERROR(D29/(D9/1000),0) -> 5.5762082 | E30: =IFERROR(E29/(E9/1000),0) -> 3.3264033 | F30: =IFERROR(F29/(F9/1000),0) -> 3.7481259 | G30: =IFERROR(G29/(G9/1000),0) -> 3.6093418 | H30: =IFERROR(H29/(H9/1000),0) -> 3.6224592 | I30: =IFERROR(I29/(I9/1000),0) -> 2.9359953 | J30: =IFERROR(J29/(J9/1000),0) -> 4.0169605 | K30: =IFERROR(K29/(K9/1000),0) -> 4.1265475 | ... P30: =IFERROR(P29/(P9/1000),0) -> 3.8521267
A31: Aluminium sulphate | B31: 1900 | C31: kg | D31: 0 | E31: 5 | F31: 3 | G31: 5 | H31: 6 | I31: 3 | J31: 6 | K31: 9 | L31: 18 | M31: 13 | N31: 5 | O31: 0 | P31: =SUM(D31:O31) -> 73
C32: kg/mg litre | D32: =IFERROR(D31/(D9/1000),0) -> 0 | E32: =IFERROR(E31/(E9/1000),0) -> 1.039501 | F32: =IFERROR(F31/(F9/1000),0) -> 0.74962519 | G32: =IFERROR(G31/(G9/1000),0) -> 1.0615711 | H32: =IFERROR(H31/(H9/1000),0) -> 1.2074864 | I32: =IFERROR(I31/(I9/1000),0) -> 0.58719906 | J32: =IFERROR(J31/(J9/1000),0) -> 1.3389868 | K32: =IFERROR(K31/(K9/1000),0) -> 2.4759285 | ... P32: =IFERROR(P31/(P9/1000),0) -> 1.4722788
A33: Soda | B33: 1900 | C33: kg | D33: 0 | E33: 3 | F33: 1 | G33: 2 | H33: 4 | I33: 2 | J33: 4 | K33: 5 | L33: 16 | M33: 12 | N33: 5 | O33: 0 | P33: =SUM(D33:O33) -> 54
C34: kg/mg litre | D34: =IFERROR(D33/(D9/1000),0) -> 0 | E34: =IFERROR(E33/(E9/1000),0) -> 0.62370062 | F34: =IFERROR(F33/(F9/1000),0) -> 0.24987506 | G34: =IFERROR(G33/(G9/1000),0) -> 0.42462845 | H34: =IFERROR(H33/(H9/1000),0) -> 0.80499094 | I34: =IFERROR(I33/(I9/1000),0) -> 0.39146604 | J34: =IFERROR(J33/(J9/1000),0) -> 0.89265789 | K34: =IFERROR(K33/(K9/1000),0) -> 1.3755158 | ... P34: =IFERROR(P33/(P9/1000),0) -> 1.089083
A35: Algae floc | B35: =745345.16/200 -> 3726.7258 | C35: litres | D35: 0 | E35: 0 | F35: 0 | G35: 0 | H35: 0 | I35: 0 | J35: 0 | K35: 0 | L35: 0 | M35: 0 | N35: 0 | O35: 0
C36: litres/mg litre
A37: Sud floc | B37: =790318.72/200 -> 3951.5936 | C37: litres | D37: 0 | E37: 0 | F37: 0 | G37: 0 | H37: 0 | I37: 0 | J37: 0 | K37: 0 | L37: 0 | M37: 0 | N37: 0 | O37: 0 | P37: =SUM(D37:O37) -> 0
C38: litres/mg litre | D38: =IFERROR(D37/(D9/1000),0) -> 0 | E38: =IFERROR(E37/(E9/1000),0) -> 0 | F38: =IFERROR(F37/(F9/1000),0) -> 0 | G38: =IFERROR(G37/(G9/1000),0) -> 0 | H38: =IFERROR(H37/(H9/1000),0) -> 0 | I38: =IFERROR(I37/(I9/1000),0) -> 0 | J38: =IFERROR(J37/(J9/1000),0) -> 0 | K38: =IFERROR(K37/(K9/1000),0) -> 0 | ... P38: =IFERROR(P37/(P9/1000),0) -> 0
A39: Potasium permanganate | B39: 1950 | C39: kg | D39: 0 | E39: 0 | F39: 0 | G39: 0 | H39: 0 | I39: 0 | J39: 0 | K39: 0 | L39: 0 | M39: 0 | N39: 0 | O39: 0 | P39: =SUM(D39:O39) -> 0
C40: kg/mg litre | D40: =IFERROR(D39/(D9/1000),0) -> 0 | E40: =IFERROR(E39/(E9/1000),0) -> 0 | F40: =IFERROR(F39/(F9/1000),0) -> 0 | G40: =IFERROR(G39/(G9/1000),0) -> 0 | H40: =IFERROR(H39/(H9/1000),0) -> 0 | I40: =IFERROR(I39/(I9/1000),0) -> 0 | J40: =IFERROR(J39/(J9/1000),0) -> 0 | K40: =IFERROR(K39/(K9/1000),0) -> 0 | ... P40: =IFERROR(P39/(P9/1000),0) -> 0
A41: Cost of Chemicals | C41: Mk | D41: =(D29*$B29)+(D31*$B31)+(D33*$B33)+(D35*$B35)+(D37*$B37)+(D39*$B39) -> 133200 | E41: =(E29*$B29)+(E31*$B31)+(E33*$B33)+(E35*$B35)+(E37*$B37)+(E39*$B39) -> 133600 | F41: =(F29*$B29)+(F31*$B31)+(F33*$B33)+(F35*$B35)+(F37*$B37)+(F39*$B39) -> 118600 | G41: =(G29*$B29)+(G31*$B31)+(G33*$B33)+(G35*$B35)+(G37*$B37)+(G39*$B39) -> 139100 | H41: =(H29*$B29)+(H31*$B31)+(H33*$B33)+(H35*$B35)+(H37*$B37)+(H39*$B39) -> 152200 | I41: =(I29*$B29)+(I31*$B31)+(I33*$B33)+(I35*$B35)+(I37*$B37)+(I39*$B39) -> 120500 | J41: =(J29*$B29)+(J31*$B31)+(J33*$B33)+(J35*$B35)+(J37*$B37)+(J39*$B39) -> 152200 | K41: =(K29*$B29)+(K31*$B31)+(K33*$B33)+(K35*$B35)+(K37*$B37)+(K39*$B39) -> 137600 | ... O41: =(O29*$B29)+(O31*$B31)+(O33*$B33)+(O35*$B35)+(O37*$B37)+(O39*$B39) -> 118400 | P41: =SUM(D41:O41) -> 1654700
A42: Cost/vol. Produced (chemicals) | C42: Mk/m3 | D42: =IFERROR(D41/D9,0) -> 41.263941 | E42: =IFERROR(E41/E9,0) -> 27.775468 | F42: =IFERROR(F41/F9,0) -> 29.635182 | G42: =IFERROR(G41/G9,0) -> 29.532909 | H42: =IFERROR(H41/H9,0) -> 30.629905 | I42: =IFERROR(I41/I9,0) -> 23.585829 | J42: =IFERROR(J41/J9,0) -> 33.965633 | K42: =IFERROR(K41/K9,0) -> 37.854195 | ... P42: =IFERROR(P41/P9,0) -> 33.372325
A43: Power
...

Sheet Chiradzulu
A1: SOUTHERN REGION WATER BOARD
A3: MONTHLY REPORTS - 2024/2025
A4: ZOMBA ZONE
A5: CHIRADZULU SCHEME
A7: PARAMETERS | C7: UNITS | D7: APRIL | E7: MAY | F7: JUNE | G7: JULY | H7: AUGUST | I7: SEPTEMBER | J7: OCTOBER | K7: NOVEMBER | L7: DECEMBER | M7: JANUARY | N7: FEBRUARY | O7: MARCH | P7: TOTALS
A8: PRODUCTION
A9: Volume Produced | C9: m3 | D9: 2480 | E9: 2258 | F9: 7389 | G9: 1944 | H9: 1660 | I9: 1556 | J9: 1442 | K9: 1140 | L9: 1021 | M9: 2544 | N9: 2024 | O9: 2702 | P9: =SUM(D9:O9) -> 28160
A10: REVENUE WATER - POSTPAID
A11: Volume Billed Individuals | C11: m3 | D11: 1152 | E11: 1160 | F11: 1218 | G11: 979 | H11: 867 | I11: 890 | J11: 780 | K11: 580 | L11: 617 | M11: 637 | N11: 1143 | O11: 325 | P11: =SUM(D11:O11) -> 10348
A12: Volume Billed CWPs | C12: m3 | D12: 0 | E12: 0 | F12: 0 | G12: 0 | H12: 0 | I12: 0 | J12: 0 | K12: 0 | L12: 0 | M12: 0 | N12: 0 | O12: 0 | P12: =SUM(D12:O12) -> 0
A13: Volume Billed Institutions | C13: m3 | D13: 7 | E13: 11 | F13: 7 | G13: 63 | H13: 7 | I13: 20 | J13: 15 | K13: 11 | L13: 11 | M13: 13 | N13: 7 | O13: 9 | P13: =SUM(D13:O13) -> 181
A14: Volume Billed Commercial/Industrial | C14: m3 | D14: 27 | E14: 24 | F14: 29 | G14: 43 | H14: 64 | I14: 18 | J14: 18 | K14: 8 | L14: 11 | M14: 8 | N14: 30 | O14: 8 | P14: =SUM(D14:O14) -> 288
A15: Total Volume Billed Post Paid | C15: m3 | D15: =SUM(D11:D14) -> 1186 | E15: =SUM(E11:E14) -> 1195 | F15: =SUM(F11:F14) -> 1254 | G15: =SUM(G11:G14) -> 1085 | H15: =SUM(H11:H14) -> 938 | I15: =SUM(I11:I14) -> 928 | J15: =SUM(J11:J14) -> 813 | K15: =SUM(K11:K14) -> 599 | ... P15: =SUM(P11:P14) -> 10817
A16: REVENUE WATER - PREPAID
A17: Individuals | C17: m3 | D17: 495.5 | E17: 507.3 | F17: 4451.1 | G17: 451.2 | H17: 315.1 | I17: 371.4 | J17: 323.4 | K17: 241.9 | L17: 254 | M17: 1556.8 | N17: 632.9 | O17: 2000.5 | P17: =SUM(D17:O17) -> 11601.1
A18: CWPs | C18: m3 | D18: 0 | E18: 0 | F18: 0 | G18: 0 | H18: 0 | I18: 0 | J18: 0 | K18: 0 | L18: 0 | M18: 0 | N18: 0 | O18: 0 | P18: =SUM(D18:O18) -> 0
A19: Institutions | C19: m3 | D19: 137.8 | E19: 132.5 | F19: 747.7 | G19: 154.5 | H19: 266.5 | I19: 95.1 | J19: 150.6 | K19: 47.1 | L19: 70.2 | M19: 209.8 | N19: 111.7 | O19: 192.5 | P19: =SUM(D19:O19) -> 2316
A20: Commercial/Industrial | C20: m3 | D20: 7 | E20: 9.3 | F20: 9.3 | G20: 11.6 | H20: 0 | I20: 0 | J20: 6.3 | K20: 0 | L20: 8.5 | M20: 0 | N20: 27.2 | O20: 25.3 | P20: =SUM(D20:O20) -> 104.5
A21: Total Volume Prepaid | C21: m3 | D21: =SUM(D17:D20) -> 640.3 | E21: =SUM(E17:E20) -> 649.1 | F21: =SUM(F17:F20) -> 5208.1 | G21: =SUM(G17:G20) -> 617.3 | H21: =SUM(H17:H20) -> 581.6 | I21: =SUM(I17:I20) -> 466.5 | J21: =SUM(J17:J20) -> 480.3 | K21: =SUM(K17:K20) -> 289 | ... P21: =SUM(P17:P20) -> 14021.6
A22: TOTAL REVENUE WATER | C22: m3 | D22: =D21+D15 -> 1826.3 | E22: =E21+E15 -> 1844.1 | F22: =F21+F15 -> 6462.1 | G22: =G21+G15 -> 1702.3 | H22: =H21+H15 -> 1519.6 | I22: =I21+I15 -> 1394.5 | J22: =J21+J15 -> 1293.3 | K22: =K21+K15 -> 888 | ... P22: =P21+P15 -> 24838.6
A24: Non-Revenue Water (NRW) | B24: Volume | C24: m3 | D24: =D9-D22 -> 653.7 | E24: =E9-E22 -> 413.9 | F24: =F9-F22 -> 926.9 | G24: =G9-G22 -> 241.7 | H24: =H9-H22 -> 140.4 | I24: =I9-I22 -> 161.5 | J24: =J9-J22 -> 148.7 | K24: =K9-K22 -> 252 | ... P24: =P9-P22 -> 3321.4
B25: Percentage | C25: % | D25: =IFERROR(D24/D9,0) -> 0.26358871 | E25: =E24/E9 -> 0.18330381 | F25: =F24/F9 -> 0.12544323 | G25: =IFERROR(G24/G9,0) -> 0.12433128 | H25: =IFERROR(H24/H9,0) -> 0.084578313 | I25: =IFERROR(I24/I9,0) -> 0.10379177 | J25: =IFERROR(J24/J9,0) -> 0.10312067 | K25: =IFERROR(K24/K9,0) -> 0.22105263 | L25: =IFERROR(L24/L9,0) -> 0.048285994 | M25: =IFERROR(M24/M9,0) -> 0.046933962 | N25: =IFERROR(N24/N9,0) -> 0.035671937 | O25: =IFERROR(O24/O9,0) -> 0.052442635 | P25: =IF(P9,P24/P9,"") -> 0.11794744
A26: OPERATING EXPENSES
A27: Chemicals
A28: Chemical | B28: Rate(MK/kg)
A29: Chlorine | B29: 7400 | C29: kg | D29: 10.2 | E29: 9.5 | F29: 7.5 | G29: 7.75 | H29: 5.5 | I29: 6.5 | J29: 6.7 | K29: 5.5 | L29: 4.5 | M29: 8.2 | N29: 7.5 | O29: 7.55 | P29: =SUM(D29:O29) -> 86.9
C30: kg/mg litre | D30: =IFERROR(D29/(D9/1000),0) -> 4.1129032 | E30: =IFERROR(E29/(E9/1000),0) -> 4.2072631 | F30: =IFERROR(F29/(F9/1000),0) -> 1.0150223 | G30: =IFERROR(G29/(G9/1000),0) -> 3.9866255 | H30: =IFERROR(H29/(H9/1000),0) -> 3.313253 | I30: =IFERROR(I29/(I9/1000),0) -> 4.1773779 | J30: =IFERROR(J29/(J9/1000),0) -> 4.6463245 | K30: =IFERROR(K29/(K9/1000),0) -> 4.8245614 | ... P30: =IFERROR(P29/(P9/1000),0) -> 3.0859375
A31: Aluminium sulphate | B31: 1900 | C31: kg | D31: 0 | E31: 0 | F31: 0 | G31: 0 | H31: 0 | I31: 0 | J31: 0 | K31: 0 | L31: 0 | M31: 0 | N31: 0 | O31: 0 | P31: =SUM(D31:O31) -> 0
C32: kg/mg litre | D32: =IFERROR(D31/(D9/1000),0) -> 0 | E32: =IFERROR(E31/(E9/1000),0) -> 0 | F32: =IFERROR(F31/(F9/1000),0) -> 0 | G32: =IFERROR(G31/(G9/1000),0) -> 0 | H32: =IFERROR(H31/(H9/1000),0) -> 0 | I32: =IFERROR(I31/(I9/1000),0) -> 0 | J32: =IFERROR(J31/(J9/1000),0) -> 0 | K32: =IFERROR(K31/(K9/1000),0) -> 0 | ... P32: =IFERROR(P31/(P9/1000),0) -> 0
A33: Soda | B33: 1900 | C33: kg | D33: 0 | E33: 0 | F33: 0 | G33: 0 | H33: 0 | I33: 0 | J33: 0 | K33: 0 | L33: 0 | M33: 0 | N33: 0 | O33: 0 | P33: =SUM(D33:O33) -> 0
C34: kg/mg litre | D34: =IFERROR(D33/(D9/1000),0) -> 0 | E34: =IFERROR(E33/(E9/1000),0) -> 0 | F34: =IFERROR(F33/(F9/1000),0) -> 0 | G34: =IFERROR(G33/(G9/1000),0) -> 0 | H34: =IFERROR(H33/(H9/1000),0) -> 0 | I34: =IFERROR(I33/(I9/1000),0) -> 0 | J34: =IFERROR(J33/(J9/1000),0) -> 0 | K34: =IFERROR(K33/(K9/1000),0) -> 0 | ... P34: =IFERROR(P33/(P9/1000),0) -> 0
A35: Algae floc | B35: =745345.16/200 -> 3726.7258 | C35: litres | D35: 0 | E35: 0 | F35: 0 | G35: 0 | H35: 0 | I35: 0 | J35: 0 | K35: 0 | L35: 0 | M35: 0 | N35: 0 | O35: 0
C36: litres/mg litre
A37: Sud floc | B37: =790318.72/200 -> 3951.5936 | C37: litres | D37: 0 | E37: 0 | F37: 0 | G37: 0 | H37: 0 | I37: 0 | J37: 0 | K37: 0 | L37: 0 | M37: 0 | N37: 0 | O37: 0 | P37: =SUM(D37:O37) -> 0
C38: litres/mg litre | D38: =IFERROR(D37/(D9/1000),0) -> 0 | E38: =IFERROR(E37/(E9/1000),0) -> 0 | F38: =IFERROR(F37/(F9/1000),0) -> 0 | G38: =IFERROR(G37/(G9/1000),0) -> 0 | H38: =IFERROR(H37/(H9/1000),0) -> 0 | I38: =IFERROR(I37/(I9/1000),0) -> 0 | J38: =IFERROR(J37/(J9/1000),0) -> 0 | K38: =IFERROR(K37/(K9/1000),0) -> 0 | ... P38: =IFERROR(P37/(P9/1000),0) -> 0
A39: Potasium permanganate | B39: 1950 | C39: kg | D39: 0 | E39: 0 | F39: 0 | G39: 0 | H39: 0 | I39: 0 | J39: 0 | K39: 0 | L39: 0 | M39: 0 | N39: 0 | O39: 0 | P39: =SUM(D39:O39) -> 0
C40: kg/mg litre | D40: =IFERROR(D39/(D9/1000),0) -> 0 | E40: =IFERROR(E39/(E9/1000),0) -> 0 | F40: =IFERROR(F39/(F9/1000),0) -> 0 | G40: =IFERROR(G39/(G9/1000),0) -> 0 | H40: =IFERROR(H39/(H9/1000),0) -> 0 | I40: =IFERROR(I39/(I9/1000),0) -> 0 | J40: =IFERROR(J39/(J9/1000),0) -> 0 | K40: =IFERROR(K39/(K9/1000),0) -> 0 | ... P40: =IFERROR(P39/(P9/1000),0) -> 0
A41: Cost of Chemicals | C41: Mk | D41: =(D29*$B29)+(D31*$B31)+(D33*$B33)+(D35*$B35)+(D37*$B37)+(D39*$B39) -> 75480 | E41: =(E29*$B29)+(E31*$B31)+(E33*$B33)+(E35*$B35)+(E37*$B37)+(E39*$B39) -> 70300 | F41: =(F29*$B29)+(F31*$B31)+(F33*$B33)+(F35*$B35)+(F37*$B37)+(F39*$B39) -> 55500 | G41: =(G29*$B29)+(G31*$B31)+(G33*$B33)+(G35*$B35)+(G37*$B37)+(G39*$B39) -> 57350 | H41: =(H29*$B29)+(H31*$B31)+(H33*$B33)+(H35*$B35)+(H37*$B37)+(H39*$B39) -> 40700 | I41: =(I29*$B29)+(I31*$B31)+(I33*$B33)+(I35*$B35)+(I37*$B37)+(I39*$B39) -> 48100 | J41: =(J29*$B29)+(J31*$B31)+(J33*$B33)+(J35*$B35)+(J37*$B37)+(J39*$B39) -> 49580 | K41: =(K29*$B29)+(K31*$B31)+(K33*$B33)+(K35*$B35)+(K37*$B37)+(K39*$B39) -> 40700 | ... O41: =(O29*$B29)+(O31*$B31)+(O33*$B33)+(O35*$B35)+(O37*$B37)+(O39*$B39) -> 55870 | P41: =SUM(D41:O41) -> 643060
A42: Cost/vol. Produced (chemicals) | C42: Mk/m3 | D42: =IFERROR(D41/D9,0) -> 30.435484 | E42: =IFERROR(E41/E9,0) -> 31.133747 | F42: =IFERROR(F41/F9,0) -> 7.5111652 | G42: =IFERROR(G41/G9,0) -> 29.501029 | H42: =IFERROR(H41/H9,0) -> 24.518072 | I42: =IFERROR(I41/I9,0) -> 30.912596 | J42: =IFERROR(J41/J9,0) -> 34.382802 | K42: =IFERROR(K41/K9,0) -> 35.701754 | ... P42: =IFERROR(P41/P9,0) -> 22.835938
A43: Power
...

Sheet Thondwe
A1: SOUTHERN REGION WATER BOARD
A3: MONTHLY REPORTS - 2024/2025
A4: ZOMBA ZONE
A5: THONDWE SCHEME
A7: PARAMETERS | C7: UNITS | D7: APRIL | E7: MAY | F7: JUNE | G7: JULY | H7: AUGUST | I7: SEPTEMBER | J7: OCTOBER | K7: NOVEMBER | L7: DECEMBER | M7: JANUARY | N7: FEBRUARY | O7: MARCH | P7: TOTALS
A8: PRODUCTION
A9: Volume Produced | C9: m3 | D9: 2150 | E9: 3240 | F9: 2180 | G9: 2240 | H9: 3000 | I9: 2900 | J9: 2970 | K9: 2440 | L9: 4490 | M9: 5450 | N9: 5520 | O9: 5600 | P9: =SUM(D9:O9) -> 42180
A10: REVENUE WATER - POSTPAID
A11: Volume Billed Individuals | C11: m3 | D11: 1504 | E11: 2338 | F11: 1745 | G11: 1896 | H11: 1576 | I11: 1975 | J11: 1971 | K11: 1884 | L11: 2371 | M11: 1979 | N11: 1885 | O11: 2077 | P11: =SUM(D11:O11) -> 23201
A12: Volume Billed CWPs | C12: m3 | D12: 0 | E12: 0 | F12: 0 | G12: 0 | H12: 0 | I12: 0 | J12: 0 | K12: 0 | L12: 0 | M12: 0 | N12: 0 | O12: 0 | P12: =SUM(D12:O12) -> 0
A13: Volume Billed Institutions | C13: m3 | D13: 12 | E13: 8 | F13: 8 | G13: 8 | H13: 8 | I13: 22 | J13: 29 | K13: 28 | L13: 39 | M13: 34 | N13: 27 | O13: 27 | P13: =SUM(D13:O13) -> 250
A14: Volume Billed Commercial/Industrial | C14: m3 | D14: 6 | E14: 8 | F14: 8 | G14: 4 | H14: 4 | I14: 4 | J14: 4 | K14: 4 | L14: 9 | M14: 4 | N14: 4 | O14: 4 | P14: =SUM(D14:O14) -> 63
A15: Total Volume Billed Post Paid | C15: m3 | D15: =SUM(D11:D14) -> 1522 | E15: =SUM(E11:E14) -> 2354 | F15: =SUM(F11:F14) -> 1761 | G15: =SUM(G11:G14) -> 1908 | H15: =SUM(H11:H14) -> 1588 | I15: =SUM(I11:I14) -> 2001 | J15: =SUM(J11:J14) -> 2004 | K15: =SUM(K11:K14) -> 1916 | ... P15: =SUM(P11:P14) -> 23514
A16: REVENUE WATER - PREPAID
