Workbook

Sheet DataEntry
A1: RECORD DIMENSIONS | H1: WATER PRODUCTION & NRW | V1: TREATMENT CHEMICALS | AJ1: POWER | AN1: TRANSPORT & OPERATIONS | AX1: STAFFING | BA1: CONNECTIONS — INDIVIDUAL | BG1: CONNECTIONS — INSTITUTIONAL | BM1: CONNECTIONS — COMMERCIAL | BS1: CONNECTIONS — CWP | BY1: AGGREGATED CONNECTIONS | CC1: METERS & DISCONNECTIONS | CI1: ACTIVE CONSUMERS | CU1: POPULATION | CX1: STUCK METERS — INSTITUTIONAL | DC1: STUCK METERS — COMMERCIAL | DH1: STUCK METERS — CWP | DM1: STUCK METERS — INDIVIDUAL | DR1: AGGREGATED STUCK METERS | DW1: PIPE BREAKDOWNS — PVC | EJ1: PIPE BREAKDOWNS — GI | ES1: PIPE BREAKDOWNS — DI | EY1: PIPE BREAKDOWNS — HDPE & AC | FG1: TOTAL BREAKDOWNS | FH1: PUMPS & SUPPLY HOURS | FL1: DEVELOPMENT LINES | FR1: CASH COLLECTED | GC1: AMOUNTS BILLED | GN1: SERVICE CHARGES | GS1: METER RENTAL | GX1: FINANCIAL KPIs | HE1: CONNECTION PERFORMANCE | HL1: QUERY PERFORMANCE
A2: Zone | B2: Scheme | C2: Fiscal Year | D2: Year | E2: Month No. | F2: Month | G2: Quarter | H2: Volume Produced (m³) | I2: Vol Billed Individual Postpaid | J2: Vol Billed CWP Postpaid | K2: Vol Billed Institutions Postpaid | L2: Vol Billed Commercial Postpaid | M2: TOTAL Vol Billed Postpaid | N2: Vol Billed Individual Prepaid | O2: Vol Billed CWP Prepaid | P2: Vol Billed Institutions Prepaid | Q2: Vol Billed Commercial Prepaid | R2: TOTAL Vol Billed Prepaid | S2: TOTAL Revenue Water m³ | T2: Non-Revenue Water m³ | U2: % NRW | V2: Chlorine kg | W2: Chlorine kg per m³ | X2: Alum Sulphate kg | Y2: Alum Sulphate kg per m³ | Z2: Soda Ash kg | AA2: Soda Ash kg per m³ | AB2: Algae Floc litres | AC2: Algae Floc per m³ | AD2: Sud Floc litres | AE2: Sud Floc per m³ | AF2: Potassium Permanganate kg | AG2: KMnO4 per m³ | AH2: Cost of Chemicals MWK | AI2: Chem Cost per m³ | AJ2: Power Usage kWh | AK2: Power per m³ | AL2: Cost of Power MWK | AM2: Power Cost per m³ | AN2: Distances Covered km | AO2: Fuel Used litres | AP2: Cost of Fuel MWK | AQ2: Maintenance MWK | AR2: Staff Costs MWK | AS2: Wages MWK | AT2: Other Overhead MWK | AU2: TOTAL Operating Costs MWK | AV2: OpCost per m³ Produced | AW2: OpCost per m³ Billed | AX2: Permanent Staff | AY2: Staff per 1000m³ 12h | AZ2: Temporary Staff | BA2: Indiv Conn BroughtFwd | BB2: Indiv Conn Applied PP | BC2: Indiv Conn Done PP | BD2: Indiv Conn Done Prepaid | BE2: Indiv Conn TOTAL Done | BF2: Indiv Conn CarriedFwd | BG2: Inst Conn BroughtFwd | BH2: Inst Conn Applied PP | BI2: Inst Conn Done PP | BJ2: Inst Conn Done Prepaid | BK2: Inst Conn TOTAL Done | BL2: Inst Conn CarriedFwd | BM2: Comm Conn BroughtFwd | BN2: Comm Conn Applied PP | BO2: Comm Conn Done PP | BP2: Comm Conn Done Prepaid | BQ2: Comm Conn TOTAL Done | BR2: Comm Conn CarriedFwd | BS2: CWP Conn BroughtFwd | BT2: CWP Conn Applied PP | BU2: CWP Conn Done PP | BV2: CWP Conn Done Prepaid | BW2: CWP Conn TOTAL Done | BX2: CWP Conn CarriedFwd | BY2: ALL Conn BroughtFwd | BZ2: ALL Conn Applied | CA2: ALL Conn TOTAL Done | CB2: ALL Conn CarriedFwd | CC2: Prepaid Meters Installed | CD2: Disconnected Individual | CE2: Disconnected Institutional | CF2: Disconnected Commercial | CG2: Disconnected CWP | CH2: TOTAL Disconnected | CI2: Active Postpaid Individual | CJ2: Active Postpaid Institutional | CK2: Active Postpaid Commercial | CL2: Active Postpaid CWP | CM2: TOTAL Active Postpaid | CN2: Active Prepaid Individual | CO2: Active Prepaid Institutional | CP2: Active Prepaid Commercial | CQ2: Active Prepaid CWP | CR2: TOTAL Active Prepaid | CS2: TOTAL Active Customers | CT2: Total Metered Consumers | CU2: Population Supply Area | CV2: Population Supplied | CW2: Pct Population Supplied | CX2: Inst StuckM BroughtFwd | CY2: Inst StuckM New | CZ2: Inst StuckM Repaired | DA2: Inst StuckM Replaced | DB2: Inst StuckM CarriedFwd | DC2: Comm StuckM BroughtFwd | DD2: Comm StuckM New | DE2: Comm StuckM Repaired | DF2: Comm StuckM Replaced | DG2: Comm StuckM CarriedFwd | DH2: CWP StuckM BroughtFwd | DI2: CWP StuckM New | DJ2: CWP StuckM Repaired | DK2: CWP StuckM Replaced | DL2: CWP StuckM CarriedFwd | DM2: Indiv StuckM BroughtFwd | DN2: Indiv StuckM New | DO2: Indiv StuckM Repaired | DP2: Indiv StuckM Replaced | DQ2: Indiv StuckM CarriedFwd | DR2: ALL StuckM BroughtFwd | DS2: ALL StuckM New | DT2: ALL StuckM Repaired | DU2: ALL StuckM Replaced | DV2: ALL StuckM CarriedFwd | DW2: PVC 20mm | DX2: PVC 25mm | DY2: PVC 32mm | DZ2: PVC 40mm | EA2: PVC 50mm | EB2: PVC 63mm | EC2: PVC 75mm | ED2: PVC 90mm | EE2: PVC 110mm | EF2: PVC 160mm | EG2: PVC 200mm | EH2: PVC 250mm | EI2: PVC 315mm | EJ2: GI 15mm | EK2: GI 20mm | EL2: GI 25mm | EM2: GI 40mm | EN2: GI 50mm | EO2: GI 75mm | EP2: GI 100mm | EQ2: GI 150mm | ER2: GI 200mm | ES2: DI 150mm | ET2: DI 200mm | EU2: DI 250mm | EV2: DI 300mm | EW2: DI 350mm | EX2: DI 525mm | EY2: HDPE 20mm | EZ2: HDPE 25mm | FA2: HDPE 32mm | FB2: HDPE 50mm | FC2: AC 50mm | FD2: AC 75mm | FE2: AC 100mm | FF2: AC 150mm | FG2: TOTAL Pipe Breakdowns | FH2: Pump Breakdowns | FI2: Pump Hours Lost | FJ2: Normal Supply Hours | FK2: Power Failure Hours | FL2: DevLines 32mm | FM2: DevLines 50mm | FN2: DevLines 63mm | FO2: DevLines 90mm | FP2: DevLines 110mm | FQ2: TOTAL Dev Lines Done | FR2: Cash Coll Indiv PP | FS2: Cash Coll CWP PP | FT2: Cash Coll Comm PP | FU2: Cash Coll Inst PP | FV2: TOTAL Cash Coll PP | FW2: Cash Coll Indiv Prepaid | FX2: Cash Coll CWP Prepaid | FY2: Cash Coll Comm Prepaid | FZ2: Cash Coll Inst Prepaid | GA2: TOTAL Cash Coll Prepaid | GB2: TOTAL Cash Collected | GC2: Amt Billed Indiv PP | GD2: Amt Billed CWP PP | GE2: Amt Billed Inst PP | GF2: Amt Billed Comm PP | GG2: TOTAL Amt Billed PP | GH2: Amt Billed Indiv Prepaid | GI2: Amt Billed CWP Prepaid | GJ2: Amt Billed Inst Prepaid | GK2: Amt Billed Comm Prepaid | GL2: TOTAL Amt Billed Prepaid | GM2: TOTAL Amount Billed | GN2: Svc Charge Individual | GO2: Svc Charge CWP | GP2: Svc Charge Institutions | GQ2: Svc Charge Commercial | GR2: TOTAL Service Charge | GS2: Meter Rental Individual | GT2: Meter Rental CWP | GU2: Meter Rental Institutions | GV2: Meter Rental Commercial | GW2: TOTAL Meter Rental | GX2: TOTAL Sales MWK | GY2: Private Debtors MWK | GZ2: Public Debtors MWK | HA2: TOTAL Debtors MWK | HB2: OpCost per Sales | HC2: Cash Collection Rate | HD2: Collection per Total Sales | HE2: Cust Applied Connection | HF2: Days to Quotation | HG2: Cust Fully Paid | HH2: Paid-up Applicants | HI2: Days to Connect | HJ2: Connection Days | HK2: Connectivity Rate | HL2: Queries Received | HM2: Time to Resolve Queries | HN2: Response Time avg
A3: Liwonde | B3: Balaka | C3: FY2025/26 | D3: 2025 | E3: 4 | F3: April | G3: Q1 | H3: 53275 | I3: 24957 | J3: 958 | K3: 90 | L3: 11 | M3: =SUM(I3,J3,K3,L3) | N3: 9562.6 | O3: 43.4 | P3: 1612.1 | Q3: 353.8 | R3: =SUM(N3,O3,P3,Q3) | S3: =M3+R3 | T3: 15687.1 | U3: =IF(H3=0,"",T3/H3) | V3: 86 | W3: =IF(H3=0,"",V3/H3) | X3: 0 | Y3: =IF(H3=0,"",X3/H3) | Z3: 0 | AA3: =IF(H3=0,"",Z3/H3) | AB3: 0 | AC3: =IF(H3=0,"",AB3/H3) | AD3: 0 | AE3: =IF(H3=0,"",AD3/H3) | AF3: 0 | AG3: =IF(H3=0,"",AF3/H3) | AH3: 303174.94 | AI3: =IF(H3=0,"",AH3/H3) | AJ3: 28941.5 | AK3: =IF(H3=0,"",AJ3/H3) | AL3: 4857706.6 | AM3: =IF(H3=0,"",AL3/H3) | AN3: 3192 | AO3: 120 | AP3: 327600 | AQ3: 0 | AR3: 17284771 | AS3: 4389039.3 | AT3: 5018013.7 | AU3: =AH3+AL3+AP3+AQ3+AR3+AS3+AT3 | AV3: =IF(H3=0,"",AU3/H3) | AW3: =IF(S3=0,"",AU3/S3) | AX3: 14 | AY3: =IF(H3=0,"",AX3/(H3/1000/12)) | AZ3: 20 | BA3: 407 | BB3: 34 | BC3: 48 | BD3: 0 | BE3: =BC3+BD3 | BF3: =BA3+BB3-BE3 | BG3: 0 | BH3: 0 | BI3: 0 | BJ3: 0 | BK3: =BI3+BJ3 | BL3: =BG3+BH3-BK3 | BM3: 0 | BN3: 0 | BO3: 0 | BP3: 0 | BQ3: =BO3+BP3 | BR3: =BM3+BN3-BQ3 | BS3: 0 | BT3: 0 | BU3: 0 | BV3: 0 | BW3: =BU3+BV3 | BX3: =BS3+BT3-BW3 | BY3: =BA3+BG3+BM3+BS3 | BZ3: =BB3+BH3+BN3+BT3 | CA3: =BE3+BK3+BQ3+BW3 | CB3: =BF3+BL3+BR3+BX3 | CC3: 61 | CD3: 2565 | CE3: 49 | CF3: 95 | CG3: 20 | CH3: =CD3+CE3+CF3+CG3 | CI3: 3360 | CJ3: 12 | CK3: 1 | CL3: 11 | CM3: =CI3+CJ3+CK3+CL3 | CN3: 1543 | CO3: 74 | CP3: 70 | CQ3: 3 | CR3: =CN3+CO3+CP3+CQ3 | CS3: =CM3+CR3 | CT3: 7803 | CU3: 41026 | CV3: 34872 | CW3: =IF(CU3=0,"",CV3/CU3) | DB3: =CX3+CY3-CZ3-DA3 | DC3: 0 | DD3: 0 | DE3: 0 | DF3: 0 | DG3: =DC3+DD3-DE3-DF3 | DH3: 0 | DI3: 0 | DJ3: 0 | DK3: 0 | DL3: =DH3+DI3-DJ3-DK3 | DM3: 376 | DN3: 0 | DO3: 46 | DP3: 0 | DQ3: =DM3+DN3-DO3-DP3 | DR3: =CX3+DC3+DH3+DM3 | DS3: =CY3+DD3+DI3+DN3 | DT3: =CZ3+DE3+DJ3+DO3 | DU3: =DA3+DF3+DK3+DP3 | DV3: =DB3+DG3+DL3+DQ3 | DW3: 91 | DX3: 52 | DY3: 24 | DZ3: 0 | EA3: 2 | EB3: 7 | EC3: 0 | ED3: 1 | EE3: 3 | EF3: 0 | EG3: 0 | EH3: 0 | EI3: 0 | EJ3: 0 | EK3: 0 | EL3: 0 | EM3: 0 | EN3: 0 | EO3: 0 | EP3: 0 | EQ3: 0 | ER3: 0 | ES3: 0 | ET3: 0 | EU3: 0 | EV3: 0 | EW3: 0 | EX3: 0 | EY3: 0 | EZ3: 0 | FA3: 0 | FB3: 0 | FC3: 0 | FD3: 0 | FE3: 0 | FF3: 0 | FG3: =SUM(DW3,DX3,DY3,DZ3,EA3,EB3,EC3,ED3,EE3,EF3,EG3,EH3,EI3,EJ3,EK3,EL3,EM3,EN3,EO3,EP3,EQ3,ER3,ES3,ET3,EU3,EV3,EW3,EX3,EY3,EZ3,FA3,FB3,FC3,FD3,FE3,FF3) | FH3: 0 | FI3: 0 | FJ3: 72 | FK3: 504 | FL3: 0 | FM3: 0 | FN3: 0 | FO3: 0 | FP3: 0 | FQ3: =FL3+FM3+FN3+FO3+FP3 | FR3: 17408596 | FS3: 178300 | FT3: 16000 | FU3: 26000 | FV3: =FR3+FS3+FT3+FU3 | FW3: 12283138 | FX3: 9324.64 | FY3: 1687222.8 | FZ3: 4930154.2 | GA3: =FW3+FX3+FY3+FZ3 | GB3: =FV3+GA3 | GC3: 24219712 | GD3: 183246.24 | GE3: 280474.64 | GF3: 32821.45 | GG3: =GC3+GD3+GE3+GF3 | GH3: 11979413 | GI3: 9324.64 | GJ3: 4896554.2 | GK3: 1660222.8 | GL3: =GH3+GI3+GJ3+GK3 | GM3: =GG3+GL3 | GN3: 1792290.4 | GO3: 2104.08 | GP3: 40723.68 | GQ3: 4637.34 | GR3: =GN3+GO3+GP3+GQ3 | GS3: 3000480 | GT3: 9823 | GU3: 10716 | GV3: 893 | GW3: =GS3+GT3+GU3+GV3 | GX3: =GM3+GR3+GW3 | GY3: 3.1612353e+08 | GZ3: 4644828 | HA3: =GY3+GZ3 | HB3: =IF(GX3=0,"",AU3/GX3) | HC3: =IF((GX3+GY3)=0,"",GB3/(GX3+GY3)) | HD3: =IF(GX3=0,"",GB3/GX3) | HE3: 34 | HF3: 1 | HG3: 393 | HH3: 34 | HI3: 20 | HJ3: =HF3+HI3 | HK3: =IF(HE3=0,"",HH3/HE3) | HL3: 12 | HM3: 30 | HN3: =IF(HL3=0,"",HM3/HL3)
A4: Liwonde | B4: Balaka | C4: FY2025/26 | D4: 2025 | E4: 5 | F4: May | G4: Q1 | H4: 41589 | I4: 17592 | J4: 714 | K4: 80 | L4: 4 | M4: =SUM(I4,J4,K4,L4) | N4: 9832.7 | O4: 118.2 | P4: 720.8 | Q4: 595.6 | R4: =SUM(N4,O4,P4,Q4) | S4: =M4+R4 | T4: 11931.7 | U4: =IF(H4=0,"",T4/H4) | V4: 110 | W4: =IF(H4=0,"",V4/H4) | X4: 0 | Y4: =IF(H4=0,"",X4/H4) | Z4: 0 | AA4: =IF(H4=0,"",Z4/H4) | AB4: 0 | AC4: =IF(H4=0,"",AB4/H4) | AD4: 0 | AE4: =IF(H4=0,"",AD4/H4) | AF4: 0 | AG4: =IF(H4=0,"",AF4/H4) | AH4: 387781.9 | AI4: =IF(H4=0,"",AH4/H4) | AJ4: 32525.4 | AK4: =IF(H4=0,"",AJ4/H4) | AL4: 5456854.1 | AM4: =IF(H4=0,"",AL4/H4) | AN4: 4415 | AO4: 166 | AP4: 453844 | AQ4: 0 | AR4: 17895362 | AS4: 3972300.8 | AT4: 5293286.2 | AU4: =AH4+AL4+AP4+AQ4+AR4+AS4+AT4 | AV4: =IF(H4=0,"",AU4/H4) | AW4: =IF(S4=0,"",AU4/S4) | AX4: 14 | AY4: =IF(H4=0,"",AX4/(H4/1000/12)) | AZ4: 20 | BA4: 393 | BB4: 38 | BC4: 32 | BD4: 0 | BE4: =BC4+BD4 | BF4: =BA4+BB4-BE4 | BG4: 0 | BH4: 0 | BI4: 0 | BJ4: 0 | BK4: =BI4+BJ4 | BL4: =BG4+BH4-BK4 | BM4: 0 | BN4: 0 | BO4: 0 | BP4: 0 | BQ4: =BO4+BP4 | BR4: =BM4+BN4-BQ4 | BS4: 0 | BT4: 0 | BU4: 0 | BV4: 0 | BW4: =BU4+BV4 | BX4: =BS4+BT4-BW4 | BY4: =BA4+BG4+BM4+BS4 | BZ4: =BB4+BH4+BN4+BT4 | CA4: =BE4+BK4+BQ4+BW4 | CB4: =BF4+BL4+BR4+BX4 | CC4: 72 | CD4: 2601 | CE4: 49 | CF4: 99 | CG4: 20 | CH4: =CD4+CE4+CF4+CG4 | CI4: 3347 | CJ4: 13 | CK4: 1 | CL4: 11 | CM4: =CI4+CJ4+CK4+CL4 | CN4: 1554 | CO4: 73 | CP4: 70 | CQ4: 3 | CR4: =CN4+CO4+CP4+CQ4 | CS4: =CM4+CR4 | CT4: 7841 | CU4: 41118 | CV4: 34127 | CW4: =IF(CU4=0,"",CV4/CU4) | DB4: =CX4+CY4-CZ4-DA4 | DC4: 0 | DD4: 0 | DE4: 0 | DF4: 0 | DG4: =DC4+DD4-DE4-DF4 | DH4: 0 | DI4: 0 | DJ4: 0 | DK4: 0 | DL4: =DH4+DI4-DJ4-DK4 | DM4: 330 | DN4: 18 | DO4: 0 | DP4: 0 | DQ4: =DM4+DN4-DO4-DP4 | DR4: =CX4+DC4+DH4+DM4 | DS4: =CY4+DD4+DI4+DN4 | DT4: =CZ4+DE4+DJ4+DO4 | DU4: =DA4+DF4+DK4+DP4 | DV4: =DB4+DG4+DL4+DQ4 | DW4: 111 | DX4: 94 | DY4: 17 | DZ4: 0 | EA4: 6 | EB4: 7 | EC4: 0 | ED4: 0 | EE4: 0 | EF4: 0 | EG4: 0 | EH4: 0 | EI4: 0 | EJ4: 0 | EK4: 0 | EL4: 0 | EM4: 0 | EN4: 0 | EO4: 0 | EP4: 0 | EQ4: 0 | ER4: 0 | ES4: 0 | ET4: 0 | EU4: 0 | EV4: 0 | EW4: 0 | EX4: 0 | EY4: 0 | EZ4: 0 | FA4: 0 | FB4: 0 | FC4: 0 | FD4: 0 | FE4: 0 | FF4: 0 | FG4: =SUM(DW4,DX4,DY4,DZ4,EA4,EB4,EC4,ED4,EE4,EF4,EG4,EH4,EI4,EJ4,EK4,EL4,EM4,EN4,EO4,EP4,EQ4,ER4,ES4,ET4,EU4,EV4,EW4,EX4,EY4,EZ4,FA4,FB4,FC4,FD4,FE4,FF4) | FH4: 0 | FI4: 0 | FJ4: 520 | FK4: 7 | FL4: 0 | FM4: 0 | FN4: 0 | FO4: 0 | FP4: 0 | FQ4: =FL4+FM4+FN4+FO4+FP4 | FR4: 37173791 | FS4: 175400 | FT4: 0 | FU4: 52800 | FV4: =FR4+FS4+FT4+FU4 | FW4: 12632085 | FX4: 25100 | FY4: 2809910.1 | FZ4: 2466546.4 | GA4: =FW4+FX4+FY4+FZ4 | GB4: =FV4+GA4 | GC4: 18210958 | GD4: 136573.92 | GE4: 262007.18 | GF4: 8410.99 | GG4: =GC4+GD4+GE4+GF4 | GH4: 12288691 | GI4: 25100 | GJ4: 2185987.3 | GK4: 2797200.9 | GL4: =GH4+GI4+GJ4+GK4 | GM4: =GG4+GL4 | GN4: 1788460.7 | GO4: 2104.08 | GP4: 44117.32 | GQ4: 4637.34 | GR4: =GN4+GO4+GP4+GQ4 | GS4: 2988871 | GT4: 9823 | GU4: 11609 | GV4: 893 | GW4: =GS4+GT4+GU4+GV4 | GX4: =GM4+GR4+GW4 | GY4: 3.0197445e+08 | GZ4: 4837013.5 | HA4: =GY4+GZ4 | HB4: =IF(GX4=0,"",AU4/GX4) | HC4: =IF((GX4+GY4)=0,"",GB4/(GX4+GY4)) | HD4: =IF(GX4=0,"",GB4/GX4) | HE4: 38 | HF4: 1 | HG4: 399 | HH4: 38 | HI4: 20 | HJ4: =HF4+HI4 | HK4: =IF(HE4=0,"",HH4/HE4) | HL4: 15 | HM4: 30 | HN4: =IF(HL4=0,"",HM4/HL4)
A5: Liwonde | B5: Balaka | C5: FY2025/26 | D5: 2025 | E5: 6 | F5: June | G5: Q1 | H5: 45200 | I5: 17881 | J5: 633 | K5: 84 | L5: 0 | M5: =SUM(I5,J5,K5,L5) | N5: 11195.3 | O5: 125.7 | P5: 569.1 | Q5: 700.1 | R5: =SUM(N5,O5,P5,Q5) | S5: =M5+R5 | T5: 14011.8 | U5: =IF(H5=0,"",T5/H5) | V5: 128 | W5: =IF(H5=0,"",V5/H5) | X5: 0 | Y5: =IF(H5=0,"",X5/H5) | Z5: 0 | AA5: =IF(H5=0,"",Z5/H5) | AB5: 0 | AC5: =IF(H5=0,"",AB5/H5) | AD5: 0 | AE5: =IF(H5=0,"",AD5/H5) | AF5: 0 | AG5: =IF(H5=0,"",AF5/H5) | AH5: 451237.12 | AI5: =IF(H5=0,"",AH5/H5) | AJ5: 23254.6 | AK5: =IF(H5=0,"",AJ5/H5) | AL5: 3906984.9 | AM5: =IF(H5=0,"",AL5/H5) | AN5: 7525 | AO5: 282 | AP5: 769860 | AQ5: 0 | AR5: 17883497 | AS5: 4462572.3 | AT5: 10710322 | AU5: =AH5+AL5+AP5+AQ5+AR5+AS5+AT5 | AV5: =IF(H5=0,"",AU5/H5) | AW5: =IF(S5=0,"",AU5/S5) | AX5: 14 | AY5: =IF(H5=0,"",AX5/(H5/1000/12)) | AZ5: 20 | BA5: 399 | BB5: 43 | BC5: 33 | BD5: 0 | BE5: =BC5+BD5 | BF5: =BA5+BB5-BE5 | BG5: 0 | BH5: 0 | BI5: 0 | BJ5: 0 | BK5: =BI5+BJ5 | BL5: =BG5+BH5-BK5 | BM5: 0 | BN5: 0 | BO5: 0 | BP5: 0 | BQ5: =BO5+BP5 | BR5: =BM5+BN5-BQ5 | BS5: 0 | BT5: 0 | BU5: 0 | BV5: 0 | BW5: =BU5+BV5 | BX5: =BS5+BT5-BW5 | BY5: =BA5+BG5+BM5+BS5 | BZ5: =BB5+BH5+BN5+BT5 | CA5: =BE5+BK5+BQ5+BW5 | CB5: =BF5+BL5+BR5+BX5 | CC5: 65 | CD5: 2569 | CE5: 51 | CF5: 99 | CG5: 20 | CH5: =CD5+CE5+CF5+CG5 | CI5: 3054 | CJ5: 9 | CK5: 1 | CL5: 11 | CM5: =CI5+CJ5+CK5+CL5 | CN5: 1726 | CO5: 75 | CP5: 71 | CQ5: 3 | CR5: =CN5+CO5+CP5+CQ5 | CS5: =CM5+CR5 | CT5: 7689 | CU5: 41203 | CV5: 35022.55 | CW5: =IF(CU5=0,"",CV5/CU5) | DB5: =CX5+CY5-CZ5-DA5 | DC5: 0 | DD5: 0 | DE5: 0 | DF5: 0 | DG5: =DC5+DD5-DE5-DF5 | DH5: 0 | DI5: 0 | DJ5: 0 | DK5: 0 | DL5: =DH5+DI5-DJ5-DK5 | DM5: 348 | DN5: 0 | DO5: 0 | DP5: 73 | DQ5: =DM5+DN5-DO5-DP5 | DR5: =CX5+DC5+DH5+DM5 | DS5: =CY5+DD5+DI5+DN5 | DT5: =CZ5+DE5+DJ5+DO5 | DU5: =DA5+DF5+DK5+DP5 | DV5: =DB5+DG5+DL5+DQ5 | DW5: 89 | DX5: 82 | DY5: 12 | DZ5: 1 | EA5: 3 | EB5: 8 | EC5: 2 | ED5: 0 | EE5: 2 | EF5: 0 | EG5: 0 | EH5: 0 | EI5: 0 | EJ5: 0 | EK5: 0 | EL5: 0 | EM5: 0 | EN5: 0 | EO5: 0 | EP5: 0 | EQ5: 0 | ER5: 0 | ES5: 0 | ET5: 0 | EU5: 0 | EV5: 0 | EW5: 0 | EX5: 0 | EY5: 0 | EZ5: 0 | FA5: 0 | FB5: 0 | FC5: 0 | FD5: 0 | FE5: 0 | FF5: 0 | FG5: =SUM(DW5,DX5,DY5,DZ5,EA5,EB5,EC5,ED5,EE5,EF5,EG5,EH5,EI5,EJ5,EK5,EL5,EM5,EN5,EO5,EP5,EQ5,ER5,ES5,ET5,EU5,EV5,EW5,EX5,EY5,EZ5,FA5,FB5,FC5,FD5,FE5,FF5) | FH5: 0 | FI5: 0 | FJ5: 504 | FK5: 36 | FL5: 0 | FM5: 0 | FN5: 0 | FO5: 0 | FP5: 0 | FQ5: =FL5+FM5+FN5+FO5+FP5 | FR5: 56748775 | FS5: 315300 | FT5: 38600 | FU5: 301267.22 | FV5: =FR5+FS5+FT5+FU5 | FW5: 14435292 | FX5: 26845.88 | FY5: 3326633.1 | FZ5: 2412218.5 | GA5: =FW5+FX5+FY5+FZ5 | GB5: =FV5+GA5 | GC5: 17754700 | GD5: 121080.24 | GE5: 266087.19 | GF5: 8410.99 | GG5: =GC5+GD5+GE5+GF5 | GH5: 14014137 | GI5: 26845.88 | GJ5: 2119718.5 | GK5: 3274923.9 | GL5: =GH5+GI5+GJ5+GK5 | GM5: =GG5+GL5 | GN5: 1626263.3 | GO5: 2104.08 | GP5: 30542.76 | GQ5: 4637.34 | GR5: =GN5+GO5+GP5+GQ5 | GS5: 2727222 | GT5: 9823 | GU5: 8037 | GV5: 893 | GW5: =GS5+GT5+GU5+GV5 | GX5: =GM5+GR5+GW5 | GY5: 2.7122601e+08 | GZ5: 2343196 | HA5: =GY5+GZ5 | HB5: =IF(GX5=0,"",AU5/GX5) | HC5: =IF((GX5+GY5)=0,"",GB5/(GX5+GY5)) | HD5: =IF(GX5=0,"",GB5/GX5) | HE5: 43 | HF5: 1 | HG5: 409 | HH5: 43 | HI5: 20 | HJ5: =HF5+HI5 | HK5: =IF(HE5=0,"",HH5/HE5) | HL5: 12 | HM5: 30 | HN5: =IF(HL5=0,"",HM5/HL5)
A6: Liwonde | B6: Balaka | C6: FY2025/26 | D6: 2025 | E6: 7 | F6: July | G6: Q2 | H6: 62022 | I6: 25332 | J6: 1028 | K6: 101 | L6: 56 | M6: =SUM(I6,J6,K6,L6) | N6: 14278.3 | O6: 267.7 | P6: 1069 | Q6: 597.6 | R6: =SUM(N6,O6,P6,Q6) | S6: =M6+R6 | T6: 19292.4 | U6: =IF(H6=0,"",T6/H6) | V6: 200 | W6: =IF(H6=0,"",V6/H6) | X6: 0 | Y6: =IF(H6=0,"",X6/H6) | Z6: 0 | AA6: =IF(H6=0,"",Z6/H6) | AB6: 0 | AC6: =IF(H6=0,"",AB6/H6) | AD6: 0 | AE6: =IF(H6=0,"",AD6/H6) | AF6: 0 | AG6: =IF(H6=0,"",AF6/H6) | AH6: 705058 | AI6: =IF(H6=0,"",AH6/H6) | AJ6: 20456 | AK6: =IF(H6=0,"",AJ6/H6) | AL6: 3439121.9 | AM6: =IF(H6=0,"",AL6/H6) | AN6: 5432 | AO6: 198 | AP6: 540540 | AQ6: 0 | AR6: 17883497 | AS6: 4854203.2 | AT6: 5255000 | AU6: =AH6+AL6+AP6+AQ6+AR6+AS6+AT6 | AV6: =IF(H6=0,"",AU6/H6) | AW6: =IF(S6=0,"",AU6/S6) | AX6: 14 | AY6: =IF(H6=0,"",AX6/(H6/1000/12)) | AZ6: 20 | BA6: 409 | BB6: 59 | BC6: 61 | BD6: 0 | BE6: =BC6+BD6 | BF6: =BA6+BB6-BE6 | BG6: 0 | BH6: 0 | BI6: 0 | BJ6: 0 | BK6: =BI6+BJ6 | BL6: =BG6+BH6-BK6 | BM6: 0 | BN6: 0 | BO6: 0 | BP6: 0 | BQ6: =BO6+BP6 | BR6: =BM6+BN6-BQ6 | BS6: 0 | BT6: 0 | BU6: 0 | BV6: 0 | BW6: =BU6+BV6 | BX6: =BS6+BT6-BW6 | BY6: =BA6+BG6+BM6+BS6 | BZ6: =BB6+BH6+BN6+BT6 | CA6: =BE6+BK6+BQ6+BW6 | CB6: =BF6+BL6+BR6+BX6 | CC6: 121 | CD6: 2642 | CE6: 51 | CF6: 99 | CG6: 19 | CH6: =CD6+CE6+CF6+CG6 | CI6: 3156 | CJ6: 9 | CK6: 1 | CL6: 11 | CM6: =CI6+CJ6+CK6+CL6 | CN6: 1795 | CO6: 75 | CP6: 71 | CQ6: 4 | CR6: =CN6+CO6+CP6+CQ6 | CS6: =CM6+CR6 | CT6: 7933 | CU6: 41615.03 | CV6: 35373.23 | CW6: =IF(CU6=0,"",CV6/CU6) | DB6: =CX6+CY6-CZ6-DA6 | DC6: 0 | DD6: 0 | DE6: 0 | DF6: 0 | DG6: =DC6+DD6-DE6-DF6 | DH6: 0 | DI6: 0 | DJ6: 0 | DK6: 0 | DL6: =DH6+DI6-DJ6-DK6 | DM6: 275 | DN6: 0 | DO6: 0 | DP6: 32 | DQ6: =DM6+DN6-DO6-DP6 | DR6: =CX6+DC6+DH6+DM6 | DS6: =CY6+DD6+DI6+DN6 | DT6: =CZ6+DE6+DJ6+DO6 | DU6: =DA6+DF6+DK6+DP6 | DV6: =DB6+DG6+DL6+DQ6 | DW6: 104 | DX6: 75 | DY6: 10 | DZ6: 1 | EA6: 2 | EB6: 3 | EC6: 0 | ED6: 0 | EE6: 1 | EF6: 0 | EG6: 0 | EH6: 0 | EI6: 0 | EJ6: 0 | EK6: 0 | EL6: 0 | EM6: 0 | EN6: 0 | EO6: 0 | EP6: 0 | EQ6: 0 | ER6: 0 | ES6: 0 | ET6: 0 | EU6: 0 | EV6: 0 | EW6: 0 | EX6: 0 | EY6: 0 | EZ6: 0 | FA6: 0 | FB6: 0 | FC6: 0 | FD6: 0 | FE6: 0 | FF6: 0 | FG6: =SUM(DW6,DX6,DY6,DZ6,EA6,EB6,EC6,ED6,EE6,EF6,EG6,EH6,EI6,EJ6,EK6,EL6,EM6,EN6,EO6,EP6,EQ6,ER6,ES6,ET6,EU6,EV6,EW6,EX6,EY6,EZ6,FA6,FB6,FC6,FD6,FE6,FF6) | FH6: 0 | FI6: 0 | FJ6: 520 | FK6: 5 | FL6: 0 | FM6: 0 | FN6: 0 | FO6: 0 | FP6: 0 | FQ6: =FL6+FM6+FN6+FO6+FP6 | FR6: 23307260 | FS6: 263000 | FT6: 61000 | FU6: 89200 | FV6: =FR6+FS6+FT6+FU6 | FW6: 18306154 | FX6: 56900 | FY6: 2836450 | FZ6: 3510164.8 | GA6: =FW6+FX6+FY6+FZ6 | GB6: =FV6+GA6 | GC6: 23938310 | GD6: 196635.84 | GE6: 313271.24 | GF6: 254121.01 | GG6: =GC6+GD6+GE6+GF6 | GH6: 17872550 | GI6: 56900 | GJ6: 3229537.6 | GK6: 2752750 | GL6: =GH6+GI6+GJ6+GK6 | GM6: =GG6+GL6 | GN6: 1682555.7 | GO6: 2104.08 | GP6: 30542.76 | GQ6: 4637.34 | GR6: =GN6+GO6+GP6+GQ6 | GS6: 2818308 | GT6: 9823 | GU6: 8037 | GV6: 893 | GW6: =GS6+GT6+GU6+GV6 | GX6: =GM6+GR6+GW6 | GY6: 2.7712767e+08 | GZ6: 2663026.8 | HA6: =GY6+GZ6 | HB6: =IF(GX6=0,"",AU6/GX6) | HC6: =IF((GX6+GY6)=0,"",GB6/(GX6+GY6)) | HD6: =IF(GX6=0,"",GB6/GX6) | HE6: 59 | HF6: 1 | HG6: 407 | HH6: 59 | HI6: 20 | HJ6: =HF6+HI6 | HK6: =IF(HE6=0,"",HH6/HE6) | HL6: 14 | HM6: 30 | HN6: =IF(HL6=0,"",HM6/HL6)
A7: Liwonde | B7: Balaka | C7: FY2025/26 | D7: 2025 | E7: 8 | F7: August | G7: Q2 | H7: 50958 | I7: 19421 | J7: 772 | K7: 96 | L7: 11 | M7: =SUM(I7,J7,K7,L7) | N7: 13978.2 | O7: 356.5 | P7: 822.6 | Q7: 603.5 | R7: =SUM(N7,O7,P7,Q7) | S7: =M7+R7 | T7: 14897.2 | U7: =IF(H7=0,"",T7/H7) | V7: 128 | W7: =IF(H7=0,"",V7/H7) | X7: 0 | Y7: =IF(H7=0,"",X7/H7) | Z7: 0 | AA7: =IF(H7=0,"",Z7/H7) | AB7: 0 | AC7: =IF(H7=0,"",AB7/H7) | AD7: 0 | AE7: =IF(H7=0,"",AD7/H7) | AF7: 0 | AG7: =IF(H7=0,"",AF7/H7) | AH7: 451237.12 | AI7: =IF(H7=0,"",AH7/H7) | AJ7: 56715 | AK7: =IF(H7=0,"",AJ7/H7) | AL7: 9500810.9 | AM7: =IF(H7=0,"",AL7/H7) | AN7: 5843.5152 | AO7: 213 | AP7: 581490 | AQ7: 0 | AR7: 17703746 | AS7: 4932611.6 | AT7: 8078460 | AU7: =AH7+AL7+AP7+AQ7+AR7+AS7+AT7 | AV7: =IF(H7=0,"",AU7/H7) | AW7: =IF(S7=0,"",AU7/S7) | AX7: 14 | AY7: =IF(H7=0,"",AX7/(H7/1000/12)) | AZ7: 20 | BA7: 407 | BB7: 63 | BC7: 54 | BD7: 0 | BE7: =BC7+BD7 | BF7: =BA7+BB7-BE7 | BG7: 0 | BH7: 0 | BI7: 0 | BJ7: 0 | BK7: =BI7+BJ7 | BL7: =BG7+BH7-BK7 | BM7: 0 | BN7: 0 | BO7: 0 | BP7: 0 | BQ7: =BO7+BP7 | BR7: =BM7+BN7-BQ7 | BS7: 0 | BT7: 0 | BU7: 0 | BV7: 0 | BW7: =BU7+BV7 | BX7: =BS7+BT7-BW7 | BY7: =BA7+BG7+BM7+BS7 | BZ7: =BB7+BH7+BN7+BT7 | CA7: =BE7+BK7+BQ7+BW7 | CB7: =BF7+BL7+BR7+BX7 | CC7: 62 | CD7: 2554 | CE7: 50 | CF7: 98 | CG7: 18 | CH7: =CD7+CE7+CF7+CG7 | CI7: 2958 | CJ7: 9 | CK7: 2 | CL7: 11 | CM7: =CI7+CJ7+CK7+CL7 | CN7: 2135 | CO7: 76 | CP7: 71 | CQ7: 5 | CR7: =CN7+CO7+CP7+CQ7 | CS7: =CM7+CR7 | CT7: 7987 | CU7: 41615.03 | CV7: 35726.96 | CW7: =IF(CU7=0,"",CV7/CU7) | DB7: =CX7+CY7-CZ7-DA7 | DC7: 0 | DD7: 0 | DE7: 0 | DF7: 0 | DG7: =DC7+DD7-DE7-DF7 | DH7: 0 | DI7: 0 | DJ7: 0 | DK7: 0 | DL7: =DH7+DI7-DJ7-DK7 | DM7: 243 | DN7: 0 | DO7: 0 | DP7: 67 | DQ7: =DM7+DN7-DO7-DP7 | DR7: =CX7+DC7+DH7+DM7 | DS7: =CY7+DD7+DI7+DN7 | DT7: =CZ7+DE7+DJ7+DO7 | DU7: =DA7+DF7+DK7+DP7 | DV7: =DB7+DG7+DL7+DQ7 | DW7: 147 | DX7: 64 | DY7: 12 | DZ7: 0 | EA7: 0 | EB7: 9 | EC7: 0 | ED7: 0 | EE7: 1 | EF7: 0 | EG7: 0 | EH7: 0 | EI7: 0 | EJ7: 0 | EK7: 0 | EL7: 0 | EM7: 0 | EN7: 0 | EO7: 0 | EP7: 0 | EQ7: 0 | ER7: 0 | ES7: 0 | ET7: 0 | EU7: 0 | EV7: 0 | EW7: 0 | EX7: 0 | EY7: 0 | EZ7: 0 | FA7: 0 | FB7: 0 | FC7: 0 | FD7: 0 | FE7: 0 | FF7: 0 | FG7: =SUM(DW7,DX7,DY7,DZ7,EA7,EB7,EC7,ED7,EE7,EF7,EG7,EH7,EI7,EJ7,EK7,EL7,EM7,EN7,EO7,EP7,EQ7,ER7,ES7,ET7,EU7,EV7,EW7,EX7,EY7,EZ7,FA7,FB7,FC7,FD7,FE7,FF7) | FH7: 0 | FI7: 0 | FJ7: 504 | FK7: 3 | FL7: 0 | FM7: 0 | FN7: 0 | FO7: 0 | FP7: 0 | FQ7: =FL7+FM7+FN7+FO7+FP7 | FR7: 27549691 | FS7: 210800 | FT7: 67.22 | FU7: 104867.22 | FV7: =FR7+FS7+FT7+FU7 | FW7: 18757806 | FX7: 83000 | FY7: 2867900 | FZ7: 2799507 | GA7: =FW7+FX7+FY7+FZ7 | GB7: =FV7+GA7 | GC7: 18832106 | GD7: 147668.16 | GE7: 283790.6 | GF7: 30364.54 | GG7: =GC7+GD7+GE7+GF7 | GH7: 17520114 | GI7: 75740 | GJ7: 2486071.8 | GK7: 2760500 | GL7: =GH7+GI7+GJ7+GK7 | GM7: =GG7+GL7 | GN7: 1587694.1 | GO7: 2104.08 | GP7: 30542.76 | GQ7: 9274.68 | GR7: =GN7+GO7+GP7+GQ7 | GS7: 2637029 | GT7: 9823 | GU7: 8037 | GV7: 1786 | GW7: =GS7+GT7+GU7+GV7 | GX7: =GM7+GR7+GW7 | GY7: 2.703971e+08 | GZ7: 2952170.9 | HA7: =GY7+GZ7 | HB7: =IF(GX7=0,"",AU7/GX7) | HC7: =IF((GX7+GY7)=0,"",GB7/(GX7+GY7)) | HD7: =IF(GX7=0,"",GB7/GX7) | HE7: 63 | HF7: 1 | HG7: 416 | HH7: 63 | HI7: 20 | HJ7: =HF7+HI7 | HK7: =IF(HE7=0,"",HH7/HE7) | HL7: 15 | HM7: 30 | HN7: =IF(HL7=0,"",HM7/HL7)
A8: Liwonde | B8: Balaka | C8: FY2025/26 | D8: 2025 | E8: 9 | F8: September | G8: Q2 | H8: 65681 | I8: 25495 | J8: 1147 | K8: 115 | L8: 6 | M8: =SUM(I8,J8,K8,L8) | N8: 16674.6 | O8: 446.5 | P8: 1097.7 | Q8: 513.5 | R8: =SUM(N8,O8,P8,Q8) | S8: =M8+R8 | T8: 20185.7 | U8: =IF(H8=0,"",T8/H8) | V8: 130 | W8: =IF(H8=0,"",V8/H8) | X8: 0 | Y8: =IF(H8=0,"",X8/H8) | Z8: 0 | AA8: =IF(H8=0,"",Z8/H8) | AB8: 0 | AC8: =IF(H8=0,"",AB8/H8) | AD8: 0 | AE8: =IF(H8=0,"",AD8/H8) | AF8: 0 | AG8: =IF(H8=0,"",AF8/H8) | AH8: 458287.7 | AI8: =IF(H8=0,"",AH8/H8) | AJ8: 25713.7 | AK8: =IF(H8=0,"",AJ8/H8) | AL8: 4318091.1 | AM8: =IF(H8=0,"",AL8/H8) | AN8: 5426 | AO8: 375.00857 | AP8: 1312530 | AQ8: 0 | AR8: 16664236 | AS8: 6601328.2 | AT8: 1657762.1 | AU8: =AH8+AL8+AP8+AQ8+AR8+AS8+AT8 | AV8: =IF(H8=0,"",AU8/H8) | AW8: =IF(S8=0,"",AU8/S8) | AX8: 14 | AY8: =IF(H8=0,"",AX8/(H8/1000/12)) | AZ8: 39 | BA8: 416 | BB8: 48 | BC8: 42 | BD8: 0 | BE8: =BC8+BD8 | BF8: =BA8+BB8-BE8 | BG8: 0 | BH8: 0 | BI8: 0 | BJ8: 0 | BK8: =BI8+BJ8 | BL8: =BG8+BH8-BK8 | BM8: 0 | BN8: 0 | BO8: 0 | BP8: 0 | BQ8: =BO8+BP8 | BR8: =BM8+BN8-BQ8 | BS8: 0 | BT8: 0 | BU8: 0 | BV8: 0 | BW8: =BU8+BV8 | BX8: =BS8+BT8-BW8 | BY8: =BA8+BG8+BM8+BS8 | BZ8: =BB8+BH8+BN8+BT8 | CA8: =BE8+BK8+BQ8+BW8 | CB8: =BF8+BL8+BR8+BX8 | CC8: 45 | CD8: 2508 | CE8: 50 | CF8: 98 | CG8: 18 | CH8: =CD8+CE8+CF8+CG8 | CI8: 2946 | CJ8: 9 | CK8: 1 | CL8: 11 | CM8: =CI8+CJ8+CK8+CL8 | CN8: 2382 | CO8: 76 | CP8: 72 | CQ8: 5 | CR8: =CN8+CO8+CP8+CQ8 | CS8: =CM8+CR8 | CT8: 8176 | CU8: 41615.03 | CV8: 36441.54 | CW8: =IF(CU8=0,"",CV8/CU8) | DB8: =CX8+CY8-CZ8-DA8 | DC8: 0 | DD8: 0 | DE8: 0 | DF8: 0 | DG8: =DC8+DD8-DE8-DF8 | DH8: 0 | DI8: 0 | DJ8: 0 | DK8: 0 | DL8: =DH8+DI8-DJ8-DK8 | DM8: 176 | DN8: 12 | DO8: 0 | DP8: 0 | DQ8: =DM8+DN8-DO8-DP8 | DR8: =CX8+DC8+DH8+DM8 | DS8: =CY8+DD8+DI8+DN8 | DT8: =CZ8+DE8+DJ8+DO8 | DU8: =DA8+DF8+DK8+DP8 | DV8: =DB8+DG8+DL8+DQ8 | DW8: 111 | DX8: 68 | DY8: 9 | DZ8: 1 | EA8: 4 | EB8: 10 | EC8: 1 | ED8: 0 | EE8: 1 | EF8: 3 | EG8: 4 | EH8: 0 | EI8: 0 | EJ8: 0 | EK8: 0 | EL8: 0 | EM8: 0 | EN8: 0 | EO8: 0 | EP8: 0 | EQ8: 0 | ER8: 0 | ES8: 0 | ET8: 0 | EU8: 0 | EV8: 0 | EW8: 0 | EX8: 0 | EY8: 0 | EZ8: 0 | FA8: 0 | FB8: 0 | FC8: 0 | FD8: 0 | FE8: 0 | FF8: 0 | FG8: =SUM(DW8,DX8,DY8,DZ8,EA8,EB8,EC8,ED8,EE8,EF8,EG8,EH8,EI8,EJ8,EK8,EL8,EM8,EN8,EO8,EP8,EQ8,ER8,ES8,ET8,EU8,EV8,EW8,EX8,EY8,EZ8,FA8,FB8,FC8,FD8,FE8,FF8) | FH8: 0 | FI8: 0 | FJ8: 520 | FK8: 3 | FL8: 0 | FM8: 0 | FN8: 0 | FO8: 0 | FP8: 0 | FQ8: =FL8+FM8+FN8+FO8+FP8 | FR8: 21691980 | FS8: 176267.22 | FT8: 350067.22 | FU8: 67000 | FV8: =FR8+FS8+FT8+FU8 | FW8: 26130022 | FX8: 154524.64 | FY8: 2554072.8 | FZ8: 3803513.9 | GA8: =FW8+FX8+FY8+FZ8 | GB8: =FV8+GA8 | GC8: 24186379 | GD8: 219398.16 | GE8: 364727.96 | GF8: 15182.27 | GG8: =GC8+GD8+GE8+GF8 | GH8: 20822945 | GI8: 94988.87 | GJ8: 3314638.2 | GK8: 2436112.8 | GL8: =GH8+GI8+GJ8+GK8 | GM8: =GG8+GL8 | GN8: 1584702.3 | GO8: 2104.08 | GP8: 30542.76 | GQ8: 4637.34 | GR8: =GN8+GO8+GP8+GQ8 | GS8: 2630778 | GT8: 9823 | GU8: 8037 | GV8: 893 | GW8: =GS8+GT8+GU8+GV8 | GX8: =GM8+GR8+GW8 | GY8: 2.7634466e+08 | GZ8: 3372797.1 | HA8: =GY8+GZ8 | HB8: =IF(GX8=0,"",AU8/GX8) | HC8: =IF((GX8+GY8)=0,"",GB8/(GX8+GY8)) | HD8: =IF(GX8=0,"",GB8/GX8) | HE8: 48 | HF8: 1 | HG8: 422 | HH8: 48 | HI8: 20 | HJ8: =HF8+HI8 | HK8: =IF(HE8=0,"",HH8/HE8) | HL8: 40 | HM8: 30 | HN8: =IF(HL8=0,"",HM8/HL8)
A9: Liwonde | B9: Balaka | C9: FY2025/26 | D9: 2025 | E9: 10 | F9: October | G9: Q3 | H9: 46567 | I9: 17150 | J9: 809 | K9: 93 | L9: 2 | M9: =SUM(I9,J9,K9,L9) | N9: 12658 | O9: 386.9 | P9: 1415.9 | Q9: 453.7 | R9: =SUM(N9,O9,P9,Q9) | S9: =M9+R9 | T9: 13598.5 | U9: =IF(H9=0,"",T9/H9) | V9: 82 | W9: =IF(H9=0,"",V9/H9) | X9: 0 | Y9: =IF(H9=0,"",X9/H9) | Z9: 0 | AA9: =IF(H9=0,"",Z9/H9) | AB9: 0 | AC9: =IF(H9=0,"",AB9/H9) | AD9: 0 | AE9: =IF(H9=0,"",AD9/H9) | AF9: 0 | AG9: =IF(H9=0,"",AF9/H9) | AH9: 289073.78 | AI9: =IF(H9=0,"",AH9/H9) | AJ9: 14255 | AK9: =IF(H9=0,"",AJ9/H9) | AL9: 2402454.3 | AM9: =IF(H9=0,"",AL9/H9) | AN9: 4123.6657 | AO9: 285 | AP9: 778050 | AQ9: 0 | AR9: 0 | AS9: 6654152.5 | AT9: 1624766.8 | AU9: =AH9+AL9+AP9+AQ9+AR9+AS9+AT9 | AV9: =IF(H9=0,"",AU9/H9) | AW9: =IF(S9=0,"",AU9/S9) | AX9: 14 | AY9: =IF(H9=0,"",AX9/(H9/1000/12)) | AZ9: 42 | BA9: 422 | BB9: 41 | BC9: 46 | BD9: 0 | BE9: =BC9+BD9 | BF9: =BA9+BB9-BE9 | BG9: 0 | BH9: 0 | BI9: 0 | BJ9: 0 | BK9: =BI9+BJ9 | BL9: =BG9+BH9-BK9 | BM9: 0 | BN9: 0 | BO9: 0 | BP9: 0 | BQ9: =BO9+BP9 | BR9: =BM9+BN9-BQ9 | BS9: 0 | BT9: 0 | BU9: 0 | BV9: 0 | BW9: =BU9+BV9 | BX9: =BS9+BT9-BW9 | BY9: =BA9+BG9+BM9+BS9 | BZ9: =BB9+BH9+BN9+BT9 | CA9: =BE9+BK9+BQ9+BW9 | CB9: =BF9+BL9+BR9+BX9 | CC9: 35 | CD9: 2520 | CE9: 50 | CF9: 97 | CG9: 18 | CH9: =CD9+CE9+CF9+CG9 | CI9: 2980 | CJ9: 8 | CK9: 1 | CL9: 11 | CM9: =CI9+CJ9+CK9+CL9 | CN9: 2382 | CO9: 77 | CP9: 73 | CQ9: 5 | CR9: =CN9+CO9+CP9+CQ9 | CS9: =CM9+CR9 | CT9: 8222 | CU9: 41823.11 | CV9: 36623.75 | CW9: =IF(CU9=0,"",CV9/CU9) | DB9: =CX9+CY9-CZ9-DA9 | DC9: 0 | DD9: 0 | DE9: 0 | DF9: 0 | DG9: =DC9+DD9-DE9-DF9 | DH9: 0 | DI9: 0 | DJ9: 0 | DK9: 0 | DL9: =DH9+DI9-DJ9-DK9 | DM9: 188 | DN9: 5 | DO9: 0 | DP9: 0 | DQ9: =DM9+DN9-DO9-DP9 | DR9: =CX9+DC9+DH9+DM9 | DS9: =CY9+DD9+DI9+DN9 | DT9: =CZ9+DE9+DJ9+DO9 | DU9: =DA9+DF9+DK9+DP9 | DV9: =DB9+DG9+DL9+DQ9 | DW9: 84 | DX9: 42 | DY9: 8 | DZ9: 1 | EA9: 5 | EB9: 7 | EC9: 0 | ED9: 0 | EE9: 1 | EF9: 0 | EG9: 1 | EH9: 0 | EI9: 0 | EJ9: 0 | EK9: 0 | EL9: 0 | EM9: 0 | EN9: 0 | EO9: 0 | EP9: 0 | EQ9: 0 | ER9: 0 | ES9: 0 | ET9: 0 | EU9: 0 | EV9: 0 | EW9: 0 | EX9: 0 | EY9: 0 | EZ9: 0 | FA9: 0 | FB9: 0 | FC9: 0 | FD9: 0 | FE9: 0 | FF9: 0 | FG9: =SUM(DW9,DX9,DY9,DZ9,EA9,EB9,EC9,ED9,EE9,EF9,EG9,EH9,EI9,EJ9,EK9,EL9,EM9,EN9,EO9,EP9,EQ9,ER9,ES9,ET9,EU9,EV9,EW9,EX9,EY9,EZ9,FA9,FB9,FC9,FD9,FE9,FF9) | FH9: 0 | FI9: 0 | FJ9: 372 | FK9: 10 | FL9: 0 | FM9: 0 | FN9: 0 | FO9: 0 | FP9: 0 | FQ9: =FL9+FM9+FN9+FO9+FP9 | FR9: 17523448 | FS9: 148100 | FT9: 28900 | FU9: 0 | FV9: =FR9+FS9+FT9+FU9 | FW9: 19671907 | FX9: 103500 | FY9: 2239345.6 | FZ9: 4819624 | GA9: =FW9+FX9+FY9+FZ9 | GB9: =FV9+GA9 | GC9: 17807809 | GD9: 154745.52 | GE9: 277155.22 | GF9: 8410.99 | GG9: =GC9+GD9+GE9+GF9 | GH9: 15820117 | GI9: 82260 | GJ9: 4303436.5 | GK9: 2122875.8 | GL9: =GH9+GI9+GJ9+GK9 | GM9: =GG9+GL9 | GN9: 1606705.6 | GO9: 2104.08 | GP9: 27149.12 | GQ9: 4637.34 | GR9: =GN9+GO9+GP9+GQ9 | GS9: 2661140 | GT9: 9823 | GU9: 7144 | GV9: 893 | GW9: =GS9+GT9+GU9+GV9 | GX9: =GM9+GR9+GW9 | GY9: 2.4064225e+08 | GZ9: 3665086.1 | HA9: =GY9+GZ9 | HB9: =IF(GX9=0,"",AU9/GX9) | HC9: =IF((GX9+GY9)=0,"",GB9/(GX9+GY9)) | HD9: =IF(GX9=0,"",GB9/GX9) | HE9: 41 | HF9: 1 | HG9: 417 | HH9: 41 | HI9: 20 | HJ9: =HF9+HI9 | HK9: =IF(HE9=0,"",HH9/HE9) | HL9: 13 | HM9: 30 | HN9: =IF(HL9=0,"",HM9/HL9)
A10: Liwonde | B10: Balaka | C10: FY2025/26 | D10: 2025 | E10: 11 | F10: November | G10: Q3 | H10: 49897 | I10: 18041 | J10: 738 | K10: 70 | L10: 7 | M10: =SUM(I10,J10,K10,L10) | N10: 13870.4 | O10: 126 | P10: 1261.7 | Q10: 489.8 | R10: =SUM(N10,O10,P10,Q10) | S10: =M10+R10 | T10: 15293.1 | U10: =IF(H10=0,"",T10/H10) | V10: 108 | W10: =IF(H10=0,"",V10/H10) | X10: 0 | Y10: =IF(H10=0,"",X10/H10) | Z10: 0 | AA10: =IF(H10=0,"",Z10/H10) | AB10: 0 | AC10: =IF(H10=0,"",AB10/H10) | AD10: 0 | AE10: =IF(H10=0,"",AD10/H10) | AF10: 0 | AG10: =IF(H10=0,"",AF10/H10) | AH10: 380731.32 | AI10: =IF(H10=0,"",AH10/H10) | AJ10: 22349 | AK10: =IF(H10=0,"",AJ10/H10) | AL10: 3755588.9 | AM10: =IF(H10=0,"",AL10/H10) | AN10: 5234 | AO10: 220 | AP10: 770000 | AQ10: 0 | AR10: 17028073 | AS10: 6654152.5 | AT10: 7454346.6 | AU10: =AH10+AL10+AP10+AQ10+AR10+AS10+AT10 | AV10: =IF(H10=0,"",AU10/H10) | AW10: =IF(S10=0,"",AU10/S10) | AX10: 14 | AY10: =IF(H10=0,"",AX10/(H10/1000/12)) | AZ10: 47 | BA10: 417 | BB10: 27 | BC10: 32 | BD10: 0 | BE10: =BC10+BD10 | BF10: =BA10+BB10-BE10 | BG10: 0 | BH10: 0 | BI10: 0 | BJ10: 0 | BK10: =BI10+BJ10 | BL10: =BG10+BH10-BK10 | BM10: 0 | BN10: 0 | BO10: 0 | BP10: 0 | BQ10: =BO10+BP10 | BR10: =BM10+BN10-BQ10 | BS10: 0 | BT10: 0 | BU10: 0 | BV10: 0 | BW10: =BU10+BV10 | BX10: =BS10+BT10-BW10 | BY10: =BA10+BG10+BM10+BS10 | BZ10: =BB10+BH10+BN10+BT10 | CA10: =BE10+BK10+BQ10+BW10 | CB10: =BF10+BL10+BR10+BX10 | CC10: 42 | CD10: 2694 | CE10: 50 | CF10: 97 | CG10: 18 | CH10: =CD10+CE10+CF10+CG10 | CI10: 2962 | CJ10: 8 | CK10: 2 | CL10: 11 | CM10: =CI10+CJ10+CK10+CL10 | CN10: 2257 | CO10: 77 | CP10: 73 | CQ10: 5 | CR10: =CN10+CO10+CP10+CQ10 | CS10: =CM10+CR10 | CT10: 8254 | CU10: 42241.341 | CV10: 38017.207 | CW10: =IF(CU10=0,"",CV10/CU10) | DB10: =CX10+CY10-CZ10-DA10 | DC10: 0 | DD10: 0 | DE10: 0 | DF10: 0 | DG10: =DC10+DD10-DE10-DF10 | DH10: 0 | DI10: 0 | DJ10: 0 | DK10: 0 | DL10: =DH10+DI10-DJ10-DK10 | DM10: 193 | DN10: 0 | DO10: 0 | DP10: 1 | DQ10: =DM10+DN10-DO10-DP10 | DR10: =CX10+DC10+DH10+DM10 | DS10: =CY10+DD10+DI10+DN10 | DT10: =CZ10+DE10+DJ10+DO10 | DU10: =DA10+DF10+DK10+DP10 | DV10: =DB10+DG10+DL10+DQ10 | DW10: 128 | DX10: 50 | DY10: 13 | DZ10: 1 | EA10: 5 | EB10: 8 | EC10: 0 | ED10: 1 | EE10: 2 | EF10: 2 | EG10: 0 | EH10: 0 | EI10: 0 | EJ10: 0 | EK10: 0 | EL10: 0 | EM10: 0 | EN10: 0 | EO10: 0 | EP10: 0 | EQ10: 0 | ER10: 0 | ES10: 0 | ET10: 0 | EU10: 0 | EV10: 0 | EW10: 0 | EX10: 0 | EY10: 0 | EZ10: 0 | FA10: 0 | FB10: 0 | FC10: 0 | FD10: 0 | FE10: 0 | FF10: 0 | FG10: =SUM(DW10,DX10,DY10,DZ10,EA10,EB10,EC10,ED10,EE10,EF10,EG10,EH10,EI10,EJ10,EK10,EL10,EM10,EN10,EO10,EP10,EQ10,ER10,ES10,ET10,EU10,EV10,EW10,EX10,EY10,EZ10,FA10,FB10,FC10,FD10,FE10,FF10) | FH10: 0 | FI10: 0 | FJ10: 520 | FK10: 30 | FL10: 0 | FM10: 0 | FN10: 0 | FO10: 0 | FP10: 0 | FQ10: =FL10+FM10+FN10+FO10+FP10 | FR10: 19268980 | FS10: 91000 | FT10: 0 | FU10: 0 | FV10: =FR10+FS10+FT10+FU10 | FW10: 23183279 | FX10: 26700 | FY10: 2530375 | FZ10: 4358291.1 | GA10: =FW10+FX10+FY10+FZ10 | GB10: =FV10+GA10 | GC10: 17976586 | GD10: 141164.64 | GE10: 207889.96 | GF10: 20207.62 | GG10: =GC10+GD10+GE10+GF10 | GH10: 17342172 | GI10: 26700 | GJ10: 3796225.7 | GK10: 2257321.6 | GL10: =GH10+GI10+GJ10+GK10 | GM10: =GG10+GL10 | GN10: 1596633.7 | GO10: 2104.08 | GP10: 27149.12 | GQ10: 9274.68 | GR10: =GN10+GO10+GP10+GQ10 | GS10: 2645066 | GT10: 9823 | GU10: 7144 | GV10: 1786 | GW10: =GS10+GT10+GU10+GV10 | GX10: =GM10+GR10+GW10 | GY10: 1.7394829e+08 | GZ10: 3213544.6 | HA10: =GY10+GZ10 | HB10: =IF(GX10=0,"",AU10/GX10) | HC10: =IF((GX10+GY10)=0,"",GB10/(GX10+GY10)) | HD10: =IF(GX10=0,"",GB10/GX10) | HE10: 27 | HF10: 1 | HG10: 412 | HH10: 27 | HI10: 32 | HJ10: =HF10+HI10 | HK10: =IF(HE10=0,"",HH10/HE10) | HL10: 40 | HM10: 7 | HN10: =IF(HL10=0,"",HM10/HL10)
A11: Liwonde | B11: Balaka | C11: FY2025/26 | D11: 2025 | E11: 12 | F11: December | G11: Q3 | H11: 50365 | I11: 17458 | J11: 660 | K11: 80 | L11: 9 | M11: =SUM(I11,J11,K11,L11) | N11: 15062.8 | O11: 123.3 | P11: 830.9 | Q11: 451.3 | R11: =SUM(N11,O11,P11,Q11) | S11: =M11+R11 | T11: 15689.7 | U11: =IF(H11=0,"",T11/H11) | V11: 110 | W11: =IF(H11=0,"",V11/H11) | X11: 0 | Y11: =IF(H11=0,"",X11/H11) | Z11: 0 | AA11: =IF(H11=0,"",Z11/H11) | AB11: 0 | AC11: =IF(H11=0,"",AB11/H11) | AD11: 0 | AE11: =IF(H11=0,"",AD11/H11) | AF11: 0 | AG11: =IF(H11=0,"",AF11/H11) | AH11: 387781.9 | AI11: =IF(H11=0,"",AH11/H11) | AJ11: 21444 | AK11: =IF(H11=0,"",AJ11/H11) | AL11: 3604293.3 | AM11: =IF(H11=0,"",AL11/H11) | AN11: 5332 | AO11: 215 | AP11: 752500 | AQ11: 0 | AR11: 17248877 | AS11: 8030643 | AT11: 5002000 | AU11: =AH11+AL11+AP11+AQ11+AR11+AS11+AT11 | AV11: =IF(H11=0,"",AU11/H11) | AW11: =IF(S11=0,"",AU11/S11) | AX11: 15 | AY11: =IF(H11=0,"",AX11/(H11/1000/12)) | AZ11: 47 | BA11: 412 | BB11: 23 | BC11: 31 | BD11: 0 | BE11: =BC11+BD11 | BF11: =BA11+BB11-BE11 | BG11: 0 | BH11: 0 | BI11: 0 | BJ11: 0 | BK11: =BI11+BJ11 | BL11: =BG11+BH11-BK11 | BM11: 0 | BN11: 0 | BO11: 0 | BP11: 0 | BQ11: =BO11+BP11 | BR11: =BM11+BN11-BQ11 | BS11: 0 | BT11: 0 | BU11: 0 | BV11: 0 | BW11: =BU11+BV11 | BX11: =BS11+BT11-BW11 | BY11: =BA11+BG11+BM11+BS11 | BZ11: =BB11+BH11+BN11+BT11 | CA11: =BE11+BK11+BQ11+BW11 | CB11: =BF11+BL11+BR11+BX11 | CC11: 15 | CD11: 2683 | CE11: 49 | CF11: 96 | CG11: 18 | CH11: =CD11+CE11+CF11+CG11 | CI11: 2964 | CJ11: 8 | CK11: 2 | CL11: 11 | CM11: =CI11+CJ11+CK11+CL11 | CN11: 2306 | CO11: 78 | CP11: 73 | CQ11: 5 | CR11: =CN11+CO11+CP11+CQ11 | CS11: =CM11+CR11 | CT11: 8293 | CU11: 46253 | CV11: 38017 | CW11: =IF(CU11=0,"",CV11/CU11) | DB11: =CX11+CY11-CZ11-DA11 | DC11: 0 | DD11: 0 | DE11: 0 | DF11: 0 | DG11: =DC11+DD11-DE11-DF11 | DH11: 0 | DI11: 0 | DJ11: 0 | DK11: 0 | DL11: =DH11+DI11-DJ11-DK11 | DM11: 192 | DN11: 10 | DO11: 5 | DP11: 3 | DQ11: =DM11+DN11-DO11-DP11 | DR11: =CX11+DC11+DH11+DM11 | DS11: =CY11+DD11+DI11+DN11 | DT11: =CZ11+DE11+DJ11+DO11 | DU11: =DA11+DF11+DK11+DP11 | DV11: =DB11+DG11+DL11+DQ11 | DW11: 71 | DX11: 29 | DY11: 5 | DZ11: 0 | EA11: 3 | EB11: 4 | EC11: 0 | ED11: 0 | EE11: 4 | EF11: 4 | EG11: 0 | EH11: 0 | EI11: 0 | EJ11: 0 | EK11: 0 | EL11: 0 | EM11: 0 | EN11: 0 | EO11: 0 | EP11: 0 | EQ11: 0 | ER11: 0 | ES11: 0 | ET11: 0 | EU11: 0 | EV11: 0 | EW11: 0 | EX11: 0 | EY11: 0 | EZ11: 0 | FA11: 0 | FB11: 0 | FC11: 0 | FD11: 0 | FE11: 0 | FF11: 0 | FG11: =SUM(DW11,DX11,DY11,DZ11,EA11,EB11,EC11,ED11,EE11,EF11,EG11,EH11,EI11,EJ11,EK11,EL11,EM11,EN11,EO11,EP11,EQ11,ER11,ES11,ET11,EU11,EV11,EW11,EX11,EY11,EZ11,FA11,FB11,FC11,FD11,FE11,FF11) | FH11: 0 | FI11: 0 | FJ11: 644 | FK11: 88 | FL11: 0 | FM11: 0 | FN11: 18 | FO11: 0 | FP11: 180 | FQ11: =FL11+FM11+FN11+FO11+FP11 | FR11: 30042506 | FS11: 130400 | FT11: 65850 | FU11: 32000 | FV11: =FR11+FS11+FT11+FU11 | FW11: 23832534 | FX11: 26200 | FY11: 2181528.1 | FZ11: 2906763.8 | GA11: =FW11+FX11+FY11+FZ11 | GB11: =FV11+GA11 | GC11: 17732946 | GD11: 126244.8 | GE11: 228676.05 | GF11: 20207.62 | GG11: =GC11+GD11+GE11+GF11 | GH11: 18795695 | GI11: 26200 | GJ11: 2489367.9 | GK11: 2055485.7 | GL11: =GH11+GI11+GJ11+GK11 | GM11: =GG11+GL11 | GN11: 1598112.2 | GO11: 2104.08 | GP11: 27149.12 | GQ11: 9274.68 | GR11: =GN11+GO11+GP11+GQ11 | GS11: 2646852 | GT11: 9823 | GU11: 7144 | GV11: 1786 | GW11: =GS11+GT11+GU11+GV11 | GX11: =GM11+GR11+GW11 | GY11: 1.6783518e+08 | GZ11: 3443415.6 | HA11: =GY11+GZ11 | HB11: =IF(GX11=0,"",AU11/GX11) | HC11: =IF((GX11+GY11)=0,"",GB11/(GX11+GY11)) | HD11: =IF(GX11=0,"",GB11/GX11) | HE11: 23 | HF11: 1 | HG11: 404 | HH11: 23 | HI11: 20 | HJ11: =HF11+HI11 | HK11: =IF(HE11=0,"",HH11/HE11) | HL11: 45 | HM11: 7 | HN11: =IF(HL11=0,"",HM11/HL11)
A12: Liwonde | B12: Balaka | C12: FY2025/26 | D12: 2026 | E12: 1 | F12: January | G12: Q4 | H12: 47566 | I12: 15995 | J12: 666 | K12: 103 | L12: 10 | M12: 16774 | N12: 13862.7 | O12: 280.9 | P12: 962.7 | Q12: 564.9 | R12: 15671.2 | S12: 32445.2 | T12: 15120.8 | U12: 0.31789093 | V12: 42 | W12: 0.88298364 | X12: 0 | Y12: 0 | Z12: 0 | AA12: 0 | AB12: 0 | AC12: 0 | AD12: 0 | AE12: 0 | AF12: 0 | AG12: 0 | AH12: 148062.18 | AI12: 3.1127734 | AJ12: 22345 | AK12: 0.46976832 | AL12: 3754920.2 | AM12: 78.941266 | AN12: 6789 | AO12: 115 | AP12: 575000 | AQ12: 0 | AR12: 17248877 | AS12: 7732934.5 | AT12: 1654402.5 | AU12: 31114197 | AV12: 654.12683 | AW12: 958.97688 | AX12: 14 | AY12: 9.1241643 | AZ12: 50 | BA12: 404 | BB12: 27 | BC12: 23 | BD12: 0 | BE12: 23 | BF12: 408 | BG12: 0 | BH12: 0 | BI12: 0 | BJ12: 0 | BK12: 0 | BL12: 0 | BM12: 0 | BN12: 0 | BO12: 0 | BP12: 0 | BQ12: 0 | BR12: 0 | BS12: 0 | BT12: 0 | BU12: 0 | BV12: 0 | BW12: 0 | BX12: 0 | BY12: 404 | BZ12: 27 | CA12: 23 | CB12: 408 | CC12: 23 | CD12: 2740 | CE12: 51 | CF12: 95 | CG12: 18 | CH12: 2904 | CI12: 2903 | CJ12: 6 | CK12: 3 | CL12: 10 | CM12: 2922 | CN12: 2333 | CO12: 78 | CP12: 74 | CQ12: 5 | CR12: 2490 | CS12: 5412 | CT12: 8316 | CU12: 46484 | CV12: 38207 | CW12: 0.82193873 | CX12: 0 | CY12: 0 | CZ12: 0 | DA12: 0 | DB12: 0 | DC12: 0 | DD12: 0 | DE12: 0 | DF12: 0 | DG12: 0 | DH12: 0 | DI12: 0 | DJ12: 0 | DK12: 0 | DL12: 0 | DM12: 194 | DN12: 25 | DO12: 5 | DP12: 3 | DQ12: 211 | DR12: 194 | DS12: 25 | DT12: 5 | DU12: 3 | DV12: 211 | DW12: 115 | DX12: 67 | DY12: 23 | DZ12: 6 | EA12: 14 | EB12: 0 | EC12: 0 | ED12: 0 | EE12: 0 | EF12: 0 | EG12: 0 | EH12: 0 | EI12: 0 | EJ12: 0 | EK12: 0 | EL12: 0 | EM12: 0 | EN12: 0 | EO12: 0 | EP12: 0 | EQ12: 0 | ER12: 0 | ES12: 0 | ET12: 0 | EU12: 0 | EV12: 0 | EW12: 0 | EX12: 0 | EY12: 0 | EZ12: 0 | FA12: 0 | FB12: 0 | FC12: 0 | FD12: 0 | FE12: 0 | FF12: 0 | FG12: 225 | FH12: 0 | FI12: 0 | FJ12: 468 | FK12: 54 | FL12: 0 | FM12: 372 | FN12: 0 | FO12: 66 | FP12: 0 | FQ12: 438 | FR12: 24140239 | FS12: 184000 | FT12: 14000 | FU12: 77000 | FV12: 24415239 | FW12: 20269195 | FX12: 81700 | FY12: 2720500 | FZ12: 3334136.3 | GA12: 26405531 | GB12: 50820770 | GC12: 16119351 | GD12: 127392.48 | GE12: 324859.8 | GF12: 32004.25 | GG12: 16603608 | GH12: 17307497 | GI12: 59680 | GJ12: 2925000.3 | GK12: 2671960 | GL12: 22964138 | GM12: 39567745 | GN12: 1566227.6 | GO12: 1912.8 | GP12: 20361.84 | GQ12: 13912.02 | GR12: 1602414.3 | GS12: 2592379 | GT12: 8930 | GU12: 5358 | GV12: 2679 | GW12: 2609346 | GX12: 43779505 | GY12: 1.2175665e+08 | GZ12: 1757068.6 | HA12: 1.2351372e+08 | HB12: 43779505 | HC12: 1.2175665e+08 | HD12: 1757068.6 | HE12: 27 | HF12: 1 | HG12: 408 | HH12: 27 | HI12: 20 | HJ12: 0.74074074 | HK12: 5.6372549 | HL12: 20 | HM12: 15 | HN12: 1.3333333
A13: Liwonde | B13: Balaka | C13: FY2025/26 | D13: 2026 | E13: 2 | F13: February | G13: Q4 | H13: 48213 | I13: 19774 | J13: 366 | K13: 56 | L13: 10 | M13: =SUM(I13,J13,K13,L13) | N13: 11339.5 | O13: 128.9 | P13: 639.2 | Q13: 1003.5 | R13: =SUM(N13,O13,P13,Q13) | S13: =M13+R13 | T13: 14895.9 | U13: =IF(H13=0,"",T13/H13) | V13: 112 | W13: =IF(H13=0,"",V13/H13) | X13: 0 | Y13: =IF(H13=0,"",X13/H13) | Z13: 0 | AA13: =IF(H13=0,"",Z13/H13) | AB13: 0 | AC13: =IF(H13=0,"",AB13/H13) | AD13: 0 | AE13: =IF(H13=0,"",AD13/H13) | AF13: 0 | AG13: =IF(H13=0,"",AF13/H13) | AH13: 394832.48 | AI13: =IF(H13=0,"",AH13/H13) | AJ13: 12203 | AK13: =IF(H13=0,"",AJ13/H13) | AL13: 2059406 | AM13: =IF(H13=0,"",AL13/H13) | AN13: 6342 | AO13: 112 | AP13: 560000 | AQ13: 0 | AR13: 18768051 | AS13: 0 | AT13: 5351000 | AU13: =AH13+AL13+AP13+AQ13+AR13+AS13+AT13 | AV13: =IF(H13=0,"",AU13/H13) | AW13: =IF(S13=0,"",AU13/S13) | AX13: 14 | AY13: =IF(H13=0,"",AX13/(H13/1000/12)) | AZ13: 50 | BA13: 408 | BB13: 35 | BC13: 30 | BD13: 0 | BE13: =BC13+BD13 | BF13: =BA13+BB13-BE13 | BG13: 0 | BH13: 0 | BI13: 0 | BJ13: 0 | BK13: =BI13+BJ13 | BL13: =BG13+BH13-BK13 | BM13: 0 | BN13: 0 | BO13: 0 | BP13: 0 | BQ13: =BO13+BP13 | BR13: =BM13+BN13-BQ13 | BS13: 0 | BT13: 0 | BU13: 0 | BV13: 0 | BW13: =BU13+BV13 | BX13: =BS13+BT13-BW13 | BY13: =BA13+BG13+BM13+BS13 | BZ13: =BB13+BH13+BN13+BT13 | CA13: =BE13+BK13+BQ13+BW13 | CB13: =BF13+BL13+BR13+BX13 | CC13: 33 | CD13: 2696 | CE13: 51 | CF13: 95 | CG13: 18 | CH13: =CD13+CE13+CF13+CG13 | CI13: 2948 | CJ13: 6 | CK13: 3 | CL13: 10 | CM13: =CI13+CJ13+CK13+CL13 | CN13: 2362 | CO13: 78 | CP13: 74 | CQ13: 5 | CR13: =CN13+CO13+CP13+CQ13 | CS13: =CM13+CR13 | CT13: 8346 | CU13: 46948 | CV13: 38589 | CW13: =IF(CU13=0,"",CV13/CU13) | DB13: =CX13+CY13-CZ13-DA13 | DC13: 0 | DD13: 0 | DE13: 0 | DF13: 0 | DG13: =DC13+DD13-DE13-DF13 | DH13: 0 | DI13: 0 | DJ13: 0 | DK13: 0 | DL13: =DH13+DI13-DJ13-DK13 | DM13: 211 | DN13: 60 | DO13: 0 | DP13: 0 | DQ13: =DM13+DN13-DO13-DP13 | DR13: =CX13+DC13+DH13+DM13 | DS13: =CY13+DD13+DI13+DN13 | DT13: =CZ13+DE13+DJ13+DO13 | DU13: =DA13+DF13+DK13+DP13 | DV13: =DB13+DG13+DL13+DQ13 | DW13: 76 | DX13: 50 | DY13: 24 | DZ13: 2 | EA13: 3 | EB13: 4 | EC13: 0 | ED13: 0 | EE13: 2 | EF13: 0 | EG13: 2 | EH13: 0 | EI13: 0 | EJ13: 0 | EK13: 0 | EL13: 0 | EM13: 0 | EN13: 0 | EO13: 0 | EP13: 0 | EQ13: 0 | ER13: 0 | ES13: 0 | ET13: 0 | EU13: 0 | EV13: 0 | EW13: 0 | EX13: 0 | EY13: 0 | EZ13: 0 | FA13: 0 | FB13: 0 | FC13: 0 | FD13: 0 | FE13: 0 | FF13: 0 | FG13: =SUM(DW13,DX13,DY13,DZ13,EA13,EB13,EC13,ED13,EE13,EF13,EG13,EH13,EI13,EJ13,EK13,EL13,EM13,EN13,EO13,EP13,EQ13,ER13,ES13,ET13,EU13,EV13,EW13,EX13,EY13,EZ13,FA13,FB13,FC13,FD13,FE13,FF13) | FH13: 0 | FI13: 0 | FJ13: 540 | FK13: 62 | FL13: 0 | FM13: 356 | FN13: 0 | FO13: 24 | FP13: 0 | FQ13: =FL13+FM13+FN13+FO13+FP13 | FR13: 15822773 | FS13: 104000 | FT13: 34700 | FU13: 364867.22 | FV13: =FR13+FS13+FT13+FU13 | FW13: 15836709 | FX13: 42260 | FY13: 4763717.5 | FZ13: 1951714.6 | GA13: =FW13+FX13+FY13+FZ13 | GB13: =FV13+GA13 | GC13: 20211628 | GD13: 70008.48 | GE13: 137731.6 | GF13: 25232.97 | GG13: =GC13+GD13+GE13+GF13 | GH13: 14156304 | GI13: 27380 | GJ13: 1942714.6 | GK13: 4743083.4 | GL13: =GH13+GI13+GJ13+GK13 | GM13: =GG13+GL13 | GN13: 1586020.5 | GO13: 1912.8 | GP13: 20361.84 | GQ13: 13912.02 | GR13: =GN13+GO13+GP13+GQ13 | GS13: 2632564 | GT13: 8930 | GU13: 5358 | GV13: 2679 | GW13: =GS13+GT13+GU13+GV13 | GX13: =GM13+GR13+GW13 | GY13: 1.31301e+08 | GZ13: 1920766.6 | HA13: =GY13+GZ13 | HB13: =IF(GX13=0,"",AU13/GX13) | HC13: =IF((GX13+GY13)=0,"",GB13/(GX13+GY13)) | HD13: =IF(GX13=0,"",GB13/GX13) | HE13: 33 | HF13: 1 | HG13: 413 | HH13: 35 | HI13: 20 | HJ13: =HF13+HI13 | HK13: =IF(HE13=0,"",HH13/HE13) | HL13: 16 | HM13: 15 | HN13: =IF(HL13=0,"",HM13/HL13)
A14: Liwonde | B14: Balaka | C14: FY2025/26 | D14: 2026 | E14: 3 | F14: March | G14: Q4 | H14: 48339 | I14: 17560 | J14: 489 | K14: 66 | L14: 4 | M14: =SUM(I14,J14,K14,L14) | N14: 14183.8 | O14: 214 | P14: 943.3 | Q14: 318 | R14: =SUM(N14,O14,P14,Q14) | S14: =M14+R14 | T14: 14560.9 | U14: =IF(H14=0,"",T14/H14) | V14: 46 | W14: =IF(H14=0,"",V14/H14) | X14: 0 | Y14: =IF(H14=0,"",X14/H14) | Z14: 0 | AA14: =IF(H14=0,"",Z14/H14) | AB14: 0 | AC14: =IF(H14=0,"",AB14/H14) | AD14: 0 | AE14: =IF(H14=0,"",AD14/H14) | AF14: 0 | AG14: =IF(H14=0,"",AF14/H14) | AH14: 162163.34 | AI14: =IF(H14=0,"",AH14/H14) | AJ14: 27325 | AK14: =IF(H14=0,"",AJ14/H14) | AL14: 19339 | AM14: =IF(H14=0,"",AL14/H14) | AN14: 6542 | AO14: 200 | AP14: 1000000 | AQ14: 0 | AR14: 17872104 | AS14: 6951595.8 | AT14: 175400 | AU14: =AH14+AL14+AP14+AQ14+AR14+AS14+AT14 | AV14: =IF(H14=0,"",AU14/H14) | AW14: =IF(S14=0,"",AU14/S14) | AX14: 14 | AY14: =IF(H14=0,"",AX14/(H14/1000/12)) | AZ14: 50 | BA14: 413 | BB14: 30 | BC14: 24 | BD14: 0 | BE14: =BC14+BD14 | BF14: =BA14+BB14-BE14 | BG14: 0 | BH14: 0 | BI14: 0 | BJ14: 0 | BK14: =BI14+BJ14 | BL14: =BG14+BH14-BK14 | BM14: 0 | BN14: 0 | BO14: 0 | BP14: 0 | BQ14: =BO14+BP14 | BR14: =BM14+BN14-BQ14 | BS14: 0 | BT14: 0 | BU14: 0 | BV14: 0 | BW14: =BU14+BV14 | BX14: =BS14+BT14-BW14 | BY14: =BA14+BG14+BM14+BS14 | BZ14: =BB14+BH14+BN14+BT14 | CA14: =BE14+BK14+BQ14+BW14 | CB14: =BF14+BL14+BR14+BX14 | CC14: 15 | CD14: 2544 | CE14: 62 | CF14: 94 | CG14: 19 | CH14: =CD14+CE14+CF14+CG14 | CI14: 3166 | CJ14: 6 | CK14: 2 | CL14: 10 | CM14: =CI14+CJ14+CK14+CL14 | CN14: 2390 | CO14: 67 | CP14: 75 | CQ14: 5 | CR14: =CN14+CO14+CP14+CQ14 | CS14: =CM14+CR14 | CT14: 8440 | CU14: 47417 | CV14: 38974 | CW14: =IF(CU14=0,"",CV14/CU14) | DB14: =CX14+CY14-CZ14-DA14 | DC14: 0 | DD14: 0 | DE14: 0 | DF14: 0 | DG14: =DC14+DD14-DE14-DF14 | DH14: 0 | DI14: 0 | DJ14: 0 | DK14: 0 | DL14: =DH14+DI14-DJ14-DK14 | DM14: 271 | DN14: 36 | DO14: 0 | DP14: 0 | DQ14: =DM14+DN14-DO14-DP14 | DR14: =CX14+DC14+DH14+DM14 | DS14: =CY14+DD14+DI14+DN14 | DT14: =CZ14+DE14+DJ14+DO14 | DU14: =DA14+DF14+DK14+DP14 | DV14: =DB14+DG14+DL14+DQ14 | DW14: 61 | DX14: 31 | DY14: 12 | DZ14: 2 | EA14: 0 | EB14: 7 | EC14: 0 | ED14: 0 | EE14: 0 | EF14: 0 | EG14: 0 | EH14: 0 | EI14: 0 | EJ14: 0 | EK14: 0 | EL14: 0 | EM14: 0 | EN14: 0 | EO14: 0 | EP14: 0 | EQ14: 0 | ER14: 0 | ES14: 0 | ET14: 0 | EU14: 0 | EV14: 0 | EW14: 0 | EX14: 0 | EY14: 0 | EZ14: 0 | FA14: 0 | FB14: 0 | FC14: 0 | FD14: 0 | FE14: 0 | FF14: 0 | FG14: =SUM(DW14,DX14,DY14,DZ14,EA14,EB14,EC14,ED14,EE14,EF14,EG14,EH14,EI14,EJ14,EK14,EL14,EM14,EN14,EO14,EP14,EQ14,ER14,ES14,ET14,EU14,EV14,EW14,EX14,EY14,EZ14,FA14,FB14,FC14,FD14,FE14,FF14) | FH14: 0 | FI14: 0 | FJ14: 480 | FK14: 52 | FL14: 390 | FM14: 0 | FN14: 0 | FO14: 0 | FP14: 150 | FQ14: =FL14+FM14+FN14+FO14+FP14 | FR14: 25246524 | FS14: 63100 | FT14: 60000 | FU14: 247867.22 | FV14: =FR14+FS14+FT14+FU14 | FW14: 19444708 | FX14: 62580 | FY14: 1542422.8 | FZ14: 2898400 | GA14: =FW14+FX14+FY14+FZ14 | GB14: =FV14+GA14 | GC14: 17559720 | GD14: 93535.92 | GE14: 175575.51 | GF14: 16821.98 | GG14: =GC14+GD14+GE14+GF14 | GH14: 17700982 | GI14: 45486 | GJ14: 2867320 | GK14: 1503002.8 | GL14: =GH14+GI14+GJ14+GK14 | GM14: =GG14+GL14 | GN14: 1554802.8 | GO14: 1912.8 | GP14: 20361.84 | GQ14: 9274.68 | GR14: =GN14+GO14+GP14+GQ14 | GS14: 2578984 | GT14: 8930 | GU14: 5358 | GV14: 1786 | GW14: =GS14+GT14+GU14+GV14 | GX14: =GM14+GR14+GW14 | GY14: 1.2641896e+08 | GZ14: 1202893.8 | HA14: =GY14+GZ14 | HB14: =IF(GX14=0,"",AU14/GX14) | HC14: =IF((GX14+GY14)=0,"",GB14/(GX14+GY14)) | HD14: =IF(GX14=0,"",GB14/GX14) | HE14: 30 | HF14: 1 | HG14: 419 | HH14: 30 | HI14: 20 | HJ14: =HF14+HI14 | HK14: =IF(HE14=0,"",HH14/HE14) | HL14: 20 | HM14: 15 | HN14: =IF(HL14=0,"",HM14/HL14)
A15: Liwonde | B15: Liwonde | C15: FY2025/26 | D15: 2025 | E15: 4 | F15: April | G15: Q1 | H15: 64376 | I15: 30208 | J15: 970 | K15: 936 | L15: 353 | M15: =SUM(I15,J15,K15,L15) | N15: 11071.6 | O15: 0 | P15: 977.6 | Q15: 1886.7 | R15: =SUM(N15,O15,P15,Q15) | S15: =M15+R15 | T15: 17973.1 | U15: =IF(H15=0,"",T15/H15) | V15: 276 | W15: =IF(H15=0,"",V15/H15) | X15: 658 | Y15: =IF(H15=0,"",X15/H15) | Z15: 0 | AA15: =IF(H15=0,"",Z15/H15) | AB15: 0 | AC15: =IF(H15=0,"",AB15/H15) | AD15: 0 | AE15: =IF(H15=0,"",AD15/H15) | AF15: 0 | AG15: =IF(H15=0,"",AF15/H15) | AH15: 1670466.8 | AI15: =IF(H15=0,"",AH15/H15) | AJ15: 56715 | AK15: =IF(H15=0,"",AJ15/H15) | AL15: 9500810.9 | AM15: =IF(H15=0,"",AL15/H15) | AN15: 2712 | AO15: 300 | AP15: 441000 | AQ15: 0 | AR15: 15500413 | AS15: 3913343.4 | AT15: 7391853.6 | AU15: =AH15+AL15+AP15+AQ15+AR15+AS15+AT15 | AV15: =IF(H15=0,"",AU15/H15) | AW15: =IF(S15=0,"",AU15/S15) | AX15: 24 | AY15: =IF(H15=0,"",AX15/(H15/1000/12)) | AZ15: 26 | BA15: 678 | BB15: 42 | BC15: 0 | BD15: 36 | BE15: =BC15+BD15 | BF15: =BA15+BB15-BE15 | BG15: 0 | BH15: 0 | BI15: 0 | BJ15: 0 | BK15: =BI15+BJ15 | BL15: =BG15+BH15-BK15 | BM15: 0 | BN15: 0 | BO15: 0 | BP15: 0 | BQ15: =BO15+BP15 | BR15: =BM15+BN15-BQ15 | BS15: 0 | BT15: 0 | BU15: 0 | BV15: 0 | BW15: =BU15+BV15 | BX15: =BS15+BT15-BW15 | BY15: =BA15+BG15+BM15+BS15 | BZ15: =BB15+BH15+BN15+BT15 | CA15: =BE15+BK15+BQ15+BW15 | CB15: =BF15+BL15+BR15+BX15 | CC15: 36 | CD15: 1458 | CE15: 33 | CF15: 20 | CG15: 15 | CH15: =CD15+CE15+CF15+CG15 | CI15: 2896 | CJ15: 14 | CK15: 9 | CL15: 13 | CM15: =CI15+CJ15+CK15+CL15 | CN15: 1128 | CO15: 105 | CP15: 186 | CQ15: 0 | CR15: =CN15+CO15+CP15+CQ15 | CS15: =CM15+CR15 | CT15: 5877 | CU15: 33916 | CV15: 30524.4 | CW15: =IF(CU15=0,"",CV15/CU15) | DB15: =CX15+CY15-CZ15-DA15 | DC15: 0 | DD15: 0 | DE15: 0 | DF15: 0 | DG15: =DC15+DD15-DE15-DF15 | DH15: 0 | DI15: 0 | DJ15: 0 | DK15: 0 | DL15: =DH15+DI15-DJ15-DK15 | DM15: 293 | DN15: 0 | DO15: 0 | DP15: 39 | DQ15: =DM15+DN15-DO15-DP15 | DR15: =CX15+DC15+DH15+DM15 | DS15: =CY15+DD15+DI15+DN15 | DT15: =CZ15+DE15+DJ15+DO15 | DU15: =DA15+DF15+DK15+DP15 | DV15: =DB15+DG15+DL15+DQ15 | DW15: 94 | DX15: 28 | DY15: 14 | DZ15: 4 | EA15: 2 | EB15: 8 | EC15: 0 | ED15: 4 | EE15: 18 | EF15: 9 | EG15: 0 | EH15: 0 | EI15: 0 | EJ15: 0 | EK15: 0 | EL15: 0 | EM15: 0 | EN15: 0 | EO15: 0 | EP15: 0 | EQ15: 0 | ER15: 0 | ES15: 0 | ET15: 0 | EU15: 0 | EV15: 0 | EW15: 0 | EX15: 0 | EY15: 0 | EZ15: 0 | FA15: 0 | FB15: 0 | FC15: 0 | FD15: 0 | FE15: 0 | FF15: 0 | FG15: =SUM(DW15,DX15,DY15,DZ15,EA15,EB15,EC15,ED15,EE15,EF15,EG15,EH15,EI15,EJ15,EK15,EL15,EM15,EN15,EO15,EP15,EQ15,ER15,ES15,ET15,EU15,EV15,EW15,EX15,EY15,EZ15,FA15,FB15,FC15,FD15,FE15,FF15) | FH15: 1 | FI15: 56 | FJ15: 720 | FK15: 0 | FL15: 0 | FM15: 0 | FN15: 0 | FO15: 0 | FP15: 0 | FQ15: =FL15+FM15+FN15+FO15+FP15 | FR15: 22564673 | FS15: 32500 | FT15: 4754131.3 | FU15: 5141655.8 | FV15: =FR15+FS15+FT15+FU15 | FW15: 13947465 | FX15: 0 | FY15: 9263418.1 | FZ15: 3163124.8 | GA15: =FW15+FX15+FY15+FZ15 | GB15: =FV15+GA15 | GC15: 27814109 | GD15: 185541.6 | GE15: 3178071.6 | GF15: 1654100.6 | GG15: =GC15+GD15+GE15+GF15 | GH15: 13814125 | GI15: 0 | GJ15: 2971124.8 | GK15: 8921850.4 | GL15: =GH15+GI15+GJ15+GK15 | GM15: =GG15+GL15 | GN15: 1551321.1 | GO15: 2486.64 | GP15: 47510.96 | GQ15: 41736.06 | GR15: =GN15+GO15+GP15+GQ15 | GS15: 2586128 | GT15: 11609 | GU15: 12502 | GV15: 8037 | GW15: =GS15+GT15+GU15+GV15 | GX15: =GM15+GR15+GW15 | GY15: 2.2634255e+08 | GZ15: 8416922.3 | HA15: =GY15+GZ15 | HB15: =IF(GX15=0,"",AU15/GX15) | HC15: =IF((GX15+GY15)=0,"",GB15/(GX15+GY15)) | HD15: =IF(GX15=0,"",GB15/GX15) | HE15: 42 | HF15: 20 | HG15: 684 | HH15: 42 | HI15: 20 | HJ15: =HF15+HI15 | HK15: =IF(HE15=0,"",HH15/HE15) | HL15: 12 | HM15: 30 | HN15: =IF(HL15=0,"",HM15/HL15)
A16: Liwonde | B16: Liwonde | C16: FY2025/26 | D16: 2025 | E16: 5 | F16: May | G16: Q1 | H16: 60718 | I16: 23130 | J16: 476 | K16: 617 | L16: 290 | M16: =SUM(I16,J16,K16,L16) | N16: 11701.7 | O16: 0 | P16: 4927.5 | Q16: 1757.4 | R16: =SUM(N16,O16,P16,Q16) | S16: =M16+R16 | T16: 17818.4 | U16: =IF(H16=0,"",T16/H16) | V16: 324 | W16: =IF(H16=0,"",V16/H16) | X16: 225 | Y16: =IF(H16=0,"",X16/H16) | Z16: 0 | AA16: =IF(H16=0,"",Z16/H16) | AB16: 336 | AC16: =IF(H16=0,"",AB16/H16) | AD16: 0 | AE16: =IF(H16=0,"",AD16/H16) | AF16: 0 | AG16: =IF(H16=0,"",AF16/H16) | AH16: 2632876.1 | AI16: =IF(H16=0,"",AH16/H16) | AJ16: 55348.8 | AK16: =IF(H16=0,"",AJ16/H16) | AL16: 9272413 | AM16: =IF(H16=0,"",AL16/H16) | AN16: 2559 | AO16: 436 | AP16: 1192024 | AQ16: 0 | AR16: 15993839 | AS16: 4019251.1 | AT16: 293286.24 | AU16: =AH16+AL16+AP16+AQ16+AR16+AS16+AT16 | AV16: =IF(H16=0,"",AU16/H16) | AW16: =IF(S16=0,"",AU16/S16) | AX16: 24 | AY16: =IF(H16=0,"",AX16/(H16/1000/12)) | AZ16: 46 | BA16: 684 | BB16: 22 | BC16: 0 | BD16: 20 | BE16: =BC16+BD16 | BF16: =BA16+BB16-BE16 | BG16: 0 | BH16: 0 | BI16: 0 | BJ16: 0 | BK16: =BI16+BJ16 | BL16: =BG16+BH16-BK16 | BM16: 0 | BN16: 0 | BO16: 0 | BP16: 0 | BQ16: =BO16+BP16 | BR16: =BM16+BN16-BQ16 | BS16: 0 | BT16: 0 | BU16: 0 | BV16: 0 | BW16: =BU16+BV16 | BX16: =BS16+BT16-BW16 | BY16: =BA16+BG16+BM16+BS16 | BZ16: =BB16+BH16+BN16+BT16 | CA16: =BE16+BK16+BQ16+BW16 | CB16: =BF16+BL16+BR16+BX16 | CC16: 20 | CD16: 1504 | CE16: 33 | CF16: 20 | CG16: 15 | CH16: =CD16+CE16+CF16+CG16 | CI16: 2855 | CJ16: 12 | CK16: 7 | CL16: 12 | CM16: =CI16+CJ16+CK16+CL16 | CN16: 1148 | CO16: 105 | CP16: 186 | CQ16: 0 | CR16: =CN16+CO16+CP16+CQ16 | CS16: =CM16+CR16 | CT16: 5897 | CU16: 33991 | CV16: 30591 | CW16: =IF(CU16=0,"",CV16/CU16) | DB16: =CX16+CY16-CZ16-DA16 | DC16: 0 | DD16: 0 | DE16: 0 | DF16: 0 | DG16: =DC16+DD16-DE16-DF16 | DH16: 0 | DI16: 0 | DJ16: 0 | DK16: 0 | DL16: =DH16+DI16-DJ16-DK16 | DM16: 254 | DN16: 18 | DO16: 0 | DP16: 4 | DQ16: =DM16+DN16-DO16-DP16 | DR16: =CX16+DC16+DH16+DM16 | DS16: =CY16+DD16+DI16+DN16 | DT16: =CZ16+DE16+DJ16+DO16 | DU16: =DA16+DF16+DK16+DP16 | DV16: =DB16+DG16+DL16+DQ16 | DW16: 91 | DX16: 52 | DY16: 6 | DZ16: 6 | EA16: 3 | EB16: 3 | EC16: 0 | ED16: 12 | EE16: 9 | EF16: 13 | EG16: 0 | EH16: 0 | EI16: 1 | EJ16: 0 | EK16: 0 | EL16: 0 | EM16: 0 | EN16: 0 | EO16: 0 | EP16: 0 | EQ16: 0 | ER16: 0 | ES16: 0 | ET16: 0 | EU16: 0 | EV16: 0 | EW16: 0 | EX16: 0 | EY16: 0 | EZ16: 0 | FA16: 0 | FB16: 0 | FC16: 0 | FD16: 0 | FE16: 0 | FF16: 0 | FG16: =SUM(DW16,DX16,DY16,DZ16,EA16,EB16,EC16,ED16,EE16,EF16,EG16,EH16,EI16,EJ16,EK16,EL16,EM16,EN16,EO16,EP16,EQ16,ER16,ES16,ET16,EU16,EV16,EW16,EX16,EY16,EZ16,FA16,FB16,FC16,FD16,FE16,FF16) | FH16: 0 | FI16: 0 | FJ16: 720 | FK16: 0 | FL16: 0 | FM16: 0 | FN16: 0 | FO16: 500 | FP16: 0 | FQ16: =FL16+FM16+FN16+FO16+FP16 | FR16: 36178587 | FS16: 57000 | FT16: 2247970 | FU16: 94867.22 | FV16: =FR16+FS16+FT16+FU16 | FW16: 14753005 | FX16: 0 | FY16: 8492989.6 | FZ16: 15057333 | GA16: =FW16+FX16+FY16+FZ16 | GB16: =FV16+GA16 | GC16: 21883104 | GD16: 91049.28 | GE16: 2083115.4 | GF16: 1273569.6 | GG16: =GC16+GD16+GE16+GF16 | GH16: 14633439 | GI16: 0 | GJ16: 14902774 | GK16: 8286889.6 | GL16: =GH16+GI16+GJ16+GK16 | GM16: =GG16+GL16 | GN16: 1528918 | GO16: 2295.36 | GP16: 40723.68 | GQ16: 32461.38 | GR16: =GN16+GO16+GP16+GQ16 | GS16: 2549515 | GT16: 10716 | GU16: 10716 | GV16: 6251 | GW16: =GS16+GT16+GU16+GV16 | GX16: =GM16+GR16+GW16 | GY16: 2.150367e+08 | GZ16: 10616783 | HA16: =GY16+GZ16 | HB16: =IF(GX16=0,"",AU16/GX16) | HC16: =IF((GX16+GY16)=0,"",GB16/(GX16+GY16)) | HD16: =IF(GX16=0,"",GB16/GX16) | HE16: 22 | HF16: 1 | HG16: 686 | HH16: 22 | HI16: 20 | HJ16: =HF16+HI16 | HK16: =IF(HE16=0,"",HH16/HE16) | HL16: 14 | HM16: 30 | HN16: =IF(HL16=0,"",HM16/HL16)
A17: Liwonde | B17: Liwonde | C17: FY2025/26 | D17: 2025 | E17: 6 | F17: June | G17: Q1 | H17: 54718 | I17: 18981 | J17: 423 | K17: 494 | L17: 191 | M17: =SUM(I17,J17,K17,L17) | N17: 12704.8 | O17: 0 | P17: 3456.1 | Q17: 1590.8 | R17: =SUM(N17,O17,P17,Q17) | S17: =M17+R17 | T17: 16877.3 | U17: =IF(H17=0,"",T17/H17) | V17: 276 | W17: =IF(H17=0,"",V17/H17) | X17: 0 | Y17: =IF(H17=0,"",X17/H17) | Z17: 0 | AA17: =IF(H17=0,"",Z17/H17) | AB17: 432 | AC17: =IF(H17=0,"",AB17/H17) | AD17: 0 | AE17: =IF(H17=0,"",AD17/H17) | AF17: 0 | AG17: =IF(H17=0,"",AF17/H17) | AH17: 2582925.6 | AI17: =IF(H17=0,"",AH17/H17) | AJ17: 71480 | AK17: =IF(H17=0,"",AJ17/H17) | AL17: 11969187 | AM17: =IF(H17=0,"",AL17/H17) | AN17: 2274 | AO17: 294 | AP17: 803796 | AQ17: 0 | AR17: 16837532 | AS17: 5358554.3 | AT17: 19454059 | AU17: =AH17+AL17+AP17+AQ17+AR17+AS17+AT17 | AV17: =IF(H17=0,"",AU17/H17) | AW17: =IF(S17=0,"",AU17/S17) | AX17: 24 | AY17: =IF(H17=0,"",AX17/(H17/1000/12)) | AZ17: 46 | BA17: 686 | BB17: 48 | BC17: 0 | BD17: 22 | BE17: =BC17+BD17 | BF17: =BA17+BB17-BE17 | BG17: 0 | BH17: 0 | BI17: 0 | BJ17: 0 | BK17: =BI17+BJ17 | BL17: =BG17+BH17-BK17 | BM17: 0 | BN17: 0 | BO17: 0 | BP17: 0 | BQ17: =BO17+BP17 | BR17: =BM17+BN17-BQ17 | BS17: 0 | BT17: 0 | BU17: 0 | BV17: 0 | BW17: =BU17+BV17 | BX17: =BS17+BT17-BW17 | BY17: =BA17+BG17+BM17+BS17 | BZ17: =BB17+BH17+BN17+BT17 | CA17: =BE17+BK17+BQ17+BW17 | CB17: =BF17+BL17+BR17+BX17 | CC17: 63 | CD17: 1689 | CE17: 33 | CF17: 20 | CG17: 15 | CH17: =CD17+CE17+CF17+CG17 | CI17: 2604 | CJ17: 10 | CK17: 6 | CL17: 7 | CM17: =CI17+CJ17+CK17+CL17 | CN17: 1383 | CO17: 44 | CP17: 108 | CQ17: 0 | CR17: =CN17+CO17+CP17+CQ17 | CS17: =CM17+CR17 | CT17: 5919 | CU17: 34068 | CV17: 30591 | CW17: =IF(CU17=0,"",CV17/CU17) | DB17: =CX17+CY17-CZ17-DA17 | DC17: 0 | DD17: 0 | DE17: 0 | DF17: 0 | DG17: =DC17+DD17-DE17-DF17 | DH17: 0 | DI17: 0 | DJ17: 0 | DK17: 0 | DL17: =DH17+DI17-DJ17-DK17 | DM17: 268 | DN17: 3 | DO17: 0 | DP17: 0 | DQ17: =DM17+DN17-DO17-DP17 | DR17: =CX17+DC17+DH17+DM17 | DS17: =CY17+DD17+DI17+DN17 | DT17: =CZ17+DE17+DJ17+DO17 | DU17: =DA17+DF17+DK17+DP17 | DV17: =DB17+DG17+DL17+DQ17 | DW17: 72 | DX17: 44 | DY17: 28 | DZ17: 2 | EA17: 2 | EB17: 5 | EC17: 2 | ED17: 6 | EE17: 9 | EF17: 2 | EG17: 0 | EH17: 0 | EI17: 0 | EJ17: 0 | EK17: 0 | EL17: 0 | EM17: 0 | EN17: 0 | EO17: 0 | EP17: 0 | EQ17: 0 | ER17: 0 | ES17: 0 | ET17: 0 | EU17: 0 | EV17: 0 | EW17: 0 | EX17: 0 | EY17: 0 | EZ17: 0 | FA17: 0 | FB17: 0 | FC17: 0 | FD17: 0 | FE17: 0 | FF17: 0 | FG17: =SUM(DW17,DX17,DY17,DZ17,EA17,EB17,EC17,ED17,EE17,EF17,EG17,EH17,EI17,EJ17,EK17,EL17,EM17,EN17,EO17,EP17,EQ17,ER17,ES17,ET17,EU17,EV17,EW17,EX17,EY17,EZ17,FA17,FB17,FC17,FD17,FE17,FF17) | FH17: 0 | FI17: 0 | FJ17: 644 | FK17: 21 | FL17: 0 | FM17: 0 | FN17: 0 | FO17: 0 | FP17: 0 | FQ17: =FL17+FM17+FN17+FO17+FP17 | FR17: 55231037 | FS17: 337100 | FT17: 1875470 | FU17: 295934.44 | FV17: =FR17+FS17+FT17+FU17 | FW17: 16014954 | FX17: 0 | FY17: 7768191 | FZ17: 10438909 | GA17: =FW17+FX17+FY17+FZ17 | GB17: =FV17+GA17 | GC17: 17723558 | GD17: 80911.44 | GE17: 1664197.6 | GF17: 824838.04 | GG17: =GC17+GD17+GE17+GF17 | GH17: 15919639 | GI17: 0 | GJ17: 10395380 | GK17: 7454188.7 | GL17: =GH17+GI17+GJ17+GK17 | GM17: =GG17+GL17 | GN17: 1395340.9 | GO17: 1338.96 | GP17: 33936.4 | GQ17: 27824.04 | GR17: =GN17+GO17+GP17+GQ17 | GS17: 2325372 | GT17: 6251 | GU17: 8930 | GV17: 5358 | GW17: =GS17+GT17+GU17+GV17 | GX17: =GM17+GR17+GW17 | GY17: 1.8129881e+08 | GZ17: 7705017.9 | HA17: =GY17+GZ17 | HB17: =IF(GX17=0,"",AU17/GX17) | HC17: =IF((GX17+GY17)=0,"",GB17/(GX17+GY17)) | HD17: =IF(GX17=0,"",GB17/GX17) | HE17: 48 | HF17: 1 | HG17: 712 | HH17: 48 | HI17: 20 | HJ17: =HF17+HI17 | HK17: =IF(HE17=0,"",HH17/HE17) | HL17: 16 | HM17: 30 | HN17: =IF(HL17=0,"",HM17/HL17)
