Workbook

Sheet Balaka
A1: SOUTHERN REGION WATER BOARD
A3: MONTHLY REPORTS - 2023/2024
A4: LIWONDE ZONE
A5: LIWONDE ZONE
A7: PARAMETERS | C7: UNITS | D7: APRIL | E7: MAY | F7: JUNE | G7: JULY | H7: AUGUST | I7: SEPTEMBER | J7: OCTOBER | K7: NOVEMBER | L7: DECEMBER | M7: JANUARY | N7: FEBRUARY | O7: MARCH | P7: TOTALS
A8: PRODUCTION | Q8: APR | R8: MAY | S8: JUN | T8: JUL | U8: AUG | V8: SEP | W8: OCT | X8: NOV | Y8: DEC | Z8: JAN | AA8: FEB | AB8: MAR | AC8: TOTAL
A9: Volume Produced | C9: m3 | D9: 48530 | E9: 61068 | F9: 63082 | G9: 60779 | H9: 62610 | I9: 67798 | J9: 70492 | K9: 72435 | L9: 66190 | M9: 65670 | N9: 65071 | O9: 52112 | P9: =SUM(D9:O9) -> 755837 | Q9: 0 | R9: 0 | S9: 0 | T9: 0 | U9: 0 | V9: 0 | W9: 0 | X9: 0 | Y9: 0 | Z9: 0 | AA9: 0 | AB9: 0 | AC9: 0
A10: REVENUE WATER - POSTPAID | Q10: 0 | R10: 0 | S10: 0 | T10: 0 | U10: 0 | V10: 0 | W10: 0 | X10: 0 | Y10: 0 | Z10: 0 | AA10: 0 | AB10: 0 | AC10: 0
A11: Volume Billed Individuals | C11: m3 | D11: 23018 | E11: 26253 | F11: 25377 | G11: 25441 | H11: 27639 | I11: 31483 | J11: 33851 | K11: 37133 | L11: 31345 | M11: 34534 | N11: 31684 | O11: 29326 | P11: =SUM(D11:O11) -> 357084 | Q11: 0 | R11: 0 | S11: 0 | T11: 0 | U11: 0 | V11: 0 | W11: 0 | X11: 0 | Y11: 0 | Z11: 0 | AA11: 0 | AB11: 0 | AC11: 0
A12: Volume Billed CWPs | C12: m3 | D12: 1035 | E12: 1000 | F12: 434 | G12: 1049 | H12: 1254 | I12: 1228 | J12: 1323 | K12: 1269 | L12: 1173 | M12: 1037 | N12: 1267 | O12: 844 | P12: =SUM(D12:O12) -> 12913 | Q12: 0 | R12: 0 | S12: 0 | T12: 0 | U12: 0 | V12: 0 | W12: 0 | X12: 0 | Y12: 0 | Z12: 0 | AA12: 0 | AB12: 0 | AC12: 0
A13: Volume Billed Institutions | C13: m3 | D13: 552 | E13: 200 | F13: 2451 | G13: 228 | H13: 290 | I13: 390 | J13: 421 | K13: 199 | L13: 171 | M13: 420 | N13: 143 | O13: 160 | P13: =SUM(D13:O13) -> 5625 | Q13: 0 | R13: 0 | S13: 0 | T13: 0 | U13: 0 | V13: 0 | W13: 0 | X13: 0 | Y13: 0 | Z13: 0 | AA13: 0 | AB13: 0 | AC13: 0
A14: Volume Billed Commercial/Industrial | C14: m3 | D14: 55 | E14: 53 | F14: 150 | G14: 43 | H14: 150 | I14: 149 | J14: 110 | K14: 39 | L14: 38 | M14: 35 | N14: 82 | O14: 91 | P14: =SUM(D14:O14) -> 995 | Q14: 0 | R14: 0 | S14: 0 | T14: 0 | U14: 0 | V14: 0 | W14: 0 | X14: 0 | Y14: 0 | Z14: 0 | AA14: 0 | AB14: 0 | AC14: 0
A15: Total Volume Billed Post Paid | C15: m3 | D15: =SUM(D11:D14) -> 24660 | E15: =SUM(E11:E14) -> 27506 | F15: =SUM(F11:F14) -> 28412 | G15: =SUM(G11:G14) -> 26761 | H15: =SUM(H11:H14) -> 29333 | I15: =SUM(I11:I14) -> 33250 | J15: =SUM(J11:J14) -> 35705 | K15: =SUM(K11:K14) -> 38640 | ... P15: =SUM(P11:P14) -> 376617 | Q15: 0 | R15: 0 | S15: 0 | T15: 0 | U15: 0 | V15: 0 | W15: 0 | X15: 0 | Y15: 0 | Z15: 0 | AA15: 0 | AB15: 0 | AC15: 0
A16: REVENUE WATER - PREPAID
A17: Individuals | C17: m3 | D17: 6897 | E17: 7593 | F17: 7232 | G17: 6169 | H17: 7905 | I17: 6351 | J17: 6689 | K17: 6507 | L17: 7205 | M17: 5531 | N17: 9809 | O17: 5458 | P17: =SUM(D17:O17) -> 83346
A18: CWPs | C18: m3 | D18: 0 | E18: 0 | F18: 0 | G18: 0 | H18: 0 | I18: 0 | K18: 0 | L18: 0 | M18: 0 | N18: 0 | O18: 47 | P18: =SUM(D18:O18) -> 47
A19: Institutions | C19: m3 | D19: 0 | E19: 0 | F19: 0 | G19: 0 | H19: 0 | I19: 1374 | J19: 1462 | K19: 1418 | L19: 1559 | M19: 1196 | N19: 2120 | O19: 392 | P19: =SUM(D19:O19) -> 9521
A20: Commercial/Industrial | C20: m3 | D20: 0 | E20: 0 | F20: 0 | G20: 0 | H20: 0 | I20: 551 | J20: 566 | K20: 549 | L20: 605 | M20: 466 | N20: 827 | O20: 390 | P20: =SUM(D20:O20) -> 3954
A21: Total Volume Prepaid | C21: m3 | D21: =SUM(D17:D20) -> 6897 | E21: =SUM(E17:E20) -> 7593 | F21: =SUM(F17:F20) -> 7232 | G21: =SUM(G17:G20) -> 6169 | H21: =SUM(H17:H20) -> 7905 | I21: =SUM(I17:I20) -> 8276 | J21: =SUM(J17:J20) -> 8717 | K21: =SUM(K17:K20) -> 8474 | ... P21: =SUM(P17:P20) -> 96868
A22: TOTAL REVENUE WATER | C22: m3 | D22: =D21+D15 -> 31557 | E22: =E21+E15 -> 35099 | F22: =F21+F15 -> 35644 | G22: =G21+G15 -> 32930 | H22: =H21+H15 -> 37238 | I22: =I21+I15 -> 41526 | J22: =J21+J15 -> 44422 | K22: =K21+K15 -> 47114 | ... P22: =P21+P15 -> 473485
A24: Non-Revenue Water (NRW) | B24: Volume | C24: m3 | D24: =D9-D22 -> 16973 | E24: =E9-E22 -> 25969 | F24: =F9-F22 -> 27438 | G24: =G9-G22 -> 27849 | H24: =H9-H22 -> 25372 | I24: =I9-I22 -> 26272 | J24: =J9-J22 -> 26070 | K24: =K9-K22 -> 25321 | ... P24: =P9-P22 -> 282352
B25: Percentage | C25: % | D25: =D24/D9 -> 0.34974243 | E25: =E24/E9 -> 0.42524727 | F25: =F24/F9 -> 0.43495767 | G25: =G24/G9 -> 0.45820102 | H25: =H24/H9 -> 0.40523878 | I25: =I24/I9 -> 0.38750406 | J25: =J24/J9 -> 0.3698292 | K25: =K24/K9 -> 0.34956858 | ... P25: =P24/P9 -> 0.37356202
A26: OPERATING EXPENSES
A27: Chemicals
A28: Chemical | B28: Rate(MK/kg)
A29: Chlorine | B29: =176264.5/50 -> 3525.29 | C29: kg | D29: 98 | E29: 120 | F29: 122 | G29: 96 | H29: 114 | I29: 110 | J29: 115 | K29: 121 | L29: 121 | M29: 119 | N29: 125 | O29: 84 | P29: =SUM(D29:O29) -> 1345
C30: kg/mg litre | D30: =D29/(D9/1000) -> 2.0193695 | E30: =E29/(E9/1000) -> 1.9650226 | F30: =F29/(F9/1000) -> 1.9339907 | G30: =G29/(G9/1000) -> 1.5794929 | H30: =H29/(H9/1000) -> 1.8207954 | I30: =I29/(I9/1000) -> 1.6224667 | J30: =J29/(J9/1000) -> 1.6313908 | K30: =K29/(K9/1000) -> 1.6704632 | ... P30: =P29/(P9/1000) -> 1.7794842
A31: Aluminium sulphate | B31: =53000.511/50 -> 1060.0102 | C31: kg | P31: =SUM(D31:O31) -> 0
C32: kg/mg litre | D32: =D31/(D9/1000) -> 0 | E32: =E31/(E9/1000) -> 0 | F32: =F31/(F9/1000) -> 0 | G32: =G31/(G9/1000) -> 0 | H32: =H31/(H9/1000) -> 0 | I32: =I31/(I9/1000) -> 0 | J32: =J31/(J9/1000) -> 0 | K32: =K31/(K9/1000) -> 0 | ... P32: =P31/(P9/1000) -> 0
A33: Soda | B33: =61414.43/50 -> 1228.2886 | C33: kg | P33: =SUM(D33:O33) -> 0
C34: kg/mg litre | D34: =D33/(D9/1000) -> 0 | E34: =E33/(E9/1000) -> 0 | F34: =F33/(F9/1000) -> 0 | G34: =G33/(G9/1000) -> 0 | H34: =H33/(H9/1000) -> 0 | I34: =I33/(I9/1000) -> 0 | J34: =J33/(J9/1000) -> 0 | K34: =K33/(K9/1000) -> 0 | ... P34: =P33/(P9/1000) -> 0
A35: Algae floc | B35: =745345.16/200 -> 3726.7258 | C35: litres
C36: litres/mg litre
A37: Sud floc | B37: =790318.72/200 -> 3951.5936 | C37: litres | D37: 0 | E37: 0 | F37: 0 | G37: 0 | H37: 0 | I37: 0 | J37: 0 | K37: 0 | L37: 0 | M37: 0 | N37: 0 | O37: 0 | P37: =SUM(D37:O37) -> 0
C38: litres/mg litre | D38: =D37/(D9/1000) -> 0 | E38: =E37/(E9/1000) -> 0 | F38: =F37/(F9/1000) -> 0 | G38: =G37/(G9/1000) -> 0 | H38: =H37/(H9/1000) -> 0 | I38: =I37/(I9/1000) -> 0 | J38: =J37/(J9/1000) -> 0 | K38: =K37/(K9/1000) -> 0 | ... P38: =P37/(P9/1000) -> 0
A39: Potasium permanganate | B39: 1950 | C39: kg | D39: 0 | E39: 0 | F39: 0 | G39: 0 | H39: 0 | I39: 0 | J39: 0 | K39: 0 | L39: 0 | M39: 0 | N39: 0 | O39: 0 | P39: =SUM(D39:O39) -> 0
C40: kg/mg litre | D40: =D39/(D9/1000) -> 0 | E40: =E39/(E9/1000) -> 0 | F40: =F39/(F9/1000) -> 0 | G40: =G39/(G9/1000) -> 0 | H40: =H39/(H9/1000) -> 0 | I40: =I39/(I9/1000) -> 0 | J40: =J39/(J9/1000) -> 0 | K40: =K39/(K9/1000) -> 0 | ... P40: =P39/(P9/1000) -> 0
A41: Cost of Chemicals | C41: Mk | D41: =(D29*$B29)+(D31*$B31)+(D33*$B33)+(D35*$B35)+(D37*$B37)+(D39*$B39) -> 345478.42 | E41: =(E29*$B29)+(E31*$B31)+(E33*$B33)+(E35*$B35)+(E37*$B37)+(E39*$B39) -> 423034.8 | F41: =(F29*$B29)+(F31*$B31)+(F33*$B33)+(F35*$B35)+(F37*$B37)+(F39*$B39) -> 430085.38 | G41: =(G29*$B29)+(G31*$B31)+(G33*$B33)+(G35*$B35)+(G37*$B37)+(G39*$B39) -> 338427.84 | H41: =(H29*$B29)+(H31*$B31)+(H33*$B33)+(H35*$B35)+(H37*$B37)+(H39*$B39) -> 401883.06 | I41: =(I29*$B29)+(I31*$B31)+(I33*$B33)+(I35*$B35)+(I37*$B37)+(I39*$B39) -> 387781.9 | J41: =(J29*$B29)+(J31*$B31)+(J33*$B33)+(J35*$B35)+(J37*$B37)+(J39*$B39) -> 405408.35 | K41: =(K29*$B29)+(K31*$B31)+(K33*$B33)+(K35*$B35)+(K37*$B37)+(K39*$B39) -> 426560.09 | ... O41: =(O29*$B29)+(O31*$B31)+(O33*$B33)+(O35*$B35)+(O37*$B37)+(O39*$B39) -> 296124.36 | P41: =SUM(D41:O41) -> 4741515
A42: Cost/vol. Produced (chemicals) | C42: Mk/m3 | D42: =D41/D9 -> 7.118863 | E42: =E41/E9 -> 6.9272745 | F42: =F41/F9 -> 6.817878 | G42: =G41/G9 -> 5.5681706 | H42: =H41/H9 -> 6.4188318 | I42: =I41/I9 -> 5.7196658 | J42: =J41/J9 -> 5.7511257 | K42: =K41/K9 -> 5.8888671 | ... P42: =P41/P9 -> 6.2731979
A43: Power
...

Sheet Liwonde
A1: SOUTHERN REGION WATER BOARD
A3: MONTHLY REPORTS - 2023/2024
A4: LIWONDE ZONE
A5: LIWONDE ZONE
A7: PARAMETERS | C7: UNITS | D7: APRIL | E7: MAY | F7: JUNE | G7: JULY | H7: AUGUST | I7: SEPTEMBER | J7: OCTOBER | K7: NOVEMBER | L7: DECEMBER | M7: JANUARY | N7: FEBRUARY | O7: MARCH | P7: TOTALS
A8: PRODUCTION
A9: Volume Produced | C9: m3 | D9: 60894 | E9: 61758 | F9: 58637 | G9: 62605 | H9: 63644 | I9: 71038 | J9: 75247 | K9: 71539 | L9: 71453.7 | M9: 74738 | N9: 63503 | O9: 53806 | P9: =SUM(D9:O9) -> 788862.7
A10: REVENUE WATER - POSTPAID
A11: Volume Billed Individuals | C11: m3 | D11: 20785 | E11: 24461 | F11: 25377 | G11: 24942 | H11: 26711 | I11: 27302 | J11: 29478 | K11: 29318 | L11: 29302 | M11: 42884 | N11: 30836 | O11: 27911 | P11: =SUM(D11:O11) -> 339307
A12: Volume Billed CWPs | C12: m3 | D12: 287 | E12: 438 | F12: 434 | G12: 428 | H12: 522 | I12: 498 | J12: 581 | K12: 426 | L12: 521 | M12: 455 | N12: 467 | O12: 478 | P12: =SUM(D12:O12) -> 5535
A13: Volume Billed Institutions | C13: m3 | D13: 2010 | E13: 2233 | F13: 2451 | G13: 2340 | H13: 2297 | I13: 2337 | J13: 2422 | K13: 2635 | L13: 2709 | M13: 1068 | N13: 804 | O13: 850 | P13: =SUM(D13:O13) -> 24156
A14: Volume Billed Commercial/Industrial | C14: m3 | D14: 122 | E14: 144 | F14: 150 | G14: 189 | H14: 216 | I14: 223 | J14: 217 | K14: 238 | L14: 386 | M14: 211 | N14: 500 | O14: 554 | P14: =SUM(D14:O14) -> 3150
A15: Total Volume Billed Post Paid | C15: m3 | D15: =SUM(D11:D14) -> 23204 | E15: =SUM(E11:E14) -> 27276 | F15: =SUM(F11:F14) -> 28412 | G15: =SUM(G11:G14) -> 27899 | H15: =SUM(H11:H14) -> 29746 | I15: =SUM(I11:I14) -> 30360 | J15: =SUM(J11:J14) -> 32698 | K15: =SUM(K11:K14) -> 32617 | ... P15: =SUM(P11:P14) -> 372148
A16: REVENUE WATER - PREPAID
A17: Individuals | C17: m3 | D17: 10799 | E17: 11460 | F17: 8397.3 | G17: 9867.2 | H17: 8837 | I17: 9833.9 | J17: 13000 | K17: 9774.7 | L17: 10968.3 | M17: 9105 | N17: 12756 | O17: 9575.3 | P17: =SUM(D17:O17) -> 124373.7
A18: CWPs | C18: m3 | D18: 0 | E18: 0 | P18: =SUM(D18:O18) -> 0
A19: Institutions | C19: m3 | D19: 0 | E19: 0 | P19: =SUM(D19:O19) -> 0
A20: Commercial/Industrial | C20: m3 | D20: 0 | E20: 0 | P20: =SUM(D20:O20) -> 0
A21: Total Volume Prepaid | C21: m3 | D21: =SUM(D17:D20) -> 10799 | E21: =SUM(E17:E20) -> 11460 | F21: =SUM(F17:F20) -> 8397.3 | G21: =SUM(G17:G20) -> 9867.2 | H21: =SUM(H17:H20) -> 8837 | I21: =SUM(I17:I20) -> 9833.9 | J21: =SUM(J17:J20) -> 13000 | K21: =SUM(K17:K20) -> 9774.7 | ... P21: =SUM(P17:P20) -> 124373.7
A22: TOTAL REVENUE WATER | C22: m3 | D22: =D21+D15 -> 34003 | E22: =E21+E15 -> 38736 | F22: =F21+F15 -> 36809.3 | G22: =G21+G15 -> 37766.2 | H22: =H21+H15 -> 38583 | I22: =I21+I15 -> 40193.9 | J22: =J21+J15 -> 45698 | K22: =K21+K15 -> 42391.7 | ... P22: =P21+P15 -> 496521.7
A24: Non-Revenue Water (NRW) | B24: Volume | C24: m3 | D24: =D9-D22 -> 26891 | E24: =E9-E22 -> 23022 | F24: =F9-F22 -> 21827.7 | G24: =G9-G22 -> 24838.8 | H24: =H9-H22 -> 25061 | I24: =I9-I22 -> 30844.1 | J24: =J9-J22 -> 29549 | K24: =K9-K22 -> 29147.3 | ... P24: =P9-P22 -> 292341
B25: Percentage | C25: % | D25: =D24/D9 -> 0.44160344 | E25: =E24/E9 -> 0.37277762 | F25: =F24/F9 -> 0.37225131 | G25: =G24/G9 -> 0.39675425 | H25: =H24/H9 -> 0.39376846 | I25: =I24/I9 -> 0.43419156 | J25: =J24/J9 -> 0.3926934 | K25: =K24/K9 -> 0.40743231 | ... P25: =P24/P9 -> 0.3705854
A26: OPERATING EXPENSES
A27: Chemicals
A28: Chemical | B28: Rate(MK/kg)
A29: Chlorine | B29: =176264.5/50 -> 3525.29 | C29: kg | D29: 333 | E29: 480 | F29: 237 | G29: 283 | H29: 209 | I29: 341 | J29: 468 | K29: 377 | L29: 368 | M29: 372 | N29: 348 | O29: 372 | P29: =SUM(D29:O29) -> 4188
C30: kg/mg litre | D30: =D29/(D9/1000) -> 5.4685191 | E30: =E29/(E9/1000) -> 7.7722724 | F30: =F29/(F9/1000) -> 4.0418166 | G30: =G29/(G9/1000) -> 4.5204057 | H30: =H29/(H9/1000) -> 3.2838916 | I30: =I29/(I9/1000) -> 4.8002478 | J30: =J29/(J9/1000) -> 6.2195171 | K30: =K29/(K9/1000) -> 5.2698528 | ... P30: =P29/(P9/1000) -> 5.3089086
A31: Aluminium sulphate | B31: =53000.511/50 -> 1060.0102 | C31: kg | P31: =SUM(D31:O31) -> 0
C32: kg/mg litre | D32: =D31/(D9/1000) -> 0 | E32: =E31/(E9/1000) -> 0 | F32: =F31/(F9/1000) -> 0 | G32: =G31/(G9/1000) -> 0 | H32: =H31/(H9/1000) -> 0 | I32: =I31/(I9/1000) -> 0 | J32: =J31/(J9/1000) -> 0 | K32: =K31/(K9/1000) -> 0 | ... P32: =P31/(P9/1000) -> 0
A33: Soda | B33: =61414.43/50 -> 1228.2886 | C33: kg | P33: =SUM(D33:O33) -> 0
C34: kg/mg litre | D34: =D33/(D9/1000) -> 0 | E34: =E33/(E9/1000) -> 0 | F34: =F33/(F9/1000) -> 0 | G34: =G33/(G9/1000) -> 0 | H34: =H33/(H9/1000) -> 0 | I34: =I33/(I9/1000) -> 0 | J34: =J33/(J9/1000) -> 0 | K34: =K33/(K9/1000) -> 0 | ... P34: =P33/(P9/1000) -> 0
A35: Algae floc | B35: =745345.16/200 -> 3726.7258 | C35: litres | E35: 248 | F35: 301 | G35: 224 | H35: 139 | I35: 155 | J35: 143 | K35: 110 | L35: 141 | M35: 473 | N35: 555 | O35: 465
C36: litres/mg litre | D36: =D35/(D9/1000) -> 0 | E36: =E35/(E9/1000) -> 4.0156741 | F36: =F35/(F9/1000) -> 5.1332776 | G36: =G35/(G9/1000) -> 3.577989 | H36: =H35/(H9/1000) -> 2.1840236 | I36: =I35/(I9/1000) -> 2.1819308 | J36: =J35/(J9/1000) -> 1.900408 | K36: =K35/(K9/1000) -> 1.5376228 | ... O36: =O35/(O9/1000) -> 8.6421589
A37: Sud floc | B37: =790318.72/200 -> 3951.5936 | C37: litres | D37: 0 | E37: 0 | F37: 0 | G37: 0 | H37: 0 | I37: 0 | J37: 0 | K37: 0 | L37: 0 | M37: 0 | N37: 0 | O37: 0 | P37: =SUM(D37:O37) -> 0
C38: litres/mg litre | D38: =D37/(D9/1000) -> 0 | E38: =E37/(E9/1000) -> 0 | F38: =F37/(F9/1000) -> 0 | G38: =G37/(G9/1000) -> 0 | H38: =H37/(H9/1000) -> 0 | I38: =I37/(I9/1000) -> 0 | J38: =J37/(J9/1000) -> 0 | K38: =K37/(K9/1000) -> 0 | ... P38: =P37/(P9/1000) -> 0
A39: Potasium permanganate | B39: 1950 | C39: kg | D39: 0 | E39: 0 | F39: 0 | G39: 0 | H39: 0 | I39: 0 | J39: 0 | K39: 0 | L39: 0 | M39: 0 | N39: 0 | O39: 0 | P39: =SUM(D39:O39) -> 0
C40: kg/mg litre | D40: =D39/(D9/1000) -> 0 | E40: =E39/(E9/1000) -> 0 | F40: =F39/(F9/1000) -> 0 | G40: =G39/(G9/1000) -> 0 | H40: =H39/(H9/1000) -> 0 | I40: =I39/(I9/1000) -> 0 | J40: =J39/(J9/1000) -> 0 | K40: =K39/(K9/1000) -> 0 | ... P40: =P39/(P9/1000) -> 0
A41: Cost of Chemicals | C41: Mk | D41: =(D29*$B29)+(D31*$B31)+(D33*$B33)+(D35*$B35)+(D37*$B37)+(D39*$B39) -> 1173921.6 | E41: =(E29*$B29)+(E31*$B31)+(E33*$B33)+(E35*$B35)+(E37*$B37)+(E39*$B39) -> 2616367.2 | F41: =(F29*$B29)+(F31*$B31)+(F33*$B33)+(F35*$B35)+(F37*$B37)+(F39*$B39) -> 1957238.2 | G41: =(G29*$B29)+(G31*$B31)+(G33*$B33)+(G35*$B35)+(G37*$B37)+(G39*$B39) -> 1832443.6 | H41: =(H29*$B29)+(H31*$B31)+(H33*$B33)+(H35*$B35)+(H37*$B37)+(H39*$B39) -> 1254800.5 | I41: =(I29*$B29)+(I31*$B31)+(I33*$B33)+(I35*$B35)+(I37*$B37)+(I39*$B39) -> 1779766.4 | J41: =(J29*$B29)+(J31*$B31)+(J33*$B33)+(J35*$B35)+(J37*$B37)+(J39*$B39) -> 2182757.5 | K41: =(K29*$B29)+(K31*$B31)+(K33*$B33)+(K35*$B35)+(K37*$B37)+(K39*$B39) -> 1738974.2 | ... O41: =(O29*$B29)+(O31*$B31)+(O33*$B33)+(O35*$B35)+(O37*$B37)+(O39*$B39) -> 3044335.4 | P41: =SUM(D41:O41) -> 25772663
A42: Cost/vol. Produced (chemicals) | C42: Mk/m3 | D42: =D41/D9 -> 19.278116 | E42: =E41/E9 -> 42.36483 | F42: =F41/F9 -> 33.378894 | G42: =G41/G9 -> 29.269925 | H42: =H41/H9 -> 19.715928 | I42: =I41/I9 -> 25.053723 | J42: =J41/J9 -> 29.007901 | K42: =K41/K9 -> 24.308058 | ... P42: =P41/P9 -> 32.670657
A43: Power
...

Sheet Machinga
A1: SOUTHERN REGION WATER BOARD
A3: MONTHLY REPORTS - 2023/2024
A4: LIWONDE ZONE
A5: LIWONDE ZONE
A7: PARAMETERS | C7: UNITS | D7: APRIL | E7: MAY | F7: JUNE | G7: JULY | H7: AUGUST | I7: SEPTEMBER | J7: OCTOBER | K7: NOVEMBER | L7: DECEMBER | M7: JANUARY | N7: FEBRUARY | O7: MARCH | P7: TOTALS
A8: PRODUCTION | Q8: APR | R8: MAY | S8: JUN | T8: JUL | U8: AUG | V8: SEP | W8: OCT | X8: NOV | Y8: DEC | Z8: JAN | AA8: FEB | AB8: MAR | AC8: TOTAL
A9: Volume Produced | C9: m3 | D9: 3300 | E9: 3402 | F9: 3360 | G9: 3075 | H9: 2765 | I9: 3240 | J9: 3348 | K9: 3075 | L9: 2911 | M9: 2816 | N9: 3190 | O9: 2809 | P9: =SUM(D9:O9) -> 37291 | Q9: 0 | R9: 0 | S9: 0 | T9: 0 | U9: 0 | V9: 0 | W9: 0 | X9: 0 | Y9: 0 | Z9: 0 | AA9: 0 | AB9: 0 | AC9: 0
A10: REVENUE WATER - POSTPAID | Q10: 0 | R10: 0 | S10: 0 | T10: 0 | U10: 0 | V10: 0 | W10: 0 | X10: 0 | Y10: 0 | Z10: 0 | AA10: 0 | AB10: 0 | AC10: 0
A11: Volume Billed Individuals | C11: m3 | D11: 2555 | E11: 804 | F11: 1009 | G11: 796 | H11: 952 | I11: 1247 | J11: 1176 | K11: 1197 | L11: 1036 | M11: 994 | N11: 932 | O11: 902 | P11: =SUM(D11:O11) -> 13600 | Q11: 0 | R11: 0 | S11: 0 | T11: 0 | U11: 0 | V11: 0 | W11: 0 | X11: 0 | Y11: 0 | Z11: 0 | AA11: 0 | AB11: 0 | AC11: 0
A12: Volume Billed CWPs | C12: m3 | P12: =SUM(D12:O12) -> 0 | Q12: 0 | R12: 0 | S12: 0 | T12: 0 | U12: 0 | V12: 0 | W12: 0 | X12: 0 | Y12: 0 | Z12: 0 | AA12: 0 | AB12: 0 | AC12: 0
A13: Volume Billed Institutions | C13: m3 | E13: 1676 | F13: 41 | G13: 43 | H13: 52 | I13: 44 | J13: 30 | K13: 38 | L13: 40 | M13: 29 | N13: 19 | O13: 33 | P13: =SUM(D13:O13) -> 2045 | Q13: 0 | R13: 0 | S13: 0 | T13: 0 | U13: 0 | V13: 0 | W13: 0 | X13: 0 | Y13: 0 | Z13: 0 | AA13: 0 | AB13: 0 | AC13: 0
A14: Volume Billed Commercial/Industrial | C14: m3 | P14: =SUM(D14:O14) -> 0 | Q14: 0 | R14: 0 | S14: 0 | T14: 0 | U14: 0 | V14: 0 | W14: 0 | X14: 0 | Y14: 0 | Z14: 0 | AA14: 0 | AB14: 0 | AC14: 0
A15: Total Volume Billed Post Paid | C15: m3 | D15: =SUM(D11:D14) -> 2555 | E15: =SUM(E11:E14) -> 2480 | F15: =SUM(F11:F14) -> 1050 | G15: =SUM(G11:G14) -> 839 | H15: =SUM(H11:H14) -> 1004 | I15: =SUM(I11:I14) -> 1291 | J15: =SUM(J11:J14) -> 1206 | K15: =SUM(K11:K14) -> 1235 | ... P15: =SUM(P11:P14) -> 15645 | Q15: 0 | R15: 0 | S15: 0 | T15: 0 | U15: 0 | V15: 0 | W15: 0 | X15: 0 | Y15: 0 | Z15: 0 | AA15: 0 | AB15: 0 | AC15: 0
A16: REVENUE WATER - PREPAID
A17: Individuals | C17: m3 | E17: 901 | F17: 1670.2 | G17: 1542.6 | H17: 1742 | I17: 1492 | J17: 1575 | K17: 1517 | L17: 1537.3 | M17: 1467 | N17: 2066.88 | O17: 1602 | P17: =SUM(D17:O17) -> 17112.98
A18: CWPs | C18: m3 | P18: =SUM(D18:O18) -> 0
A19: Institutions | C19: m3 | P19: =SUM(D19:O19) -> 0
A20: Commercial/Industrial | C20: m3 | P20: =SUM(D20:O20) -> 0
A21: Total Volume Prepaid | C21: m3 | D21: =SUM(D17:D20) -> 0 | E21: =SUM(E17:E20) -> 901 | F21: =SUM(F17:F20) -> 1670.2 | G21: =SUM(G17:G20) -> 1542.6 | H21: =SUM(H17:H20) -> 1742 | I21: =SUM(I17:I20) -> 1492 | J21: =SUM(J17:J20) -> 1575 | K21: =SUM(K17:K20) -> 1517 | ... P21: =SUM(P17:P20) -> 17112.98
A22: TOTAL REVENUE WATER | C22: m3 | D22: =D21+D15 -> 2555 | E22: =E21+E15 -> 3381 | F22: =F21+F15 -> 2720.2 | G22: =G21+G15 -> 2381.6 | H22: =H21+H15 -> 2746 | I22: =I21+I15 -> 2783 | J22: =J21+J15 -> 2781 | K22: =K21+K15 -> 2752 | ... P22: =P21+P15 -> 32757.98
A24: Non-Revenue Water (NRW) | B24: Volume | C24: m3 | D24: =D9-D22 -> 745 | E24: =E9-E22 -> 21 | F24: =F9-F22 -> 639.8 | G24: =G9-G22 -> 693.4 | H24: =H9-H22 -> 19 | I24: =I9-I22 -> 457 | J24: =J9-J22 -> 567 | K24: =K9-K22 -> 323 | ... P24: =P9-P22 -> 4533.02
B25: Percentage | C25: % | D25: =D24/D9 -> 0.22575758 | E25: =E24/E9 -> 0.0061728395 | F25: =F24/F9 -> 0.19041667 | G25: =G24/G9 -> 0.22549593 | H25: =H24/H9 -> 0.0068716094 | I25: =I24/I9 -> 0.14104938 | J25: =J24/J9 -> 0.16935484 | K25: =K24/K9 -> 0.10504065 | ... P25: =P24/P9 -> 0.12155802
A26: OPERATING EXPENSES
A27: Chemicals
A28: Chemical | B28: Rate(MK/kg)
A29: Chlorine | B29: =176264.5/50 -> 3525.29 | C29: kg | D29: 12 | E29: 11 | F29: 10 | G29: 10 | H29: 10 | I29: 10 | J29: 11 | K29: 10 | L29: 11 | M29: 8 | N29: 7 | O29: 8 | P29: =SUM(D29:O29) -> 118
C30: kg/mg litre | D30: =D29/(D9/1000) -> 3.6363636 | E30: =E29/(E9/1000) -> 3.2333921 | F30: =F29/(F9/1000) -> 2.9761905 | G30: =G29/(G9/1000) -> 3.2520325 | H30: =H29/(H9/1000) -> 3.6166365 | I30: =I29/(I9/1000) -> 3.0864198 | J30: =J29/(J9/1000) -> 3.2855436 | K30: =K29/(K9/1000) -> 3.2520325 | ... P30: =P29/(P9/1000) -> 3.1643024
A31: Aluminium sulphate | B31: =53000.511/50 -> 1060.0102 | C31: kg | P31: =SUM(D31:O31) -> 0
C32: kg/mg litre | D32: =D31/(D9/1000) -> 0 | E32: =E31/(E9/1000) -> 0 | F32: =F31/(F9/1000) -> 0 | G32: =G31/(G9/1000) -> 0 | H32: =H31/(H9/1000) -> 0 | I32: =I31/(I9/1000) -> 0 | J32: =J31/(J9/1000) -> 0 | K32: =K31/(K9/1000) -> 0 | ... P32: =P31/(P9/1000) -> 0
A33: Soda | B33: =61414.43/50 -> 1228.2886 | C33: kg | P33: =SUM(D33:O33) -> 0
C34: kg/mg litre | D34: =D33/(D9/1000) -> 0 | E34: =E33/(E9/1000) -> 0 | F34: =F33/(F9/1000) -> 0 | G34: =G33/(G9/1000) -> 0 | H34: =H33/(H9/1000) -> 0 | I34: =I33/(I9/1000) -> 0 | J34: =J33/(J9/1000) -> 0 | K34: =K33/(K9/1000) -> 0 | ... P34: =P33/(P9/1000) -> 0
A35: Algae floc | B35: =745345.16/200 -> 3726.7258 | C35: litres
C36: litres/mg litre
A37: Sud floc | B37: =790318.72/200 -> 3951.5936 | C37: litres | D37: 0 | E37: 0 | F37: 0 | G37: 0 | H37: 0 | I37: 0 | J37: 0 | K37: 0 | L37: 0 | M37: 0 | N37: 0 | O37: 0 | P37: =SUM(D37:O37) -> 0
C38: litres/mg litre | D38: =D37/(D9/1000) -> 0 | E38: =E37/(E9/1000) -> 0 | F38: =F37/(F9/1000) -> 0 | G38: =G37/(G9/1000) -> 0 | H38: =H37/(H9/1000) -> 0 | I38: =I37/(I9/1000) -> 0 | J38: =J37/(J9/1000) -> 0 | K38: =K37/(K9/1000) -> 0 | ... P38: =P37/(P9/1000) -> 0
A39: Potasium permanganate | B39: 1950 | C39: kg | D39: 0 | E39: 0 | F39: 0 | G39: 0 | H39: 0 | I39: 0 | J39: 0 | K39: 0 | L39: 0 | M39: 0 | N39: 0 | O39: 0 | P39: =SUM(D39:O39) -> 0
C40: kg/mg litre | D40: =D39/(D9/1000) -> 0 | E40: =E39/(E9/1000) -> 0 | F40: =F39/(F9/1000) -> 0 | G40: =G39/(G9/1000) -> 0 | H40: =H39/(H9/1000) -> 0 | I40: =I39/(I9/1000) -> 0 | J40: =J39/(J9/1000) -> 0 | K40: =K39/(K9/1000) -> 0 | ... P40: =P39/(P9/1000) -> 0
A41: Cost of Chemicals | C41: Mk | D41: =(D29*$B29)+(D31*$B31)+(D33*$B33)+(D35*$B35)+(D37*$B37)+(D39*$B39) -> 42303.48 | E41: =(E29*$B29)+(E31*$B31)+(E33*$B33)+(E35*$B35)+(E37*$B37)+(E39*$B39) -> 38778.19 | F41: =(F29*$B29)+(F31*$B31)+(F33*$B33)+(F35*$B35)+(F37*$B37)+(F39*$B39) -> 35252.9 | G41: =(G29*$B29)+(G31*$B31)+(G33*$B33)+(G35*$B35)+(G37*$B37)+(G39*$B39) -> 35252.9 | H41: =(H29*$B29)+(H31*$B31)+(H33*$B33)+(H35*$B35)+(H37*$B37)+(H39*$B39) -> 35252.9 | I41: =(I29*$B29)+(I31*$B31)+(I33*$B33)+(I35*$B35)+(I37*$B37)+(I39*$B39) -> 35252.9 | J41: =(J29*$B29)+(J31*$B31)+(J33*$B33)+(J35*$B35)+(J37*$B37)+(J39*$B39) -> 38778.19 | K41: =(K29*$B29)+(K31*$B31)+(K33*$B33)+(K35*$B35)+(K37*$B37)+(K39*$B39) -> 35252.9 | ... O41: =(O29*$B29)+(O31*$B31)+(O33*$B33)+(O35*$B35)+(O37*$B37)+(O39*$B39) -> 28202.32 | P41: =SUM(D41:O41) -> 415984.22
A42: Cost/vol. Produced (chemicals) | C42: Mk/m3 | D42: =D41/D9 -> 12.819236 | E42: =E41/E9 -> 11.398645 | F42: =F41/F9 -> 10.491935 | G42: =G41/G9 -> 11.464358 | H42: =H41/H9 -> 12.749693 | I42: =I41/I9 -> 10.880525 | J42: =J41/J9 -> 11.582494 | K42: =K41/K9 -> 11.464358 | ... P42: =P41/P9 -> 11.155084
A43: Power
...

Sheet Ntaja
A1: SOUTHERN REGION WATER BOARD
A3: MONTHLY REPORTS - 2023/2024
A4: LIWONDE ZONE
A5: LIWONDE ZONE
A7: PARAMETERS | C7: UNITS | D7: APRIL | E7: MAY | F7: JUNE | G7: JULY | H7: AUGUST | I7: SEPTEMBER | J7: OCTOBER | K7: NOVEMBER | L7: DECEMBER | M7: JANUARY | N7: FEBRUARY | O7: MARCH | P7: TOTALS
A8: PRODUCTION | Q8: APR | R8: MAY | S8: JUN | T8: JUL | U8: AUG | V8: SEP | W8: OCT | X8: NOV | Y8: DEC | Z8: JAN | AA8: FEB | AB8: MAR | AC8: TOTAL
A9: Volume Produced | C9: m3 | D9: 6552 | E9: 1800 | F9: 2556.01 | G9: 2432 | H9: 2810 | I9: 2860 | J9: 2921 | K9: 2981 | L9: 3069 | M9: 2518 | N9: 2718 | O9: 2909 | P9: =SUM(D9:O9) -> 36126.01 | Q9: 0 | R9: 0 | S9: 0 | T9: 0 | U9: 0 | V9: 0 | W9: 0 | X9: 0 | Y9: 0 | Z9: 0 | AA9: 0 | AB9: 0 | AC9: 0
A10: REVENUE WATER - POSTPAID | Q10: 0 | R10: 0 | S10: 0 | T10: 0 | U10: 0 | V10: 0 | W10: 0 | X10: 0 | Y10: 0 | Z10: 0 | AA10: 0 | AB10: 0 | AC10: 0
A11: Volume Billed Individuals | C11: m3 | D11: 620 | E11: 446 | F11: 5 | G11: 4 | H11: 5 | I11: 5 | J11: 37 | K11: 65 | L11: 103 | M11: 92 | N11: 47 | O11: 76 | P11: =SUM(D11:O11) -> 1505 | Q11: 0 | R11: 0 | S11: 0 | T11: 0 | U11: 0 | V11: 0 | W11: 0 | X11: 0 | Y11: 0 | Z11: 0 | AA11: 0 | AB11: 0 | AC11: 0
A12: Volume Billed CWPs | C12: m3 | D12: 0 | E12: 0 | F12: 0 | G12: 0 | H12: 0 | I12: 0 | J12: 0 | K12: 0 | L12: 0 | M12: 0 | N12: 0 | O12: 0 | P12: =SUM(D12:O12) -> 0 | Q12: 0 | R12: 0 | S12: 0 | T12: 0 | U12: 0 | V12: 0 | W12: 0 | X12: 0 | Y12: 0 | Z12: 0 | AA12: 0 | AB12: 0 | AC12: 0
A13: Volume Billed Institutions | C13: m3 | D13: 23 | E13: 8 | F13: 14 | G13: 13 | H13: 14 | I13: 32 | J13: 6 | K13: 5 | M13: 11 | N13: 11 | O13: 19 | P13: =SUM(D13:O13) -> 156 | Q13: 0 | R13: 0 | S13: 0 | T13: 0 | U13: 0 | V13: 0 | W13: 0 | X13: 0 | Y13: 0 | Z13: 0 | AA13: 0 | AB13: 0 | AC13: 0
A14: Volume Billed Commercial/Industrial | C14: m3 | D14: 0 | E14: 2 | F14: 0 | G14: 0 | H14: 0 | I14: 0 | J14: 0 | K14: 0 | L14: 0 | M14: 0 | N14: 0 | O14: 0 | P14: =SUM(D14:O14) -> 2 | Q14: 0 | R14: 0 | S14: 0 | T14: 0 | U14: 0 | V14: 0 | W14: 0 | X14: 0 | Y14: 0 | Z14: 0 | AA14: 0 | AB14: 0 | AC14: 0
A15: Total Volume Billed Post Paid | C15: m3 | D15: =SUM(D11:D14) -> 643 | E15: =SUM(E11:E14) -> 456 | F15: =SUM(F11:F14) -> 19 | G15: =SUM(G11:G14) -> 17 | H15: =SUM(H11:H14) -> 19 | I15: =SUM(I11:I14) -> 37 | J15: =SUM(J11:J14) -> 43 | K15: =SUM(K11:K14) -> 70 | ... P15: =SUM(P11:P14) -> 1663 | Q15: 0 | R15: 0 | S15: 0 | T15: 0 | U15: 0 | V15: 0 | W15: 0 | X15: 0 | Y15: 0 | Z15: 0 | AA15: 0 | AB15: 0 | AC15: 0
A16: REVENUE WATER - PREPAID | Q16: 0 | R16: 0 | S16: 0 | T16: 0 | U16: 0 | V16: 0 | W16: 0 | X16: 0 | Y16: 0 | Z16: 0 | AA16: 0 | AB16: 0 | AC16: 0
A17: Individuals | C17: m3 | D17: 577 | E17: 659 | F17: 2068.9 | G17: 2081 | H17: 2351 | I17: 2038 | J17: 2301 | K17: 2423 | L17: 2340 | M17: 1890 | N17: 2069 | O17: 2305 | P17: =SUM(D17:O17) -> 23102.9
A18: CWPs | C18: m3 | D18: 21 | E18: 11 | F18: 60 | G18: 75 | H18: 71 | I18: 86 | J18: 131 | K18: 148 | L18: 118 | M18: 118 | N18: 104 | O18: 94 | P18: =SUM(D18:O18) -> 1037
A19: Institutions | C19: m3 | D19: 23 | E19: 30 | F19: 75 | G19: 61 | H19: 52 | I19: 97 | J19: 88 | K19: 64 | L19: 201 | M19: 44 | N19: 48 | O19: 45 | P19: =SUM(D19:O19) -> 828
A20: Commercial/Industrial | C20: m3 | D20: 52 | E20: 28 | F20: 83 | G20: 86 | H20: 81 | I20: 120 | J20: 95 | K20: 156 | L20: 116 | M20: 86 | N20: 111 | O20: 113 | P20: =SUM(D20:O20) -> 1127
A21: Total Volume Prepaid | C21: m3 | D21: =SUM(D17:D20) -> 673 | E21: =SUM(E17:E20) -> 728 | F21: =SUM(F17:F20) -> 2286.9 | G21: =SUM(G17:G20) -> 2303 | H21: =SUM(H17:H20) -> 2555 | I21: =SUM(I17:I20) -> 2341 | J21: =SUM(J17:J20) -> 2615 | K21: =SUM(K17:K20) -> 2791 | ... P21: =SUM(P17:P20) -> 26094.9
A22: TOTAL REVENUE WATER | C22: m3 | D22: =D21+D15 -> 1316 | E22: =E21+E15 -> 1184 | F22: =F21+F15 -> 2305.9 | G22: =G21+G15 -> 2320 | H22: =H21+H15 -> 2574 | I22: =I21+I15 -> 2378 | J22: =J21+J15 -> 2658 | K22: =K21+K15 -> 2861 | ... P22: =P21+P15 -> 27757.9
A24: Non-Revenue Water (NRW) | B24: Volume | C24: m3 | D24: =D9-D22 -> 5236 | E24: =E9-E22 -> 616 | F24: =F9-F22 -> 250.11 | G24: =G9-G22 -> 112 | H24: =H9-H22 -> 236 | I24: =I9-I22 -> 482 | J24: =J9-J22 -> 263 | K24: =K9-K22 -> 120 | ... P24: =P9-P22 -> 8368.11
B25: Percentage | C25: % | D25: =D24/D9 -> 0.7991453 | E25: =E24/E9 -> 0.34222222 | F25: =F24/F9 -> 0.09785173 | G25: =G24/G9 -> 0.046052632 | H25: =H24/H9 -> 0.083985765 | I25: =I24/I9 -> 0.16853147 | J25: =J24/J9 -> 0.090037658 | K25: =K24/K9 -> 0.040254948 | ... P25: =P24/P9 -> 0.23163671
A26: OPERATING EXPENSES
A27: Chemicals
A28: Chemical | B28: Rate(MK/kg)
A29: Chlorine | B29: =176264.5/50 -> 3525.29 | C29: kg | D29: 8 | E29: 8 | F29: 4 | G29: 8 | H29: 8 | I29: 8 | J29: 8 | K29: 9 | L29: 11 | M29: 13 | N29: 12 | O29: 6 | P29: =SUM(D29:O29) -> 103
C30: kg/mg litre | D30: =D29/(D9/1000) -> 1.2210012 | E30: =E29/(E9/1000) -> 4.4444444 | F30: =F29/(F9/1000) -> 1.5649391 | G30: =G29/(G9/1000) -> 3.2894737 | H30: =H29/(H9/1000) -> 2.8469751 | I30: =I29/(I9/1000) -> 2.7972028 | J30: =J29/(J9/1000) -> 2.7387881 | K30: =K29/(K9/1000) -> 3.0191211 | ... P30: =P29/(P9/1000) -> 2.8511314
A31: Aluminium sulphate | B31: =53000.511/50 -> 1060.0102 | C31: kg | P31: =SUM(D31:O31) -> 0
C32: kg/mg litre | D32: =D31/(D9/1000) -> 0 | E32: =E31/(E9/1000) -> 0 | F32: =F31/(F9/1000) -> 0 | G32: =G31/(G9/1000) -> 0 | H32: =H31/(H9/1000) -> 0 | I32: =I31/(I9/1000) -> 0 | J32: =J31/(J9/1000) -> 0 | K32: =K31/(K9/1000) -> 0 | ... P32: =P31/(P9/1000) -> 0
A33: Soda | B33: =61414.43/50 -> 1228.2886 | C33: kg | P33: =SUM(D33:O33) -> 0
C34: kg/mg litre | D34: =D33/(D9/1000) -> 0 | E34: =E33/(E9/1000) -> 0 | F34: =F33/(F9/1000) -> 0 | G34: =G33/(G9/1000) -> 0 | H34: =H33/(H9/1000) -> 0 | I34: =I33/(I9/1000) -> 0 | J34: =J33/(J9/1000) -> 0 | K34: =K33/(K9/1000) -> 0 | ... P34: =P33/(P9/1000) -> 0
A35: Algae floc | B35: =745345.16/200 -> 3726.7258 | C35: litres
C36: litres/mg litre
A37: Sud floc | B37: =790318.72/200 -> 3951.5936 | C37: litres | D37: 0 | E37: 0 | F37: 0 | G37: 0 | H37: 0 | I37: 0 | J37: 0 | K37: 0 | L37: 0 | M37: 0 | N37: 0 | O37: 0 | P37: =SUM(D37:O37) -> 0
C38: litres/mg litre | D38: =D37/(D9/1000) -> 0 | E38: =E37/(E9/1000) -> 0 | F38: =F37/(F9/1000) -> 0 | G38: =G37/(G9/1000) -> 0 | H38: =H37/(H9/1000) -> 0 | I38: =I37/(I9/1000) -> 0 | J38: =J37/(J9/1000) -> 0 | K38: =K37/(K9/1000) -> 0 | ... P38: =P37/(P9/1000) -> 0
A39: Potasium permanganate | B39: 1950 | C39: kg | D39: 0 | E39: 0 | F39: 0 | G39: 0 | H39: 0 | I39: 0 | J39: 0 | K39: 0 | L39: 0 | M39: 0 | N39: 0 | O39: 0 | P39: =SUM(D39:O39) -> 0
C40: kg/mg litre | D40: =D39/(D9/1000) -> 0 | E40: =E39/(E9/1000) -> 0 | F40: =F39/(F9/1000) -> 0 | G40: =G39/(G9/1000) -> 0 | H40: =H39/(H9/1000) -> 0 | I40: =I39/(I9/1000) -> 0 | J40: =J39/(J9/1000) -> 0 | K40: =K39/(K9/1000) -> 0 | ... P40: =P39/(P9/1000) -> 0
A41: Cost of Chemicals | C41: Mk | D41: =(D29*$B29)+(D31*$B31)+(D33*$B33)+(D35*$B35)+(D37*$B37)+(D39*$B39) -> 28202.32 | E41: =(E29*$B29)+(E31*$B31)+(E33*$B33)+(E35*$B35)+(E37*$B37)+(E39*$B39) -> 28202.32 | F41: =(F29*$B29)+(F31*$B31)+(F33*$B33)+(F35*$B35)+(F37*$B37)+(F39*$B39) -> 14101.16 | G41: =(G29*$B29)+(G31*$B31)+(G33*$B33)+(G35*$B35)+(G37*$B37)+(G39*$B39) -> 28202.32 | H41: =(H29*$B29)+(H31*$B31)+(H33*$B33)+(H35*$B35)+(H37*$B37)+(H39*$B39) -> 28202.32 | I41: =(I29*$B29)+(I31*$B31)+(I33*$B33)+(I35*$B35)+(I37*$B37)+(I39*$B39) -> 28202.32 | J41: =(J29*$B29)+(J31*$B31)+(J33*$B33)+(J35*$B35)+(J37*$B37)+(J39*$B39) -> 28202.32 | K41: =(K29*$B29)+(K31*$B31)+(K33*$B33)+(K35*$B35)+(K37*$B37)+(K39*$B39) -> 31727.61 | ... O41: =(O29*$B29)+(O31*$B31)+(O33*$B33)+(O35*$B35)+(O37*$B37)+(O39*$B39) -> 21151.74 | P41: =SUM(D41:O41) -> 363104.87
A42: Cost/vol. Produced (chemicals) | C42: Mk/m3 | D42: =D41/D9 -> 4.3043834 | E42: =E41/E9 -> 15.667956 | F42: =F41/F9 -> 5.5168642 | G42: =G41/G9 -> 11.596349 | H42: =H41/H9 -> 10.036413 | I42: =I41/I9 -> 9.860951 | J42: =J41/J9 -> 9.6550223 | K42: =K41/K9 -> 10.643277 | ... P42: =P41/P9 -> 10.051065
A43: Power
...

Sheet Zone Monthly
A1: SOUTHERN REGION WATER BOARD
A3: MONTHLY REPORTS - 2023/2024
A4: LIWONDE ZONE
A5: LIWONDE ZONE
A7: PARAMETERS | C7: UNITS | D7: APRIL | E7: MAY | F7: JUNE | G7: JULY | H7: AUGUST | I7: SEPTEMBER | J7: OCTOBER | K7: NOVEMBER | L7: DECEMBER | M7: JANUARY | N7: FEBRUARY | O7: MARCH | P7: TOTALS
A8: PRODUCTION
A9: Volume Produced | C9: m3 | D9: =Balaka!D9+Liwonde!D9+Machinga!D9+Ntaja!D9 -> 119276 | E9: =Balaka!E9+Liwonde!E9+Machinga!E9+Ntaja!E9 -> 128028 | F9: =Balaka!F9+Liwonde!F9+Machinga!F9+Ntaja!F9 -> 127635.01 | G9: =Balaka!G9+Liwonde!G9+Machinga!G9+Ntaja!G9 -> 128891 | H9: =Balaka!H9+Liwonde!H9+Machinga!H9+Ntaja!H9 -> 131829 | I9: =Balaka!I9+Liwonde!I9+Machinga!I9+Ntaja!I9 -> 144936 | J9: =Balaka!J9+Liwonde!J9+Machinga!J9+Ntaja!J9 -> 152008 | K9: =Balaka!K9+Liwonde!K9+Machinga!K9+Ntaja!K9 -> 150030 | ... O9: =Balaka!O9+Liwonde!O9+Machinga!O9+Ntaja!O9 -> 111636 | P9: =SUM(D9:O9) -> 1618116.7
A10: REVENUE WATER - POSTPAID
A11: Volume Billed Individuals | C11: m3 | D11: =Balaka!D11+Liwonde!D11+Machinga!D11+Ntaja!D11 -> 46978 | E11: =Balaka!E11+Liwonde!E11+Machinga!E11+Ntaja!E11 -> 51964 | F11: =Balaka!F11+Liwonde!F11+Machinga!F11+Ntaja!F11 -> 51768 | G11: =Balaka!G11+Liwonde!G11+Machinga!G11+Ntaja!G11 -> 51183 | H11: =Balaka!H11+Liwonde!H11+Machinga!H11+Ntaja!H11 -> 55307 | I11: =Balaka!I11+Liwonde!I11+Machinga!I11+Ntaja!I11 -> 60037 | J11: =Balaka!J11+Liwonde!J11+Machinga!J11+Ntaja!J11 -> 64542 | K11: =Balaka!K11+Liwonde!K11+Machinga!K11+Ntaja!K11 -> 67713 | ... O11: =Balaka!O11+Liwonde!O11+Machinga!O11+Ntaja!O11 -> 58215 | P11: =SUM(D11:O11) -> 711496
A12: Volume Billed CWPs | C12: m3 | D12: =Balaka!D12+Liwonde!D12+Machinga!D12+Ntaja!D12 -> 1322 | E12: =Balaka!E12+Liwonde!E12+Machinga!E12+Ntaja!E12 -> 1438 | F12: =Balaka!F12+Liwonde!F12+Machinga!F12+Ntaja!F12 -> 868 | G12: =Balaka!G12+Liwonde!G12+Machinga!G12+Ntaja!G12 -> 1477 | H12: =Balaka!H12+Liwonde!H12+Machinga!H12+Ntaja!H12 -> 1776 | I12: =Balaka!I12+Liwonde!I12+Machinga!I12+Ntaja!I12 -> 1726 | J12: =Balaka!J12+Liwonde!J12+Machinga!J12+Ntaja!J12 -> 1904 | K12: =Balaka!K12+Liwonde!K12+Machinga!K12+Ntaja!K12 -> 1695 | ... O12: =Balaka!O12+Liwonde!O12+Machinga!O12+Ntaja!O12 -> 1322 | P12: =SUM(D12:O12) -> 18448
A13: Volume Billed Institutions | C13: m3 | D13: =Balaka!D13+Liwonde!D13+Machinga!D13+Ntaja!D13 -> 2585 | E13: =Balaka!E13+Liwonde!E13+Machinga!E13+Ntaja!E13 -> 4117 | F13: =Balaka!F13+Liwonde!F13+Machinga!F13+Ntaja!F13 -> 4957 | G13: =Balaka!G13+Liwonde!G13+Machinga!G13+Ntaja!G13 -> 2624 | H13: =Balaka!H13+Liwonde!H13+Machinga!H13+Ntaja!H13 -> 2653 | I13: =Balaka!I13+Liwonde!I13+Machinga!I13+Ntaja!I13 -> 2803 | J13: =Balaka!J13+Liwonde!J13+Machinga!J13+Ntaja!J13 -> 2879 | K13: =Balaka!K13+Liwonde!K13+Machinga!K13+Ntaja!K13 -> 2877 | ... O13: =Balaka!O13+Liwonde!O13+Machinga!O13+Ntaja!O13 -> 1062 | P13: =SUM(D13:O13) -> 31982
A14: Volume Billed Commercial/Industrial | C14: m3 | D14: =Balaka!D14+Liwonde!D14+Machinga!D14+Ntaja!D14 -> 177 | E14: =Balaka!E14+Liwonde!E14+Machinga!E14+Ntaja!E14 -> 199 | F14: =Balaka!F14+Liwonde!F14+Machinga!F14+Ntaja!F14 -> 300 | G14: =Balaka!G14+Liwonde!G14+Machinga!G14+Ntaja!G14 -> 232 | H14: =Balaka!H14+Liwonde!H14+Machinga!H14+Ntaja!H14 -> 366 | I14: =Balaka!I14+Liwonde!I14+Machinga!I14+Ntaja!I14 -> 372 | J14: =Balaka!J14+Liwonde!J14+Machinga!J14+Ntaja!J14 -> 327 | K14: =Balaka!K14+Liwonde!K14+Machinga!K14+Ntaja!K14 -> 277 | ... O14: =Balaka!O14+Liwonde!O14+Machinga!O14+Ntaja!O14 -> 645 | P14: =SUM(D14:O14) -> 4147
A15: Total Volume Billed Post Paid | C15: m3 | D15: =SUM(D11:D14) -> 51062 | E15: =SUM(E11:E14) -> 57718 | F15: =SUM(F11:F14) -> 57893 | G15: =SUM(G11:G14) -> 55516 | H15: =SUM(H11:H14) -> 60102 | I15: =SUM(I11:I14) -> 64938 | J15: =SUM(J11:J14) -> 69652 | K15: =SUM(K11:K14) -> 72562 | ... P15: =SUM(P11:P14) -> 766073
A16: REVENUE WATER - PREPAID
A17: Individuals | C17: m3 | D17: =Balaka!D17+Liwonde!D17+Machinga!D17+Ntaja!D17 -> 18273 | E17: =Balaka!E17+Liwonde!E17+Machinga!E17+Ntaja!E17 -> 20613 | F17: =Balaka!F17+Liwonde!F17+Machinga!F17+Ntaja!F17 -> 19368.4 | G17: =Balaka!G17+Liwonde!G17+Machinga!G17+Ntaja!G17 -> 19659.8 | H17: =Balaka!H17+Liwonde!H17+Machinga!H17+Ntaja!H17 -> 20835 | I17: =Balaka!I17+Liwonde!I17+Machinga!I17+Ntaja!I17 -> 19714.9 | J17: =Balaka!J17+Liwonde!J17+Machinga!J17+Ntaja!J17 -> 23565 | K17: =Balaka!K17+Liwonde!K17+Machinga!K17+Ntaja!K17 -> 20221.7 | ... O17: =Balaka!O17+Liwonde!O17+Machinga!O17+Ntaja!O17 -> 18940.3 | P17: =SUM(D17:O17) -> 247935.58
A18: CWPs | C18: m3 | D18: =Balaka!D18+Liwonde!D18+Machinga!D18+Ntaja!D18 -> 21 | E18: =Balaka!E18+Liwonde!E18+Machinga!E18+Ntaja!E18 -> 11 | F18: =Balaka!F18+Liwonde!F18+Machinga!F18+Ntaja!F18 -> 60 | G18: =Balaka!G18+Liwonde!G18+Machinga!G18+Ntaja!G18 -> 75 | H18: =Balaka!H18+Liwonde!H18+Machinga!H18+Ntaja!H18 -> 71 | I18: =Balaka!I18+Liwonde!I18+Machinga!I18+Ntaja!I18 -> 86 | J18: =Balaka!J18+Liwonde!J18+Machinga!J18+Ntaja!J18 -> 131 | K18: =Balaka!K18+Liwonde!K18+Machinga!K18+Ntaja!K18 -> 148 | ... O18: =Balaka!O18+Liwonde!O18+Machinga!O18+Ntaja!O18 -> 141 | P18: =SUM(D18:O18) -> 1084
A19: Institutions | C19: m3 | D19: =Balaka!D19+Liwonde!D19+Machinga!D19+Ntaja!D19 -> 23 | E19: =Balaka!E19+Liwonde!E19+Machinga!E19+Ntaja!E19 -> 30 | F19: =Balaka!F19+Liwonde!F19+Machinga!F19+Ntaja!F19 -> 75 | G19: =Balaka!G19+Liwonde!G19+Machinga!G19+Ntaja!G19 -> 61 | H19: =Balaka!H19+Liwonde!H19+Machinga!H19+Ntaja!H19 -> 52 | I19: =Balaka!I19+Liwonde!I19+Machinga!I19+Ntaja!I19 -> 1471 | J19: =Balaka!J19+Liwonde!J19+Machinga!J19+Ntaja!J19 -> 1550 | K19: =Balaka!K19+Liwonde!K19+Machinga!K19+Ntaja!K19 -> 1482 | ... O19: =Balaka!O19+Liwonde!O19+Machinga!O19+Ntaja!O19 -> 437 | P19: =SUM(D19:O19) -> 10349
A20: Commercial/Industrial | C20: m3 | D20: =Balaka!D20+Liwonde!D20+Machinga!D20+Ntaja!D20 -> 52 | E20: =Balaka!E20+Liwonde!E20+Machinga!E20+Ntaja!E20 -> 28 | F20: =Balaka!F20+Liwonde!F20+Machinga!F20+Ntaja!F20 -> 83 | G20: =Balaka!G20+Liwonde!G20+Machinga!G20+Ntaja!G20 -> 86 | H20: =Balaka!H20+Liwonde!H20+Machinga!H20+Ntaja!H20 -> 81 | I20: =Balaka!I20+Liwonde!I20+Machinga!I20+Ntaja!I20 -> 671 | J20: =Balaka!J20+Liwonde!J20+Machinga!J20+Ntaja!J20 -> 661 | K20: =Balaka!K20+Liwonde!K20+Machinga!K20+Ntaja!K20 -> 705 | ... O20: =Balaka!O20+Liwonde!O20+Machinga!O20+Ntaja!O20 -> 503 | P20: =SUM(D20:O20) -> 5081
A21: Total Volume Prepaid | C21: m3 | D21: =SUM(D17:D20) -> 18369 | E21: =SUM(E17:E20) -> 20682 | F21: =SUM(F17:F20) -> 19586.4 | G21: =SUM(G17:G20) -> 19881.8 | H21: =SUM(H17:H20) -> 21039 | I21: =SUM(I17:I20) -> 21942.9 | J21: =SUM(J17:J20) -> 25907 | K21: =SUM(K17:K20) -> 22556.7 | ... P21: =SUM(P17:P20) -> 264449.58
A22: TOTAL REVENUE WATER | C22: m3 | D22: =D21+D15 -> 69431 | E22: =E21+E15 -> 78400 | F22: =F21+F15 -> 77479.4 | G22: =G21+G15 -> 75397.8 | H22: =H21+H15 -> 81141 | I22: =I21+I15 -> 86880.9 | J22: =J21+J15 -> 95559 | K22: =K21+K15 -> 95118.7 | ... P22: =P21+P15 -> 1030522.6
A24: Non-Revenue Water (NRW) | B24: Volume | C24: m3 | D24: =Balaka!D24+Liwonde!D24+Machinga!D24+Ntaja!D24 -> 49845 | E24: =Balaka!E24+Liwonde!E24+Machinga!E24+Ntaja!E24 -> 49628 | F24: =Balaka!F24+Liwonde!F24+Machinga!F24+Ntaja!F24 -> 50155.61 | G24: =Balaka!G24+Liwonde!G24+Machinga!G24+Ntaja!G24 -> 53493.2 | H24: =Balaka!H24+Liwonde!H24+Machinga!H24+Ntaja!H24 -> 50688 | I24: =Balaka!I24+Liwonde!I24+Machinga!I24+Ntaja!I24 -> 58055.1 | J24: =Balaka!J24+Liwonde!J24+Machinga!J24+Ntaja!J24 -> 56449 | K24: =Balaka!K24+Liwonde!K24+Machinga!K24+Ntaja!K24 -> 54911.3 | ... O24: =Balaka!O24+Liwonde!O24+Machinga!O24+Ntaja!O24 -> 30370.7 | P24: =P9-P22 -> 587594.13
B25: Percentage | C25: % | D25: =D24/D9 -> 0.41789631 | E25: =E24/E9 -> 0.38763396 | F25: =F24/F9 -> 0.39296123 | G25: =G24/G9 -> 0.41502665 | H25: =H24/H9 -> 0.3844981 | I25: =I24/I9 -> 0.4005568 | J25: =J24/J9 -> 0.37135545 | K25: =K24/K9 -> 0.36600213 | ... P25: =P24/P9 -> 0.36313458
A26: OPERATING EXPENSES
A27: Chemicals
A28: Chemical | B28: Rate(MK/kg)
A29: Chlorine | B29: =176264.5/50 -> 3525.29 | C29: kg | D29: =Balaka!D29+Liwonde!D29+Machinga!D29+Ntaja!D29 -> 451 | E29: =Balaka!E29+Liwonde!E29+Machinga!E29+Ntaja!E29 -> 619 | F29: =Balaka!F29+Liwonde!F29+Machinga!F29+Ntaja!F29 -> 373 | G29: =Balaka!G29+Liwonde!G29+Machinga!G29+Ntaja!G29 -> 397 | H29: =Balaka!H29+Liwonde!H29+Machinga!H29+Ntaja!H29 -> 341 | I29: =Balaka!I29+Liwonde!I29+Machinga!I29+Ntaja!I29 -> 469 | J29: =Balaka!J29+Liwonde!J29+Machinga!J29+Ntaja!J29 -> 602 | K29: =Balaka!K29+Liwonde!K29+Machinga!K29+Ntaja!K29 -> 517 | ... O29: =Balaka!O29+Liwonde!O29+Machinga!O29+Ntaja!O29 -> 470 | P29: =SUM(D29:O29) -> 5754
C30: kg/mg litre | D30: =D29/(D9/1000) -> 3.7811462 | E30: =E29/(E9/1000) -> 4.8348799 | F30: =F29/(F9/1000) -> 2.9223957 | G30: =G29/(G9/1000) -> 3.080122 | H30: =H29/(H9/1000) -> 2.5866843 | I30: =I29/(I9/1000) -> 3.235911 | J30: =J29/(J9/1000) -> 3.9603179 | K30: =K29/(K9/1000) -> 3.4459775 | ... P30: =P29/(P9/1000) -> 3.5559858
A31: Aluminium sulphate | B31: =53000.511/50 -> 1060.0102 | C31: kg | D31: =Balaka!D31+Liwonde!D31+Machinga!D31+Ntaja!D31 -> 0 | E31: =Balaka!E31+Liwonde!E31+Machinga!E31+Ntaja!E31 -> 0 | F31: =Balaka!F31+Liwonde!F31+Machinga!F31+Ntaja!F31 -> 0 | G31: =Balaka!G31+Liwonde!G31+Machinga!G31+Ntaja!G31 -> 0 | H31: =Balaka!H31+Liwonde!H31+Machinga!H31+Ntaja!H31 -> 0 | I31: =Balaka!I31+Liwonde!I31+Machinga!I31+Ntaja!I31 -> 0 | J31: =Balaka!J31+Liwonde!J31+Machinga!J31+Ntaja!J31 -> 0 | K31: =Balaka!K31+Liwonde!K31+Machinga!K31+Ntaja!K31 -> 0 | ... O31: =Balaka!O31+Liwonde!O31+Machinga!O31+Ntaja!O31 -> 0 | P31: =SUM(D31:O31) -> 0
C32: kg/mg litre | D32: =D31/(D9/1000) -> 0 | E32: =E31/(E9/1000) -> 0 | F32: =F31/(F9/1000) -> 0 | G32: =G31/(G9/1000) -> 0 | H32: =H31/(H9/1000) -> 0 | I32: =I31/(I9/1000) -> 0 | J32: =J31/(J9/1000) -> 0 | K32: =K31/(K9/1000) -> 0 | ... P32: =P31/(P9/1000) -> 0
A33: Soda | B33: =61414.43/50 -> 1228.2886 | C33: kg | D33: =Balaka!D33+Liwonde!D33+Machinga!D33+Ntaja!D33 -> 0 | E33: =Balaka!E33+Liwonde!E33+Machinga!E33+Ntaja!E33 -> 0 | F33: =Balaka!F33+Liwonde!F33+Machinga!F33+Ntaja!F33 -> 0 | G33: =Balaka!G33+Liwonde!G33+Machinga!G33+Ntaja!G33 -> 0 | H33: =Balaka!H33+Liwonde!H33+Machinga!H33+Ntaja!H33 -> 0 | I33: =Balaka!I33+Liwonde!I33+Machinga!I33+Ntaja!I33 -> 0 | J33: =Balaka!J33+Liwonde!J33+Machinga!J33+Ntaja!J33 -> 0 | K33: =Balaka!K33+Liwonde!K33+Machinga!K33+Ntaja!K33 -> 0 | ... O33: =Balaka!O33+Liwonde!O33+Machinga!O33+Ntaja!O33 -> 0 | P33: =SUM(D33:O33) -> 0
C34: kg/mg litre | D34: =D33/(D9/1000) -> 0 | E34: =E33/(E9/1000) -> 0 | F34: =F33/(F9/1000) -> 0 | G34: =G33/(G9/1000) -> 0 | H34: =H33/(H9/1000) -> 0 | I34: =I33/(I9/1000) -> 0 | J34: =J33/(J9/1000) -> 0 | K34: =K33/(K9/1000) -> 0 | ... P34: =P33/(P9/1000) -> 0
A35: Algae floc | B35: =745345.16/200 -> 3726.7258 | C35: litres | D35: =Balaka!D35+Liwonde!D35+Machinga!D35+Ntaja!D35 -> 0 | E35: =Balaka!E35+Liwonde!E35+Machinga!E35+Ntaja!E35 -> 248 | F35: =Balaka!F35+Liwonde!F35+Machinga!F35+Ntaja!F35 -> 301 | G35: =Balaka!G35+Liwonde!G35+Machinga!G35+Ntaja!G35 -> 224 | H35: =Balaka!H35+Liwonde!H35+Machinga!H35+Ntaja!H35 -> 139 | I35: =Balaka!I35+Liwonde!I35+Machinga!I35+Ntaja!I35 -> 155 | J35: =Balaka!J35+Liwonde!J35+Machinga!J35+Ntaja!J35 -> 143 | K35: =Balaka!K35+Liwonde!K35+Machinga!K35+Ntaja!K35 -> 110 | ... O35: =Balaka!O35+Liwonde!O35+Machinga!O35+Ntaja!O35 -> 465
C36: litres/mg litre
A37: Sud floc | B37: =790318.72/200 -> 3951.5936 | C37: litres | D37: =Balaka!D37+Liwonde!D37+Machinga!D37+Ntaja!D37 -> 0 | E37: =Balaka!E37+Liwonde!E37+Machinga!E37+Ntaja!E37 -> 0 | F37: =Balaka!F37+Liwonde!F37+Machinga!F37+Ntaja!F37 -> 0 | G37: =Balaka!G37+Liwonde!G37+Machinga!G37+Ntaja!G37 -> 0 | H37: =Balaka!H37+Liwonde!H37+Machinga!H37+Ntaja!H37 -> 0 | I37: =Balaka!I37+Liwonde!I37+Machinga!I37+Ntaja!I37 -> 0 | J37: =Balaka!J37+Liwonde!J37+Machinga!J37+Ntaja!J37 -> 0 | K37: =Balaka!K37+Liwonde!K37+Machinga!K37+Ntaja!K37 -> 0 | ... O37: =Balaka!O37+Liwonde!O37+Machinga!O37+Ntaja!O37 -> 0 | P37: =SUM(D37:O37) -> 0
C38: litres/mg litre | D38: =D37/(D9/1000) -> 0 | E38: =E37/(E9/1000) -> 0 | F38: =F37/(F9/1000) -> 0 | G38: =G37/(G9/1000) -> 0 | H38: =H37/(H9/1000) -> 0 | I38: =I37/(I9/1000) -> 0 | J38: =J37/(J9/1000) -> 0 | K38: =K37/(K9/1000) -> 0 | ... P38: =P37/(P9/1000) -> 0
A39: Potasium permanganate | B39: 1950 | C39: kg | D39: =Balaka!D39+Liwonde!D39+Machinga!D39+Ntaja!D39 -> 0 | E39: =Balaka!E39+Liwonde!E39+Machinga!E39+Ntaja!E39 -> 0 | F39: =Balaka!F39+Liwonde!F39+Machinga!F39+Ntaja!F39 -> 0 | G39: =Balaka!G39+Liwonde!G39+Machinga!G39+Ntaja!G39 -> 0 | H39: =Balaka!H39+Liwonde!H39+Machinga!H39+Ntaja!H39 -> 0 | I39: =Balaka!I39+Liwonde!I39+Machinga!I39+Ntaja!I39 -> 0 | J39: =Balaka!J39+Liwonde!J39+Machinga!J39+Ntaja!J39 -> 0 | K39: =Balaka!K39+Liwonde!K39+Machinga!K39+Ntaja!K39 -> 0 | ... O39: =Balaka!O39+Liwonde!O39+Machinga!O39+Ntaja!O39 -> 0 | P39: =SUM(D39:O39) -> 0
C40: kg/mg litre | D40: =D39/(D9/1000) -> 0 | E40: =E39/(E9/1000) -> 0 | F40: =F39/(F9/1000) -> 0 | G40: =G39/(G9/1000) -> 0 | H40: =H39/(H9/1000) -> 0 | I40: =I39/(I9/1000) -> 0 | J40: =J39/(J9/1000) -> 0 | K40: =K39/(K9/1000) -> 0 | ... P40: =P39/(P9/1000) -> 0
A41: Cost of Chemicals | C41: Mk | D41: =(D29*$B29)+(D31*$B31)+(D33*$B33)+(D35*$B35)+(D37*$B37)+(D39*$B39) -> 1589905.8 | E41: =(E29*$B29)+(E31*$B31)+(E33*$B33)+(E35*$B35)+(E37*$B37)+(E39*$B39) -> 3106382.5 | F41: =(F29*$B29)+(F31*$B31)+(F33*$B33)+(F35*$B35)+(F37*$B37)+(F39*$B39) -> 2436677.6 | G41: =(G29*$B29)+(G31*$B31)+(G33*$B33)+(G35*$B35)+(G37*$B37)+(G39*$B39) -> 2234326.7 | H41: =(H29*$B29)+(H31*$B31)+(H33*$B33)+(H35*$B35)+(H37*$B37)+(H39*$B39) -> 1720138.8 | I41: =(I29*$B29)+(I31*$B31)+(I33*$B33)+(I35*$B35)+(I37*$B37)+(I39*$B39) -> 2231003.5 | J41: =(J29*$B29)+(J31*$B31)+(J33*$B33)+(J35*$B35)+(J37*$B37)+(J39*$B39) -> 2655146.4 | K41: =(K29*$B29)+(K31*$B31)+(K33*$B33)+(K35*$B35)+(K37*$B37)+(K39*$B39) -> 2232514.8 | ... O41: =(O29*$B29)+(O31*$B31)+(O33*$B33)+(O35*$B35)+(O37*$B37)+(O39*$B39) -> 3389813.8 | P41: =SUM(D41:O41) -> 31293267
A42: Cost/vol. Produced (chemicals) | C42: Mk/m3 | D42: =D41/D9 -> 13.329637 | E42: =E41/E9 -> 24.263306 | F42: =F41/F9 -> 19.090982 | G42: =G41/G9 -> 17.335009 | H42: =H41/H9 -> 13.048258 | I42: =I41/I9 -> 15.393025 | J42: =J41/J9 -> 17.467149 | K42: =K41/K9 -> 14.880456 | ... P42: =P41/P9 -> 19.339314
A43: Power
...

Sheet 1st QTR
A1: SOUTHERN REGION WATER BOARD
A3: MONTHLY REPORTS - 2023/2024
A4: LIWONDE ZONE
A5: LIWONDE ZONE
A7: PARAMETERS | C7: UNITS | D7: Balaka | E7: Liwonde | F7: Machinga | G7: Ntaja | H7: TOTALS
A8: PRODUCTION
A9: Volume Produced | C9: m3 | D9: =Balaka!D9+Balaka!E9+Balaka!F9 -> 172680 | E9: =Liwonde!D9+Liwonde!E9+Liwonde!F9 -> 181289 | F9: =Machinga!D9+Machinga!E9+Machinga!F9 -> 10062 | G9: =Ntaja!D9+Ntaja!E9+Ntaja!F9 -> 10908.01 | H9: =SUM(D9:G9) -> 374939.01
A10: REVENUE WATER - POSTPAID
A11: Volume Billed Individuals | C11: m3 | D11: =Balaka!D11+Balaka!E11+Balaka!F11 -> 74648 | E11: =Liwonde!D11+Liwonde!E11+Liwonde!F11 -> 70623 | F11: =Machinga!D11+Machinga!E11+Machinga!F11 -> 4368 | G11: =Ntaja!D11+Ntaja!E11+Ntaja!F11 -> 1071 | H11: =SUM(D11:G11) -> 150710
A12: Volume Billed CWPs | C12: m3 | D12: =Balaka!D12+Balaka!E12+Balaka!F12 -> 2469 | E12: =Liwonde!D12+Liwonde!E12+Liwonde!F12 -> 1159 | F12: =Machinga!D12+Machinga!E12+Machinga!F12 -> 0 | G12: =Ntaja!D12+Ntaja!E12+Ntaja!F12 -> 0 | H12: =SUM(D12:G12) -> 3628
A13: Volume Billed Institutions | C13: m3 | D13: =Balaka!D13+Balaka!E13+Balaka!F13 -> 3203 | E13: =Liwonde!D13+Liwonde!E13+Liwonde!F13 -> 6694 | F13: =Machinga!D13+Machinga!E13+Machinga!F13 -> 1717 | G13: =Ntaja!D13+Ntaja!E13+Ntaja!F13 -> 45 | H13: =SUM(D13:G13) -> 11659
A14: Volume Billed Commercial/Industrial | C14: m3 | D14: =Balaka!D14+Balaka!E14+Balaka!F14 -> 258 | E14: =Liwonde!D14+Liwonde!E14+Liwonde!F14 -> 416 | F14: =Machinga!D14+Machinga!E14+Machinga!F14 -> 0 | G14: =Ntaja!D14+Ntaja!E14+Ntaja!F14 -> 2 | H14: =SUM(D14:G14) -> 676
A15: Total Volume Billed Post Paid | C15: m3 | D15: =SUM(D11:D14) -> 80578 | E15: =SUM(E11:E14) -> 78892 | F15: =SUM(F11:F14) -> 6085 | G15: =SUM(G11:G14) -> 1118 | H15: =SUM(H11:H14) -> 166673
A16: REVENUE WATER - PREPAID
A17: Individuals | C17: m3 | D17: =Balaka!D17+Balaka!E17+Balaka!F17 -> 21722 | E17: =Liwonde!D17+Liwonde!E17+Liwonde!F17 -> 30656.3 | F17: =Machinga!D17+Machinga!E17+Machinga!F17 -> 2571.2 | G17: =Ntaja!D17+Ntaja!E17+Ntaja!F17 -> 3304.9 | H17: =SUM(D17:G17) -> 58254.4
A18: CWPs | C18: m3 | D18: =Balaka!D18+Balaka!E18+Balaka!F18 -> 0 | E18: =Liwonde!D18+Liwonde!E18+Liwonde!F18 -> 0 | F18: =Machinga!D18+Machinga!E18+Machinga!F18 -> 0 | G18: =Ntaja!D18+Ntaja!E18+Ntaja!F18 -> 92 | H18: =SUM(D18:G18) -> 92
A19: Institutions | C19: m3 | D19: =Balaka!D19+Balaka!E19+Balaka!F19 -> 0 | E19: =Liwonde!D19+Liwonde!E19+Liwonde!F19 -> 0 | F19: =Machinga!D19+Machinga!E19+Machinga!F19 -> 0 | G19: =Ntaja!D19+Ntaja!E19+Ntaja!F19 -> 128 | H19: =SUM(D19:G19) -> 128
A20: Commercial/Industrial | C20: m3 | D20: =Balaka!D20+Balaka!E20+Balaka!F20 -> 0 | E20: =Liwonde!D20+Liwonde!E20+Liwonde!F20 -> 0 | F20: =Machinga!D20+Machinga!E20+Machinga!F20 -> 0 | G20: =Ntaja!D20+Ntaja!E20+Ntaja!F20 -> 163 | H20: =SUM(D20:G20) -> 163
A21: Total Volume Prepaid | C21: m3 | D21: =SUM(D17:D20) -> 21722 | E21: =SUM(E17:E20) -> 30656.3 | F21: =SUM(F17:F20) -> 2571.2 | G21: =SUM(G17:G20) -> 3687.9 | H21: =SUM(H17:H20) -> 58637.4
A22: TOTAL REVENUE WATER | C22: m3 | D22: =D21+D15 -> 102300 | E22: =E21+E15 -> 109548.3 | F22: =F21+F15 -> 8656.2 | G22: =G21+G15 -> 4805.9 | H22: =H21+H15 -> 225310.4
A23: NON-REVENUE WATER (NRW)
A24: Non-Revenue Water (NRW) | B24: Volume | C24: m3 | D24: =D9-D22 -> 70380 | E24: =E9-E22 -> 71740.7 | F24: =F9-F22 -> 1405.8 | G24: =G9-G22 -> 6102.11 | H24: =H9-H22 -> 149628.61
B25: Percentage | C25: % | D25: =D24/D9 -> 0.4075747 | E25: =E24/E9 -> 0.39572561 | F25: =F24/F9 -> 0.13971377 | G25: =G24/G9 -> 0.55941551 | H25: =H24/H9 -> 0.39907453
A26: OPERATING EXPENSES
A27: Chemicals
A28: Chemical | B28: Rate(MK/kg)
A29: Chlorine | B29: =176264.5/50 -> 3525.29 | C29: kg | D29: =Balaka!D29+Balaka!E29+Balaka!F29 -> 340 | E29: =Liwonde!D29+Liwonde!E29+Liwonde!F29 -> 1050 | F29: =Machinga!D29+Machinga!E29+Machinga!F29 -> 33 | G29: =Ntaja!D29+Ntaja!E29+Ntaja!F29 -> 20 | H29: =SUM(D29:G29) -> 1443
C30: kg/mg litre | D30: =D29/(D9/1000) -> 1.9689599 | E30: =E29/(E9/1000) -> 5.7918572 | F30: =F29/(F9/1000) -> 3.2796661 | G30: =G29/(G9/1000) -> 1.833515 | H30: =H29/(H9/1000) -> 3.8486259
A31: Aluminium sulphate | B31: =53000.511/50 -> 1060.0102 | C31: kg | D31: =Balaka!D31+Balaka!E31+Balaka!F31 -> 0 | E31: =Liwonde!D31+Liwonde!E31+Liwonde!F31 -> 0 | F31: =Machinga!D31+Machinga!E31+Machinga!F31 -> 0 | G31: =Ntaja!D31+Ntaja!E31+Ntaja!F31 -> 0 | H31: =SUM(D31:G31) -> 0
C32: kg/mg litre | D32: =D31/(D9/1000) -> 0 | E32: =E31/(E9/1000) -> 0 | F32: =F31/(F9/1000) -> 0 | G32: =G31/(G9/1000) -> 0 | H32: =H31/(H9/1000) -> 0
A33: Soda | B33: =61414.43/50 -> 1228.2886 | C33: kg | D33: =Balaka!D33+Balaka!E33+Balaka!F33 -> 0 | E33: =Liwonde!D33+Liwonde!E33+Liwonde!F33 -> 0 | F33: =Machinga!D33+Machinga!E33+Machinga!F33 -> 0 | G33: =Ntaja!D33+Ntaja!E33+Ntaja!F33 -> 0 | H33: =SUM(D33:G33) -> 0
C34: kg/mg litre | D34: =D33/(D9/1000) -> 0 | E34: =E33/(E9/1000) -> 0 | F34: =F33/(F9/1000) -> 0 | G34: =G33/(G9/1000) -> 0 | H34: =H33/(H9/1000) -> 0
A35: Algae floc | B35: =745345.16/200 -> 3726.7258 | C35: litres | D35: =Balaka!D35+Balaka!E35+Balaka!F35 -> 0 | E35: =Liwonde!D35+Liwonde!E35+Liwonde!F35 -> 549 | F35: =Machinga!D35+Machinga!E35+Machinga!F35 -> 0 | G35: =Ntaja!D35+Ntaja!E35+Ntaja!F35 -> 0 | H35: =SUM(D35:G35) -> 549
C36: litres/mg litre | D36: =D35/(D11/1000) -> 0 | E36: =E35/(E11/1000) -> 7.7736715 | F36: =F35/(F11/1000) -> 0 | G36: =G35/(G11/1000) -> 0 | H36: =H35/(H11/1000) -> 3.6427576
A37: Sud floc | B37: =790318.72/200 -> 3951.5936 | C37: litres | D37: =Balaka!D37+Balaka!E37+Balaka!F37 -> 0 | E37: =Liwonde!D37+Liwonde!E37+Liwonde!F37 -> 0 | F37: =Machinga!D37+Machinga!E37+Machinga!F37 -> 0 | G37: =Ntaja!D37+Ntaja!E37+Ntaja!F37 -> 0 | H37: =SUM(D37:G37) -> 0
C38: litres/mg litre | D38: =D37/(D13/1000) -> 0 | E38: =E37/(E13/1000) -> 0 | F38: =F37/(F13/1000) -> 0 | G38: =G37/(G13/1000) -> 0 | H38: =H37/(H13/1000) -> 0
A39: Potasium permanganate | B39: 1950 | C39: kg | D39: =Balaka!D39+Balaka!E39+Balaka!F39 -> 0 | E39: =Liwonde!D39+Liwonde!E39+Liwonde!F39 -> 0 | F39: =Machinga!D39+Machinga!E39+Machinga!F39 -> 0 | G39: =Ntaja!D39+Ntaja!E39+Ntaja!F39 -> 0 | H39: =SUM(D39:G39) -> 0
C40: kg/mg litre | D40: =D39/(D9/1000) -> 0 | E40: =E39/(E9/1000) -> 0 | F40: =F39/(F9/1000) -> 0 | G40: =G39/(G9/1000) -> 0 | H40: =H39/(H9/1000) -> 0
A41: Cost of Chemicals | C41: Mk | D41: =(D29*$B29)+(D31*$B31)+(D33*$B33)+(D35*$B35)+(D37*$B37)+(D39*$B39) -> 1198598.6 | E41: =(E29*$B29)+(E31*$B31)+(E33*$B33)+(E35*$B35)+(E37*$B37)+(E39*$B39) -> 5747527 | F41: =(F29*$B29)+(F31*$B31)+(F33*$B33)+(F35*$B35)+(F37*$B37)+(F39*$B39) -> 116334.57 | G41: =(G29*$B29)+(G31*$B31)+(G33*$B33)+(G35*$B35)+(G37*$B37)+(G39*$B39) -> 70505.8 | H41: =SUM(D41:G41) -> 7132965.9
A42: Cost/vol. Produced (chemicals) | C42: Mk/m3 | D42: =D41/D9 -> 6.9411547 | E42: =E41/E9 -> 31.703672 | F42: =F41/F9 -> 11.561774 | G42: =G41/G9 -> 6.4636721 | H42: =H41/H9 -> 19.024337
...

Sheet 2nd QTR 
A1: SOUTHERN REGION WATER BOARD
A3: MONTHLY REPORTS - 2023/2024
A4: LIWONDE ZONE
A5: LIWONDE ZONE
A7: PARAMETERS | C7: UNITS | D7: Balaka | E7: Liwonde | F7: Machinga | G7: Ntaja | H7: TOTALS
A8: PRODUCTION
A9: Volume Produced | C9: m3 | D9: =Balaka!G9+Balaka!H9+Balaka!I9 -> 191187 | E9: =Liwonde!G9+Liwonde!H9+Liwonde!I9 -> 197287 | F9: =Machinga!G9+Machinga!H9+Machinga!I9 -> 9080 | G9: =Ntaja!G9+Ntaja!H9+Ntaja!I9 -> 8102 | H9: =SUM(D9:G9) -> 405656
A10: REVENUE WATER - POSTPAID
A11: Volume Billed Individuals | C11: m3 | D11: =Balaka!G11+Balaka!H11+Balaka!I11 -> 84563 | E11: =Liwonde!G11+Liwonde!H11+Liwonde!I11 -> 78955 | F11: =Machinga!G11+Machinga!H11+Machinga!I11 -> 2995 | G11: =Ntaja!G11+Ntaja!H11+Ntaja!I11 -> 14 | H11: =SUM(D11:G11) -> 166527
A12: Volume Billed CWPs | C12: m3 | D12: =Balaka!G12+Balaka!H12+Balaka!I12 -> 3531 | E12: =Liwonde!G12+Liwonde!H12+Liwonde!I12 -> 1448 | F12: =Machinga!G12+Machinga!H12+Machinga!I12 -> 0 | G12: =Ntaja!G12+Ntaja!H12+Ntaja!I12 -> 0 | H12: =SUM(D12:G12) -> 4979
A13: Volume Billed Institutions | C13: m3 | D13: =Balaka!G13+Balaka!H13+Balaka!I13 -> 908 | E13: =Liwonde!G13+Liwonde!H13+Liwonde!I13 -> 6974 | F13: =Machinga!G13+Machinga!H13+Machinga!I13 -> 139 | G13: =Ntaja!G13+Ntaja!H13+Ntaja!I13 -> 59 | H13: =SUM(D13:G13) -> 8080
A14: Volume Billed Commercial/Industrial | C14: m3 | D14: =Balaka!G14+Balaka!H14+Balaka!I14 -> 342 | E14: =Liwonde!G14+Liwonde!H14+Liwonde!I14 -> 628 | F14: =Machinga!G14+Machinga!H14+Machinga!I14 -> 0 | G14: =Ntaja!G14+Ntaja!H14+Ntaja!I14 -> 0 | H14: =SUM(D14:G14) -> 970
A15: Total Volume Billed Post Paid | C15: m3 | D15: =SUM(D11:D14) -> 89344 | E15: =SUM(E11:E14) -> 88005 | F15: =SUM(F11:F14) -> 3134 | G15: =SUM(G11:G14) -> 73 | H15: =SUM(H11:H14) -> 180556
A16: REVENUE WATER - PREPAID
A17: Individuals | C17: m3 | D17: =Balaka!G17+Balaka!H17+Balaka!I17 -> 20425 | E17: =Liwonde!G17+Liwonde!H17+Liwonde!I17 -> 28538.1 | F17: =Machinga!G17+Machinga!H17+Machinga!I17 -> 4776.6 | G17: =Ntaja!G17+Ntaja!H17+Ntaja!I17 -> 6470 | H17: =SUM(D17:G17) -> 60209.7
A18: CWPs | C18: m3 | D18: =Balaka!G18+Balaka!H18+Balaka!I18 -> 0 | E18: =Liwonde!G18+Liwonde!H18+Liwonde!I18 -> 0 | F18: =Machinga!G18+Machinga!H18+Machinga!I18 -> 0 | G18: =Ntaja!G18+Ntaja!H18+Ntaja!I18 -> 232 | H18: =SUM(D18:G18) -> 232
A19: Institutions | C19: m3 | D19: =Balaka!G19+Balaka!H19+Balaka!I19 -> 1374 | E19: =Liwonde!G19+Liwonde!H19+Liwonde!I19 -> 0 | F19: =Machinga!G19+Machinga!H19+Machinga!I19 -> 0 | G19: =Ntaja!G19+Ntaja!H19+Ntaja!I19 -> 210 | H19: =SUM(D19:G19) -> 1584
A20: Commercial/Industrial | C20: m3 | D20: =Balaka!G20+Balaka!H20+Balaka!I20 -> 551 | E20: =Liwonde!G20+Liwonde!H20+Liwonde!I20 -> 0 | F20: =Machinga!G20+Machinga!H20+Machinga!I20 -> 0 | G20: =Ntaja!G20+Ntaja!H20+Ntaja!I20 -> 287 | H20: =SUM(D20:G20) -> 838
A21: Total Volume Prepaid | C21: m3 | D21: =SUM(D17:D20) -> 22350 | E21: =SUM(E17:E20) -> 28538.1 | F21: =SUM(F17:F20) -> 4776.6 | G21: =SUM(G17:G20) -> 7199 | H21: =SUM(H17:H20) -> 62863.7
A22: TOTAL REVENUE WATER | C22: m3 | D22: =D21+D15 -> 111694 | E22: =E21+E15 -> 116543.1 | F22: =F21+F15 -> 7910.6 | G22: =G21+G15 -> 7272 | H22: =H21+H15 -> 243419.7
A23: NON-REVENUE WATER (NRW)
A24: Non-Revenue Water (NRW) | B24: Volume | C24: m3 | D24: =D9-D22 -> 79493 | E24: =E9-E22 -> 80743.9 | F24: =F9-F22 -> 1169.4 | G24: =G9-G22 -> 830 | H24: =H9-H22 -> 162236.3
B25: Percentage | C25: % | D25: =D24/D9 -> 0.41578664 | E25: =E24/E9 -> 0.40927126 | F25: =F24/F9 -> 0.12878855 | G25: =G24/G9 -> 0.10244384 | H25: =H24/H9 -> 0.39993566
A26: OPERATING EXPENSES
A27: Chemicals
A28: Chemical | B28: Rate(MK/kg)
A29: Chlorine | B29: =176264.5/50 -> 3525.29 | C29: kg | D29: =Balaka!G29+Balaka!H29+Balaka!I29 -> 320 | E29: =Liwonde!G29+Liwonde!H29+Liwonde!I29 -> 833 | F29: =Machinga!G29+Machinga!H29+Machinga!I29 -> 30 | G29: =Ntaja!G29+Ntaja!H29+Ntaja!I29 -> 24 | H29: =SUM(D29:G29) -> 1207
C30: kg/mg litre | D30: =D29/(D9/1000) -> 1.673754 | E30: =E29/(E9/1000) -> 4.2222752 | F30: =F29/(F9/1000) -> 3.3039648 | G30: =G29/(G9/1000) -> 2.9622315 | H30: =H29/(H9/1000) -> 2.9754275
A31: Aluminium sulphate | B31: =53000.511/50 -> 1060.0102 | C31: kg | D31: =Balaka!G31+Balaka!H31+Balaka!I31 -> 0 | E31: =Liwonde!G31+Liwonde!H31+Liwonde!I31 -> 0 | F31: =Machinga!G31+Machinga!H31+Machinga!I31 -> 0 | G31: =Ntaja!G31+Ntaja!H31+Ntaja!I31 -> 0 | H31: =SUM(D31:G31) -> 0
C32: kg/mg litre | D32: =D31/(D9/1000) -> 0 | E32: =E31/(E9/1000) -> 0 | F32: =F31/(F9/1000) -> 0 | G32: =G31/(G9/1000) -> 0 | H32: =H31/(H9/1000) -> 0
A33: Soda | B33: =61414.43/50 -> 1228.2886 | C33: kg | D33: =Balaka!G33+Balaka!H33+Balaka!I33 -> 0 | E33: =Liwonde!G33+Liwonde!H33+Liwonde!I33 -> 0 | F33: =Machinga!G33+Machinga!H33+Machinga!I33 -> 0 | G33: =Ntaja!G33+Ntaja!H33+Ntaja!I33 -> 0 | H33: =SUM(D33:G33) -> 0
C34: kg/mg litre | D34: =D33/(D9/1000) -> 0 | E34: =E33/(E9/1000) -> 0 | F34: =F33/(F9/1000) -> 0 | G34: =G33/(G9/1000) -> 0 | H34: =H33/(H9/1000) -> 0
A35: Algae floc | B35: =745345.16/200 -> 3726.7258 | C35: litres | D35: =Balaka!G35+Balaka!H35+Balaka!I35 -> 0 | E35: =Liwonde!G35+Liwonde!H35+Liwonde!I35 -> 518 | F35: =Machinga!G35+Machinga!H35+Machinga!I35 -> 0 | G35: =Ntaja!G35+Ntaja!H35+Ntaja!I35 -> 0
C36: litres/mg litre
A37: Sud floc | B37: =790318.72/200 -> 3951.5936 | C37: litres | D37: =Balaka!G37+Balaka!H37+Balaka!I37 -> 0 | E37: =Liwonde!G37+Liwonde!H37+Liwonde!I37 -> 0 | F37: =Machinga!G37+Machinga!H37+Machinga!I37 -> 0 | G37: =Ntaja!G37+Ntaja!H37+Ntaja!I37 -> 0 | H37: =SUM(D37:G37) -> 0
C38: litres/mg litre | D38: =D37/(D9/1000) -> 0 | E38: =E37/(E9/1000) -> 0 | F38: =F37/(F9/1000) -> 0 | G38: =G37/(G9/1000) -> 0 | H38: =H37/(H9/1000) -> 0
A39: Potasium permanganate | B39: 1950 | C39: kg | D39: =Balaka!G39+Balaka!H39+Balaka!I39 -> 0 | E39: =Liwonde!G39+Liwonde!H39+Liwonde!I39 -> 0 | F39: =Machinga!G39+Machinga!H39+Machinga!I39 -> 0 | G39: =Ntaja!G39+Ntaja!H39+Ntaja!I39 -> 0 | H39: =SUM(D39:G39) -> 0
C40: kg/mg litre | D40: =D39/(D9/1000) -> 0 | E40: =E39/(E9/1000) -> 0 | F40: =F39/(F9/1000) -> 0 | G40: =G39/(G9/1000) -> 0 | H40: =H39/(H9/1000) -> 0
A41: Cost of Chemicals | C41: Mk | D41: =(D29*$B29)+(D31*$B31)+(D33*$B33)+(D35*$B35)+(D37*$B37)+(D39*$B39) -> 1128092.8 | E41: =(E29*$B29)+(E31*$B31)+(E33*$B33)+(E35*$B35)+(E37*$B37)+(E39*$B39) -> 4867010.5 | F41: =(F29*$B29)+(F31*$B31)+(F33*$B33)+(F35*$B35)+(F37*$B37)+(F39*$B39) -> 105758.7 | G41: =(G29*$B29)+(G31*$B31)+(G33*$B33)+(G35*$B35)+(G37*$B37)+(G39*$B39) -> 84606.96 | H41: =SUM(D41:G41) -> 6185469
A42: Cost/vol. Produced (chemicals) | C42: Mk/m3 | D42: =D41/D9 -> 5.9004681 | E42: =E41/E9 -> 24.669697 | F42: =F41/F9 -> 11.647434 | G42: =G41/G9 -> 10.442725 | H42: =H41/H9 -> 15.248065
...

Sheet Midyear Summary
A1: SOUTHERN REGION WATER BOARD
A3: MONTHLY REPORTS - 2023/2024
A4: LIWONDE ZONE
A5: LIWONDE ZONE
A7: PARAMETERS | C7: UNITS | D7: Balaka | E7: Liwonde | F7: Machinga | G7: Ntaja | H7: TOTALS
A8: PRODUCTION
A9: Volume Produced | C9: m3 | D9: =Balaka!D9+Balaka!E9+Balaka!F9+Balaka!G9+Balaka!H9+Balaka!I9 -> 363867 | E9: =Liwonde!D9+Liwonde!E9+Liwonde!F9+Liwonde!G9+Liwonde!H9+Liwonde!I9 -> 378576 | F9: =Machinga!D9+Machinga!E9+Machinga!F9+Machinga!G9+Machinga!H9+Machinga!I9 -> 19142 | G9: =Ntaja!D9+Ntaja!E9+Ntaja!F9+Ntaja!G9+Ntaja!H9+Ntaja!I9 -> 19010.01 | H9: =SUM(D9:G9) -> 780595.01
A10: REVENUE WATER - POSTPAID
A11: Volume Billed Individuals | C11: m3 | D11: =Balaka!D11+Balaka!E11+Balaka!F11+Balaka!G11+Balaka!H11+Balaka!I11 -> 159211 | E11: =Liwonde!D11+Liwonde!E11+Liwonde!F11+Liwonde!G11+Liwonde!H11+Liwonde!I11 -> 149578 | F11: =Machinga!D11+Machinga!E11+Machinga!F11+Machinga!G11+Machinga!H11+Machinga!I11 -> 7363 | G11: =Ntaja!D11+Ntaja!E11+Ntaja!F11+Ntaja!G11+Ntaja!H11+Ntaja!I11 -> 1085 | H11: =SUM(D11:G11) -> 317237
A12: Volume Billed CWPs | C12: m3 | D12: =Balaka!D12+Balaka!E12+Balaka!F12+Balaka!G12+Balaka!H12+Balaka!I12 -> 6000 | E12: =Liwonde!D12+Liwonde!E12+Liwonde!F12+Liwonde!G12+Liwonde!H12+Liwonde!I12 -> 2607 | F12: =Machinga!D12+Machinga!E12+Machinga!F12+Machinga!G12+Machinga!H12+Machinga!I12 -> 0 | G12: =Ntaja!D12+Ntaja!E12+Ntaja!F12+Ntaja!G12+Ntaja!H12+Ntaja!I12 -> 0 | H12: =SUM(D12:G12) -> 8607
