Workbook

Sheet Mangochi
A1: SOUTHERN REGION WATER BOARD
A3: MONTHLY REPORTS - 2023/2024
A4: MANGOCHI ZONE
A5: MANGOCHI ZONE
A7: PARAMETERS | C7: UNITS | D7: APRIL | E7: MAY | F7: JUNE | G7: JULY | H7: AUGUST | I7: SEPTEMBER | J7: OCTOBER | K7: NOVEMBER | L7: DECEMBER | M7: JANUARY | N7: FEBRUARY | O7: MARCH | P7: TOTALS
A8: PRODUCTION | Q8: APR
A9: Volume Produced | C9: m3 | D9: 128967 | E9: 126274 | F9: 133435 | G9: 129170 | H9: 127011 | I9: 120296 | J9: 123700 | K9: 153120 | L9: 138608 | M9: 141058 | N9: 129551 | O9: 124206 | P9: =SUM(D9:O9) -> 1575396 | Q9: 0
A10: REVENUE WATER - POSTPAID
A11: Volume Billed Individuals | C11: m3 | D11: 53390 | E11: 57141 | F11: 57885 | G11: 57872 | H11: 59635 | I11: 60374 | J11: 63088 | K11: 63200 | L11: 58777 | M11: 64972 | N11: 67205 | O11: 68023 | P11: =SUM(D11:O11) -> 731562
A12: Volume Billed CWPs | C12: m3 | D12: 0 | E12: 0 | F12: 0 | G12: 0 | H12: 0 | I12: 0 | J12: 0 | K12: 0 | M12: 0 | N12: 0 | O12: 0 | P12: =SUM(D12:O12) -> 0
A13: Volume Billed Institutions | C13: m3 | D13: 315 | E13: 296 | F13: 309 | G13: 231 | H13: 307 | I13: 309 | J13: 289 | K13: 276 | L13: 279 | M13: 142 | N13: 120 | O13: 174 | P13: =SUM(D13:O13) -> 3047
A14: Volume Billed Commercial/Industrial | C14: m3 | D14: 217 | E14: 217 | F14: 78 | G14: 22 | H14: 105 | I14: 42 | J14: 47 | K14: 78 | L14: 105 | M14: 57 | N14: 60 | O14: 59 | P14: =SUM(D14:O14) -> 1087
A15: Total Volume Billed Post Paid | C15: m3 | D15: =SUM(D11:D14) -> 53922 | E15: =SUM(E11:E14) -> 57654 | F15: =SUM(F11:F14) -> 58272 | G15: =SUM(G11:G14) -> 58125 | H15: =SUM(H11:H14) -> 60047 | I15: =SUM(I11:I14) -> 60725 | J15: =SUM(J11:J14) -> 63424 | K15: =SUM(K11:K14) -> 63554 | ... P15: =SUM(P11:P14) -> 735696
A16: REVENUE WATER - PREPAID
A17: Individuals | C17: m3 | D17: 13086.4 | E17: 17006.9 | F17: 14082 | G17: 16217.3 | H17: 15436 | I17: 15196.9 | J17: 16970.2 | K17: 17078.1 | L17: 18202 | M17: 17323.6 | N17: 23958.5 | O17: 17257.6 | P17: =SUM(D17:O17) -> 201815.5
A18: CWPs | C18: m3 | D18: 0 | E18: 0 | F18: 0 | G18: 0 | H18: 0 | I18: 0 | J18: 0 | K18: 0 | L18: 0 | M18: 0 | N18: 0 | O18: 0 | P18: =SUM(D18:O18) -> 0
A19: Institutions | C19: m3 | D19: 0 | E19: 0 | F19: 0 | G19: 0 | H19: 0 | I19: 0 | J19: 0 | K19: 0 | L19: 0 | M19: 0 | N19: 0 | O19: 0 | P19: =SUM(D19:O19) -> 0
A20: Commercial/Industrial | C20: m3 | D20: 0 | E20: 0 | F20: 0 | G20: 0 | H20: 0 | I20: 0 | J20: 0 | K20: 0 | L20: 0 | M20: 0 | N20: 0 | O20: 0 | P20: =SUM(D20:O20) -> 0
A21: Total Volume Prepaid | C21: m3 | D21: =SUM(D17:D20) -> 13086.4 | E21: =SUM(E17:E20) -> 17006.9 | F21: =SUM(F17:F20) -> 14082 | G21: =SUM(G17:G20) -> 16217.3 | H21: =SUM(H17:H20) -> 15436 | I21: =SUM(I17:I20) -> 15196.9 | J21: =SUM(J17:J20) -> 16970.2 | K21: =SUM(K17:K20) -> 17078.1 | ... P21: =SUM(P17:P20) -> 201815.5
A22: TOTAL REVENUE WATER | C22: m3 | D22: =D21+D15 -> 67008.4 | E22: =E21+E15 -> 74660.9 | F22: =F21+F15 -> 72354 | G22: =G21+G15 -> 74342.3 | H22: =H21+H15 -> 75483 | I22: =I21+I15 -> 75921.9 | J22: =J21+J15 -> 80394.2 | K22: =K21+K15 -> 80632.1 | ... P22: =P21+P15 -> 937511.5
D23: 0 | E23: 0 | F23: 0 | G23: 0 | H23: 0 | I23: 0 | J23: 0 | K23: 0 | L23: 0
A24: Non-Revenue Water (NRW) | B24: Volume | C24: m3 | D24: =D9-D22 -> 61958.6 | E24: =E9-E22 -> 51613.1 | F24: =F9-F22 -> 61081 | G24: =G9-G22 -> 54827.7 | H24: =H9-H22 -> 51528 | I24: =I9-I22 -> 44374.1 | J24: =J9-J22 -> 43305.8 | K24: =K9-K22 -> 72487.9 | ... P24: =P9-P22 -> 637884.5
B25: Percentage | C25: % | D25: =D24/D9 -> 0.48042212 | E25: =E24/E9 -> 0.40873893 | F25: =F24/F9 -> 0.45775846 | G25: =G24/G9 -> 0.42446156 | H25: =H24/H9 -> 0.40569714 | I25: =I24/I9 -> 0.36887428 | J25: =J24/J9 -> 0.35008731 | K25: =K24/K9 -> 0.47340583 | ... P25: =P24/P9 -> 0.40490423
A26: OPERATING EXPENSES
A27: Chemicals
A28: Chemical | B28: Rate(MK/kg) | D28: 0 | E28: 0 | F28: 0 | G28: 0
A29: Chlorine | B29: 3525.29 | C29: kg | D29: 393 | E29: 637 | F29: 599 | G29: 539 | H29: 517 | I29: 500 | J29: 525 | K29: 520 | L29: 450 | M29: 460 | N29: 546 | O29: 550 | P29: =SUM(D29:O29) -> 6236
C30: kg/mg litre | D30: =D29/(D9/1000) -> 3.0472912 | E30: =E29/(E9/1000) -> 5.0445856 | F30: =F29/(F9/1000) -> 4.4890771 | G30: =G29/(G9/1000) -> 4.1727955 | H30: =H29/(H9/1000) -> 4.0705136 | I30: =I29/(I9/1000) -> 4.1564142 | J30: =J29/(J9/1000) -> 4.244139 | K30: =K29/(K9/1000) -> 3.3960293 | ... P30: =P29/(P9/1000) -> 3.9583698
A31: Aluminium sulphate | B31: 1060.0102 | C31: kg | D31: 800 | E31: 0 | F31: 0 | G31: 0 | M31: 200 | N31: 50 | O31: 50 | P31: =SUM(D31:O31) -> 1100
C32: kg/mg litre | D32: =D31/(D9/1000) -> 6.2031372 | E32: =E31/(E9/1000) -> 0 | F32: =F31/(F9/1000) -> 0 | G32: =G31/(G9/1000) -> 0 | H32: =H31/(H9/1000) -> 0 | I32: =I31/(I9/1000) -> 0 | J32: =J31/(J9/1000) -> 0 | K32: =K31/(K9/1000) -> 0 | ... P32: =P31/(P9/1000) -> 0.69823714
A33: Soda | B33: 1228.2886 | C33: kg | D33: 0 | E33: 0 | F33: 0 | G33: 0 | P33: =SUM(D33:O33) -> 0
C34: kg/mg litre | D34: =D33/(D9/1000) -> 0 | E34: =E33/(E9/1000) -> 0 | F34: =F33/(F9/1000) -> 0 | G34: =G33/(G9/1000) -> 0 | H34: =H33/(H9/1000) -> 0 | I34: =I33/(I9/1000) -> 0 | J34: =J33/(J9/1000) -> 0 | K34: =K33/(K9/1000) -> 0 | ... P34: =P33/(P9/1000) -> 0
A35: Algae floc | B35: 3726.7258 | C35: litres | D35: 0 | E35: 0 | F35: 0 | G35: 0
C36: litres/mg litre | D36: 0 | E36: 0 | F36: 0 | G36: 0
A37: Sud floc | B37: 3951.5936 | C37: litres | D37: 0 | E37: 0 | F37: 0 | G37: 0 | H37: 0 | I37: 0 | J37: 0 | K37: 0 | L37: 0 | M37: 0 | N37: 0 | O37: 0 | P37: =SUM(D37:O37) -> 0
C38: litres/mg litre | D38: =D37/(D9/1000) -> 0 | E38: =E37/(E9/1000) -> 0 | F38: =F37/(F9/1000) -> 0 | G38: =G37/(G9/1000) -> 0 | H38: =H37/(H9/1000) -> 0 | I38: =I37/(I9/1000) -> 0 | J38: =J37/(J9/1000) -> 0 | K38: =K37/(K9/1000) -> 0 | ... P38: =P37/(P9/1000) -> 0
A39: Potasium permanganate | B39: 1950 | C39: kg | D39: 0 | E39: 0 | F39: 0 | G39: 0 | H39: 0 | I39: 0 | J39: 0 | K39: 0 | L39: 0 | M39: 0 | N39: 0 | O39: 0 | P39: =SUM(D39:O39) -> 0
C40: kg/mg litre | D40: =D39/(D9/1000) -> 0 | E40: =E39/(E9/1000) -> 0 | F40: =F39/(F9/1000) -> 0 | G40: =G39/(G9/1000) -> 0 | H40: =H39/(H9/1000) -> 0 | I40: =I39/(I9/1000) -> 0 | J40: =J39/(J9/1000) -> 0 | K40: =K39/(K9/1000) -> 0 | ... P40: =P39/(P9/1000) -> 0
A41: Cost of Chemicals | C41: Mk | D41: =(D29*$B29)+(D31*$B31)+(D33*$B33)+(D35*$B35)+(D37*$B37)+(D39*$B39) -> 2233447.1 | E41: =(E29*$B29)+(E31*$B31)+(E33*$B33)+(E35*$B35)+(E37*$B37)+(E39*$B39) -> 2245609.7 | F41: =(F29*$B29)+(F31*$B31)+(F33*$B33)+(F35*$B35)+(F37*$B37)+(F39*$B39) -> 2111648.7 | G41: =(G29*$B29)+(G31*$B31)+(G33*$B33)+(G35*$B35)+(G37*$B37)+(G39*$B39) -> 1900131.3 | H41: =(H29*$B29)+(H31*$B31)+(H33*$B33)+(H35*$B35)+(H37*$B37)+(H39*$B39) -> 1822574.9 | I41: =(I29*$B29)+(I31*$B31)+(I33*$B33)+(I35*$B35)+(I37*$B37)+(I39*$B39) -> 1762645 | J41: =(J29*$B29)+(J31*$B31)+(J33*$B33)+(J35*$B35)+(J37*$B37)+(J39*$B39) -> 1850777.2 | K41: =(K29*$B29)+(K31*$B31)+(K33*$B33)+(K35*$B35)+(K37*$B37)+(K39*$B39) -> 1833150.8 | ... O41: =(O29*$B29)+(O31*$B31)+(O33*$B33)+(O35*$B35)+(O37*$B37)+(O39*$B39) -> 1991910 | P41: =SUM(D41:O41) -> 23149720
A42: Cost/vol. Produced (chemicals) | C42: Mk/m3 | D42: =D41/D9 -> 17.317974 | E42: =E41/E9 -> 17.783627 | F42: =F41/F9 -> 15.825299 | G42: =G41/G9 -> 14.710314 | H42: =H41/H9 -> 14.349741 | I42: =I41/I9 -> 14.652565 | J42: =J41/J9 -> 14.961821 | K42: =K41/K9 -> 11.971988 | ... P42: =P41/P9 -> 14.69454
...

Sheet Monkey Bay
A1: SOUTHERN REGION WATER BOARD
A3: MONTHLY REPORTS - 2023/2024
A4: MANGOCHI ZONE
A5: MANGOCHI ZONE
A7: PARAMETERS | C7: UNITS | D7: APRIL | E7: MAY | F7: JUNE | G7: JULY | H7: AUGUST | I7: SEPTEMBER | J7: OCTOBER | K7: NOVEMBER | L7: DECEMBER | M7: JANUARY | N7: FEBRUARY | O7: MARCH | P7: TOTALS
A8: PRODUCTION
A9: Volume Produced | C9: m3 | D9: 55692 | E9: 62300 | F9: 62717 | G9: 59070 | H9: 62919 | I9: 65109 | J9: 73800 | K9: 69579 | L9: 53793 | M9: 60549 | N9: 62890 | O9: 54660 | P9: =SUM(D9:O9) -> 743078
A10: REVENUE WATER - POSTPAID
A11: Volume Billed Individuals | C11: m3 | D11: 17067 | E11: 17057 | F11: 18777 | G11: 19307 | H11: 19682 | I11: 20446 | J11: 23429 | K11: 29339 | L11: 18848 | M11: 18956 | N11: 22084 | O11: 18370 | P11: =SUM(D11:O11) -> 243362
A12: Volume Billed CWPs | C12: m3 | D12: 0 | E12: 0 | F12: 0 | G12: 0 | P12: =SUM(D12:O12) -> 0
A13: Volume Billed Institutions | C13: m3 | D13: 20124 | E13: 18545 | F13: 22583 | G13: 21093 | H13: 18587 | I13: 29123 | J13: 22837 | K13: 21844 | L13: 12572 | M13: 24760 | N13: 21318 | O13: 21442 | P13: =SUM(D13:O13) -> 254828
A14: Volume Billed Commercial/Industrial | C14: m3 | D14: 855 | E14: 719 | F14: 7732 | G14: 717 | H14: 590 | I14: 60 | J14: 102 | K14: 151 | L14: 98 | M14: 90 | N14: 104 | O14: 80 | P14: =SUM(D14:O14) -> 11298
A15: Total Volume Billed Post Paid | C15: m3 | D15: =SUM(D11:D14) -> 38046 | E15: =SUM(E11:E14) -> 36321 | F15: =SUM(F11:F14) -> 49092 | G15: =SUM(G11:G14) -> 41117 | H15: =SUM(H11:H14) -> 38859 | I15: =SUM(I11:I14) -> 49629 | J15: =SUM(J11:J14) -> 46368 | K15: =SUM(K11:K14) -> 51334 | ... P15: =SUM(P11:P14) -> 509488
A16: REVENUE WATER - PREPAID
A17: Individuals | C17: m3 | D17: 2147 | E17: 2953 | F17: 2866 | G17: 3265 | H17: 2916 | I17: 3004 | J17: 3124 | K17: 3025 | L17: 11038 | M17: 2957 | N17: 2818 | O17: 3261 | P17: =SUM(D17:O17) -> 43374
A18: CWPs | C18: m3 | D18: 1201 | E18: 1204 | F18: 1117 | G18: 1425 | H18: 1203 | I18: 1159 | J18: 1219 | K18: 1021 | M18: 1498 | N18: 1601 | O18: 1354 | P18: =SUM(D18:O18) -> 14002
A19: Institutions | C19: m3 | D19: 2821 | E19: 3616 | F19: 2878 | G19: 2311 | H19: 2905 | I19: 3579 | J19: 3724 | K19: 3856 | M19: 5001 | N19: 4672 | O19: 3363 | P19: =SUM(D19:O19) -> 38726
A20: Commercial/Industrial | C20: m3 | D20: 395 | E20: 539 | F20: 461 | G20: 294 | H20: 485 | I20: 495 | J20: 485 | K20: 401 | M20: 501 | N20: 496 | O20: 388 | P20: =SUM(D20:O20) -> 4940
A21: Total Volume Prepaid | C21: m3 | D21: =SUM(D17:D20) -> 6564 | E21: =SUM(E17:E20) -> 8312 | F21: =SUM(F17:F20) -> 7322 | G21: =SUM(G17:G20) -> 7295 | H21: =SUM(H17:H20) -> 7509 | I21: =SUM(I17:I20) -> 8237 | J21: =SUM(J17:J20) -> 8552 | K21: 8303 | L21: =SUM(L17:L20) -> 11038 | M21: =SUM(M17:M20) -> 9957 | N21: =SUM(N17:N20) -> 9587 | O21: =SUM(O17:O20) -> 8366 | P21: =SUM(P17:P20) -> 101042
A22: TOTAL REVENUE WATER | C22: m3 | D22: =D21+D15 -> 44610 | E22: =E21+E15 -> 44633 | F22: =F21+F15 -> 56414 | G22: =G21+G15 -> 48412 | H22: =H21+H15 -> 46368 | I22: =I21+I15 -> 57866 | J22: =J21+J15 -> 54920 | K22: =K21+K15 -> 59637 | ... P22: =P21+P15 -> 610530
A24: Non-Revenue Water (NRW) | B24: Volume | C24: m3 | D24: =D9-D22 -> 11082 | E24: =E9-E22 -> 17667 | F24: =F9-F22 -> 6303 | G24: =G9-G22 -> 10658 | H24: =H9-H22 -> 16551 | I24: =I9-I22 -> 7243 | J24: =J9-J22 -> 18880 | K24: =K9-K22 -> 9942 | ... P24: =P9-P22 -> 132548
B25: Percentage | C25: % | D25: =D24/D9 -> 0.19898729 | E25: =E24/E9 -> 0.28357945 | F25: =F24/F9 -> 0.10049907 | G25: =G24/G9 -> 0.18043 | H25: =H24/H9 -> 0.2630525 | I25: =I24/I9 -> 0.11124422 | J25: =J24/J9 -> 0.25582656 | K25: =K24/K9 -> 0.14288794 | ... P25: =P24/P9 -> 0.17837697
A26: OPERATING EXPENSES
A27: Chemicals
A28: Chemical | B28: Rate(MK/kg)
A29: Chlorine | B29: =176264.5/50 -> 3525.29 | C29: kg | D29: 150 | E29: 155 | F29: 150 | G29: 155 | H29: 155 | I29: 150 | J29: 155 | K29: 155 | L29: 155 | M29: 155 | N29: 145 | O29: 155 | P29: =SUM(D29:O29) -> 1835
C30: kg/mg litre | D30: =D29/(D9/1000) -> 2.693385 | E30: =E29/(E9/1000) -> 2.4879615 | F30: =F29/(F9/1000) -> 2.391696 | G30: =G29/(G9/1000) -> 2.6240054 | H30: =H29/(H9/1000) -> 2.4634848 | I30: =I29/(I9/1000) -> 2.303829 | J30: =J29/(J9/1000) -> 2.100271 | K30: =K29/(K9/1000) -> 2.2276836 | ... P30: =P29/(P9/1000) -> 2.4694581
A31: Aluminium sulphate | B31: =53000.511/50 -> 1060.0102 | C31: kg | P31: =SUM(D31:O31) -> 0
C32: kg/mg litre | D32: =D31/(D9/1000) -> 0 | E32: =E31/(E9/1000) -> 0 | F32: =F31/(F9/1000) -> 0 | G32: =G31/(G9/1000) -> 0 | H32: =H31/(H9/1000) -> 0 | I32: =I31/(I9/1000) -> 0 | J32: =J31/(J9/1000) -> 0 | K32: =K31/(K9/1000) -> 0 | ... P32: =P31/(P9/1000) -> 0
A33: Soda | B33: =61414.43/50 -> 1228.2886 | C33: kg | P33: =SUM(D33:O33) -> 0
C34: kg/mg litre | D34: =D33/(D9/1000) -> 0 | E34: =E33/(E9/1000) -> 0 | F34: =F33/(F9/1000) -> 0 | G34: =G33/(G9/1000) -> 0 | H34: =H33/(H9/1000) -> 0 | I34: =I33/(I9/1000) -> 0 | J34: =J33/(J9/1000) -> 0 | K34: =K33/(K9/1000) -> 0 | ... P34: =P33/(P9/1000) -> 0
A35: Algae floc | B35: =745345.16/200 -> 3726.7258 | C35: litres
C36: litres/mg litre
A37: Sud floc | B37: =790318.72/200 -> 3951.5936 | C37: litres | D37: 0 | E37: 0 | F37: 0 | G37: 0 | H37: 0 | I37: 0 | J37: 0 | K37: 0 | L37: 0 | M37: 0 | N37: 0 | O37: 0 | P37: =SUM(D37:O37) -> 0
C38: litres/mg litre | D38: =D37/(D9/1000) -> 0 | E38: =E37/(E9/1000) -> 0 | F38: =F37/(F9/1000) -> 0 | G38: =G37/(G9/1000) -> 0 | H38: =H37/(H9/1000) -> 0 | I38: =I37/(I9/1000) -> 0 | J38: =J37/(J9/1000) -> 0 | K38: =K37/(K9/1000) -> 0 | ... P38: =P37/(P9/1000) -> 0
A39: Potasium permanganate | B39: 1950 | C39: kg | D39: 0 | E39: 0 | F39: 0 | G39: 0 | H39: 0 | I39: 0 | J39: 0 | K39: 0 | L39: 0 | M39: 0 | N39: 0 | O39: 0 | P39: =SUM(D39:O39) -> 0
C40: kg/mg litre | D40: =D39/(D9/1000) -> 0 | E40: =E39/(E9/1000) -> 0 | F40: =F39/(F9/1000) -> 0 | G40: =G39/(G9/1000) -> 0 | H40: =H39/(H9/1000) -> 0 | I40: =I39/(I9/1000) -> 0 | J40: =J39/(J9/1000) -> 0 | K40: =K39/(K9/1000) -> 0 | ... P40: =P39/(P9/1000) -> 0
A41: Cost of Chemicals | C41: Mk | D41: =(D29*$B29)+(D31*$B31)+(D33*$B33)+(D35*$B35)+(D37*$B37)+(D39*$B39) -> 528793.5 | E41: =(E29*$B29)+(E31*$B31)+(E33*$B33)+(E35*$B35)+(E37*$B37)+(E39*$B39) -> 546419.95 | F41: =(F29*$B29)+(F31*$B31)+(F33*$B33)+(F35*$B35)+(F37*$B37)+(F39*$B39) -> 528793.5 | G41: =(G29*$B29)+(G31*$B31)+(G33*$B33)+(G35*$B35)+(G37*$B37)+(G39*$B39) -> 546419.95 | H41: =(H29*$B29)+(H31*$B31)+(H33*$B33)+(H35*$B35)+(H37*$B37)+(H39*$B39) -> 546419.95 | I41: =(I29*$B29)+(I31*$B31)+(I33*$B33)+(I35*$B35)+(I37*$B37)+(I39*$B39) -> 528793.5 | J41: =(J29*$B29)+(J31*$B31)+(J33*$B33)+(J35*$B35)+(J37*$B37)+(J39*$B39) -> 546419.95 | K41: =(K29*$B29)+(K31*$B31)+(K33*$B33)+(K35*$B35)+(K37*$B37)+(K39*$B39) -> 546419.95 | ... O41: =(O29*$B29)+(O31*$B31)+(O33*$B33)+(O35*$B35)+(O37*$B37)+(O39*$B39) -> 546419.95 | P41: =SUM(D41:O41) -> 6468907.2
A42: Cost/vol. Produced (chemicals) | C42: Mk/m3 | D42: =D41/D9 -> 9.4949634 | E42: =E41/E9 -> 8.7707857 | F42: =F41/F9 -> 8.4314221 | G42: =G41/G9 -> 9.2503801 | H42: =H41/H9 -> 8.6844983 | I42: =I41/I9 -> 8.1216652 | J42: =J41/J9 -> 7.4040644 | K42: =K41/K9 -> 7.8532309 | ... P42: =P41/P9 -> 8.705556
A43: Power
...

Sheet Namwera
A1: SOUTHERN REGION WATER BOARD
A3: MONTHLY REPORTS - 2023/2024
A4: MANGOCHI ZONE
A5: MANGOCHI ZONE
A7: PARAMETERS | C7: UNITS | D7: APRIL | E7: MAY | F7: JUNE | G7: JULY | H7: AUGUST | I7: SEPTEMBER | J7: OCTOBER | K7: NOVEMBER | L7: DECEMBER | M7: JANUARY | N7: FEBRUARY | O7: MARCH | P7: TOTALS
A8: PRODUCTION
A9: Volume Produced | C9: m3 | D9: 4151 | E9: 6307 | F9: 5434 | G9: 5272 | H9: 4870 | I9: 6120 | J9: 5217 | K9: 4619 | L9: 4389 | M9: 4509 | N9: 4052 | O9: 3782 | P9: =SUM(D9:O9) -> 58722
A10: REVENUE WATER - POSTPAID
A11: Volume Billed Individuals | C11: m3 | D11: 1751 | E11: 1706 | F11: 2117 | G11: 2161 | H11: 1868 | I11: 2079 | J11: 2011 | K11: 1825 | L11: 2027 | M11: 1559 | N11: 1915 | O11: 1719 | P11: =SUM(D11:O11) -> 22738
A12: Volume Billed CWPs | C12: m3 | D12: 0 | E12: 0 | F12: 0 | G12: 0 | H12: 0 | I12: 0 | J12: 0 | K12: 0 | L12: 0 | M12: 0 | N12: 0 | O12: 0 | P12: =SUM(D12:O12) -> 0
A13: Volume Billed Institutions | C13: m3 | D13: 12 | E13: 11 | F13: 16 | G13: 16 | H13: 14 | I13: 14 | J13: 16 | K13: 11 | L13: 11 | M13: 4 | N13: 2 | O13: 2 | P13: =SUM(D13:O13) -> 129
A14: Volume Billed Commercial/Industrial | C14: m3 | D14: 0 | E14: 0 | F14: 0 | G14: 0 | H14: 0 | I14: 0 | J14: 0 | K14: 0 | L14: 0 | M14: 0 | N14: 0 | O14: 0 | P14: =SUM(D14:O14) -> 0
A15: Total Volume Billed Post Paid | C15: m3 | D15: =SUM(D11:D14) -> 1763 | E15: =SUM(E11:E14) -> 1717 | F15: =SUM(F11:F14) -> 2133 | G15: =SUM(G11:G14) -> 2177 | H15: =SUM(H11:H14) -> 1882 | I15: =SUM(I11:I14) -> 2093 | J15: =SUM(J11:J14) -> 2027 | K15: =SUM(K11:K14) -> 1836 | ... P15: =SUM(P11:P14) -> 22867
A16: REVENUE WATER - PREPAID
A17: Individuals | C17: m3 | D17: 851 | E17: 1529 | F17: 1121 | G17: 1393 | H17: 1221 | I17: 1374 | J17: 1235 | K17: 1318 | L17: 1000 | M17: 1145 | N17: 1228 | O17: 959 | P17: =SUM(D17:O17) -> 14374
A18: CWPs | C18: m3 | D18: 0 | E18: 0 | F18: 0 | G18: 0 | H18: 7 | I18: 0 | J18: 0 | K18: 0 | L18: 0 | M18: 8 | N18: 0 | O18: 1 | P18: =SUM(D18:O18) -> 16
A19: Institutions | C19: m3 | D19: 265 | E19: 409 | F19: 595 | G19: 462 | H19: 496 | I19: 559 | J19: 742 | K19: 657 | L19: 200 | M19: 280 | N19: 126 | O19: 110 | P19: =SUM(D19:O19) -> 4901
A20: Commercial/Industrial | C20: m3 | D20: 19 | E20: 26 | F20: 21 | G20: 60 | H20: 54 | I20: 44 | J20: 65 | K20: 40 | L20: 33 | M20: 44 | N20: 80 | O20: 46 | P20: =SUM(D20:O20) -> 532
A21: Total Volume Prepaid | C21: m3 | D21: =SUM(D17:D20) -> 1135 | E21: =SUM(E17:E20) -> 1964 | F21: =SUM(F17:F20) -> 1737 | G21: =SUM(G17:G20) -> 1915 | H21: =SUM(H17:H20) -> 1778 | I21: =SUM(I17:I20) -> 1977 | J21: =SUM(J17:J20) -> 2042 | K21: =SUM(K17:K20) -> 2015 | ... P21: =SUM(P17:P20) -> 19823
A22: TOTAL REVENUE WATER | C22: m3 | D22: =D21+D15 -> 2898 | E22: =E21+E15 -> 3681 | F22: =F21+F15 -> 3870 | G22: =G21+G15 -> 4092 | H22: =H21+H15 -> 3660 | I22: =I21+I15 -> 4070 | J22: =J21+J15 -> 4069 | K22: =K21+K15 -> 3851 | ... P22: =P21+P15 -> 42690
A24: Non-Revenue Water (NRW) | B24: Volume | C24: m3 | D24: =D9-D22 -> 1253 | E24: =E9-E22 -> 2626 | F24: =F9-F22 -> 1564 | G24: =G9-G22 -> 1180 | H24: =H9-H22 -> 1210 | I24: =I9-I22 -> 2050 | J24: =J9-J22 -> 1148 | K24: =K9-K22 -> 768 | ... P24: =P9-P22 -> 16032
B25: Percentage | C25: % | D25: =D24/D9 -> 0.30185497 | E25: =E24/E9 -> 0.41636277 | F25: =F24/F9 -> 0.28781745 | G25: =G24/G9 -> 0.22382398 | H25: =H24/H9 -> 0.24845996 | I25: =I24/I9 -> 0.33496732 | J25: =J24/J9 -> 0.22004984 | K25: =K24/K9 -> 0.16626976 | ... P25: =P24/P9 -> 0.27301522
A26: OPERATING EXPENSES
A27: Chemicals
A28: Chemical | B28: Rate(MK/kg)
A29: Chlorine | B29: =176264.5/50 -> 3525.29 | C29: kg | D29: 9 | E29: 15 | F29: 11.5 | G29: 16 | H29: 12 | I29: 13 | J29: 15 | K29: 15 | L29: 16 | M29: 16 | N29: 13.5 | O29: 16 | P29: =SUM(D29:O29) -> 168
C30: kg/mg litre | D30: =D29/(D9/1000) -> 2.1681523 | E30: =E29/(E9/1000) -> 2.3783098 | F30: =F29/(F9/1000) -> 2.1163047 | G30: =G29/(G9/1000) -> 3.0349014 | H30: =H29/(H9/1000) -> 2.4640657 | I30: =I29/(I9/1000) -> 2.124183 | J30: =J29/(J9/1000) -> 2.8752156 | K30: =K29/(K9/1000) -> 3.2474562 | ... P30: =P29/(P9/1000) -> 2.860938
A31: Aluminium sulphate | B31: =53000.511/50 -> 1060.0102 | C31: kg | P31: =SUM(D31:O31) -> 0
C32: kg/mg litre | D32: =D31/(D9/1000) -> 0 | E32: =E31/(E9/1000) -> 0 | F32: =F31/(F9/1000) -> 0 | G32: =G31/(G9/1000) -> 0 | H32: =H31/(H9/1000) -> 0 | I32: =I31/(I9/1000) -> 0 | J32: =J31/(J9/1000) -> 0 | K32: =K31/(K9/1000) -> 0 | ... P32: =P31/(P9/1000) -> 0
A33: Soda | B33: =61414.43/50 -> 1228.2886 | C33: kg | P33: =SUM(D33:O33) -> 0
C34: kg/mg litre | D34: =D33/(D9/1000) -> 0 | E34: =E33/(E9/1000) -> 0 | F34: =F33/(F9/1000) -> 0 | G34: =G33/(G9/1000) -> 0 | H34: =H33/(H9/1000) -> 0 | I34: =I33/(I9/1000) -> 0 | J34: =J33/(J9/1000) -> 0 | K34: =K33/(K9/1000) -> 0 | ... P34: =P33/(P9/1000) -> 0
A35: Algae floc | B35: =745345.16/200 -> 3726.7258 | C35: litres
C36: litres/mg litre
A37: Sud floc | B37: =790318.72/200 -> 3951.5936 | C37: litres | D37: 0 | E37: 0 | F37: 0 | G37: 0 | H37: 0 | I37: 0 | J37: 0 | K37: 0 | L37: 0 | M37: 0 | N37: 0 | O37: 0 | P37: =SUM(D37:O37) -> 0
C38: litres/mg litre | D38: =D37/(D9/1000) -> 0 | E38: =E37/(E9/1000) -> 0 | F38: =F37/(F9/1000) -> 0 | G38: =G37/(G9/1000) -> 0 | H38: =H37/(H9/1000) -> 0 | I38: =I37/(I9/1000) -> 0 | J38: =J37/(J9/1000) -> 0 | K38: =K37/(K9/1000) -> 0 | ... P38: =P37/(P9/1000) -> 0
A39: Potasium permanganate | B39: 1950 | C39: kg | D39: 0 | E39: 0 | F39: 0 | G39: 0 | H39: 0 | I39: 0 | J39: 0 | K39: 0 | L39: 0 | M39: 0 | N39: 0 | O39: 0 | P39: =SUM(D39:O39) -> 0
C40: kg/mg litre | D40: =D39/(D9/1000) -> 0 | E40: =E39/(E9/1000) -> 0 | F40: =F39/(F9/1000) -> 0 | G40: =G39/(G9/1000) -> 0 | H40: =H39/(H9/1000) -> 0 | I40: =I39/(I9/1000) -> 0 | J40: =J39/(J9/1000) -> 0 | K40: =K39/(K9/1000) -> 0 | ... P40: =P39/(P9/1000) -> 0
A41: Cost of Chemicals | C41: Mk | D41: =(D29*$B29)+(D31*$B31)+(D33*$B33)+(D35*$B35)+(D37*$B37)+(D39*$B39) -> 31727.61 | E41: =(E29*$B29)+(E31*$B31)+(E33*$B33)+(E35*$B35)+(E37*$B37)+(E39*$B39) -> 52879.35 | F41: =(F29*$B29)+(F31*$B31)+(F33*$B33)+(F35*$B35)+(F37*$B37)+(F39*$B39) -> 40540.835 | G41: =(G29*$B29)+(G31*$B31)+(G33*$B33)+(G35*$B35)+(G37*$B37)+(G39*$B39) -> 56404.64 | H41: =(H29*$B29)+(H31*$B31)+(H33*$B33)+(H35*$B35)+(H37*$B37)+(H39*$B39) -> 42303.48 | I41: =(I29*$B29)+(I31*$B31)+(I33*$B33)+(I35*$B35)+(I37*$B37)+(I39*$B39) -> 45828.77 | J41: =(J29*$B29)+(J31*$B31)+(J33*$B33)+(J35*$B35)+(J37*$B37)+(J39*$B39) -> 52879.35 | K41: =(K29*$B29)+(K31*$B31)+(K33*$B33)+(K35*$B35)+(K37*$B37)+(K39*$B39) -> 52879.35 | ... O41: =(O29*$B29)+(O31*$B31)+(O33*$B33)+(O35*$B35)+(O37*$B37)+(O39*$B39) -> 56404.64 | P41: =SUM(D41:O41) -> 592248.72
A42: Cost/vol. Produced (chemicals) | C42: Mk/m3 | D42: =D41/D9 -> 7.6433655 | E42: =E41/E9 -> 8.3842318 | F42: =F41/F9 -> 7.460588 | G42: =G41/G9 -> 10.698907 | H42: =H41/H9 -> 8.6865462 | I42: =I41/I9 -> 7.4883611 | J42: =J41/J9 -> 10.135969 | K42: =K41/K9 -> 11.448225 | ... P42: =P41/P9 -> 10.085636
A43: Power
...

Sheet Nkhudzi
A1: SOUTHERN REGION WATER BOARD
A3: MONTHLY REPORTS - 2023/2024
A4: MANGOCHI ZONE
A5: MANGOCHI ZONE
A7: PARAMETERS | C7: UNITS | D7: APRIL | E7: MAY | F7: JUNE | G7: JULY | H7: AUGUST | I7: SEPTEMBER | J7: OCTOBER | K7: NOVEMBER | L7: DECEMBER | M7: JANUARY | N7: FEBRUARY | O7: MARCH | P7: TOTALS
A8: PRODUCTION
A9: Volume Produced | C9: m3 | D9: 0 | E9: 0 | F9: 0 | G9: 0 | H9: 0 | I9: 0 | J9: 2578 | K9: 3087.1 | L9: 4408 | M9: 3878 | N9: 4121.7 | O9: 3043 | P9: =SUM(J9:O9) -> 21115.8
A10: REVENUE WATER - POSTPAID
A11: Volume Billed Individuals | C11: m3 | D11: 0 | E11: 0 | F11: 0 | G11: 0 | H11: 0 | I11: 0 | J11: 0 | K11: 0 | L11: 0 | M11: 0 | N11: 0 | O11: 8 | P11: =SUM(J11:O11) -> 8
A12: Volume Billed CWPs | C12: m3 | D12: 0 | E12: 0 | F12: 0 | G12: 0 | H12: 0 | I12: 0 | J12: 0 | K12: 0 | L12: 0 | M12: 0 | N12: 0 | O12: 0 | P12: =SUM(J12:O12) -> 0
A13: Volume Billed Institutions | C13: m3 | D13: 0 | E13: 0 | F13: 0 | G13: 0 | H13: 0 | I13: 0 | J13: 0 | K13: 0 | L13: 0 | M13: 0 | N13: 0 | O13: 0 | P13: =SUM(J13:O13) -> 0
A14: Volume Billed Commercial/Industrial | C14: m3 | D14: 0 | E14: 0 | F14: 0 | G14: 0 | H14: 0 | I14: 0 | J14: 0 | K14: 0 | L14: 0 | M14: 0 | N14: 0 | O14: 0 | P14: =SUM(J14:O14) -> 0
A15: Total Volume Billed Post Paid | C15: m3 | D15: =SUM(D11:D14) -> 0 | E15: =SUM(E11:E14) -> 0 | F15: =SUM(F11:F14) -> 0 | G15: =SUM(G11:G14) -> 0 | H15: =SUM(H11:H14) -> 0 | I15: =SUM(I11:I14) -> 0 | J15: =SUM(J11:J14) -> 0 | K15: =SUM(K11:K14) -> 0 | ... P15: =SUM(P11:P14) -> 8
A16: REVENUE WATER - PREPAID
A17: Individuals | C17: m3 | D17: 0 | E17: 0 | F17: 0 | G17: 0 | H17: 0 | I17: 0 | J17: 2578 | K17: 3087.1 | L17: 4408 | M17: 3877.9 | N17: 4121.7 | O17: 2834 | P17: =SUM(J17:O17) -> 20906.7
A18: CWPs | C18: m3 | D18: 0 | E18: 0 | F18: 0 | G18: 0 | H18: 0 | I18: 0 | J18: 0 | K18: 0 | L18: 0 | M18: 0 | N18: 0 | O18: 71 | P18: =SUM(J18:O18) -> 71
A19: Institutions | C19: m3 | D19: 0 | E19: 0 | F19: 0 | G19: 0 | H19: 0 | I19: 0 | J19: 0 | K19: 0 | L19: 0 | M19: 0 | N19: 0 | O19: 30 | P19: =SUM(J19:O19) -> 30
A20: Commercial/Industrial | C20: m3 | D20: 0 | E20: 0 | F20: 0 | G20: 0 | H20: 0 | I20: 0 | J20: 0 | K20: 0 | L20: 0 | M20: 0 | N20: 0 | O20: 100 | P20: =SUM(J20:O20) -> 100
A21: Total Volume Prepaid | C21: m3 | D21: =SUM(D17:D20) -> 0 | E21: =SUM(E17:E20) -> 0 | F21: =SUM(F17:F20) -> 0 | G21: =SUM(G17:G20) -> 0 | H21: =SUM(H17:H20) -> 0 | I21: =SUM(I17:I20) -> 0 | J21: =SUM(J17:J20) -> 2578 | K21: =SUM(K17:K20) -> 3087.1 | ... P21: =SUM(P17:P20) -> 21107.7
A22: TOTAL REVENUE WATER | C22: m3 | D22: =D21+D15 -> 0 | E22: =E21+E15 -> 0 | F22: =F21+F15 -> 0 | G22: =G21+G15 -> 0 | H22: =H21+H15 -> 0 | I22: =I21+I15 -> 0 | J22: =J21+J15 -> 2578 | K22: =K21+K15 -> 3087.1 | ... P22: =P21+P15 -> 21115.7
A24: Non-Revenue Water (NRW) | B24: Volume | C24: m3 | D24: =D9-D22 -> 0 | E24: =E9-E22 -> 0 | F24: =F9-F22 -> 0 | G24: =G9-G22 -> 0 | H24: =H9-H22 -> 0 | I24: =I9-I22 -> 0 | J24: =J9-J22 -> 0 | K24: =K9-K22 -> 0 | ... P24: =P9-P22 -> 0.1
B25: Percentage | C25: % | D25: =D24/D9 -> #DIV/0! | E25: =E24/E9 -> #DIV/0! | F25: =F24/F9 -> #DIV/0! | G25: =G24/G9 -> #DIV/0! | H25: =H24/H9 -> #DIV/0! | I25: =I24/I9 -> #DIV/0! | J25: =J24/J9 -> 0 | K25: =K24/K9 -> 0 | ... P25: =P24/P9 -> 4.7357903e-06
A26: OPERATING EXPENSES
A27: Chemicals
A28: Chemical | B28: Rate(MK/kg)
A29: Chlorine | B29: =176264.5/50 -> 3525.29 | C29: kg | D29: 0 | E29: 0 | F29: 0 | G29: 0 | H29: 0 | I29: 0 | J29: 225 | K29: 125 | L29: 125 | M29: 125 | N29: 125 | O29: 150 | P29: =SUM(J29:O29) -> 875
C30: kg/mg litre | D30: =D29/(D9/1000) -> #DIV/0! | E30: =E29/(E9/1000) -> #DIV/0! | F30: =F29/(F9/1000) -> #DIV/0! | G30: =G29/(G9/1000) -> #DIV/0! | H30: =H29/(H9/1000) -> #DIV/0! | I30: =I29/(I9/1000) -> #DIV/0! | J30: =J29/(J9/1000) -> 87.276959 | K30: =K29/(K9/1000) -> 40.491076 | ... P30: =P29/(P9/1000) -> 41.438165
A31: Aluminium sulphate | B31: =53000.511/50 -> 1060.0102 | C31: kg | P31: =SUM(J31:O31) -> 0
C32: kg/mg litre | D32: =D31/(D9/1000) -> #DIV/0! | E32: =E31/(E9/1000) -> #DIV/0! | F32: =F31/(F9/1000) -> #DIV/0! | G32: =G31/(G9/1000) -> #DIV/0! | H32: =H31/(H9/1000) -> #DIV/0! | I32: =I31/(I9/1000) -> #DIV/0! | J32: =J31/(J9/1000) -> 0 | K32: =K31/(K9/1000) -> 0 | ... P32: =P31/(P9/1000) -> 0
A33: Soda | B33: =61414.43/50 -> 1228.2886 | C33: kg | P33: =SUM(J33:O33) -> 0
C34: kg/mg litre | D34: =D33/(D9/1000) -> #DIV/0! | E34: =E33/(E9/1000) -> #DIV/0! | F34: =F33/(F9/1000) -> #DIV/0! | G34: =G33/(G9/1000) -> #DIV/0! | H34: =H33/(H9/1000) -> #DIV/0! | I34: =I33/(I9/1000) -> #DIV/0! | J34: =J33/(J9/1000) -> 0 | K34: =K33/(K9/1000) -> 0 | ... P34: =P33/(P9/1000) -> 0
A35: Algae floc | B35: =745345.16/200 -> 3726.7258 | C35: litres
C36: litres/mg litre
A37: Sud floc | B37: =790318.72/200 -> 3951.5936 | C37: litres | D37: 0 | E37: 0 | F37: 0 | G37: 0 | H37: 0 | I37: 0 | J37: 0 | K37: 0 | L37: 0 | M37: 0 | N37: 0 | O37: 0 | P37: =SUM(J37:O37) -> 0
C38: litres/mg litre | D38: =D37/(D9/1000) -> #DIV/0! | E38: =E37/(E9/1000) -> #DIV/0! | F38: =F37/(F9/1000) -> #DIV/0! | G38: =G37/(G9/1000) -> #DIV/0! | H38: =H37/(H9/1000) -> #DIV/0! | I38: =I37/(I9/1000) -> #DIV/0! | J38: =J37/(J9/1000) -> 0 | K38: =K37/(K9/1000) -> 0 | ... P38: =P37/(P9/1000) -> 0
A39: Potasium permanganate | B39: 1950 | C39: kg | D39: 0 | E39: 0 | F39: 0 | G39: 0 | H39: 0 | I39: 0 | J39: 0 | K39: 0 | L39: 0 | M39: 0 | N39: 0 | O39: 0 | P39: =SUM(J39:O39) -> 0
C40: kg/mg litre | D40: =D39/(D9/1000) -> #DIV/0! | E40: =E39/(E9/1000) -> #DIV/0! | F40: =F39/(F9/1000) -> #DIV/0! | G40: =G39/(G9/1000) -> #DIV/0! | H40: =H39/(H9/1000) -> #DIV/0! | I40: =I39/(I9/1000) -> #DIV/0! | J40: =J39/(J9/1000) -> 0 | K40: =K39/(K9/1000) -> 0 | ... P40: =P39/(P9/1000) -> 0
A41: Cost of Chemicals | C41: Mk | D41: =(D29*$B29)+(D31*$B31)+(D33*$B33)+(D35*$B35)+(D37*$B37)+(D39*$B39) -> 0 | E41: =(E29*$B29)+(E31*$B31)+(E33*$B33)+(E35*$B35)+(E37*$B37)+(E39*$B39) -> 0 | F41: =(F29*$B29)+(F31*$B31)+(F33*$B33)+(F35*$B35)+(F37*$B37)+(F39*$B39) -> 0 | G41: =(G29*$B29)+(G31*$B31)+(G33*$B33)+(G35*$B35)+(G37*$B37)+(G39*$B39) -> 0 | H41: =(H29*$B29)+(H31*$B31)+(H33*$B33)+(H35*$B35)+(H37*$B37)+(H39*$B39) -> 0 | I41: =(I29*$B29)+(I31*$B31)+(I33*$B33)+(I35*$B35)+(I37*$B37)+(I39*$B39) -> 0 | J41: =(J29*$B29)+(J31*$B31)+(J33*$B33)+(J35*$B35)+(J37*$B37)+(J39*$B39) -> 793190.25 | K41: =(K29*$B29)+(K31*$B31)+(K33*$B33)+(K35*$B35)+(K37*$B37)+(K39*$B39) -> 440661.25 | ... O41: =(O29*$B29)+(O31*$B31)+(O33*$B33)+(O35*$B35)+(O37*$B37)+(O39*$B39) -> 528793.5 | P41: =SUM(J41:O41) -> 3084628.8
A42: Cost/vol. Produced (chemicals) | C42: Mk/m3 | D42: =D41/D9 -> #DIV/0! | E42: =E41/E9 -> #DIV/0! | F42: =F41/F9 -> #DIV/0! | G42: =G41/G9 -> #DIV/0! | H42: =H41/H9 -> #DIV/0! | I42: =I41/I9 -> #DIV/0! | J42: =J41/J9 -> 307.67659 | K42: =K41/K9 -> 142.74278 | ... P42: =P41/P9 -> 146.08155
A43: Power
...

Sheet Zone Monthly
A1: SOUTHERN REGION WATER BOARD
A3: MONTHLY REPORTS - 2023/2024
A4: MANGOCHI ZONE
A5: MANGOCHI ZONE
A7: PARAMETERS | C7: UNITS | D7: APRIL | E7: MAY | F7: JUNE | G7: JULY | H7: AUGUST | I7: SEPTEMBER | J7: OCTOBER | K7: NOVEMBER | L7: DECEMBER | M7: JANUARY | N7: FEBRUARY | O7: MARCH | P7: TOTALS
A8: PRODUCTION
A9: Volume Produced | C9: m3 | D9: =Mangochi!D9+'Monkey Bay'!D9+Namwera!D9 -> 188810 | E9: =Mangochi!E9+'Monkey Bay'!E9+Namwera!E9 -> 194881 | F9: =Mangochi!F9+'Monkey Bay'!F9+Namwera!F9 -> 201586 | G9: =Mangochi!G9+'Monkey Bay'!G9+Namwera!G9 -> 193512 | H9: =Mangochi!H9+'Monkey Bay'!H9+Namwera!H9 -> 194800 | I9: =Mangochi!I9+'Monkey Bay'!I9+Namwera!I9 -> 191525 | J9: =Mangochi!J9+'Monkey Bay'!J9+Namwera!J9+Nkhudzi!J9 -> 205295 | K9: =Mangochi!K9+'Monkey Bay'!K9+Namwera!K9+Nkhudzi!K9 -> 230405.1 | L9: =Mangochi!L9+'Monkey Bay'!L9+Namwera!L9+Nkhudzi!L9 -> 201198 | M9: =Mangochi!M9+'Monkey Bay'!M9+Namwera!M9+Nkhudzi!M9 -> 209994 | N9: =Mangochi!N9+'Monkey Bay'!N9+Namwera!N9+Nkhudzi!N9 -> 200614.7 | O9: =Mangochi!O9+'Monkey Bay'!O9+Namwera!O9+Nkhudzi!O9 -> 185691 | P9: =SUM(D9:O9) -> 2398311.8
A10: REVENUE WATER - POSTPAID
A11: Volume Billed Individuals | C11: m3 | D11: =Mangochi!D11+'Monkey Bay'!D11+Namwera!D11 -> 72208 | E11: =Mangochi!E11+'Monkey Bay'!E11+Namwera!E11 -> 75904 | F11: =Mangochi!F11+'Monkey Bay'!F11+Namwera!F11 -> 78779 | G11: =Mangochi!G11+'Monkey Bay'!G11+Namwera!G11 -> 79340 | H11: =Mangochi!H11+'Monkey Bay'!H11+Namwera!H11 -> 81185 | I11: =Mangochi!I11+'Monkey Bay'!I11+Namwera!I11 -> 82899 | J11: =Mangochi!J11+'Monkey Bay'!J11+Namwera!J11+Nkhudzi!J11 -> 88528 | K11: =Mangochi!K11+'Monkey Bay'!K11+Namwera!K11+Nkhudzi!K11 -> 94364 | L11: =Mangochi!L11+'Monkey Bay'!L11+Namwera!L11+Nkhudzi!L11 -> 79652 | M11: =Mangochi!M11+'Monkey Bay'!M11+Namwera!M11+Nkhudzi!M11 -> 85487 | N11: =Mangochi!N11+'Monkey Bay'!N11+Namwera!N11+Nkhudzi!N11 -> 91204 | O11: =Mangochi!O11+'Monkey Bay'!O11+Namwera!O11+Nkhudzi!O11 -> 88120 | P11: =SUM(D11:O11) -> 997670
A12: Volume Billed CWPs | C12: m3 | D12: =Mangochi!D12+'Monkey Bay'!D12+Namwera!D12 -> 0 | E12: =Mangochi!E12+'Monkey Bay'!E12+Namwera!E12 -> 0 | F12: =Mangochi!F12+'Monkey Bay'!F12+Namwera!F12 -> 0 | G12: =Mangochi!G12+'Monkey Bay'!G12+Namwera!G12 -> 0 | H12: =Mangochi!H12+'Monkey Bay'!H12+Namwera!H12 -> 0 | I12: =Mangochi!I12+'Monkey Bay'!I12+Namwera!I12 -> 0 | J12: =Mangochi!J12+'Monkey Bay'!J12+Namwera!J12+Nkhudzi!J12 -> 0 | K12: =Mangochi!K12+'Monkey Bay'!K12+Namwera!K12+Nkhudzi!K12 -> 0 | L12: =Mangochi!L12+'Monkey Bay'!L12+Namwera!L12+Nkhudzi!L12 -> 0 | M12: =Mangochi!M12+'Monkey Bay'!M12+Namwera!M12+Nkhudzi!M12 -> 0 | N12: =Mangochi!N12+'Monkey Bay'!N12+Namwera!N12+Nkhudzi!N12 -> 0 | O12: =Mangochi!O12+'Monkey Bay'!O12+Namwera!O12+Nkhudzi!O12 -> 0 | P12: =SUM(D12:O12) -> 0
A13: Volume Billed Institutions | C13: m3 | D13: =Mangochi!D13+'Monkey Bay'!D13+Namwera!D13 -> 20451 | E13: =Mangochi!E13+'Monkey Bay'!E13+Namwera!E13 -> 18852 | F13: =Mangochi!F13+'Monkey Bay'!F13+Namwera!F13 -> 22908 | G13: =Mangochi!G13+'Monkey Bay'!G13+Namwera!G13 -> 21340 | H13: =Mangochi!H13+'Monkey Bay'!H13+Namwera!H13 -> 18908 | I13: =Mangochi!I13+'Monkey Bay'!I13+Namwera!I13 -> 29446 | J13: =Mangochi!J13+'Monkey Bay'!J13+Namwera!J13+Nkhudzi!J13 -> 23142 | K13: =Mangochi!K13+'Monkey Bay'!K13+Namwera!K13+Nkhudzi!K13 -> 22131 | L13: =Mangochi!L13+'Monkey Bay'!L13+Namwera!L13+Nkhudzi!L13 -> 12862 | M13: =Mangochi!M13+'Monkey Bay'!M13+Namwera!M13+Nkhudzi!M13 -> 24906 | N13: =Mangochi!N13+'Monkey Bay'!N13+Namwera!N13+Nkhudzi!N13 -> 21440 | O13: =Mangochi!O13+'Monkey Bay'!O13+Namwera!O13+Nkhudzi!O13 -> 21618 | P13: =SUM(D13:O13) -> 258004
A14: Volume Billed Commercial/Industrial | C14: m3 | D14: =Mangochi!D14+'Monkey Bay'!D14+Namwera!D14 -> 1072 | E14: =Mangochi!E14+'Monkey Bay'!E14+Namwera!E14 -> 936 | F14: =Mangochi!F14+'Monkey Bay'!F14+Namwera!F14 -> 7810 | G14: =Mangochi!G14+'Monkey Bay'!G14+Namwera!G14 -> 739 | H14: =Mangochi!H14+'Monkey Bay'!H14+Namwera!H14 -> 695 | I14: =Mangochi!I14+'Monkey Bay'!I14+Namwera!I14 -> 102 | J14: =Mangochi!J14+'Monkey Bay'!J14+Namwera!J14+Nkhudzi!J14 -> 149 | K14: =Mangochi!K14+'Monkey Bay'!K14+Namwera!K14+Nkhudzi!K14 -> 229 | L14: =Mangochi!L14+'Monkey Bay'!L14+Namwera!L14+Nkhudzi!L14 -> 203 | M14: =Mangochi!M14+'Monkey Bay'!M14+Namwera!M14+Nkhudzi!M14 -> 147 | N14: =Mangochi!N14+'Monkey Bay'!N14+Namwera!N14+Nkhudzi!N14 -> 164 | O14: =Mangochi!O14+'Monkey Bay'!O14+Namwera!O14+Nkhudzi!O14 -> 139 | P14: =SUM(D14:O14) -> 12385
A15: Total Volume Billed Post Paid | C15: m3 | D15: =SUM(D11:D14) -> 93731 | E15: =SUM(E11:E14) -> 95692 | F15: =SUM(F11:F14) -> 109497 | G15: =SUM(G11:G14) -> 101419 | H15: =SUM(H11:H14) -> 100788 | I15: =SUM(I11:I14) -> 112447 | J15: =SUM(J11:J14) -> 111819 | K15: =SUM(K11:K14) -> 116724 | ... P15: =SUM(P11:P14) -> 1268059
A16: REVENUE WATER - PREPAID
A17: Individuals | C17: m3 | D17: =Mangochi!D17+'Monkey Bay'!D17+Namwera!D17 -> 16084.4 | E17: =Mangochi!E17+'Monkey Bay'!E17+Namwera!E17 -> 21488.9 | F17: =Mangochi!F17+'Monkey Bay'!F17+Namwera!F17 -> 18069 | G17: =Mangochi!G17+'Monkey Bay'!G17+Namwera!G17 -> 20875.3 | H17: =Mangochi!H17+'Monkey Bay'!H17+Namwera!H17 -> 19573 | I17: =Mangochi!I17+'Monkey Bay'!I17+Namwera!I17 -> 19574.9 | J17: =Mangochi!J17+'Monkey Bay'!J17+Namwera!J17+Nkhudzi!J17 -> 23907.2 | K17: =Mangochi!K17+'Monkey Bay'!K17+Namwera!K17+Nkhudzi!K17 -> 24508.2 | L17: =Mangochi!L17+'Monkey Bay'!L17+Namwera!L17+Nkhudzi!L17 -> 34648 | M17: =Mangochi!M17+'Monkey Bay'!M17+Namwera!M17+Nkhudzi!M17 -> 25303.5 | N17: =Mangochi!N17+'Monkey Bay'!N17+Namwera!N17+Nkhudzi!N17 -> 32126.2 | O17: =Mangochi!O17+'Monkey Bay'!O17+Namwera!O17+Nkhudzi!O17 -> 24311.6 | P17: =SUM(D17:O17) -> 280470.2
A18: CWPs | C18: m3 | D18: =Mangochi!D18+'Monkey Bay'!D18+Namwera!D18 -> 1201 | E18: =Mangochi!E18+'Monkey Bay'!E18+Namwera!E18 -> 1204 | F18: =Mangochi!F18+'Monkey Bay'!F18+Namwera!F18 -> 1117 | G18: =Mangochi!G18+'Monkey Bay'!G18+Namwera!G18 -> 1425 | H18: =Mangochi!H18+'Monkey Bay'!H18+Namwera!H18 -> 1210 | I18: =Mangochi!I18+'Monkey Bay'!I18+Namwera!I18 -> 1159 | J18: =Mangochi!J18+'Monkey Bay'!J18+Namwera!J18+Nkhudzi!J18 -> 1219 | K18: =Mangochi!K18+'Monkey Bay'!K18+Namwera!K18+Nkhudzi!K18 -> 1021 | L18: =Mangochi!L18+'Monkey Bay'!L18+Namwera!L18+Nkhudzi!L18 -> 0 | M18: =Mangochi!M18+'Monkey Bay'!M18+Namwera!M18+Nkhudzi!M18 -> 1506 | N18: =Mangochi!N18+'Monkey Bay'!N18+Namwera!N18+Nkhudzi!N18 -> 1601 | O18: =Mangochi!O18+'Monkey Bay'!O18+Namwera!O18+Nkhudzi!O18 -> 1426 | P18: =SUM(D18:O18) -> 14089
A19: Institutions | C19: m3 | D19: =Mangochi!D19+'Monkey Bay'!D19+Namwera!D19 -> 3086 | E19: =Mangochi!E19+'Monkey Bay'!E19+Namwera!E19 -> 4025 | F19: =Mangochi!F19+'Monkey Bay'!F19+Namwera!F19 -> 3473 | G19: =Mangochi!G19+'Monkey Bay'!G19+Namwera!G19 -> 2773 | H19: =Mangochi!H19+'Monkey Bay'!H19+Namwera!H19 -> 3401 | I19: =Mangochi!I19+'Monkey Bay'!I19+Namwera!I19 -> 4138 | J19: =Mangochi!J19+'Monkey Bay'!J19+Namwera!J19+Nkhudzi!J19 -> 4466 | K19: =Mangochi!K19+'Monkey Bay'!K19+Namwera!K19+Nkhudzi!K19 -> 4513 | L19: =Mangochi!L19+'Monkey Bay'!L19+Namwera!L19+Nkhudzi!L19 -> 200 | M19: =Mangochi!M19+'Monkey Bay'!M19+Namwera!M19+Nkhudzi!M19 -> 5281 | N19: =Mangochi!N19+'Monkey Bay'!N19+Namwera!N19+Nkhudzi!N19 -> 4798 | O19: =Mangochi!O19+'Monkey Bay'!O19+Namwera!O19+Nkhudzi!O19 -> 3503 | P19: =SUM(D19:O19) -> 43657
A20: Commercial/Industrial | C20: m3 | D20: =Mangochi!D20+'Monkey Bay'!D20+Namwera!D20 -> 414 | E20: =Mangochi!E20+'Monkey Bay'!E20+Namwera!E20 -> 565 | F20: =Mangochi!F20+'Monkey Bay'!F20+Namwera!F20 -> 482 | G20: =Mangochi!G20+'Monkey Bay'!G20+Namwera!G20 -> 354 | H20: =Mangochi!H20+'Monkey Bay'!H20+Namwera!H20 -> 539 | I20: =Mangochi!I20+'Monkey Bay'!I20+Namwera!I20 -> 539 | J20: =Mangochi!J20+'Monkey Bay'!J20+Namwera!J20+Nkhudzi!J20 -> 550 | K20: =Mangochi!K20+'Monkey Bay'!K20+Namwera!K20+Nkhudzi!K20 -> 441 | L20: =Mangochi!L20+'Monkey Bay'!L20+Namwera!L20+Nkhudzi!L20 -> 33 | M20: =Mangochi!M20+'Monkey Bay'!M20+Namwera!M20+Nkhudzi!M20 -> 545 | N20: =Mangochi!N20+'Monkey Bay'!N20+Namwera!N20+Nkhudzi!N20 -> 576 | O20: =Mangochi!O20+'Monkey Bay'!O20+Namwera!O20+Nkhudzi!O20 -> 534 | P20: =SUM(D20:O20) -> 5572
A21: Total Volume Prepaid | C21: m3 | D21: =SUM(D17:D20) -> 20785.4 | E21: =SUM(E17:E20) -> 27282.9 | F21: =SUM(F17:F20) -> 23141 | G21: =SUM(G17:G20) -> 25427.3 | H21: =SUM(H17:H20) -> 24723 | I21: =SUM(I17:I20) -> 25410.9 | J21: =SUM(J17:J20) -> 30142.2 | K21: =SUM(K17:K20) -> 30483.2 | ... P21: =SUM(P17:P20) -> 343788.2
A22: TOTAL REVENUE WATER | C22: m3 | D22: =D21+D15 -> 114516.4 | E22: =E21+E15 -> 122974.9 | F22: =F21+F15 -> 132638 | G22: =G21+G15 -> 126846.3 | H22: =H21+H15 -> 125511 | I22: =I21+I15 -> 137857.9 | J22: =J21+J15 -> 141961.2 | K22: =K21+K15 -> 147207.2 | ... P22: =P21+P15 -> 1611847.2
A24: Non-Revenue Water (NRW) | B24: Volume | C24: m3 | D24: =D9-D22 -> 74293.6 | E24: =E9-E22 -> 71906.1 | F24: =F9-F22 -> 68948 | G24: =G9-G22 -> 66665.7 | H24: =H9-H22 -> 69289 | I24: =I9-I22 -> 53667.1 | J24: =J9-J22 -> 63333.8 | K24: =K9-K22 -> 83197.9 | ... P24: =P9-P22 -> 786464.6
B25: Percentage | C25: % | D25: =D24/D9 -> 0.3934834 | E25: =E24/E9 -> 0.3689744 | F25: =F24/F9 -> 0.34202772 | G25: =G24/G9 -> 0.34450422 | H25: =H24/H9 -> 0.35569302 | I25: =I24/I9 -> 0.28020937 | J25: =J24/J9 -> 0.30850142 | K25: =K24/K9 -> 0.361094 | ... P25: =P24/P9 -> 0.32792425
A26: OPERATING EXPENSES
A27: Chemicals
A28: Chemical | B28: Rate(MK/kg)
A29: Chlorine | B29: 7400 | C29: kg | D29: =Mangochi!D29+'Monkey Bay'!D29+Namwera!D29 -> 552 | E29: =Mangochi!E29+'Monkey Bay'!E29+Namwera!E29 -> 807 | F29: =Mangochi!F29+'Monkey Bay'!F29+Namwera!F29 -> 760.5 | G29: =Mangochi!G29+'Monkey Bay'!G29+Namwera!G29 -> 710 | H29: =Mangochi!H29+'Monkey Bay'!H29+Namwera!H29 -> 684 | I29: =Mangochi!I29+'Monkey Bay'!I29+Namwera!I29 -> 663 | J29: =Mangochi!J29+'Monkey Bay'!J29+Namwera!J29+Nkhudzi!J29 -> 920 | K29: =Mangochi!K29+'Monkey Bay'!K29+Namwera!K29+Nkhudzi!K29 -> 815 | L29: =Mangochi!L29+'Monkey Bay'!L29+Namwera!L29+Nkhudzi!L29 -> 746 | M29: =Mangochi!M29+'Monkey Bay'!M29+Namwera!M29+Nkhudzi!M29 -> 756 | N29: =Mangochi!N29+'Monkey Bay'!N29+Namwera!N29+Nkhudzi!N29 -> 829.5 | O29: =Mangochi!O29+'Monkey Bay'!O29+Namwera!O29+Nkhudzi!O29 -> 871 | P29: =SUM(D29:O29) -> 9114
C30: kg/mg litre | D30: =Mangochi!D30+'Monkey Bay'!D30+Namwera!D30 -> 7.9088285 | E30: =Mangochi!E30+'Monkey Bay'!E30+Namwera!E30 -> 9.9108569 | F30: =Mangochi!F30+'Monkey Bay'!F30+Namwera!F30 -> 8.9970779 | G30: =Mangochi!G30+'Monkey Bay'!G30+Namwera!G30 -> 9.8317023 | H30: =Mangochi!H30+'Monkey Bay'!H30+Namwera!H30 -> 8.9980641 | I30: =Mangochi!I30+'Monkey Bay'!I30+Namwera!I30 -> 8.5844261 | J30: =Mangochi!J30+'Monkey Bay'!J30+Namwera!J30+Nkhudzi!J30 -> 96.496585 | K30: =Mangochi!K30+'Monkey Bay'!K30+Namwera!K30+Nkhudzi!K30 -> 49.362245 | L30: =Mangochi!L30+'Monkey Bay'!L30+Namwera!L30+Nkhudzi!L30 -> 38.130991 | M30: =Mangochi!M30+'Monkey Bay'!M30+Namwera!M30+Nkhudzi!M30 -> 41.602549 | N30: =Mangochi!N30+'Monkey Bay'!N30+Namwera!N30+Nkhudzi!N30 -> 40.17915 | O30: =Mangochi!O30+'Monkey Bay'!O30+Namwera!O30+Nkhudzi!O30 -> 60.787865 | P30: =P29/(P9/1000) -> 3.8001731
A31: Aluminium sulphate | B31: 1900 | C31: kg | D31: =Mangochi!D31+'Monkey Bay'!D31+Namwera!D31 -> 800 | E31: =Mangochi!E31+'Monkey Bay'!E31+Namwera!E31 -> 0 | F31: =Mangochi!F31+'Monkey Bay'!F31+Namwera!F31 -> 0 | G31: =Mangochi!G31+'Monkey Bay'!G31+Namwera!G31 -> 0 | H31: =Mangochi!H31+'Monkey Bay'!H31+Namwera!H31 -> 0 | I31: =Mangochi!I31+'Monkey Bay'!I31+Namwera!I31 -> 0 | J31: =Mangochi!J31+'Monkey Bay'!J31+Namwera!J31 -> 0 | K31: =Mangochi!K31+'Monkey Bay'!K31+Namwera!K31 -> 0 | ... O31: =Mangochi!O31+'Monkey Bay'!O31+Namwera!O31 -> 50 | P31: =SUM(D31:O31) -> 1100
C32: kg/mg litre | D32: =Mangochi!D32+'Monkey Bay'!D32+Namwera!D32 -> 6.2031372 | E32: =Mangochi!E32+'Monkey Bay'!E32+Namwera!E32 -> 0 | F32: =Mangochi!F32+'Monkey Bay'!F32+Namwera!F32 -> 0 | G32: =Mangochi!G32+'Monkey Bay'!G32+Namwera!G32 -> 0 | H32: =Mangochi!H32+'Monkey Bay'!H32+Namwera!H32 -> 0 | I32: =Mangochi!I32+'Monkey Bay'!I32+Namwera!I32 -> 0 | J32: =Mangochi!J32+'Monkey Bay'!J32+Namwera!J32 -> 0 | K32: =Mangochi!K32+'Monkey Bay'!K32+Namwera!K32 -> 0 | ... O32: =Mangochi!O32+'Monkey Bay'!O32+Namwera!O32 -> 0.40255704 | P32: =P31/(P9/1000) -> 0.45865596
A33: Soda | B33: 1900 | C33: kg | D33: =Mangochi!D33+'Monkey Bay'!D33+Namwera!D33 -> 0 | E33: =Mangochi!E33+'Monkey Bay'!E33+Namwera!E33 -> 0 | F33: =Mangochi!F33+'Monkey Bay'!F33+Namwera!F33 -> 0 | G33: =Mangochi!G33+'Monkey Bay'!G33+Namwera!G33 -> 0 | H33: =Mangochi!H33+'Monkey Bay'!H33+Namwera!H33 -> 0 | I33: =Mangochi!I33+'Monkey Bay'!I33+Namwera!I33 -> 0 | J33: =Mangochi!J33+'Monkey Bay'!J33+Namwera!J33 -> 0 | K33: =Mangochi!K33+'Monkey Bay'!K33+Namwera!K33 -> 0 | ... O33: =Mangochi!O33+'Monkey Bay'!O33+Namwera!O33 -> 0 | P33: =SUM(D33:O33) -> 0
C34: kg/mg litre | D34: =Mangochi!D34+'Monkey Bay'!D34+Namwera!D34 -> 0 | E34: =Mangochi!E34+'Monkey Bay'!E34+Namwera!E34 -> 0 | F34: =Mangochi!F34+'Monkey Bay'!F34+Namwera!F34 -> 0 | G34: =Mangochi!G34+'Monkey Bay'!G34+Namwera!G34 -> 0 | H34: =Mangochi!H34+'Monkey Bay'!H34+Namwera!H34 -> 0 | I34: =Mangochi!I34+'Monkey Bay'!I34+Namwera!I34 -> 0 | J34: =Mangochi!J34+'Monkey Bay'!J34+Namwera!J34 -> 0 | K34: =Mangochi!K34+'Monkey Bay'!K34+Namwera!K34 -> 0 | ... O34: =Mangochi!O34+'Monkey Bay'!O34+Namwera!O34 -> 0 | P34: =P33/(P9/1000) -> 0
A35: Algae floc | B35: =745345.16/200 -> 3726.7258 | C35: litres | D35: =Mangochi!D35+'Monkey Bay'!D35+Namwera!D35 -> 0 | E35: =Mangochi!E35+'Monkey Bay'!E35+Namwera!E35 -> 0 | F35: =Mangochi!F35+'Monkey Bay'!F35+Namwera!F35 -> 0 | G35: =Mangochi!G35+'Monkey Bay'!G35+Namwera!G35 -> 0 | H35: =Mangochi!H35+'Monkey Bay'!H35+Namwera!H35 -> 0 | I35: =Mangochi!I35+'Monkey Bay'!I35+Namwera!I35 -> 0 | J35: =Mangochi!J35+'Monkey Bay'!J35+Namwera!J35 -> 0 | K35: =Mangochi!K35+'Monkey Bay'!K35+Namwera!K35 -> 0 | ... O35: =Mangochi!O35+'Monkey Bay'!O35+Namwera!O35 -> 0
C36: litres/mg litre
A37: Sud floc | B37: =790318.72/200 -> 3951.5936 | C37: litres | D37: =Mangochi!D37+'Monkey Bay'!D37+Namwera!D37 -> 0 | E37: =Mangochi!E37+'Monkey Bay'!E37+Namwera!E37 -> 0 | F37: =Mangochi!F37+'Monkey Bay'!F37+Namwera!F37 -> 0 | G37: =Mangochi!G37+'Monkey Bay'!G37+Namwera!G37 -> 0 | H37: =Mangochi!H37+'Monkey Bay'!H37+Namwera!H37 -> 0 | I37: =Mangochi!I37+'Monkey Bay'!I37+Namwera!I37 -> 0 | J37: =Mangochi!J37+'Monkey Bay'!J37+Namwera!J37 -> 0 | K37: =Mangochi!K37+'Monkey Bay'!K37+Namwera!K37 -> 0 | ... O37: =Mangochi!O37+'Monkey Bay'!O37+Namwera!O37 -> 0 | P37: =SUM(D37:O37) -> 0
C38: litres/mg litre | D38: =Mangochi!D38+'Monkey Bay'!D38+Namwera!D38 -> 0 | E38: =Mangochi!E38+'Monkey Bay'!E38+Namwera!E38 -> 0 | F38: =Mangochi!F38+'Monkey Bay'!F38+Namwera!F38 -> 0 | G38: =Mangochi!G38+'Monkey Bay'!G38+Namwera!G38 -> 0 | H38: =Mangochi!H38+'Monkey Bay'!H38+Namwera!H38 -> 0 | I38: =Mangochi!I38+'Monkey Bay'!I38+Namwera!I38 -> 0 | J38: =Mangochi!J38+'Monkey Bay'!J38+Namwera!J38 -> 0 | K38: =Mangochi!K38+'Monkey Bay'!K38+Namwera!K38 -> 0 | ... O38: =Mangochi!O38+'Monkey Bay'!O38+Namwera!O38 -> 0 | P38: =P37/(P9/1000) -> 0
A39: Potasium permanganate | B39: 1950 | C39: kg | D39: =Mangochi!D39+'Monkey Bay'!D39+Namwera!D39 -> 0 | E39: =Mangochi!E39+'Monkey Bay'!E39+Namwera!E39 -> 0 | F39: =Mangochi!F39+'Monkey Bay'!F39+Namwera!F39 -> 0 | G39: =Mangochi!G39+'Monkey Bay'!G39+Namwera!G39 -> 0 | H39: =Mangochi!H39+'Monkey Bay'!H39+Namwera!H39 -> 0 | I39: =Mangochi!I39+'Monkey Bay'!I39+Namwera!I39 -> 0 | J39: =Mangochi!J39+'Monkey Bay'!J39+Namwera!J39 -> 0 | K39: =Mangochi!K39+'Monkey Bay'!K39+Namwera!K39 -> 0 | ... O39: =Mangochi!O39+'Monkey Bay'!O39+Namwera!O39 -> 0 | P39: =SUM(D39:O39) -> 0
C40: kg/mg litre | D40: =Mangochi!D40+'Monkey Bay'!D40+Namwera!D40 -> 0 | E40: =Mangochi!E40+'Monkey Bay'!E40+Namwera!E40 -> 0 | F40: =Mangochi!F40+'Monkey Bay'!F40+Namwera!F40 -> 0 | G40: =Mangochi!G40+'Monkey Bay'!G40+Namwera!G40 -> 0 | H40: =Mangochi!H40+'Monkey Bay'!H40+Namwera!H40 -> 0 | I40: =Mangochi!I40+'Monkey Bay'!I40+Namwera!I40 -> 0 | J40: =Mangochi!J40+'Monkey Bay'!J40+Namwera!J40 -> 0 | K40: =Mangochi!K40+'Monkey Bay'!K40+Namwera!K40 -> 0 | ... O40: =Mangochi!O40+'Monkey Bay'!O40+Namwera!O40 -> 0 | P40: =P39/(P9/1000) -> 0
A41: Cost of Chemicals | C41: Mk | D41: =Mangochi!D41+'Monkey Bay'!D41+Namwera!D41 -> 2793968.3 | E41: =Mangochi!E41+'Monkey Bay'!E41+Namwera!E41 -> 2844909 | F41: =Mangochi!F41+'Monkey Bay'!F41+Namwera!F41 -> 2680983 | G41: =Mangochi!G41+'Monkey Bay'!G41+Namwera!G41 -> 2502955.9 | H41: =Mangochi!H41+'Monkey Bay'!H41+Namwera!H41 -> 2411298.4 | I41: =Mangochi!I41+'Monkey Bay'!I41+Namwera!I41 -> 2337267.3 | J41: =Mangochi!J41+'Monkey Bay'!J41+Namwera!J41+Nkhudzi!J41 -> 3243266.8 | K41: =Mangochi!K41+'Monkey Bay'!K41+Namwera!K41+Nkhudzi!K41 -> 2873111.4 | L41: =Mangochi!L41+'Monkey Bay'!L41+Namwera!L41+Nkhudzi!L41 -> 2629866.3 | M41: =Mangochi!M41+'Monkey Bay'!M41+Namwera!M41+Nkhudzi!M41 -> 2877121.3 | N41: =Mangochi!N41+'Monkey Bay'!N41+Namwera!N41+Nkhudzi!N41 -> 2977228.6 | O41: =Mangochi!O41+'Monkey Bay'!O41+Namwera!O41+Nkhudzi!O41 -> 3123528.1 | P41: =SUM(D41:O41) -> 33295504
A42: Cost/vol. Produced (chemicals) | C42: Mk/m3 | D42: =Mangochi!D42+'Monkey Bay'!D42+Namwera!D42 -> 34.456303 | E42: =Mangochi!E42+'Monkey Bay'!E42+Namwera!E42 -> 34.938645 | F42: =Mangochi!F42+'Monkey Bay'!F42+Namwera!F42 -> 31.717309 | G42: =Mangochi!G42+'Monkey Bay'!G42+Namwera!G42 -> 34.659602 | H42: =Mangochi!H42+'Monkey Bay'!H42+Namwera!H42 -> 31.720785 | I42: =Mangochi!I42+'Monkey Bay'!I42+Namwera!I42 -> 30.262592 | J42: =Mangochi!J42+'Monkey Bay'!J42+Namwera!J42+Nkhudzi!J42 -> 340.17844 | K42: =Mangochi!K42+'Monkey Bay'!K42+Namwera!K42+Nkhudzi!K42 -> 174.01623 | L42: =Mangochi!L42+'Monkey Bay'!L42+Namwera!L42+Nkhudzi!L42 -> 134.4228 | M42: =Mangochi!M42+'Monkey Bay'!M42+Namwera!M42+Nkhudzi!M42 -> 148.16399 | N42: =Mangochi!N42+'Monkey Bay'!N42+Namwera!N42+Nkhudzi!N42 -> 142.05226 | O42: =Mangochi!O42+'Monkey Bay'!O42+Namwera!O42+Nkhudzi!O42 -> 214.72157 | P42: =P41/P9 -> 13.882892
A43: Power
...

Sheet 1st QTR
A1: SOUTHERN REGION WATER BOARD
A3: MONTHLY REPORTS - 2023/2024
A4: MANGOCHI ZONE
A5: MANGOCHI ZONE
A7: PARAMETERS | C7: UNITS | D7: Mangochi | E7: Monkey Bay | F7: Namwera | G7: Nkhudzi | H7: TOTALS
A8: PRODUCTION
A9: Volume Produced | C9: m3 | D9: =Mangochi!D9+Mangochi!E9+Mangochi!F9 -> 388676 | E9: ='Monkey Bay'!D9+'Monkey Bay'!E9+'Monkey Bay'!F9 -> 180709 | F9: =Namwera!D9+Namwera!E9+Namwera!F9 -> 15892 | H9: =SUM(D9:F9) -> 585277
A10: REVENUE WATER - POSTPAID
A11: Volume Billed Individuals | C11: m3 | D11: =Mangochi!D11+Mangochi!E11+Mangochi!F11 -> 168416 | E11: ='Monkey Bay'!D11+'Monkey Bay'!E11+'Monkey Bay'!F11 -> 52901 | F11: =Namwera!D11+Namwera!E11+Namwera!F11 -> 5574 | H11: =SUM(D11:F11) -> 226891
A12: Volume Billed CWPs | C12: m3 | D12: =Mangochi!D12+Mangochi!E12+Mangochi!F12 -> 0 | E12: ='Monkey Bay'!D12+'Monkey Bay'!E12+'Monkey Bay'!F12 -> 0 | F12: =Namwera!D12+Namwera!E12+Namwera!F12 -> 0 | H12: =SUM(D12:F12) -> 0
A13: Volume Billed Institutions | C13: m3 | D13: =Mangochi!D13+Mangochi!E13+Mangochi!F13 -> 920 | E13: ='Monkey Bay'!D13+'Monkey Bay'!E13+'Monkey Bay'!F13 -> 61252 | F13: =Namwera!D13+Namwera!E13+Namwera!F13 -> 39 | H13: =SUM(D13:F13) -> 62211
A14: Volume Billed Commercial/Industrial | C14: m3 | D14: =Mangochi!D14+Mangochi!E14+Mangochi!F14 -> 512 | E14: ='Monkey Bay'!D14+'Monkey Bay'!E14+'Monkey Bay'!F14 -> 9306 | F14: =Namwera!D14+Namwera!E14+Namwera!F14 -> 0 | H14: =SUM(D14:F14) -> 9818
A15: Total Volume Billed Post Paid | C15: m3 | D15: =SUM(D11:D14) -> 169848 | E15: =SUM(E11:E14) -> 123459 | F15: =SUM(F11:F14) -> 5613 | H15: =SUM(H11:H14) -> 298920
A16: REVENUE WATER - PREPAID
A17: Individuals | C17: m3 | D17: =Mangochi!D17+Mangochi!E17+Mangochi!F17 -> 44175.3 | E17: ='Monkey Bay'!D17+'Monkey Bay'!E17+'Monkey Bay'!F17 -> 7966 | F17: =Namwera!D17+Namwera!E17+Namwera!F17 -> 3501 | H17: =SUM(D17:F17) -> 55642.3
A18: CWPs | C18: m3 | D18: =Mangochi!D18+Mangochi!E18+Mangochi!F18 -> 0 | E18: ='Monkey Bay'!D18+'Monkey Bay'!E18+'Monkey Bay'!F18 -> 3522 | F18: =Namwera!D18+Namwera!E18+Namwera!F18 -> 0 | H18: =SUM(D18:F18) -> 3522
A19: Institutions | C19: m3 | D19: =Mangochi!D19+Mangochi!E19+Mangochi!F19 -> 0 | E19: ='Monkey Bay'!D19+'Monkey Bay'!E19+'Monkey Bay'!F19 -> 9315 | F19: =Namwera!D19+Namwera!E19+Namwera!F19 -> 1269 | H19: =SUM(D19:F19) -> 10584
A20: Commercial/Industrial | C20: m3 | D20: =Mangochi!D20+Mangochi!E20+Mangochi!F20 -> 0 | E20: ='Monkey Bay'!D20+'Monkey Bay'!E20+'Monkey Bay'!F20 -> 1395 | F20: =Namwera!D20+Namwera!E20+Namwera!F20 -> 66 | H20: =SUM(D20:F20) -> 1461
A21: Total Volume Prepaid | C21: m3 | D21: =SUM(D17:D20) -> 44175.3 | E21: =SUM(E17:E20) -> 22198 | F21: =SUM(F17:F20) -> 4836 | H21: =SUM(H17:H20) -> 71209.3
A22: TOTAL REVENUE WATER | C22: m3 | D22: =D21+D15 -> 214023.3 | E22: =E21+E15 -> 145657 | F22: =F21+F15 -> 10449 | H22: =H21+H15 -> 370129.3
A23: NON-REVENUE WATER (NRW)
A24: Non-Revenue Water (NRW) | B24: Volume | C24: m3 | D24: =D9-D22 -> 174652.7 | E24: =E9-E22 -> 35052 | F24: =F9-F22 -> 5443 | H24: =H9-H22 -> 215147.7
B25: Percentage | C25: % | D25: =D24/D9 -> 0.44935293 | E25: =E24/E9 -> 0.19396931 | F25: =F24/F9 -> 0.34249937 | H25: =H24/H9 -> 0.36759979
A26: OPERATING EXPENSES
A27: Chemicals
A28: Chemical | B28: Rate(MK/kg)
A29: Chlorine | B29: 7400 | C29: kg | D29: =Mangochi!D29+Mangochi!E29+Mangochi!F29 -> 1629 | E29: ='Monkey Bay'!D29+'Monkey Bay'!E29+'Monkey Bay'!F29 -> 455 | F29: =Namwera!D29+Namwera!E29+Namwera!F29 -> 35.5 | H29: =SUM(D29:F29) -> 2119.5
C30: kg/mg litre | D30: =D29/(D9/1000) -> 4.1911515 | E30: =E29/(E9/1000) -> 2.5178602 | F30: =F29/(F9/1000) -> 2.2338283 | H30: =H29/(H9/1000) -> 3.6213622
A31: Aluminium sulphate | B31: 1900 | C31: kg | D31: =Mangochi!D31+Mangochi!E31+Mangochi!F31 -> 800 | E31: ='Monkey Bay'!D31+'Monkey Bay'!E31+'Monkey Bay'!F31 -> 0 | F31: =Namwera!D31+Namwera!E31+Namwera!F31 -> 0 | H31: =SUM(D31:F31) -> 800
C32: kg/mg litre | D32: =D31/(D9/1000) -> 2.0582696 | E32: =E31/(E9/1000) -> 0 | F32: =F31/(F9/1000) -> 0 | H32: =H31/(H9/1000) -> 1.3668741
A33: Soda | B33: 1900 | C33: kg | D33: =Mangochi!D33+Mangochi!E33+Mangochi!F33 -> 0 | E33: ='Monkey Bay'!D33+'Monkey Bay'!E33+'Monkey Bay'!F33 -> 0 | F33: =Namwera!D33+Namwera!E33+Namwera!F33 -> 0 | H33: =SUM(D33:F33) -> 0
C34: kg/mg litre | D34: =D33/(D9/1000) -> 0 | E34: =E33/(E9/1000) -> 0 | F34: =F33/(F9/1000) -> 0 | H34: =H33/(H9/1000) -> 0
A35: Algae floc | B35: =745345.16/200 -> 3726.7258 | C35: litres | D35: =Mangochi!D35+Mangochi!E35+Mangochi!F35 -> 0 | E35: ='Monkey Bay'!D35+'Monkey Bay'!E35+'Monkey Bay'!F35 -> 0 | F35: =Namwera!D35+Namwera!E35+Namwera!F35 -> 0 | H35: =SUM(D35:F35) -> 0
C36: litres/mg litre | D36: =D35/(D11/1000) -> 0 | E36: =E35/(E11/1000) -> 0 | F36: =F35/(F11/1000) -> 0 | H36: =H35/(H11/1000) -> 0
A37: Sud floc | B37: =790318.72/200 -> 3951.5936 | C37: litres | D37: =Mangochi!D37+Mangochi!E37+Mangochi!F37 -> 0 | E37: ='Monkey Bay'!D37+'Monkey Bay'!E37+'Monkey Bay'!F37 -> 0 | F37: =Namwera!D37+Namwera!E37+Namwera!F37 -> 0 | H37: =SUM(D37:F37) -> 0
C38: litres/mg litre | D38: =D37/(D13/1000) -> 0 | E38: =E37/(E13/1000) -> 0 | F38: =F37/(F13/1000) -> 0 | H38: =H37/(H13/1000) -> 0
A39: Potasium permanganate | B39: 1950 | C39: kg | D39: =Mangochi!D39+Mangochi!E39+Mangochi!F39 -> 0 | E39: ='Monkey Bay'!D39+'Monkey Bay'!E39+'Monkey Bay'!F39 -> 0 | F39: =Namwera!D39+Namwera!E39+Namwera!F39 -> 0 | H39: =SUM(D39:F39) -> 0
C40: kg/mg litre | D40: =D39/(D9/1000) -> 0 | E40: =E39/(E9/1000) -> 0 | F40: =F39/(F9/1000) -> 0 | H40: =H39/(H9/1000) -> 0
A41: Cost of Chemicals | C41: Mk | D41: =(D29*$B29)+(D31*$B31)+(D33*$B33)+(D35*$B35)+(D37*$B37)+(D39*$B39) -> 13574600 | E41: =(E29*$B29)+(E31*$B31)+(E33*$B33)+(E35*$B35)+(E37*$B37)+(E39*$B39) -> 3367000 | F41: =(F29*$B29)+(F31*$B31)+(F33*$B33)+(F35*$B35)+(F37*$B37)+(F39*$B39) -> 262700 | H41: =SUM(D41:F41) -> 17204300
A42: Cost/vol. Produced (chemicals) | C42: Mk/m3 | D42: =D41/D9 -> 34.925233 | E42: =E41/E9 -> 18.632166 | F42: =F41/F9 -> 16.53033 | H42: =H41/H9 -> 29.395141
...

Sheet 2nd QTR 
A1: SOUTHERN REGION WATER BOARD
A3: MONTHLY REPORTS - 2023/2024
A4: MANGOCHI ZONE
A5: MANGOCHI ZONE
A7: PARAMETERS | C7: UNITS | D7: Mangochi | E7: Monkey Bay | F7: Namwera | G7: Nkhudzi | H7: TOTALS
A8: PRODUCTION
A9: Volume Produced | C9: m3 | D9: =Mangochi!G9+Mangochi!H9+Mangochi!I9 -> 376477 | E9: ='Monkey Bay'!G9+'Monkey Bay'!H9+'Monkey Bay'!I9 -> 187098 | F9: =Namwera!G9+Namwera!H9+Namwera!I9 -> 16262 | H9: =SUM(D9:F9) -> 579837
A10: REVENUE WATER - POSTPAID
A11: Volume Billed Individuals | C11: m3 | D11: =Mangochi!G11+Mangochi!H11+Mangochi!I11 -> 177881 | E11: ='Monkey Bay'!G11+'Monkey Bay'!H11+'Monkey Bay'!I11 -> 59435 | F11: =Namwera!G11+Namwera!H11+Namwera!I11 -> 6108 | H11: =SUM(D11:F11) -> 243424
A12: Volume Billed CWPs | C12: m3 | D12: =Mangochi!G12+Mangochi!H12+Mangochi!I12 -> 0 | E12: ='Monkey Bay'!G12+'Monkey Bay'!H12+'Monkey Bay'!I12 -> 0 | F12: =Namwera!G12+Namwera!H12+Namwera!I12 -> 0 | H12: =SUM(D12:F12) -> 0
A13: Volume Billed Institutions | C13: m3 | D13: =Mangochi!G13+Mangochi!H13+Mangochi!I13 -> 847 | E13: ='Monkey Bay'!G13+'Monkey Bay'!H13+'Monkey Bay'!I13 -> 68803 | F13: =Namwera!G13+Namwera!H13+Namwera!I13 -> 44 | H13: =SUM(D13:F13) -> 69694
A14: Volume Billed Commercial/Industrial | C14: m3 | D14: =Mangochi!G14+Mangochi!H14+Mangochi!I14 -> 169 | E14: ='Monkey Bay'!G14+'Monkey Bay'!H14+'Monkey Bay'!I14 -> 1367 | F14: =Namwera!G14+Namwera!H14+Namwera!I14 -> 0 | H14: =SUM(D14:F14) -> 1536
A15: Total Volume Billed Post Paid | C15: m3 | D15: =SUM(D11:D14) -> 178897 | E15: =SUM(E11:E14) -> 129605 | F15: =SUM(F11:F14) -> 6152 | H15: =SUM(H11:H14) -> 314654
A16: REVENUE WATER - PREPAID
A17: Individuals | C17: m3 | D17: =Mangochi!G17+Mangochi!H17+Mangochi!I17 -> 46850.2 | E17: ='Monkey Bay'!G17+'Monkey Bay'!H17+'Monkey Bay'!I17 -> 9185 | F17: =Namwera!G17+Namwera!H17+Namwera!I17 -> 3988 | H17: =SUM(D17:F17) -> 60023.2
A18: CWPs | C18: m3 | D18: =Mangochi!G18+Mangochi!H18+Mangochi!I18 -> 0 | E18: ='Monkey Bay'!G18+'Monkey Bay'!H18+'Monkey Bay'!I18 -> 3787 | F18: =Namwera!G18+Namwera!H18+Namwera!I18 -> 7 | H18: =SUM(D18:F18) -> 3794
A19: Institutions | C19: m3 | D19: =Mangochi!G19+Mangochi!H19+Mangochi!I19 -> 0 | E19: ='Monkey Bay'!G19+'Monkey Bay'!H19+'Monkey Bay'!I19 -> 8795 | F19: =Namwera!G19+Namwera!H19+Namwera!I19 -> 1517 | H19: =SUM(D19:F19) -> 10312
A20: Commercial/Industrial | C20: m3 | D20: =Mangochi!G20+Mangochi!H20+Mangochi!I20 -> 0 | E20: ='Monkey Bay'!G20+'Monkey Bay'!H20+'Monkey Bay'!I20 -> 1274 | F20: =Namwera!G20+Namwera!H20+Namwera!I20 -> 158 | H20: =SUM(D20:F20) -> 1432
A21: Total Volume Prepaid | C21: m3 | D21: =SUM(D17:D20) -> 46850.2 | E21: =SUM(E17:E20) -> 23041 | F21: =SUM(F17:F20) -> 5670 | H21: =SUM(H17:H20) -> 75561.2
A22: TOTAL REVENUE WATER | C22: m3 | D22: =D21+D15 -> 225747.2 | E22: =E21+E15 -> 152646 | F22: =F21+F15 -> 11822 | H22: =H21+H15 -> 390215.2
A23: NON-REVENUE WATER (NRW)
A24: Non-Revenue Water (NRW) | B24: Volume | C24: m3 | D24: =D9-D22 -> 150729.8 | E24: =E9-E22 -> 34452 | F24: =F9-F22 -> 4440 | H24: =H9-H22 -> 189621.8
B25: Percentage | C25: % | D25: =D24/D9 -> 0.40036921 | E25: =E24/E9 -> 0.18413879 | F25: =F24/F9 -> 0.27302915 | H25: =H24/H9 -> 0.32702604
A26: OPERATING EXPENSES
A27: Chemicals
A28: Chemical | B28: Rate(MK/kg)
A29: Chlorine | B29: 7400 | C29: kg | D29: =Mangochi!G29+Mangochi!H29+Mangochi!I29 -> 1556 | E29: ='Monkey Bay'!G29+'Monkey Bay'!H29+'Monkey Bay'!I29 -> 460 | F29: =Namwera!G29+Namwera!H29+Namwera!I29 -> 41 | H29: =SUM(D29:F29) -> 2057
C30: kg/mg litre | D30: =D29/(D9/1000) -> 4.1330546 | E30: =E29/(E9/1000) -> 2.4586046 | F30: =F29/(F9/1000) -> 2.5212151 | H30: =H29/(H9/1000) -> 3.5475487
A31: Aluminium sulphate | B31: 1900 | C31: kg | D31: =Mangochi!G31+Mangochi!H31+Mangochi!I31 -> 0 | E31: ='Monkey Bay'!G31+'Monkey Bay'!H31+'Monkey Bay'!I31 -> 0 | F31: =Namwera!G31+Namwera!H31+Namwera!I31 -> 0 | H31: =SUM(D31:F31) -> 0
C32: kg/mg litre | D32: =D31/(D9/1000) -> 0 | E32: =E31/(E9/1000) -> 0 | F32: =F31/(F9/1000) -> 0 | H32: =H31/(H9/1000) -> 0
A33: Soda | B33: 1900 | C33: kg | D33: =Mangochi!G33+Mangochi!H33+Mangochi!I33 -> 0 | E33: ='Monkey Bay'!G33+'Monkey Bay'!H33+'Monkey Bay'!I33 -> 0 | F33: =Namwera!G33+Namwera!H33+Namwera!I33 -> 0 | H33: =SUM(D33:F33) -> 0
C34: kg/mg litre | D34: =D33/(D9/1000) -> 0 | E34: =E33/(E9/1000) -> 0 | F34: =F33/(F9/1000) -> 0 | H34: =H33/(H9/1000) -> 0
A35: Algae floc | B35: =745345.16/200 -> 3726.7258 | C35: litres | D35: =Mangochi!G35+Mangochi!H35+Mangochi!I35 -> 0 | E35: ='Monkey Bay'!G35+'Monkey Bay'!H35+'Monkey Bay'!I35 -> 0 | F35: =Namwera!G35+Namwera!H35+Namwera!I35 -> 0
C36: litres/mg litre
A37: Sud floc | B37: =790318.72/200 -> 3951.5936 | C37: litres | D37: =Mangochi!G37+Mangochi!H37+Mangochi!I37 -> 0 | E37: ='Monkey Bay'!G37+'Monkey Bay'!H37+'Monkey Bay'!I37 -> 0 | F37: =Namwera!G37+Namwera!H37+Namwera!I37 -> 0 | H37: =SUM(D37:F37) -> 0
C38: litres/mg litre | D38: =D37/(D9/1000) -> 0 | E38: =E37/(E9/1000) -> 0 | F38: =F37/(F9/1000) -> 0 | H38: =H37/(H9/1000) -> 0
A39: Potasium permanganate | B39: 1950 | C39: kg | D39: =Mangochi!G39+Mangochi!H39+Mangochi!I39 -> 0 | E39: ='Monkey Bay'!G39+'Monkey Bay'!H39+'Monkey Bay'!I39 -> 0 | F39: =Namwera!G39+Namwera!H39+Namwera!I39 -> 0 | H39: =SUM(D39:F39) -> 0
C40: kg/mg litre | D40: =D39/(D9/1000) -> 0 | E40: =E39/(E9/1000) -> 0 | F40: =F39/(F9/1000) -> 0 | H40: =H39/(H9/1000) -> 0
A41: Cost of Chemicals | C41: Mk | D41: =(D29*$B29)+(D31*$B31)+(D33*$B33)+(D35*$B35)+(D37*$B37)+(D39*$B39) -> 11514400 | E41: =(E29*$B29)+(E31*$B31)+(E33*$B33)+(E35*$B35)+(E37*$B37)+(E39*$B39) -> 3404000 | F41: =(F29*$B29)+(F31*$B31)+(F33*$B33)+(F35*$B35)+(F37*$B37)+(F39*$B39) -> 303400 | H41: =SUM(D41:F41) -> 15221800
A42: Cost/vol. Produced (chemicals) | C42: Mk/m3 | D42: =D41/D9 -> 30.584604 | E42: =E41/E9 -> 18.193674 | F42: =F41/F9 -> 18.656992 | H42: =H41/H9 -> 26.25186
...

Sheet Midyear Summary
A1: SOUTHERN REGION WATER BOARD
A3: MONTHLY REPORTS - 2023/2024
A4: MANGOCHI ZONE
A5: MANGOCHI ZONE
A7: PARAMETERS | C7: UNITS | D7: Mangochi | E7: Monkey Bay | F7: Namwera | G7: Nkhudzi | H7: TOTALS
A8: PRODUCTION
A9: Volume Produced | C9: m3 | D9: =Mangochi!D9+Mangochi!E9+Mangochi!F9+Mangochi!G9+Mangochi!H9+Mangochi!I9 -> 765153 | E9: ='Monkey Bay'!D9+'Monkey Bay'!E9+'Monkey Bay'!F9+'Monkey Bay'!G9+'Monkey Bay'!H9+'Monkey Bay'!I9 -> 367807 | F9: =Namwera!D9+Namwera!E9+Namwera!F9+Namwera!G9+Namwera!H9+Namwera!I9 -> 32154 | H9: =SUM(D9:F9) -> 1165114
A10: REVENUE WATER - POSTPAID
A11: Volume Billed Individuals | C11: m3 | D11: =Mangochi!D11+Mangochi!E11+Mangochi!F11+Mangochi!G11+Mangochi!H11+Mangochi!I11 -> 346297 | E11: ='Monkey Bay'!D11+'Monkey Bay'!E11+'Monkey Bay'!F11+'Monkey Bay'!G11+'Monkey Bay'!H11+'Monkey Bay'!I11 -> 112336 | F11: =Namwera!D11+Namwera!E11+Namwera!F11+Namwera!G11+Namwera!H11+Namwera!I11 -> 11682 | H11: =SUM(D11:F11) -> 470315
A12: Volume Billed CWPs | C12: m3 | D12: =Mangochi!D12+Mangochi!E12+Mangochi!F12+Mangochi!G12+Mangochi!H12+Mangochi!I12 -> 0 | E12: ='Monkey Bay'!D12+'Monkey Bay'!E12+'Monkey Bay'!F12+'Monkey Bay'!G12+'Monkey Bay'!H12+'Monkey Bay'!I12 -> 0 | F12: =Namwera!D12+Namwera!E12+Namwera!F12+Namwera!G12+Namwera!H12+Namwera!I12 -> 0 | H12: =SUM(D12:F12) -> 0
A13: Volume Billed Institutions | C13: m3 | D13: =Mangochi!D13+Mangochi!E13+Mangochi!F13+Mangochi!G13+Mangochi!H13+Mangochi!I13 -> 1767 | E13: ='Monkey Bay'!D13+'Monkey Bay'!E13+'Monkey Bay'!F13+'Monkey Bay'!G13+'Monkey Bay'!H13+'Monkey Bay'!I13 -> 130055 | F13: =Namwera!D13+Namwera!E13+Namwera!F13+Namwera!G13+Namwera!H13+Namwera!I13 -> 83 | H13: =SUM(D13:F13) -> 131905
