Workbook

Sheet Mulanje
A1: SOUTHERN REGION WATER BOARD
A3: MONTHLY REPORTS - 2023/2024
A4: MULANJE ZONE
A5: MULANJE ZONE
A7: PARAMETERS | C7: UNITS | D7: APRIL | E7: MAY | F7: JUNE | G7: JULY | H7: AUGUST | I7: SEPTEMBER | J7: OCTOBER | K7: NOVEMBER | L7: DECEMBER | M7: JANUARY | N7: FEBRUARY | O7: MARCH | P7: TOTALS
A8: PRODUCTION
A9: Volume Produced | C9: m3 | D9: 43953 | E9: 41245 | F9: 41892 | G9: 39179 | H9: 52514 | I9: 43543 | J9: 44155 | K9: 44934 | L9: 45410 | M9: 45896 | N9: 43928 | O9: 51845 | P9: =SUM(D9:O9) -> 538494
A10: REVENUE WATER - POSTPAID
A11: Volume Billed Individuals | C11: m3 | D11: =1286+3748+14504 -> 19538 | E11: =1322+3787+15196 -> 20305 | F11: 20935 | G11: =1253+3719+14646 -> 19618 | H11: 20388 | I11: 22357 | J11: 22373 | K11: 22000 | L11: 21079 | M11: =1274+4377+17891 -> 23542 | N11: 20468 | O11: 39141 | P11: =SUM(D11:O11) -> 271744
A12: Volume Billed CWPs | C12: m3 | D12: 1143 | E12: 1047 | F12: 1140 | G12: 1021 | H12: 1030 | I12: 1108 | J12: 1178 | K12: 1200 | L12: 1175 | M12: 958 | N12: 946 | O12: 870 | P12: =SUM(D12:O12) -> 12816
A13: Volume Billed Institutions | C13: m3 | D13: 4078 | E13: 210 | F13: 230 | G13: 195 | H13: 202 | I13: 213 | J13: 241 | K13: 250 | L13: 191 | M13: 166 | N13: 220 | O13: 202 | P13: =SUM(D13:O13) -> 6398
A14: Volume Billed Commercial/Industrial | C14: m3 | D14: 48 | E14: 45 | F14: 52 | G14: 61 | H14: 55 | I14: 69 | J14: 64 | K14: 68 | L14: 79 | M14: 89 | N14: 83 | O14: 89 | P14: =SUM(D14:O14) -> 802
A15: Total Volume Billed Post Paid | C15: m3 | D15: =SUM(D11:D14) -> 24807 | E15: =SUM(E11:E14) -> 21607 | F15: =SUM(F11:F14) -> 22357 | G15: =SUM(G11:G14) -> 20895 | H15: =SUM(H11:H14) -> 21675 | I15: =SUM(I11:I14) -> 23747 | J15: =SUM(J11:J14) -> 23856 | K15: =SUM(K11:K14) -> 23518 | ... N15: =SUM(N11:N14) -> 21717 | O15: 40302 | P15: =SUM(P11:P14) -> 291760
A16: REVENUE WATER - PREPAID
A17: Individuals | C17: m3 | D17: 1856 | E17: 2120 | F17: 4154 | G17: 1736 | H17: 9567.1 | I17: =8146-6327 -> 1819 | J17: =8048.9-3607 -> 4441.9 | K17: 3500 | L17: 2896 | M17: 2998 | N17: 3162 | O17: 2822 | P17: =SUM(D17:O17) -> 41072
A18: CWPs | C18: m3 | D18: 65 | E18: 72 | F18: 110 | G18: 73 | H18: 162 | I18: 98 | J18: 127 | K18: 133 | L18: 141 | M18: 461 | N18: 427 | O18: 231 | P18: =SUM(D18:O18) -> 2100
A19: Institutions | C19: m3 | D19: 5022 | E19: =6753-2485 -> 4268 | F19: 5180 | G19: =5492-2007 -> 3485 | H19: 5051 | I19: 6055 | J19: =5+7+72+36+362+362+362+742+145+22+724+36+36+47+200 -> 3158 | K19: =7885-3333 -> 4552 | L19: 4620 | M19: 5450 | N19: 10505 | O19: 1449 | P19: =SUM(D19:O19) -> 58795
A20: Commercial/Industrial | C20: m3 | D20: =7058-6943 -> 115 | E20: 293 | F20: =9685-9444 -> 241 | G20: 198 | H20: 2841 | I20: 174 | J20: =17.7+37+46.5+46.5+17.5+23+116.3+17.7 -> 322.2 | K20: 416 | L20: 407 | M20: =9732.4-8909 -> 823.4 | N20: 1185 | O20: 486 | P20: =SUM(D20:O20) -> 7501.6
A21: Total Volume Prepaid | C21: m3 | D21: =SUM(D17:D20) -> 7058 | E21: =SUM(E17:E20) -> 6753 | F21: =SUM(F17:F20) -> 9685 | G21: =SUM(G17:G20) -> 5492 | H21: =SUM(H17:H20) -> 17621.1 | I21: =SUM(I17:I20) -> 8146 | J21: =SUM(J17:J20) -> 8049.1 | K21: =SUM(K17:K20) -> 8601 | ... N21: =SUM(N17:N20) -> 15279 | O21: 4988 | P21: =SUM(P17:P20) -> 109468.6
A22: TOTAL REVENUE WATER | C22: m3 | D22: =D21+D15 -> 31865 | E22: =E21+E15 -> 28360 | F22: =F21+F15 -> 32042 | G22: =G21+G15 -> 26387 | H22: =H21+H15 -> 39296.1 | I22: =I21+I15 -> 31893 | J22: =J21+J15 -> 31905.1 | K22: =K21+K15 -> 32119 | ... N22: =N21+N15 -> 36996 | O22: 45290 | P22: =P21+P15 -> 401228.6
A24: Non-Revenue Water (NRW) | B24: Volume | C24: m3 | D24: =D9-D22 -> 12088 | E24: =E9-E22 -> 12885 | F24: =F9-F22 -> 9850 | G24: =G9-G22 -> 12792 | H24: =H9-H22 -> 13217.9 | I24: =I9-I22 -> 11650 | J24: =J9-J22 -> 12249.9 | K24: =K9-K22 -> 12815 | ... N24: =N9-N22 -> 6932 | O24: 6555 | P24: =P9-P22 -> 137265.4
B25: Percentage | C25: % | D25: =D24/D9 -> 0.27502105 | E25: =E24/E9 -> 0.3124015 | F25: =F24/F9 -> 0.23512843 | G25: =G24/G9 -> 0.32650144 | H25: =H24/H9 -> 0.2517024 | I25: =I24/I9 -> 0.26755162 | J25: =J24/J9 -> 0.27742951 | K25: =K24/K9 -> 0.28519607 | ... N25: =N24/N9 -> 0.15780368 | O25: 0.12643456 | P25: =P24/P9 -> 0.25490609
A26: OPERATING EXPENSES
A27: Chemicals
A28: Chemical | B28: Rate(MK/kg)
A29: Chlorine | B29: 5111.67 | C29: kg | D29: 88 | E29: 87 | F29: 89 | G29: 96 | H29: 90 | I29: 93 | J29: 91 | K29: 93 | L29: 90 | M29: 88 | N29: 86 | O29: 88 | P29: =SUM(D29:O29) -> 1079
C30: kg/mg litre | D30: =D29/(D9/1000) -> 2.0021386 | E30: =E29/(E9/1000) -> 2.1093466 | F30: =F29/(F9/1000) -> 2.1245106 | G30: =G29/(G9/1000) -> 2.4502922 | H30: =H29/(H9/1000) -> 1.7138287 | I30: =I29/(I9/1000) -> 2.1358198 | J30: =J29/(J9/1000) -> 2.0609218 | K30: =K29/(K9/1000) -> 2.0697022 | L30: 1.9819423 | M30: =M29/(M9/1000) -> 1.9173784 | N30: =N29/(N9/1000) -> 1.957749 | O30: 1.6973672 | P30: =P29/(P9/1000) -> 2.0037363
A31: Aluminium sulphate | B31: 1537 | C31: kg | F31: 0 | P31: =SUM(D31:O31) -> 0
C32: kg/mg litre | D32: =D31/(D9/1000) -> 0 | E32: =E31/(E9/1000) -> 0 | F32: =F31/(F9/1000) -> 0 | G32: =G31/(G9/1000) -> 0 | H32: =H31/(H9/1000) -> 0 | I32: =I31/(I9/1000) -> 0 | J32: =J31/(J9/1000) -> 0 | K32: =K31/(K9/1000) -> 0 | ... N32: =N31/(N9/1000) -> 0 | O32: 0 | P32: =P31/(P9/1000) -> 0
A33: Soda | B33: 1781.02 | C33: kg | F33: 0 | P33: =SUM(D33:O33) -> 0
C34: kg/mg litre | D34: =D33/(D9/1000) -> 0 | E34: =E33/(E9/1000) -> 0 | F34: =F33/(F9/1000) -> 0 | G34: =G33/(G9/1000) -> 0 | H34: =H33/(H9/1000) -> 0 | I34: =I33/(I9/1000) -> 0 | J34: =J33/(J9/1000) -> 0 | K34: =K33/(K9/1000) -> 0 | ... N34: =N33/(N9/1000) -> 0 | O34: 0 | P34: =P33/(P9/1000) -> 0
A35: Algae floc | B35: 5979.95 | C35: litres | D35: 0 | F35: 0
C36: litres/mg litre
A37: Sud floc | B37: 5403.75 | C37: litres | D37: 0 | E37: 0 | F37: 0 | G37: 0 | H37: 0 | I37: 0 | J37: 0 | K37: 0 | L37: 0 | M37: 0 | N37: 0 | O37: 0 | P37: =SUM(D37:O37) -> 0
C38: litres/mg litre | D38: =D37/(D9/1000) -> 0 | E38: =E37/(E9/1000) -> 0 | F38: =F37/(F9/1000) -> 0 | G38: =G37/(G9/1000) -> 0 | H38: =H37/(H9/1000) -> 0 | I38: =I37/(I9/1000) -> 0 | J38: =J37/(J9/1000) -> 0 | K38: =K37/(K9/1000) -> 0 | ... N38: =N37/(N9/1000) -> 0 | O38: 0 | P38: =P37/(P9/1000) -> 0
A39: Potasium permanganate | B39: 1950 | C39: kg | D39: 0 | E39: 0 | F39: 0 | G39: 0 | H39: 0 | I39: 0 | J39: 0 | K39: 0 | L39: 0 | M39: 0 | N39: 0 | O39: 0 | P39: =SUM(D39:O39) -> 0
C40: kg/mg litre | D40: =D39/(D9/1000) -> 0 | E40: =E39/(E9/1000) -> 0 | F40: =F39/(F9/1000) -> 0 | G40: =G39/(G9/1000) -> 0 | H40: =H39/(H9/1000) -> 0 | I40: =I39/(I9/1000) -> 0 | J40: =J39/(J9/1000) -> 0 | K40: =K39/(K9/1000) -> 0 | ... N40: =N39/(N9/1000) -> 0 | O40: 0 | P40: =P39/(P9/1000) -> 0
A41: Cost of Chemicals | C41: Mk | D41: =(D29*$B29)+(D31*$B31)+(D33*$B33)+(D35*$B35)+(D37*$B37)+(D39*$B39) -> 449826.96 | E41: =(E29*$B29)+(E31*$B31)+(E33*$B33)+(E35*$B35)+(E37*$B37)+(E39*$B39) -> 444715.29 | F41: =(F29*$B29)+(F31*$B31)+(F33*$B33)+(F35*$B35)+(F37*$B37)+(F39*$B39) -> 454938.63 | G41: =(G29*$B29)+(G31*$B31)+(G33*$B33)+(G35*$B35)+(G37*$B37)+(G39*$B39) -> 490720.32 | H41: =(H29*$B29)+(H31*$B31)+(H33*$B33)+(H35*$B35)+(H37*$B37)+(H39*$B39) -> 460050.3 | I41: =(I29*$B29)+(I31*$B31)+(I33*$B33)+(I35*$B35)+(I37*$B37)+(I39*$B39) -> 475385.31 | J41: =(J29*$B29)+(J31*$B31)+(J33*$B33)+(J35*$B35)+(J37*$B37)+(J39*$B39) -> 465161.97 | K41: =(K29*$B29)+(K31*$B31)+(K33*$B33)+(K35*$B35)+(K37*$B37)+(K39*$B39) -> 475385.31 | ... N41: =(N29*$B29)+(N31*$B31)+(N33*$B33)+(N35*$B35)+(N37*$B37)+(N39*$B39) -> 439603.62 | O41: 449826.96 | P41: =SUM(D41:O41) -> 5515491.9
A42: Cost/vol. Produced (chemicals) | C42: Mk/m3 | D42: =D41/D9 -> 10.234272 | E42: =E41/E9 -> 10.782284 | F42: =F41/F9 -> 10.859797 | G42: =G41/G9 -> 12.525085 | H42: =H41/H9 -> 8.7605267 | I42: =I41/I9 -> 10.917606 | J42: =J41/J9 -> 10.534752 | K42: =K41/K9 -> 10.579635 | ... N42: =N41/N9 -> 10.007367 | O42: 8.6763808 | P42: =P41/P9 -> 10.242439
A43: Power
...

Sheet Luchenza
A1: SOUTHERN REGION WATER BOARD
A3: MONTHLY REPORTS - 2023/2024
A4: MULANJE ZONE
A5: MULANJE ZONE
A7: PARAMETERS | C7: UNITS | D7: APRIL | E7: MAY | F7: JUNE | G7: JULY | H7: AUGUST | I7: SEPTEMBER | J7: OCTOBER | K7: NOVEMBER | L7: DECEMBER | M7: JANUARY | N7: FEBRUARY | O7: MARCH | P7: TOTALS
A8: PRODUCTION
A9: Volume Produced | C9: m3 | D9: 14568 | E9: 14182 | F9: 16548 | G9: 16789 | H9: 18130 | I9: 17000 | J9: 19105 | K9: 17500 | L9: 19189 | M9: 16635 | N9: 16303 | O9: 15772 | P9: =SUM(D9:O9) -> 201721
A10: REVENUE WATER - POSTPAID
A11: Volume Billed Individuals | C11: m3 | D11: =756+1266+5487 -> 7509 | E11: =601+1401+4891 -> 6893 | F11: =655+1293+5174 -> 7122 | G11: =613+1197+5045 -> 6855 | H11: =664+928+4571 -> 6163 | I11: =659+1118+5665 -> 7442 | J11: 3352 | K11: =757+1235+5328 -> 7320 | L11: 7818 | M11: 7897 | N11: 7333 | O11: 6795 | P11: =SUM(D11:O11) -> 82499
A12: Volume Billed CWPs | C12: m3 | D12: 20 | E12: 23 | F12: 23 | G12: 32 | H12: 11 | I12: 10 | J12: 4 | K12: 14 | L12: 14 | M12: 7 | N12: 6 | O12: 7 | P12: =SUM(D12:O12) -> 171
A13: Volume Billed Institutions | C13: m3 | D13: 1093 | E13: 1249 | F13: 3956 | G13: 3585 | H13: 3350 | I13: 3802 | J13: 4986 | K13: 3034 | L13: 3477 | M13: 1455 | N13: 2265 | O13: 2705 | P13: =SUM(D13:O13) -> 34957
A14: Volume Billed Commercial/Industrial | C14: m3 | D14: 88 | E14: 99 | F14: 146 | G14: 174 | H14: 260 | I14: 184 | J14: 2976 | K14: 1700 | L14: 177 | M14: 147 | N14: 91 | O14: 194 | P14: =SUM(D14:O14) -> 6236
A15: Total Volume Billed Post Paid | C15: m3 | D15: =SUM(D11:D14) -> 8710 | E15: =SUM(E11:E14) -> 8264 | F15: =SUM(F11:F14) -> 11247 | G15: =SUM(G11:G14) -> 10646 | H15: =SUM(H11:H14) -> 9784 | I15: =SUM(I11:I14) -> 11438 | J15: =SUM(J11:J14) -> 11318 | K15: =SUM(K11:K14) -> 12068 | ... N15: =SUM(N11:N14) -> 9695 | O15: 9701 | P15: =SUM(P11:P14) -> 123863
A16: REVENUE WATER - PREPAID
A17: Individuals | C17: m3 | D17: 1066 | E17: =630+530 -> 1160 | F17: 920 | G17: 752 | H17: 1498 | I17: 524 | J17: 1170 | K17: 611 | L17: 640 | M17: 692 | N17: 723 | O17: 694 | P17: =SUM(D17:O17) -> 10450
A18: CWPs | C18: m3 | D18: 0 | E18: 0 | F18: 0 | G18: 0 | H18: 0 | I18: 0 | J18: 0 | K18: 0 | L18: 0 | N18: 0 | O18: 0 | P18: =SUM(D18:O18) -> 0
A19: Institutions | C19: m3 | D19: 1241 | E19: 230 | F19: 253 | G19: 745 | H19: 1624 | I19: 646 | J19: 384 | K19: 253 | L19: 521 | M19: 513 | N19: 2218 | O19: 387 | P19: =SUM(D19:O19) -> 9015
A20: Commercial/Industrial | C20: m3 | D20: =2433-2307 -> 126 | E20: =1862-1390 -> 472 | F20: =1447-1173 -> 274 | G20: 189 | H20: =3562-3120 -> 442 | I20: =177+92 -> 269 | J20: 293 | K20: =1228-1080 -> 148 | L20: 230 | M20: 229 | N20: 690 | O20: 31 | P20: =SUM(D20:O20) -> 3393
A21: Total Volume Prepaid | C21: m3 | D21: =SUM(D17:D20) -> 2433 | E21: =SUM(E17:E20) -> 1862 | F21: =SUM(F17:F20) -> 1447 | G21: =SUM(G17:G20) -> 1686 | H21: =SUM(H17:H20) -> 3564 | I21: =SUM(I17:I20) -> 1439 | J21: =SUM(J17:J20) -> 1847 | K21: =SUM(K17:K20) -> 1012 | ... N21: =SUM(N17:N20) -> 3631 | O21: 1112 | P21: =SUM(P17:P20) -> 22858
A22: TOTAL REVENUE WATER | C22: m3 | D22: =D21+D15 -> 11143 | E22: =E21+E15 -> 10126 | F22: =F21+F15 -> 12694 | G22: =G21+G15 -> 12332 | H22: =H21+H15 -> 13348 | I22: =I21+I15 -> 12877 | J22: =J21+J15 -> 13165 | K22: =K21+K15 -> 13080 | ... N22: =N21+N15 -> 13326 | O22: 10813 | P22: =P21+P15 -> 146721
A24: Non-Revenue Water (NRW) | B24: Volume | C24: m3 | D24: =D9-D22 -> 3425 | E24: =E9-E22 -> 4056 | F24: =F9-F22 -> 3854 | G24: =G9-G22 -> 4457 | H24: =H9-H22 -> 4782 | I24: =I9-I22 -> 4123 | J24: =J9-J22 -> 5940 | K24: =K9-K22 -> 4420 | ... N24: =N9-N22 -> 2977 | O24: 4959 | P24: =P9-P22 -> 55000
B25: Percentage | C25: % | D25: =D24/D9 -> 0.23510434 | E25: =E24/E9 -> 0.28599633 | F25: =F24/F9 -> 0.23289824 | G25: =G24/G9 -> 0.26547144 | H25: =H24/H9 -> 0.26376172 | I25: =I24/I9 -> 0.24252941 | J25: =J24/J9 -> 0.31091337 | K25: =K24/K9 -> 0.25257143 | ... N25: =N24/N9 -> 0.18260443 | O25: 0.31441796 | P25: =P24/P9 -> 0.27265381
A26: OPERATING EXPENSES
A27: Chemicals
A28: Chemical | B28: Rate(MK/kg)
A29: Chlorine | B29: 5111.67 | C29: kg | D29: 50 | E29: 50 | F29: 50 | G29: 49 | H29: 39 | I29: 35 | J29: 42 | K29: 42 | L29: 40 | M29: 39 | N29: 41 | O29: 40 | P29: =SUM(D29:O29) -> 517
C30: kg/mg litre | D30: =D29/(D9/1000) -> 3.4321801 | E30: =E29/(E9/1000) -> 3.5255958 | F30: =F29/(F9/1000) -> 3.0215132 | G30: =G29/(G9/1000) -> 2.9185776 | H30: =H29/(H9/1000) -> 2.1511307 | I30: =I29/(I9/1000) -> 2.0588235 | J30: =J29/(J9/1000) -> 2.1983774 | K30: =K29/(K9/1000) -> 2.4 | L30: 2.0845276 | M30: =M29/(M9/1000) -> 2.3444545 | N30: =N29/(N9/1000) -> 2.5148746 | O30: 2.53614 | P30: =P29/(P9/1000) -> 2.5629459
A31: Aluminium sulphate | B31: 1537 | C31: kg | P31: =SUM(D31:O31) -> 0
C32: kg/mg litre | D32: =D31/(D9/1000) -> 0 | E32: =E31/(E9/1000) -> 0 | F32: =F31/(F9/1000) -> 0 | G32: =G31/(G9/1000) -> 0 | H32: =H31/(H9/1000) -> 0 | I32: =I31/(I9/1000) -> 0 | J32: =J31/(J9/1000) -> 0 | K32: =K31/(K9/1000) -> 0 | ... N32: =N31/(N9/1000) -> 0 | O32: 0 | P32: =P31/(P9/1000) -> 0
A33: Soda | B33: 1781.02 | C33: kg | P33: =SUM(D33:O33) -> 0
C34: kg/mg litre | D34: =D33/(D9/1000) -> 0 | E34: =E33/(E9/1000) -> 0 | F34: =F33/(F9/1000) -> 0 | G34: =G33/(G9/1000) -> 0 | H34: =H33/(H9/1000) -> 0 | I34: =I33/(I9/1000) -> 0 | J34: =J33/(J9/1000) -> 0 | K34: =K33/(K9/1000) -> 0 | ... N34: =N33/(N9/1000) -> 0 | O34: 0 | P34: =P33/(P9/1000) -> 0
A35: Algae floc | B35: 5979.95 | C35: litres | D35: 0
C36: litres/mg litre
A37: Sud floc | B37: 5403.75 | C37: litres | D37: 0 | E37: 0 | F37: 0 | G37: 0 | H37: 0 | I37: 0 | J37: 0 | K37: 0 | L37: 0 | M37: 0 | N37: 0 | O37: 0 | P37: =SUM(D37:O37) -> 0
C38: litres/mg litre | D38: =D37/(D9/1000) -> 0 | E38: =E37/(E9/1000) -> 0 | F38: =F37/(F9/1000) -> 0 | G38: =G37/(G9/1000) -> 0 | H38: =H37/(H9/1000) -> 0 | I38: =I37/(I9/1000) -> 0 | J38: =J37/(J9/1000) -> 0 | K38: =K37/(K9/1000) -> 0 | ... N38: =N37/(N9/1000) -> 0 | O38: 0 | P38: =P37/(P9/1000) -> 0
A39: Potasium permanganate | B39: 1950 | C39: kg | D39: 0 | E39: 0 | F39: 0 | G39: 0 | H39: 0 | I39: 0 | J39: 0 | K39: 0 | L39: 0 | M39: 0 | N39: 0 | O39: 0 | P39: =SUM(D39:O39) -> 0
C40: kg/mg litre | D40: =D39/(D9/1000) -> 0 | E40: =E39/(E9/1000) -> 0 | F40: =F39/(F9/1000) -> 0 | G40: =G39/(G9/1000) -> 0 | H40: =H39/(H9/1000) -> 0 | I40: =I39/(I9/1000) -> 0 | J40: =J39/(J9/1000) -> 0 | K40: =K39/(K9/1000) -> 0 | ... N40: =N39/(N9/1000) -> 0 | O40: 0 | P40: =P39/(P9/1000) -> 0
A41: Cost of Chemicals | C41: Mk | D41: =(D29*$B29)+(D31*$B31)+(D33*$B33)+(D35*$B35)+(D37*$B37)+(D39*$B39) -> 255583.5 | E41: =(E29*$B29)+(E31*$B31)+(E33*$B33)+(E35*$B35)+(E37*$B37)+(E39*$B39) -> 255583.5 | F41: =(F29*$B29)+(F31*$B31)+(F33*$B33)+(F35*$B35)+(F37*$B37)+(F39*$B39) -> 255583.5 | G41: =(G29*$B29)+(G31*$B31)+(G33*$B33)+(G35*$B35)+(G37*$B37)+(G39*$B39) -> 250471.83 | H41: =(H29*$B29)+(H31*$B31)+(H33*$B33)+(H35*$B35)+(H37*$B37)+(H39*$B39) -> 199355.13 | I41: =(I29*$B29)+(I31*$B31)+(I33*$B33)+(I35*$B35)+(I37*$B37)+(I39*$B39) -> 178908.45 | J41: =(J29*$B29)+(J31*$B31)+(J33*$B33)+(J35*$B35)+(J37*$B37)+(J39*$B39) -> 214690.14 | K41: =(K29*$B29)+(K31*$B31)+(K33*$B33)+(K35*$B35)+(K37*$B37)+(K39*$B39) -> 214690.14 | ... N41: =(N29*$B29)+(N31*$B31)+(N33*$B33)+(N35*$B35)+(N37*$B37)+(N39*$B39) -> 209578.47 | O41: 204466.8 | P41: =SUM(D41:O41) -> 2642733.4
A42: Cost/vol. Produced (chemicals) | C42: Mk/m3 | D42: =D41/D9 -> 17.544172 | E42: =E41/E9 -> 18.021682 | F42: =F41/F9 -> 15.444978 | G42: =G41/G9 -> 14.918806 | H42: =H41/H9 -> 10.99587 | I42: =I41/I9 -> 10.524026 | J42: =J41/J9 -> 11.23738 | K42: =K41/K9 -> 12.268008 | ... N42: =N41/N9 -> 12.855209 | O42: 12.963911 | P42: =P41/P9 -> 13.100933
A43: Power
...

Sheet Thyolo
A1: SOUTHERN REGION WATER BOARD
A3: MONTHLY REPORTS - 2023/2024
A4: MULANJE ZONE
A5: MULANJE ZONE
A7: PARAMETERS | C7: UNITS | D7: APRIL | E7: MAY | F7: JUNE | G7: JULY | H7: AUGUST | I7: SEPTEMBER | J7: OCTOBER | K7: NOVEMBER | L7: DECEMBER | M7: JANUARY | N7: FEBRUARY | O7: MARCH | P7: TOTALS
A8: PRODUCTION
A9: Volume Produced | C9: m3 | D9: 25590 | E9: 26150 | F9: 24640 | G9: 25540 | H9: 21660 | I9: 20110 | J9: 20310 | K9: 19870 | L9: 19380 | M9: 20340 | N9: 26980 | O9: 23260 | P9: =SUM(D9:O9) -> 273830
A10: REVENUE WATER - POSTPAID
A11: Volume Billed Individuals | C11: m3 | D11: =1935+1375+3536 -> 6846 | E11: =2383+1663+4047 -> 8093 | F11: =2444+1749+4501 -> 8694 | G11: =2286+1623+4149 -> 8058 | H11: 7825 | I11: =2165+1712+4109 -> 7986 | J11: =1831+1140+3358 -> 6329 | K11: =2104+1428+3829 -> 7361 | L11: 7548 | M11: 7070 | N11: 7437 | O11: 6813 | P11: =SUM(D11:O11) -> 90060
A12: Volume Billed CWPs | C12: m3 | D12: 16 | E12: 22 | F12: 17 | G12: 23 | H12: 21 | I12: 23 | J12: 17 | K12: 20 | L12: 25 | M12: 16 | N12: 16 | O12: 16 | P12: =SUM(D12:O12) -> 232
A13: Volume Billed Institutions | C13: m3 | D13: 1427 | E13: 1303 | F13: 2262 | G13: 1099 | H13: 77 | I13: 85 | J13: 77 | K13: 84 | L13: 89 | M13: 53 | N13: 41 | O13: 33 | P13: =SUM(D13:O13) -> 6630
A14: Volume Billed Commercial/Industrial | C14: m3 | D14: 278 | E14: 321 | F14: 366 | G14: 231 | H14: 230 | I14: 270 | J14: 218 | K14: 217 | L14: 211 | M14: 215 | N14: 227 | O14: 202 | P14: =SUM(D14:O14) -> 2986
A15: Total Volume Billed Post Paid | C15: m3 | D15: =SUM(D11:D14) -> 8567 | E15: =SUM(E11:E14) -> 9739 | F15: =SUM(F11:F14) -> 11339 | G15: =SUM(G11:G14) -> 9411 | H15: =SUM(H11:H14) -> 8153 | I15: =SUM(I11:I14) -> 8364 | J15: =SUM(J11:J14) -> 6641 | K15: =SUM(K11:K14) -> 7682 | ... N15: =SUM(N11:N14) -> 7721 | O15: 7064 | P15: =SUM(P11:P14) -> 99908
A16: REVENUE WATER - PREPAID
A17: Individuals | C17: m3 | D17: 1208 | E17: 1102 | F17: 1875 | G17: 1086 | H17: =3925-1372-240 -> 2313 | I17: =1308 -> 1308 | J17: 1294 | K17: 1383 | L17: 1482 | M17: 2094 | N17: 1219 | O17: 3173 | P17: =SUM(D17:O17) -> 19537
A18: CWPs | C18: m3 | D18: 0 | E18: 0 | F18: 0 | G18: 0 | H18: 0 | I18: 0 | J18: 0 | K18: 0 | L18: 0 | M18: 0 | N18: 0 | O18: 0 | P18: =SUM(D18:O18) -> 0
A19: Institutions | C19: m3 | D19: 1384 | E19: =193+1329 -> 1522 | F19: 2262 | G19: =2341-1357 -> 984 | H19: =240+988 -> 1228 | I19: =2441-1544 -> 897 | J19: 1361 | K19: =2788-1758 -> 1030 | L19: 1637 | M19: 3186 | N19: 720 | O19: 829 | P19: =SUM(D19:O19) -> 17040
A20: Commercial/Industrial | C20: m3 | D20: =2755-2592 -> 163 | E20: 229 | F20: 366 | G20: 271 | H20: 388 | I20: 236 | J20: =2836-2655 -> 181 | K20: 375 | L20: 223 | M20: 474 | N20: 281 | O20: 471 | P20: =SUM(D20:O20) -> 3658
A21: Total Volume Prepaid | C21: m3 | D21: =SUM(D17:D20) -> 2755 | E21: =SUM(E17:E20) -> 2853 | F21: =SUM(F17:F20) -> 4503 | G21: =SUM(G17:G20) -> 2341 | H21: =SUM(H17:H20) -> 3929 | I21: =SUM(I17:I20) -> 2441 | J21: =SUM(J17:J20) -> 2836 | K21: =SUM(K17:K20) -> 2788 | ... N21: =SUM(N17:N20) -> 2220 | O21: 4473 | P21: =SUM(P17:P20) -> 40235
A22: TOTAL REVENUE WATER | C22: m3 | D22: =D21+D15 -> 11322 | E22: =E21+E15 -> 12592 | F22: =F21+F15 -> 15842 | G22: =G21+G15 -> 11752 | H22: =H21+H15 -> 12082 | I22: =I21+I15 -> 10805 | J22: =J21+J15 -> 9477 | K22: =K21+K15 -> 10470 | ... N22: =N21+N15 -> 9941 | O22: 11537 | P22: =P21+P15 -> 140143
A24: Non-Revenue Water (NRW) | B24: Volume | C24: m3 | D24: =D9-D22 -> 14268 | E24: =E9-E22 -> 13558 | F24: =F9-F22 -> 8798 | G24: =G9-G22 -> 13788 | H24: =H9-H22 -> 9578 | I24: =I9-I22 -> 9305 | J24: =J9-J22 -> 10833 | K24: =K9-K22 -> 9400 | ... N24: =N9-N22 -> 17039 | O24: 11723 | P24: =P9-P22 -> 133687
B25: Percentage | C25: % | D25: =D24/D9 -> 0.55756155 | E25: =E24/E9 -> 0.51847036 | F25: =F24/F9 -> 0.35706169 | G25: =G24/G9 -> 0.53985904 | H25: =H24/H9 -> 0.4421976 | I25: =I24/I9 -> 0.46270512 | J25: =J24/J9 -> 0.53338257 | K25: =K24/K9 -> 0.47307499 | ... N25: =N24/N9 -> 0.63154188 | O25: 0.50399828 | P25: =P24/P9 -> 0.48821166
A26: OPERATING EXPENSES
A27: Chemicals
A28: Chemical | B28: Rate(MK/kg)
A29: Chlorine | B29: 5111.67 | C29: kg | D29: 82 | E29: 86 | F29: 76 | G29: 100 | H29: 88 | I29: 100 | J29: 75 | K29: 73 | L29: 80 | M29: 70 | N29: 84 | O29: 74 | P29: =SUM(D29:O29) -> 988
C30: kg/mg litre | D30: =D29/(D9/1000) -> 3.2043767 | E30: =E29/(E9/1000) -> 3.2887189 | F30: =F29/(F9/1000) -> 3.0844156 | G30: =G29/(G9/1000) -> 3.9154268 | H30: =H29/(H9/1000) -> 4.0627886 | I30: =I29/(I9/1000) -> 4.9726504 | J30: =J29/(J9/1000) -> 3.6927622 | K30: =K29/(K9/1000) -> 3.6738802 | L30: 4.127967 | M30: =M29/(M9/1000) -> 3.4414946 | N30: =N29/(N9/1000) -> 3.1134173 | O30: 3.1814273 | P30: =P29/(P9/1000) -> 3.608078
A31: Aluminium sulphate | B31: 1537 | C31: kg | F31: 0 | P31: =SUM(D31:O31) -> 0
C32: kg/mg litre | D32: =D31/(D9/1000) -> 0 | E32: =E31/(E9/1000) -> 0 | F32: =F31/(F9/1000) -> 0 | G32: =G31/(G9/1000) -> 0 | H32: =H31/(H9/1000) -> 0 | I32: =I31/(I9/1000) -> 0 | J32: =J31/(J9/1000) -> 0 | K32: =K31/(K9/1000) -> 0 | ... N32: =N31/(N9/1000) -> 0 | O32: 0 | P32: =P31/(P9/1000) -> 0
A33: Soda | B33: 1781.02 | C33: kg | F33: 0 | P33: =SUM(D33:O33) -> 0
C34: kg/mg litre | D34: =D33/(D9/1000) -> 0 | E34: =E33/(E9/1000) -> 0 | F34: =F33/(F9/1000) -> 0 | G34: =G33/(G9/1000) -> 0 | H34: =H33/(H9/1000) -> 0 | I34: =I33/(I9/1000) -> 0 | J34: =J33/(J9/1000) -> 0 | K34: =K33/(K9/1000) -> 0 | ... N34: =N33/(N9/1000) -> 0 | O34: 0 | P34: =P33/(P9/1000) -> 0
A35: Algae floc | B35: 5979.95 | C35: litres | D35: 72 | E35: 84 | F35: 72 | G35: 78 | H35: 78 | I35: 79 | J35: 79 | K35: 86 | L35: 118 | M35: 65 | O35: 117
C36: litres/mg litre | D36: =D35/(D15/1000) -> 8.4043422
A37: Sud floc | B37: 5403.75 | C37: litres | D37: 0 | E37: 0 | F37: 0 | G37: 0 | H37: 0 | I37: 0 | J37: 0 | K37: 0 | L37: 0 | M37: 0 | N37: 0 | O37: 0 | P37: =SUM(D37:O37) -> 0
C38: litres/mg litre | D38: =D37/(D9/1000) -> 0 | E38: =E37/(E9/1000) -> 0 | F38: =F37/(F9/1000) -> 0 | G38: =G37/(G9/1000) -> 0 | H38: =H37/(H9/1000) -> 0 | I38: =I37/(I9/1000) -> 0 | J38: =J37/(J9/1000) -> 0 | K38: =K37/(K9/1000) -> 0 | ... N38: =N37/(N9/1000) -> 0 | O38: 0 | P38: =P37/(P9/1000) -> 0
A39: Potasium permanganate | B39: 1950 | C39: kg | D39: 0 | E39: 0 | F39: 0 | G39: 0 | H39: 0 | I39: 0 | J39: 0 | K39: 0 | L39: 0 | M39: 0 | N39: 0 | O39: 0 | P39: =SUM(D39:O39) -> 0
C40: kg/mg litre | D40: =D39/(D9/1000) -> 0 | E40: =E39/(E9/1000) -> 0 | F40: =F39/(F9/1000) -> 0 | G40: =G39/(G9/1000) -> 0 | H40: =H39/(H9/1000) -> 0 | I40: =I39/(I9/1000) -> 0 | J40: =J39/(J9/1000) -> 0 | K40: =K39/(K9/1000) -> 0 | ... N40: =N39/(N9/1000) -> 0 | O40: 0 | P40: =P39/(P9/1000) -> 0
A41: Cost of Chemicals | C41: Mk | D41: =(D29*$B29)+(D31*$B31)+(D33*$B33)+(D35*$B35)+(D37*$B37)+(D39*$B39) -> 849713.34 | E41: =(E29*$B29)+(E31*$B31)+(E33*$B33)+(E35*$B35)+(E37*$B37)+(E39*$B39) -> 941919.42 | F41: =(F29*$B29)+(F31*$B31)+(F33*$B33)+(F35*$B35)+(F37*$B37)+(F39*$B39) -> 819043.32 | G41: =(G29*$B29)+(G31*$B31)+(G33*$B33)+(G35*$B35)+(G37*$B37)+(G39*$B39) -> 977603.1 | H41: =(H29*$B29)+(H31*$B31)+(H33*$B33)+(H35*$B35)+(H37*$B37)+(H39*$B39) -> 916263.06 | I41: =(I29*$B29)+(I31*$B31)+(I33*$B33)+(I35*$B35)+(I37*$B37)+(I39*$B39) -> 983583.05 | J41: =(J29*$B29)+(J31*$B31)+(J33*$B33)+(J35*$B35)+(J37*$B37)+(J39*$B39) -> 855791.3 | K41: =(K29*$B29)+(K31*$B31)+(K33*$B33)+(K35*$B35)+(K37*$B37)+(K39*$B39) -> 887427.61 | ... N41: =(N29*$B29)+(N31*$B31)+(N33*$B33)+(N35*$B35)+(N37*$B37)+(N39*$B39) -> 429380.28 | O41: 1077917.7 | P41: =SUM(D41:O41) -> 10599724
A42: Cost/vol. Produced (chemicals) | C42: Mk/m3 | D42: =D41/D9 -> 33.204898 | E42: =E41/E9 -> 36.019863 | F42: =F41/F9 -> 33.240394 | G42: =G41/G9 -> 38.277334 | H42: =H41/H9 -> 42.30208 | I42: =I41/I9 -> 48.910147 | J42: =J41/J9 -> 42.13645 | K42: =K41/K9 -> 44.661681 | ... N42: =N41/N9 -> 15.914762 | O42: 46.342121 | P42: =P41/P9 -> 38.709139
A43: Power
...

Sheet Muloza
A1: SOUTHERN REGION WATER BOARD
A3: MONTHLY REPORTS - 2023/2024
A4: MULANJE ZONE
A5: MULANJE ZONE
A7: PARAMETERS | C7: UNITS | D7: APRIL | E7: MAY | F7: JUNE | G7: JULY | H7: AUGUST | I7: SEPTEMBER | J7: OCTOBER | K7: NOVEMBER | L7: DECEMBER | M7: JANUARY | N7: FEBRUARY | O7: MARCH | P7: TOTALS
A8: PRODUCTION
A9: Volume Produced | C9: m3 | D9: 5343 | E9: 8541 | F9: 7689 | G9: 7562 | H9: 8349 | I9: 7182 | J9: 8063 | K9: 7892 | L9: 8596 | M9: 9482 | N9: 9222 | O9: 9113 | P9: =SUM(D9:O9) -> 97034
A10: REVENUE WATER - POSTPAID
A11: Volume Billed Individuals | C11: m3 | D11: =480+11+2737 -> 3228 | E11: =696+9+3465 -> 4170 | F11: =604+11+3577 -> 4192 | G11: =490+10+3109 -> 3609 | H11: =642+11+3625 -> 4278 | I11: =488+11+3383 -> 3882 | J11: =714+10+4332 -> 5056 | K11: 5000 | L11: 5333 | M11: 5127 | N11: 5090 | O11: 4876 | P11: =SUM(D11:O11) -> 53841
A12: Volume Billed CWPs | C12: m3 | D12: 6 | E12: 8 | F12: 11 | G12: 11 | H12: 12 | I12: 15 | J12: 6 | K12: 8 | L12: 31 | M12: 21 | N12: 26 | O12: 19 | P12: =SUM(D12:O12) -> 174
A13: Volume Billed Institutions | C13: m3 | D13: 238 | E13: 425 | F13: 691 | G13: 752 | H13: 343 | I13: 72 | J13: 129 | K13: 91 | L13: 275 | M13: 246 | N13: 513 | O13: 524 | P13: =SUM(D13:O13) -> 4299
A14: Volume Billed Commercial/Industrial | C14: m3 | D14: 90 | E14: 106 | F14: 145 | G14: 86 | H14: 127 | I14: 97 | J14: 102 | K14: 131 | L14: 106 | M14: 105 | N14: 99 | O14: 90 | P14: =SUM(D14:O14) -> 1284
A15: Total Volume Billed Post Paid | C15: m3 | D15: =SUM(D11:D14) -> 3562 | E15: =SUM(E11:E14) -> 4709 | F15: =SUM(F11:F14) -> 5039 | G15: =SUM(G11:G14) -> 4458 | H15: =SUM(H11:H14) -> 4760 | I15: =SUM(I11:I14) -> 4066 | J15: =SUM(J11:J14) -> 5293 | K15: =SUM(K11:K14) -> 5230 | ... N15: =SUM(N11:N14) -> 5728 | O15: 5509 | P15: =SUM(P11:P14) -> 59598
A16: REVENUE WATER - PREPAID
A17: Individuals | C17: m3 | D17: 752 | E17: 1203 | F17: 912 | G17: 927 | H17: 911 | I17: 726 | J17: 998 | K17: 960 | L17: 1266 | M17: 871 | N17: 720 | O17: 912 | P17: =SUM(D17:O17) -> 11158
A18: CWPs | C18: m3 | D18: 0 | E18: 0 | F18: 0 | G18: 0 | H18: 0 | I18: 0 | J18: 0 | K18: 0 | L18: 0 | M18: 0 | N18: 0 | O18: 0 | P18: =SUM(D18:O18) -> 0
A19: Institutions | C19: m3 | D19: 104 | E19: =108+125 -> 233 | F19: 123 | G19: 163 | H19: 134 | I19: =1094-927 -> 167 | J19: 197 | K19: 77 | L19: 71 | M19: 62 | N19: 84 | O19: 106 | P19: =SUM(D19:O19) -> 1521
A20: Commercial/Industrial | C20: m3 | D20: 198 | E20: 355 | F20: =1157-1035 -> 122 | G20: =1366-1090 -> 276 | H20: =1264-1045 -> 219 | I20: 201 | J20: =1407-1195 -> 212 | K20: =108+73 -> 181 | L20: 208 | M20: 182.1 | N20: 417.6 | O20: 139 | P20: =SUM(D20:O20) -> 2710.7
A21: Total Volume Prepaid | C21: m3 | D21: =SUM(D17:D20) -> 1054 | E21: =SUM(E17:E20) -> 1791 | F21: =SUM(F17:F20) -> 1157 | G21: =SUM(G17:G20) -> 1366 | H21: =SUM(H17:H20) -> 1264 | I21: =SUM(I17:I20) -> 1094 | J21: =SUM(J17:J20) -> 1407 | K21: =SUM(K17:K20) -> 1218 | ... N21: =SUM(N17:N20) -> 1221.6 | O21: 1157 | P21: =SUM(P17:P20) -> 15389.7
A22: TOTAL REVENUE WATER | C22: m3 | D22: =D21+D15 -> 4616 | E22: =E21+E15 -> 6500 | F22: =F21+F15 -> 6196 | G22: =G21+G15 -> 5824 | H22: =H21+H15 -> 6024 | I22: =I21+I15 -> 5160 | J22: =J21+J15 -> 6700 | K22: =K21+K15 -> 6448 | ... N22: =N21+N15 -> 6949.6 | O22: 6666 | P22: =P21+P15 -> 74987.7
A24: Non-Revenue Water (NRW) | B24: Volume | C24: m3 | D24: =D9-D22 -> 727 | E24: =E9-E22 -> 2041 | F24: =F9-F22 -> 1493 | G24: =G9-G22 -> 1738 | H24: =H9-H22 -> 2325 | I24: =I9-I22 -> 2022 | J24: =J9-J22 -> 1363 | K24: =K9-K22 -> 1444 | ... N24: =N9-N22 -> 2272.4 | O24: 2447 | P24: =P9-P22 -> 22046.3
B25: Percentage | C25: % | D25: =D24/D9 -> 0.13606588 | E25: =E24/E9 -> 0.23896499 | F25: =F24/F9 -> 0.19417349 | G25: =G24/G9 -> 0.22983338 | H25: =H24/H9 -> 0.27847646 | I25: =I24/I9 -> 0.28153718 | J25: =J24/J9 -> 0.16904378 | K25: =K24/K9 -> 0.1829701 | ... N25: =N24/N9 -> 0.24641076 | O25: 0.2685175 | P25: =P24/P9 -> 0.22720181
A26: OPERATING EXPENSES
A27: Chemicals
A28: Chemical | B28: Rate(MK/kg)
A29: Chlorine | B29: 5111.67 | C29: kg | D29: 6 | E29: 14 | F29: 16 | G29: 15 | H29: 8 | I29: 8 | J29: 7 | K29: 8 | L29: 10 | M29: 11 | N29: 9 | O29: 7 | P29: =SUM(D29:O29) -> 119
C30: kg/mg litre | D30: =D29/(D9/1000) -> 1.1229646 | E30: =E29/(E9/1000) -> 1.6391523 | F30: =F29/(F9/1000) -> 2.0808948 | G30: =G29/(G9/1000) -> 1.9836022 | H30: =H29/(H9/1000) -> 0.95819859 | I30: =I29/(I9/1000) -> 1.1138959 | J30: =J29/(J9/1000) -> 0.86816321 | K30: =K29/(K9/1000) -> 1.0136847 | L30: 1.1633318 | M30: =M29/(M9/1000) -> 1.1600928 | N30: =N29/(N9/1000) -> 0.97592713 | O30: 0.76813344 | P30: =P29/(P9/1000) -> 1.2263743
A31: Aluminium sulphate | B31: 1537 | C31: kg | P31: =SUM(D31:O31) -> 0
C32: kg/mg litre | D32: =D31/(D9/1000) -> 0 | E32: =E31/(E9/1000) -> 0 | F32: =F31/(F9/1000) -> 0 | G32: =G31/(G9/1000) -> 0 | H32: =H31/(H9/1000) -> 0 | I32: =I31/(I9/1000) -> 0 | J32: =J31/(J9/1000) -> 0 | K32: =K31/(K9/1000) -> 0 | ... N32: =N31/(N9/1000) -> 0 | O32: 0 | P32: =P31/(P9/1000) -> 0
A33: Soda | B33: 1781.02 | C33: kg | P33: =SUM(D33:O33) -> 0
C34: kg/mg litre | D34: =D33/(D9/1000) -> 0 | E34: =E33/(E9/1000) -> 0 | F34: =F33/(F9/1000) -> 0 | G34: =G33/(G9/1000) -> 0 | H34: =H33/(H9/1000) -> 0 | I34: =I33/(I9/1000) -> 0 | J34: =J33/(J9/1000) -> 0 | K34: =K33/(K9/1000) -> 0 | ... N34: =N33/(N9/1000) -> 0 | O34: 0 | P34: =P33/(P9/1000) -> 0
A35: Algae floc | B35: 5979.95 | C35: litres | D35: 0
C36: litres/mg litre
A37: Sud floc | B37: 5403.75 | C37: litres | D37: 0 | E37: 0 | F37: 0 | G37: 0 | H37: 0 | I37: 0 | J37: 0 | K37: 0 | L37: 0 | M37: 0 | N37: 0 | O37: 0 | P37: =SUM(D37:O37) -> 0
C38: litres/mg litre | D38: =D37/(D9/1000) -> 0 | E38: =E37/(E9/1000) -> 0 | F38: =F37/(F9/1000) -> 0 | G38: =G37/(G9/1000) -> 0 | H38: =H37/(H9/1000) -> 0 | I38: =I37/(I9/1000) -> 0 | J38: =J37/(J9/1000) -> 0 | K38: =K37/(K9/1000) -> 0 | ... N38: =N37/(N9/1000) -> 0 | O38: 0 | P38: =P37/(P9/1000) -> 0
A39: Potasium permanganate | B39: 1950 | C39: kg | D39: 0 | E39: 0 | F39: 0 | G39: 0 | H39: 0 | I39: 0 | J39: 0 | K39: 0 | L39: 0 | M39: 0 | N39: 0 | O39: 0 | P39: =SUM(D39:O39) -> 0
C40: kg/mg litre | D40: =D39/(D9/1000) -> 0 | E40: =E39/(E9/1000) -> 0 | F40: =F39/(F9/1000) -> 0 | G40: =G39/(G9/1000) -> 0 | H40: =H39/(H9/1000) -> 0 | I40: =I39/(I9/1000) -> 0 | J40: =J39/(J9/1000) -> 0 | K40: =K39/(K9/1000) -> 0 | ... N40: =N39/(N9/1000) -> 0 | O40: 0 | P40: =P39/(P9/1000) -> 0
A41: Cost of Chemicals | C41: Mk | D41: =(D29*$B29)+(D31*$B31)+(D33*$B33)+(D35*$B35)+(D37*$B37)+(D39*$B39) -> 30670.02 | E41: =(E29*$B29)+(E31*$B31)+(E33*$B33)+(E35*$B35)+(E37*$B37)+(E39*$B39) -> 71563.38 | F41: =(F29*$B29)+(F31*$B31)+(F33*$B33)+(F35*$B35)+(F37*$B37)+(F39*$B39) -> 81786.72 | G41: =(G29*$B29)+(G31*$B31)+(G33*$B33)+(G35*$B35)+(G37*$B37)+(G39*$B39) -> 76675.05 | H41: =(H29*$B29)+(H31*$B31)+(H33*$B33)+(H35*$B35)+(H37*$B37)+(H39*$B39) -> 40893.36 | I41: =(I29*$B29)+(I31*$B31)+(I33*$B33)+(I35*$B35)+(I37*$B37)+(I39*$B39) -> 40893.36 | J41: =(J29*$B29)+(J31*$B31)+(J33*$B33)+(J35*$B35)+(J37*$B37)+(J39*$B39) -> 35781.69 | K41: =(K29*$B29)+(K31*$B31)+(K33*$B33)+(K35*$B35)+(K37*$B37)+(K39*$B39) -> 40893.36 | ... N41: =(N29*$B29)+(N31*$B31)+(N33*$B33)+(N35*$B35)+(N37*$B37)+(N39*$B39) -> 46005.03 | O41: 35781.69 | P41: =SUM(D41:O41) -> 608288.73
A42: Cost/vol. Produced (chemicals) | C42: Mk/m3 | D42: =D41/D9 -> 5.7402246 | E42: =E41/E9 -> 8.3788058 | F42: =F41/F9 -> 10.636847 | G42: =G41/G9 -> 10.13952 | H42: =H41/H9 -> 4.897995 | I42: =I41/I9 -> 5.693868 | J42: =J41/J9 -> 4.4377639 | K42: =K41/K9 -> 5.1816219 | ... N42: =N41/N9 -> 4.9886174 | O42: 3.9264446 | P42: =P41/P9 -> 6.2688205
A43: Power
...

Sheet MUST
A1: SOUTHERN REGION WATER BOARD
A3: MONTHLY REPORTS - 2023/2024
A4: MULANJE ZONE
A5: MULANJE ZONE
A7: PARAMETERS | C7: UNITS | D7: APRIL | E7: MAY | F7: JUNE | G7: JULY | H7: AUGUST | I7: SEPTEMBER | J7: OCTOBER | K7: NOVEMBER | L7: DECEMBER | M7: JANUARY | N7: FEBRUARY | O7: MARCH | P7: TOTALS
A8: PRODUCTION
A9: Volume Produced | C9: m3 | D9: 20543 | E9: 14001 | F9: 9442 | G9: 13028 | H9: 26032 | I9: 14779 | J9: 15745 | K9: 16982 | L9: 16346 | M9: 2257 | N9: 14870 | O9: 15646 | P9: =SUM(D9:O9) -> 179671
A10: REVENUE WATER - POSTPAID
A11: Volume Billed Individuals | C11: m3 | D11: =544+214 -> 758 | E11: =538+32 -> 570 | F11: =193+842 -> 1035 | G11: =211+628 -> 839 | H11: =226+805 -> 1031 | I11: =194+815 -> 1009 | J11: =186+897 -> 1083 | K11: =126+969 -> 1095 | L11: 989 | M11: 855 | N11: 964 | O11: 1236 | P11: =SUM(D11:O11) -> 11464
A12: Volume Billed CWPs | C12: m3 | D12: 0 | E12: 0 | F12: 0 | G12: 0 | H12: 0 | I12: 0 | J12: 0 | K12: 0 | L12: 0 | M12: 0 | N12: 0 | O12: 0 | P12: =SUM(D12:O12) -> 0
A13: Volume Billed Institutions | C13: m3 | D13: 14800 | E13: 10356 | F13: 6309 | G13: 9357 | H13: =8499 -> 8499 | I13: 30 | J13: 30 | K13: 31 | L13: 37 | M13: 29 | N13: 29 | O13: 24 | P13: =SUM(D13:O13) -> 49531
A14: Volume Billed Commercial/Industrial | C14: m3 | D14: 51 | E14: 65 | F14: 54 | G14: 56 | H14: 60 | I14: 65 | J14: 43 | K14: 32 | L14: 24 | M14: 20 | N14: 32 | O14: 8 | P14: =SUM(D14:O14) -> 510
A15: Total Volume Billed Post Paid | C15: m3 | D15: =SUM(D11:D14) -> 15609 | E15: =SUM(E11:E14) -> 10991 | F15: =SUM(F11:F14) -> 7398 | G15: =SUM(G11:G14) -> 10252 | H15: =SUM(H11:H14) -> 9590 | I15: =SUM(I11:I14) -> 1104 | J15: =SUM(J11:J14) -> 1156 | K15: =SUM(K11:K14) -> 1158 | ... N15: =SUM(N11:N14) -> 1025 | O15: 1268 | P15: =SUM(P11:P14) -> 61505
A16: REVENUE WATER - PREPAID
A17: Individuals | C17: m3 | D17: =159.3+0.8 -> 160.1 | E17: 268 | F17: 291 | G17: 327 | H17: 307 | I17: 295 | J17: 263.6 | K17: =13.6+217.4 -> 231 | L17: 221 | M17: 192 | N17: 213 | O17: 254.3 | P17: =SUM(D17:O17) -> 3023
A18: CWPs | C18: m3 | D18: 0 | E18: 0 | F18: 0 | G18: 0 | H18: 0 | I18: 0 | J18: 0 | K18: 0 | L18: 0 | M18: 0 | N18: 0 | O18: 0 | P18: =SUM(D18:O18) -> 0
A19: Institutions | C19: m3 | D19: 0 | E19: 0 | F19: 0 | G19: 0 | H19: 11399 | I19: 10929 | J19: 10857 | K19: 11041 | L19: 11037 | M19: 0 | N19: 11037 | O19: 11762 | P19: =SUM(D19:O19) -> 78062
A20: Commercial/Industrial | C20: m3 | D20: 857 | E20: 858 | F20: 536 | G20: 751 | H20: 729 | I20: 715 | J20: 713 | K20: 749 | L20: 1447 | M20: 749 | N20: 717 | O20: 726 | P20: =SUM(D20:O20) -> 9547
A21: Total Volume Prepaid | C21: m3 | D21: =SUM(D17:D20) -> 1017.1 | E21: =SUM(E17:E20) -> 1126 | F21: =SUM(F17:F20) -> 827 | G21: =SUM(G17:G20) -> 1078 | H21: =SUM(H17:H20) -> 12435 | I21: =SUM(I17:I20) -> 11939 | J21: =SUM(J17:J20) -> 11833.6 | K21: =SUM(K17:K20) -> 12021 | ... N21: =SUM(N17:N20) -> 11967 | O21: 12742.3 | P21: =SUM(P17:P20) -> 90632
A22: TOTAL REVENUE WATER | C22: m3 | D22: =D21+D15 -> 16626.1 | E22: =E21+E15 -> 12117 | F22: =F21+F15 -> 8225 | G22: =G21+G15 -> 11330 | H22: =H21+H15 -> 22025 | I22: =I21+I15 -> 13043 | J22: =J21+J15 -> 12989.6 | K22: =K21+K15 -> 13179 | ... N22: =N21+N15 -> 12992 | O22: 14010.3 | P22: =P21+P15 -> 152137
A24: Non-Revenue Water (NRW) | B24: Volume | C24: m3 | D24: =D9-D22 -> 3916.9 | E24: =E9-E22 -> 1884 | F24: =F9-F22 -> 1217 | G24: =G9-G22 -> 1698 | H24: =H9-H22 -> 4007 | I24: =I9-I22 -> 1736 | J24: =J9-J22 -> 2755.4 | K24: =K9-K22 -> 3803 | ... N24: =N9-N22 -> 1878 | O24: 1635.7 | P24: =P9-P22 -> 27534
B25: Percentage | C25: % | D25: =D24/D9 -> 0.19066835 | E25: =E24/E9 -> 0.13456182 | F25: =F24/F9 -> 0.12889218 | G25: =G24/G9 -> 0.13033466 | H25: =H24/H9 -> 0.15392594 | I25: =I24/I9 -> 0.11746397 | J25: =J24/J9 -> 0.17500159 | K25: =K24/K9 -> 0.223943 | ... N25: =N24/N9 -> 0.12629455 | O25: 0.10454429 | P25: =P24/P9 -> 0.15324677
A26: OPERATING EXPENSES
A27: Chemicals
A28: Chemical | B28: Rate(MK/kg)
A29: Chlorine | B29: 5111.67 | C29: kg | D29: 16 | E29: 16 | F29: 10 | G29: 15 | H29: 17 | I29: 15 | J29: 17 | K29: 18 | L29: 9 | M29: 12 | N29: 14 | O29: 17 | P29: =SUM(D29:O29) -> 176
C30: kg/mg litre | D30: =D29/(D9/1000) -> 0.77885411 | E30: =E29/(E9/1000) -> 1.1427755 | F30: =F29/(F9/1000) -> 1.0590976 | G30: =G29/(G9/1000) -> 1.1513663 | H30: =H29/(H9/1000) -> 0.65304241 | I30: =I29/(I9/1000) -> 1.0149537 | J30: =J29/(J9/1000) -> 1.0797078 | K30: =K29/(K9/1000) -> 1.0599458 | L30: 0.55059342 | M30: =M29/(M9/1000) -> 5.3167922 | N30: =N29/(N9/1000) -> 0.94149294 | O30: 1.0865397 | P30: =P29/(P9/1000) -> 0.97956821
A31: Aluminium sulphate | B31: 1537 | C31: kg | P31: =SUM(D31:O31) -> 0
C32: kg/mg litre | D32: =D31/(D9/1000) -> 0 | E32: =E31/(E9/1000) -> 0 | F32: =F31/(F9/1000) -> 0 | G32: =G31/(G9/1000) -> 0 | H32: =H31/(H9/1000) -> 0 | I32: =I31/(I9/1000) -> 0 | J32: =J31/(J9/1000) -> 0 | K32: =K31/(K9/1000) -> 0 | ... N32: =N31/(N9/1000) -> 0 | O32: 0 | P32: =P31/(P9/1000) -> 0
A33: Soda | B33: 1781.02 | C33: kg | P33: =SUM(D33:O33) -> 0
C34: kg/mg litre | D34: =D33/(D9/1000) -> 0 | E34: =E33/(E9/1000) -> 0 | F34: =F33/(F9/1000) -> 0 | G34: =G33/(G9/1000) -> 0 | H34: =H33/(H9/1000) -> 0 | I34: =I33/(I9/1000) -> 0 | J34: =J33/(J9/1000) -> 0 | K34: =K33/(K9/1000) -> 0 | ... N34: =N33/(N9/1000) -> 0 | O34: 0 | P34: =P33/(P9/1000) -> 0
A35: Algae floc | B35: 5979.95 | C35: litres
C36: litres/mg litre
A37: Sud floc | B37: 5403.75 | C37: litres | D37: 0 | E37: 0 | F37: 0 | G37: 0 | H37: 0 | I37: 0 | J37: 0 | K37: 0 | L37: 0 | M37: 0 | N37: 0 | O37: 0 | P37: =SUM(D37:O37) -> 0
C38: litres/mg litre | D38: =D37/(D9/1000) -> 0 | E38: =E37/(E9/1000) -> 0 | F38: =F37/(F9/1000) -> 0 | G38: =G37/(G9/1000) -> 0 | H38: =H37/(H9/1000) -> 0 | I38: =I37/(I9/1000) -> 0 | J38: =J37/(J9/1000) -> 0 | K38: =K37/(K9/1000) -> 0 | ... N38: =N37/(N9/1000) -> 0 | O38: 0 | P38: =P37/(P9/1000) -> 0
A39: Potasium permanganate | B39: 1950 | C39: kg | D39: 0 | E39: 0 | F39: 0 | G39: 0 | H39: 0 | I39: 0 | J39: 0 | K39: 0 | L39: 0 | M39: 0 | N39: 0 | O39: 0 | P39: =SUM(D39:O39) -> 0
C40: kg/mg litre | D40: =D39/(D9/1000) -> 0 | E40: =E39/(E9/1000) -> 0 | F40: =F39/(F9/1000) -> 0 | G40: =G39/(G9/1000) -> 0 | H40: =H39/(H9/1000) -> 0 | I40: =I39/(I9/1000) -> 0 | J40: =J39/(J9/1000) -> 0 | K40: =K39/(K9/1000) -> 0 | ... N40: =N39/(N9/1000) -> 0 | O40: 0 | P40: =P39/(P9/1000) -> 0
A41: Cost of Chemicals | C41: Mk | D41: =(D29*$B29)+(D31*$B31)+(D33*$B33)+(D35*$B35)+(D37*$B37)+(D39*$B39) -> 81786.72 | E41: =(E29*$B29)+(E31*$B31)+(E33*$B33)+(E35*$B35)+(E37*$B37)+(E39*$B39) -> 81786.72 | F41: =(F29*$B29)+(F31*$B31)+(F33*$B33)+(F35*$B35)+(F37*$B37)+(F39*$B39) -> 51116.7 | G41: =(G29*$B29)+(G31*$B31)+(G33*$B33)+(G35*$B35)+(G37*$B37)+(G39*$B39) -> 76675.05 | H41: =(H29*$B29)+(H31*$B31)+(H33*$B33)+(H35*$B35)+(H37*$B37)+(H39*$B39) -> 86898.39 | I41: =(I29*$B29)+(I31*$B31)+(I33*$B33)+(I35*$B35)+(I37*$B37)+(I39*$B39) -> 76675.05 | J41: =(J29*$B29)+(J31*$B31)+(J33*$B33)+(J35*$B35)+(J37*$B37)+(J39*$B39) -> 86898.39 | K41: =(K29*$B29)+(K31*$B31)+(K33*$B33)+(K35*$B35)+(K37*$B37)+(K39*$B39) -> 92010.06 | ... N41: =(N29*$B29)+(N31*$B31)+(N33*$B33)+(N35*$B35)+(N37*$B37)+(N39*$B39) -> 71563.38 | O41: 86898.39 | P41: =SUM(D41:O41) -> 899653.92
A42: Cost/vol. Produced (chemicals) | C42: Mk/m3 | D42: =D41/D9 -> 3.9812452 | E42: =E41/E9 -> 5.8414913 | F42: =F41/F9 -> 5.4137577 | G42: =G41/G9 -> 5.8854045 | H42: =H41/H9 -> 3.3381373 | I42: =I41/I9 -> 5.1881081 | J42: =J41/J9 -> 5.5191102 | K42: =K41/K9 -> 5.4180933 | ... N42: =N41/N9 -> 4.8126012 | O42: 5.5540323 | P42: =P41/P9 -> 5.0072294
A43: Power
...

Sheet Phalombe
A1: SOUTHERN REGION WATER BOARD
A3: MONTHLY REPORTS - 2023/2024
A4: MULANJE ZONE
A5: MULANJE ZONE
A7: PARAMETERS | C7: UNITS | D7: APRIL | E7: MAY | F7: JUNE | G7: JULY | H7: AUGUST | I7: SEPTEMBER | J7: OCTOBER | K7: NOVEMBER | L7: DECEMBER | M7: JANUARY | N7: FEBRUARY | O7: MARCH | P7: TOTALS
A8: PRODUCTION
A9: Volume Produced | C9: m3 | D9: 8853 | E9: 17966 | F9: 13530 | G9: 8346 | H9: 11917 | I9: 10995 | J9: 10454 | K9: 10025 | L9: 9226 | M9: 9471 | N9: 9893 | O9: 8353 | P9: =SUM(D9:O9) -> 129029
A10: REVENUE WATER - POSTPAID
A11: Volume Billed Individuals | C11: m3 | D11: =4+512+3329 -> 3845 | E11: =7+766+13396 -> 14169 | F11: =7+789+4099 -> 4895 | G11: =8+693+3910 -> 4611 | H11: =24+705+4340 -> 5069 | I11: =10+753+5193 -> 5956 | J11: 5657 | K11: 5700 | L11: 5045 | M11: 4578 | N11: =5+593+4185 -> 4783 | O11: 4288 | P11: =SUM(D11:O11) -> 68596
A12: Volume Billed CWPs | C12: m3 | D12: 0 | E12: 0 | F12: 0 | G12: 0 | H12: 0 | I12: 0 | J12: 0 | K12: 0 | L12: 0 | M12: 0 | N12: 0 | O12: 0 | P12: =SUM(D12:O12) -> 0
A13: Volume Billed Institutions | C13: m3 | D13: 352 | E13: 480 | F13: 401 | G13: 63 | H13: 27 | I13: 32 | J13: 33 | K13: 31 | L13: 9 | M13: 10 | N13: 26 | O13: 14 | P13: =SUM(D13:O13) -> 1478
A14: Volume Billed Commercial/Industrial | C14: m3 | D14: 53 | E14: 53 | F14: 37 | G14: 47 | H14: 45 | I14: 37 | J14: 45 | K14: 17 | L14: 21 | M14: 23 | N14: 21 | O14: 23 | P14: =SUM(D14:O14) -> 422
A15: Total Volume Billed Post Paid | C15: m3 | D15: =SUM(D11:D14) -> 4250 | E15: =SUM(E11:E14) -> 14702 | F15: =SUM(F11:F14) -> 5333 | G15: =SUM(G11:G14) -> 4721 | H15: =SUM(H11:H14) -> 5141 | I15: =SUM(I11:I14) -> 6025 | J15: =SUM(J11:J14) -> 5735 | K15: =SUM(K11:K14) -> 5748 | ... N15: =SUM(N11:N14) -> 4830 | O15: 4325 | P15: =SUM(P11:P14) -> 70496
A16: REVENUE WATER - PREPAID
A17: Individuals | C17: m3 | D17: 738 | E17: =2+684 -> 686 | F17: 911 | G17: =783 -> 783 | H17: 1421.4 | I17: 802 | J17: 992.1 | K17: =19+896.2 -> 915.2 | L17: 858 | M17: 1684 | N17: 430.3 | O17: 785.7 | P17: =SUM(D17:O17) -> 11006.7 | Q17: =P17/14458% -> 76.128787
A18: CWPs | C18: m3 | D18: 0 | E18: 0 | F18: 0 | G18: 0 | H18: 0 | I18: 0 | J18: 0 | K18: 0 | L18: 0 | M18: 0 | O18: 0 | P18: =SUM(D18:O18) -> 0 | Q18: =P18/14458% -> 0
A19: Institutions | C19: m3 | D19: =864+27 -> 891 | E19: 118 | F19: 3803 | G19: 92 | H19: 978 | I19: 148 | J19: =48 -> 48 | K19: 108 | L19: 90 | M19: 384 | N19: 2104 | O19: 224 | P19: =SUM(D19:O19) -> 8988 | Q19: =P19/14458% -> 62.166275
A20: Commercial/Industrial | C20: m3 | D20: 102 | E20: 72 | F20: =4981-4848 -> 133 | G20: 37 | H20: 53.6 | I20: 51 | J20: =65.6+5 -> 70.6 | K20: 76.3 | L20: 37 | M20: 76 | N20: 63 | O20: 65 | P20: =SUM(D20:O20) -> 836.5 | Q20: =P20/14458% -> 5.7857242
A21: Total Volume Prepaid | C21: m3 | D21: =SUM(D17:D20) -> 1731 | E21: =SUM(E17:E20) -> 876 | F21: =SUM(F17:F20) -> 4847 | G21: =SUM(G17:G20) -> 912 | H21: =SUM(H17:H20) -> 2453 | I21: =SUM(I17:I20) -> 1001 | J21: =SUM(J17:J20) -> 1110.7 | K21: =SUM(K17:K20) -> 1099.5 | ... N21: =SUM(N17:N20) -> 2597.3 | O21: 1074.7 | P21: =SUM(P17:P20) -> 20831.2 | Q21: =P21/14458% -> 144.08079
A22: TOTAL REVENUE WATER | C22: m3 | D22: =D21+D15 -> 5981 | E22: =E21+E15 -> 15578 | F22: =F21+F15 -> 10180 | G22: =G21+G15 -> 5633 | H22: =H21+H15 -> 7594 | I22: =I21+I15 -> 7026 | J22: =J21+J15 -> 6845.7 | K22: =K21+K15 -> 6847.5 | ... N22: =N21+N15 -> 7427.3 | O22: 5399.7 | P22: =P21+P15 -> 91327.2
A24: Non-Revenue Water (NRW) | B24: Volume | C24: m3 | D24: =D9-D22 -> 2872 | E24: =E9-E22 -> 2388 | F24: =F9-F22 -> 3350 | G24: =G9-G22 -> 2713 | H24: =H9-H22 -> 4323 | I24: =I9-I22 -> 3969 | J24: =J9-J22 -> 3608.3 | K24: =K9-K22 -> 3177.5 | ... N24: =N9-N22 -> 2465.7 | O24: 2953.3 | P24: =P9-P22 -> 37701.8
B25: Percentage | C25: % | D25: =D24/D9 -> 0.3244098 | E25: =E24/E9 -> 0.13291773 | F25: =F24/F9 -> 0.24759793 | G25: =G24/G9 -> 0.3250659 | H25: =H24/H9 -> 0.36275908 | I25: =I24/I9 -> 0.36098226 | J25: =J24/J9 -> 0.34515975 | K25: =K24/K9 -> 0.31695761 | ... N25: =N24/N9 -> 0.24923683 | O25: 0.35356159 | P25: =P24/P9 -> 0.29219633
A26: OPERATING EXPENSES
A27: Chemicals
A28: Chemical | B28: Rate(MK/kg)
A29: Chlorine | B29: 5111.67 | C29: kg | D29: 30 | E29: 31 | F29: 30 | G29: 30 | H29: 25 | I29: 24 | J29: 24 | K29: 24 | L29: 24 | M29: 24 | N29: 24 | O29: 24 | P29: =SUM(D29:O29) -> 314
C30: kg/mg litre | D30: =D29/(D9/1000) -> 3.3886818 | E30: =E29/(E9/1000) -> 1.7254815 | F30: =F29/(F9/1000) -> 2.2172949 | G30: =G29/(G9/1000) -> 3.5945363 | H30: =H29/(H9/1000) -> 2.0978434 | I30: =I29/(I9/1000) -> 2.1828104 | J30: =J29/(J9/1000) -> 2.295772 | K30: =K29/(K9/1000) -> 2.394015 | L30: 2.601344 | M30: =M29/(M9/1000) -> 2.5340513 | N30: =N29/(N9/1000) -> 2.4259577 | O30: 2.8732192 | P30: =P29/(P9/1000) -> 2.4335614
A31: Aluminium sulphate | B31: 1537 | C31: kg | P31: =SUM(D31:O31) -> 0
C32: kg/mg litre | D32: =D31/(D9/1000) -> 0 | E32: =E31/(E9/1000) -> 0 | F32: =F31/(F9/1000) -> 0 | G32: =G31/(G9/1000) -> 0 | H32: =H31/(H9/1000) -> 0 | I32: =I31/(I9/1000) -> 0 | J32: =J31/(J9/1000) -> 0 | K32: =K31/(K9/1000) -> 0 | ... N32: =N31/(N9/1000) -> 0 | O32: 0 | P32: =P31/(P9/1000) -> 0
A33: Soda | B33: 1781.02 | C33: kg | P33: =SUM(D33:O33) -> 0
C34: kg/mg litre | D34: =D33/(D9/1000) -> 0 | E34: =E33/(E9/1000) -> 0 | F34: =F33/(F9/1000) -> 0 | G34: =G33/(G9/1000) -> 0 | H34: =H33/(H9/1000) -> 0 | I34: =I33/(I9/1000) -> 0 | J34: =J33/(J9/1000) -> 0 | K34: =K33/(K9/1000) -> 0 | ... N34: =N33/(N9/1000) -> 0 | O34: 0 | P34: =P33/(P9/1000) -> 0
A35: Algae floc | B35: 5979.95 | C35: litres
C36: litres/mg litre
A37: Sud floc | B37: 5403.75 | C37: litres | D37: 0 | E37: 0 | F37: 0 | G37: 0 | H37: 0 | I37: 0 | J37: 0 | K37: 0 | L37: 0 | M37: 0 | N37: 0 | O37: 0 | P37: =SUM(D37:O37) -> 0
C38: litres/mg litre | D38: =D37/(D9/1000) -> 0 | E38: =E37/(E9/1000) -> 0 | F38: =F37/(F9/1000) -> 0 | G38: =G37/(G9/1000) -> 0 | H38: =H37/(H9/1000) -> 0 | I38: =I37/(I9/1000) -> 0 | J38: =J37/(J9/1000) -> 0 | K38: =K37/(K9/1000) -> 0 | ... N38: =N37/(N9/1000) -> 0 | O38: 0 | P38: =P37/(P9/1000) -> 0
A39: Potasium permanganate | B39: 1950 | C39: kg | D39: 0 | E39: 0 | F39: 0 | G39: 0 | H39: 0 | I39: 0 | J39: 0 | K39: 0 | L39: 0 | M39: 0 | N39: 0 | O39: 0 | P39: =SUM(D39:O39) -> 0
C40: kg/mg litre | D40: =D39/(D9/1000) -> 0 | E40: =E39/(E9/1000) -> 0 | F40: =F39/(F9/1000) -> 0 | G40: =G39/(G9/1000) -> 0 | H40: =H39/(H9/1000) -> 0 | I40: =I39/(I9/1000) -> 0 | J40: =J39/(J9/1000) -> 0 | K40: =K39/(K9/1000) -> 0 | ... N40: =N39/(N9/1000) -> 0 | O40: 0 | P40: =P39/(P9/1000) -> 0
A41: Cost of Chemicals | C41: Mk | D41: =(D29*$B29)+(D31*$B31)+(D33*$B33)+(D35*$B35)+(D37*$B37)+(D39*$B39) -> 153350.1 | E41: =(E29*$B29)+(E31*$B31)+(E33*$B33)+(E35*$B35)+(E37*$B37)+(E39*$B39) -> 158461.77 | F41: =(F29*$B29)+(F31*$B31)+(F33*$B33)+(F35*$B35)+(F37*$B37)+(F39*$B39) -> 153350.1 | G41: =(G29*$B29)+(G31*$B31)+(G33*$B33)+(G35*$B35)+(G37*$B37)+(G39*$B39) -> 153350.1 | H41: =(H29*$B29)+(H31*$B31)+(H33*$B33)+(H35*$B35)+(H37*$B37)+(H39*$B39) -> 127791.75 | I41: =(I29*$B29)+(I31*$B31)+(I33*$B33)+(I35*$B35)+(I37*$B37)+(I39*$B39) -> 122680.08 | J41: =(J29*$B29)+(J31*$B31)+(J33*$B33)+(J35*$B35)+(J37*$B37)+(J39*$B39) -> 122680.08 | K41: =(K29*$B29)+(K31*$B31)+(K33*$B33)+(K35*$B35)+(K37*$B37)+(K39*$B39) -> 122680.08 | ... N41: =(N29*$B29)+(N31*$B31)+(N33*$B33)+(N35*$B35)+(N37*$B37)+(N39*$B39) -> 122680.08 | O41: 122680.08 | P41: =SUM(D41:O41) -> 1605064.4
A42: Cost/vol. Produced (chemicals) | C42: Mk/m3 | D42: =D41/D9 -> 17.321823 | E42: =E41/E9 -> 8.8200918 | F42: =F41/F9 -> 11.33408 | G42: =G41/G9 -> 18.374083 | H42: =H41/H9 -> 10.723483 | I42: =I41/I9 -> 11.157806 | J42: =J41/J9 -> 11.735229 | K42: =K41/K9 -> 12.237414 | ... N42: =N41/N9 -> 12.400695 | O42: 14.686948 | P42: =P41/P9 -> 12.439563
A43: Power
...

Sheet Mikolongwe
A1: SOUTHERN REGION WATER BOARD
A3: MONTHLY REPORTS - 2023/2024
A4: MULANJE ZONE
A5: MULANJE ZONE
A7: PARAMETERS | C7: UNITS | D7: APRIL | E7: MAY | F7: JUNE | G7: JULY | H7: AUGUST | I7: SEPTEMBER | J7: OCTOBER | K7: NOVEMBER | L7: DECEMBER | M7: JANUARY | N7: FEBRUARY | O7: MARCH | P7: TOTALS
A8: PRODUCTION
A9: Volume Produced | C9: m3 | D9: 312 | E9: 952 | F9: 3195 | G9: 931 | H9: 487 | I9: 603 | J9: 467 | K9: 383 | L9: 1571 | M9: 632 | N9: 292 | O9: 417 | P9: =SUM(D9:O9) -> 10242
A10: REVENUE WATER - POSTPAID
A11: Volume Billed Individuals | C11: m3 | D11: =84+32 -> 116 | E11: =193+108 -> 301 | F11: =33+78 -> 111 | G11: =29+81 -> 110 | H11: =32+80 -> 112 | I11: =30+66 -> 96 | J11: =59+68 -> 127 | K11: =23+80 -> 103 | L11: 177 | M11: 99 | N11: =29+91 -> 120 | O11: 109 | P11: =SUM(D11:O11) -> 1581
A12: Volume Billed CWPs | C12: m3 | D12: 0 | E12: 0 | F12: 0 | G12: 0 | H12: 0 | P12: =SUM(D12:O12) -> 0
A13: Volume Billed Institutions | C13: m3 | D13: 0 | F13: 0 | G13: 0 | H13: 0 | P13: =SUM(D13:O13) -> 0
A14: Volume Billed Commercial/Industrial | C14: m3 | D14: 0 | F14: 0 | G14: 0 | H14: 0 | P14: =SUM(D14:O14) -> 0
A15: Total Volume Billed Post Paid | C15: m3 | D15: =SUM(D11:D14) -> 116 | E15: =SUM(E11:E14) -> 301 | F15: =SUM(F11:F14) -> 111 | G15: =SUM(G11:G14) -> 110 | H15: =SUM(H11:H14) -> 112 | I15: =SUM(I11:I14) -> 96 | J15: =SUM(J11:J14) -> 127 | K15: =SUM(K11:K14) -> 103 | ... N15: =SUM(N11:N14) -> 120 | O15: 109 | P15: =SUM(P11:P14) -> 1581
A16: REVENUE WATER - PREPAID
A17: Individuals | C17: m3 | D17: 54 | E17: 139 | F17: 598.3 | G17: 54 | H17: 46 | I17: 57 | J17: 46 | K17: 61 | L17: 257 | M17: 55.1 | N17: =62.8+2.9 -> 65.7 | O17: 27.9 | P17: =SUM(D17:O17) -> 1461
A18: CWPs | C18: m3 | F18: 0 | G18: 0 | H18: 0 | I18: 0 | J18: 0 | K18: 0 | L18: 0 | O18: 0 | P18: =SUM(D18:O18) -> 0
A19: Institutions | C19: m3 | D19: 80 | E19: 332 | F19: 1824.6 | G19: 459 | H19: 216 | I19: 363 | J19: 162.2 | K19: 34 | L19: 869 | M19: 365.1 | O19: 188.4 | P19: =SUM(D19:O19) -> 4893.3
A20: Commercial/Industrial | C20: m3 | F20: 0 | H20: 0 | K20: 0 | O20: 0 | P20: =SUM(D20:O20) -> 0
A21: Total Volume Prepaid | C21: m3 | D21: =SUM(D17:D20) -> 134 | E21: =SUM(E17:E20) -> 471 | F21: =SUM(F17:F20) -> 2422.9 | G21: =SUM(G17:G20) -> 513 | H21: =SUM(H17:H20) -> 262 | I21: =SUM(I17:I20) -> 420 | J21: =SUM(J17:J20) -> 208.2 | K21: =SUM(K17:K20) -> 95 | ... N21: =SUM(N17:N20) -> 65.7 | O21: 216.3 | P21: =SUM(P17:P20) -> 6354.3
A22: TOTAL REVENUE WATER | C22: m3 | D22: =D21+D15 -> 250 | E22: =E21+E15 -> 772 | F22: =F21+F15 -> 2533.9 | G22: =G21+G15 -> 623 | H22: =H21+H15 -> 374 | I22: =I21+I15 -> 516 | J22: =J21+J15 -> 335.2 | K22: =K21+K15 -> 198 | ... N22: =N21+N15 -> 185.7 | O22: 325.3 | P22: =P21+P15 -> 7935.3
A24: Non-Revenue Water (NRW) | B24: Volume | C24: m3 | D24: =D9-D22 -> 62 | E24: =E9-E22 -> 180 | F24: =F9-F22 -> 661.1 | G24: =G9-G22 -> 308 | H24: =H9-H22 -> 113 | I24: =I9-I22 -> 87 | J24: =J9-J22 -> 131.8 | K24: =K9-K22 -> 185 | ... N24: =N9-N22 -> 106.3 | O24: 91.7 | P24: =P9-P22 -> 2306.7
B25: Percentage | C25: % | D25: =D24/D9 -> 0.19871795 | E25: =E24/E9 -> 0.18907563 | F25: =F24/F9 -> 0.20691706 | G25: =G24/G9 -> 0.33082707 | H25: =H24/H9 -> 0.23203285 | I25: =I24/I9 -> 0.14427861 | J25: =J24/J9 -> 0.28222698 | K25: =K24/K9 -> 0.48302872 | ... N25: =N24/N9 -> 0.3640411 | O25: 0.21990408 | P25: =P24/P9 -> 0.22521968
A26: OPERATING EXPENSES
A27: Chemicals
A28: Chemical | B28: Rate(MK/kg)
A29: Chlorine | B29: 5111.67 | C29: kg | D29: 3 | E29: 5 | F29: 4 | G29: 2 | H29: 3 | I29: 3 | J29: 4 | K29: 4 | L29: 4 | M29: 3 | N29: 1 | O29: 4 | P29: =SUM(D29:O29) -> 40
C30: kg/mg litre | D30: =D29/(D9/1000) -> 9.6153846 | E30: =E29/(E9/1000) -> 5.2521008 | F30: =F29/(F9/1000) -> 1.2519562 | G30: =G29/(G9/1000) -> 2.1482277 | H30: =H29/(H9/1000) -> 6.1601643 | I30: =I29/(I9/1000) -> 4.9751244 | J30: =J29/(J9/1000) -> 8.5653105 | K30: =K29/(K9/1000) -> 10.443864 | L30: 2.5461489 | M30: =M29/(M9/1000) -> 4.7468354 | N30: =N29/(N9/1000) -> 3.4246575 | O30: 9.5923261 | P30: =P29/(P9/1000) -> 3.9054872
A31: Aluminium sulphate | B31: 1537 | C31: kg | P31: =SUM(D31:O31) -> 0
C32: kg/mg litre | D32: =D31/(D9/1000) -> 0 | E32: =E31/(E9/1000) -> 0 | F32: =F31/(F9/1000) -> 0 | G32: =G31/(G9/1000) -> 0 | H32: =H31/(H9/1000) -> 0 | I32: =I31/(I9/1000) -> 0 | J32: =J31/(J9/1000) -> 0 | K32: =K31/(K9/1000) -> 0 | ... N32: =N31/(N9/1000) -> 0 | O32: 0 | P32: =P31/(P9/1000) -> 0
A33: Soda | B33: 1781.02 | C33: kg | P33: =SUM(D33:O33) -> 0
C34: kg/mg litre | D34: =D33/(D9/1000) -> 0 | E34: =E33/(E9/1000) -> 0 | F34: =F33/(F9/1000) -> 0 | G34: =G33/(G9/1000) -> 0 | H34: =H33/(H9/1000) -> 0 | I34: =I33/(I9/1000) -> 0 | J34: =J33/(J9/1000) -> 0 | K34: =K33/(K9/1000) -> 0 | ... N34: =N33/(N9/1000) -> 0 | O34: 0 | P34: =P33/(P9/1000) -> 0
A35: Algae floc | B35: 5979.95 | C35: litres
C36: litres/mg litre
A37: Sud floc | B37: 5403.75 | C37: litres | D37: 0 | E37: 0 | F37: 0 | G37: 0 | H37: 0 | I37: 0 | J37: 0 | K37: 0 | L37: 0 | M37: 0 | N37: 0 | O37: 0 | P37: =SUM(D37:O37) -> 0
C38: litres/mg litre | D38: =D37/(D9/1000) -> 0 | E38: =E37/(E9/1000) -> 0 | F38: =F37/(F9/1000) -> 0 | G38: =G37/(G9/1000) -> 0 | H38: =H37/(H9/1000) -> 0 | I38: =I37/(I9/1000) -> 0 | J38: =J37/(J9/1000) -> 0 | K38: =K37/(K9/1000) -> 0 | ... N38: =N37/(N9/1000) -> 0 | O38: 0 | P38: =P37/(P9/1000) -> 0
A39: Potasium permanganate | B39: 1950 | C39: kg | D39: 0 | E39: 0 | F39: 0 | G39: 0 | H39: 0 | I39: 0 | J39: 0 | K39: 0 | L39: 0 | M39: 0 | N39: 0 | O39: 0 | P39: =SUM(D39:O39) -> 0
C40: kg/mg litre | D40: =D39/(D9/1000) -> 0 | E40: =E39/(E9/1000) -> 0 | F40: =F39/(F9/1000) -> 0 | G40: =G39/(G9/1000) -> 0 | H40: =H39/(H9/1000) -> 0 | I40: =I39/(I9/1000) -> 0 | J40: =J39/(J9/1000) -> 0 | K40: =K39/(K9/1000) -> 0 | ... N40: =N39/(N9/1000) -> 0 | O40: 0 | P40: =P39/(P9/1000) -> 0
A41: Cost of Chemicals | C41: Mk | D41: =(D29*$B29)+(D31*$B31)+(D33*$B33)+(D35*$B35)+(D37*$B37)+(D39*$B39) -> 15335.01 | E41: =(E29*$B29)+(E31*$B31)+(E33*$B33)+(E35*$B35)+(E37*$B37)+(E39*$B39) -> 25558.35 | F41: =(F29*$B29)+(F31*$B31)+(F33*$B33)+(F35*$B35)+(F37*$B37)+(F39*$B39) -> 20446.68 | G41: =(G29*$B29)+(G31*$B31)+(G33*$B33)+(G35*$B35)+(G37*$B37)+(G39*$B39) -> 10223.34 | H41: =(H29*$B29)+(H31*$B31)+(H33*$B33)+(H35*$B35)+(H37*$B37)+(H39*$B39) -> 15335.01 | I41: =(I29*$B29)+(I31*$B31)+(I33*$B33)+(I35*$B35)+(I37*$B37)+(I39*$B39) -> 15335.01 | J41: =(J29*$B29)+(J31*$B31)+(J33*$B33)+(J35*$B35)+(J37*$B37)+(J39*$B39) -> 20446.68 | K41: =(K29*$B29)+(K31*$B31)+(K33*$B33)+(K35*$B35)+(K37*$B37)+(K39*$B39) -> 20446.68 | ... N41: =(N29*$B29)+(N31*$B31)+(N33*$B33)+(N35*$B35)+(N37*$B37)+(N39*$B39) -> 5111.67 | O41: 20446.68 | P41: =SUM(D41:O41) -> 204466.8
A42: Cost/vol. Produced (chemicals) | C42: Mk/m3 | D42: =D41/D9 -> 49.150673 | E42: =E41/E9 -> 26.847006 | F42: =F41/F9 -> 6.3995869 | G42: =G41/G9 -> 10.981031 | H42: =H41/H9 -> 31.488727 | I42: =I41/I9 -> 25.431194 | J42: =J41/J9 -> 43.783041 | K42: =K41/K9 -> 53.385587 | ... N42: =N41/N9 -> 17.505719 | O42: 49.032806 | P42: =P41/P9 -> 19.963562
A43: Power
...

Sheet Migowi
A1: SOUTHERN REGION WATER BOARD
A3: MONTHLY REPORTS - 2023/2024
A4: MULANJE ZONE
A5: MULANJE ZONE
A7: PARAMETERS | C7: UNITS | D7: APRIL | E7: MAY | F7: JUNE | G7: JULY | H7: AUGUST | I7: SEPTEMBER | J7: OCTOBER | K7: NOVEMBER | L7: DECEMBER | M7: JANUARY | N7: FEBRUARY | O7: MARCH | P7: TOTALS
A8: PRODUCTION
A9: Volume Produced | C9: m3 | D9: 1386 | E9: 2405 | F9: 4660 | G9: 3405 | H9: 3163 | I9: 3546 | J9: 3456 | K9: 3113 | L9: 3888 | M9: 3391 | N9: 6091 | O9: 4293 | P9: =SUM(D9:O9) -> 42797
A10: REVENUE WATER - POSTPAID
A11: Volume Billed Individuals | C11: m3 | D11: 0 | E11: 0 | F11: 0 | O11: 688.7 | P11: =SUM(D11:O11) -> 688.7
A12: Volume Billed CWPs | C12: m3 | D12: 0 | E12: 0 | F12: 0 | O12: 0 | P12: =SUM(D12:O12) -> 0
A13: Volume Billed Institutions | C13: m3 | D13: 0 | E13: 0 | F13: 0 | O13: 3258 | P13: =SUM(D13:O13) -> 3258
A14: Volume Billed Commercial/Industrial | C14: m3 | D14: 0 | E14: 0 | F14: 0 | O14: 0 | P14: =SUM(D14:O14) -> 0
A15: Total Volume Billed Post Paid | C15: m3 | D15: =SUM(D11:D14) -> 0 | E15: =SUM(E11:E14) -> 0 | F15: =SUM(F11:F14) -> 0 | G15: =SUM(G11:G14) -> 0 | H15: =SUM(H11:H14) -> 0 | I15: =SUM(I11:I14) -> 0 | J15: =SUM(J11:J14) -> 0 | K15: =SUM(K11:K14) -> 0 | ... N15: =SUM(N11:N14) -> 0 | O15: 3946.7 | P15: =SUM(P11:P14) -> 3946.7
A16: REVENUE WATER - PREPAID
A17: Individuals | C17: m3 | D17: 931 | E17: 734 | F17: 865.6 | G17: =966.5+0.1 -> 966.6 | H17: 883 | I17: 920 | J17: 758.3 | K17: =7+907 -> 914 | L17: 769 | M17: 848 | N17: 830 | P17: =SUM(D17:O17) -> 9419.5
A18: CWPs | C18: m3 | D18: 0 | E18: 0 | F18: 0 | G18: 0 | I18: 0 | J18: 0 | K18: 0 | L18: 0 | P18: =SUM(D18:O18) -> 0
A19: Institutions | C19: m3 | D19: 100 | E19: 1086 | F19: 2804 | G19: 1847 | H19: 1788 | I19: =2171+14 -> 2185 | J19: 2172 | K19: =109+1281 -> 1390 | L19: 2548 | M19: 2172 | N19: 4357 | P19: =SUM(D19:O19) -> 22449
A20: Commercial/Industrial | C20: m3 | D20: 0 | E20: 0 | F20: 0 | G20: 0 | P20: =SUM(D20:O20) -> 0
A21: Total Volume Prepaid | C21: m3 | D21: =SUM(D17:D20) -> 1031 | E21: =SUM(E17:E20) -> 1820 | F21: =SUM(F17:F20) -> 3669.6 | G21: =SUM(G17:G20) -> 2813.6 | H21: =SUM(H17:H20) -> 2671 | I21: =SUM(I17:I20) -> 3105 | J21: =SUM(J17:J20) -> 2930.3 | K21: =SUM(K17:K20) -> 2304 | ... N21: =SUM(N17:N20) -> 5187 | O21: 0 | P21: =SUM(P17:P20) -> 31868.5
A22: TOTAL REVENUE WATER | C22: m3 | D22: =D21+D15 -> 1031 | E22: =E21+E15 -> 1820 | F22: =F21+F15 -> 3669.6 | G22: =G21+G15 -> 2813.6 | H22: =H21+H15 -> 2671 | I22: =I21+I15 -> 3105 | J22: =J21+J15 -> 2930.3 | K22: =K21+K15 -> 2304 | ... N22: =N21+N15 -> 5187 | O22: 3946.7 | P22: =P21+P15 -> 35815.2
A24: Non-Revenue Water (NRW) | B24: Volume | C24: m3 | D24: =D9-D22 -> 355 | E24: =E9-E22 -> 585 | F24: =F9-F22 -> 990.4 | G24: =G9-G22 -> 591.4 | H24: =H9-H22 -> 492 | I24: =I9-I22 -> 441 | J24: =J9-J22 -> 525.7 | K24: =K9-K22 -> 809 | ... N24: =N9-N22 -> 904 | O24: 346.3 | P24: =P9-P22 -> 6981.8
B25: Percentage | C25: % | D25: =D24/D9 -> 0.25613276 | E25: =E24/E9 -> 0.24324324 | F25: =F24/F9 -> 0.21253219 | G25: =G24/G9 -> 0.17368576 | H25: =H24/H9 -> 0.15554853 | I25: =I24/I9 -> 0.12436548 | J25: =J24/J9 -> 0.15211227 | K25: =K24/K9 -> 0.25987793 | ... N25: =N24/N9 -> 0.1484157 | O25: 0.080666201 | P25: =P24/P9 -> 0.1631376
A26: OPERATING EXPENSES
A27: Chemicals
A28: Chemical | B28: Rate(MK/kg)
A29: Chlorine | B29: 5111.67 | C29: kg | D29: 5 | E29: 8 | F29: 8 | G29: 7 | H29: 4 | I29: 1 | J29: 1 | K29: 1 | L29: 1 | M29: 2 | N29: 3 | O29: 1 | P29: =SUM(D29:O29) -> 42
C30: kg/mg litre | D30: =D29/(D9/1000) -> 3.6075036 | E30: =E29/(E9/1000) -> 3.3264033 | F30: =F29/(F9/1000) -> 1.7167382 | G30: =G29/(G9/1000) -> 2.0558003 | H30: =H29/(Migowi!H9/1000) -> 1.2646222 | I30: =I29/(I9/1000) -> 0.2820079 | J30: =J29/(J9/1000) -> 0.28935185 | K30: =K29/(K9/1000) -> 0.32123354 | L30: 0.25720165 | M30: =M29/(M9/1000) -> 0.58979652 | N30: =N29/(N9/1000) -> 0.49252996 | O30: 0.23293734 | P30: =P29/(P9/1000) -> 0.9813772
A31: Aluminium sulphate | B31: 1537 | C31: kg | P31: =SUM(D31:O31) -> 0
C32: kg/mg litre | D32: =D31/(D9/1000) -> 0 | E32: =E31/(E9/1000) -> 0 | F32: =F31/(F9/1000) -> 0 | G32: =G31/(G9/1000) -> 0 | H32: 0 | I32: =I31/(I9/1000) -> 0 | J32: =J31/(J9/1000) -> 0 | K32: =K31/(K9/1000) -> 0 | L32: =L31/(L9/1000) -> 0 | M32: =M31/(M9/1000) -> 0 | N32: =N31/(N9/1000) -> 0 | O32: 0 | P32: =P31/(P9/1000) -> 0
A33: Soda | B33: 1781.02 | C33: kg | P33: =SUM(D33:O33) -> 0
C34: kg/mg litre | D34: =D33/(D9/1000) -> 0 | E34: =E33/(E9/1000) -> 0 | F34: =F33/(F9/1000) -> 0 | G34: =G33/(G9/1000) -> 0 | H34: 0 | I34: =I33/(I9/1000) -> 0 | J34: =J33/(J9/1000) -> 0 | K34: =K33/(K9/1000) -> 0 | L34: =L33/(L9/1000) -> 0 | M34: =M33/(M9/1000) -> 0 | N34: =N33/(N9/1000) -> 0 | O34: 0 | P34: =P33/(P9/1000) -> 0
A35: Algae floc | B35: 5979.95 | C35: litres
C36: litres/mg litre
A37: Sud floc | B37: 5403.75 | C37: litres | D37: 0 | E37: 0 | F37: 0 | G37: 0 | H37: 0 | I37: 0 | J37: 0 | K37: 0 | L37: 0 | M37: 0 | N37: 0 | O37: 0 | P37: =SUM(D37:O37) -> 0
C38: litres/mg litre | D38: =D37/(D9/1000) -> 0 | E38: =E37/(E9/1000) -> 0 | F38: =F37/(F9/1000) -> 0 | G38: =G37/(G9/1000) -> 0 | H38: =H37/(H9/1000) -> 0 | I38: =I37/(I9/1000) -> 0 | J38: =J37/(J9/1000) -> 0 | K38: =K37/(K9/1000) -> 0 | ... N38: =N37/(N9/1000) -> 0 | O38: 0 | P38: =P37/(P9/1000) -> 0
A39: Potasium permanganate | B39: 1950 | C39: kg | D39: 0 | E39: 0 | F39: 0 | G39: 0 | H39: 0 | I39: 0 | J39: 0 | K39: 0 | L39: 0 | M39: 0 | N39: 0 | O39: 0 | P39: =SUM(D39:O39) -> 0
C40: kg/mg litre | D40: =D39/(D9/1000) -> 0 | E40: =E39/(E9/1000) -> 0 | F40: =F39/(F9/1000) -> 0 | G40: =G39/(G9/1000) -> 0 | H40: =H39/(H9/1000) -> 0 | I40: =I39/(I9/1000) -> 0 | J40: =J39/(J9/1000) -> 0 | K40: =K39/(K9/1000) -> 0 | ... N40: =N39/(N9/1000) -> 0 | O40: 0 | P40: =P39/(P9/1000) -> 0
