Workbook

Sheet Bangula
A1: SOUTHERN REGION WATER BOARD
A3: MONTHLY REPORTS - 2023/2024
A4: NGABU ZONE
A5: NGABU ZONE
A7: PARAMETERS | C7: UNITS | D7: APRIL | E7: MAY | F7: JUNE | G7: JULY | H7: AUGUST | I7: SEPTEMBER | J7: OCTOBER | K7: NOVEMBER | L7: DECEMBER | M7: JANUARY | N7: FEBRUARY | O7: MARCH | P7: TOTALS
A8: PRODUCTION
A9: Volume Produced | C9: m3 | D9: 11837 | E9: 11868 | F9: 11498 | G9: 11420 | H9: 11560 | I9: 11251 | J9: 11739 | K9: 11906 | L9: 10701 | M9: 8807 | N9: 8766 | O9: 7883 | P9: =SUM(D9:O9) -> 129236
A10: REVENUE WATER - POSTPAID
A11: Volume Billed Individuals | C11: m3 | D11: 5274 | E11: =27+661+4051 -> 4739 | F11: =33+705+3999 -> 4737 | G11: =41+697+3719 -> 4457 | H11: =28+839+3952 -> 4819 | I11: =31+821+4291 -> 5143 | J11: =37+825+4739 -> 5601 | K11: =42+830+4718 -> 5590 | L11: 5132 | M11: 4517 | N11: 4557 | O11: 3742 | P11: =SUM(D11:O11) -> 58308
A12: Volume Billed CWPs | C12: m3 | D12: 2253 | E12: 1750 | F12: 1597 | G12: 1696 | H12: 1782 | I12: 1175 | J12: 1291 | K12: 1319 | L12: 1208 | M12: 1029 | N12: 1005 | O12: 930 | P12: =SUM(D12:O12) -> 17035
A13: Volume Billed Institutions | C13: m3 | D13: 67 | E13: 55 | F13: 58 | G13: 67 | H13: 53 | I13: 55 | J13: 33 | K13: 61 | L13: 177 | M13: 56 | N13: 39 | O13: 33 | P13: =SUM(D13:O13) -> 754
A14: Volume Billed Commercial/Industrial | C14: m3 | D14: 5 | E14: 7 | F14: 13 | G14: 1 | I14: 26 | P14: =SUM(D14:O14) -> 52
A15: Total Volume Billed Post Paid | C15: m3 | D15: =SUM(D11:D14) -> 7599 | E15: =SUM(E11:E14) -> 6551 | F15: =SUM(F11:F14) -> 6405 | G15: =SUM(G11:G14) -> 6221 | H15: =SUM(H11:H14) -> 6654 | I15: =SUM(I11:I14) -> 6399 | J15: =SUM(J11:J14) -> 6925 | K15: =SUM(K11:K14) -> 6970 | ... N15: =SUM(N11:N14) -> 5601 | O15: 4705 | P15: =SUM(P11:P14) -> 76149
A16: REVENUE WATER - PREPAID
A17: Individuals | C17: m3 | D17: 0 | F17: 1796 | G17: 1646 | I17: 1604 | J17: 1034 | K17: 1436 | L17: 1556 | M17: 1711 | N17: 1465 | O17: 1044 | P17: =SUM(D17:O17) -> 13292
A18: CWPs | C18: m3 | D18: 0 | I18: 57 | K18: 1 | L18: 1 | P18: =SUM(D18:O18) -> 59
A19: Institutions | C19: m3 | D19: 2139 | E19: 3686.9 | F19: 583 | G19: 981 | H19: 3018.5 | I19: 309 | J19: 583 | K19: 614 | L19: 463 | M19: 165 | N19: 389 | O19: 180 | P19: =SUM(D19:O19) -> 13111.4
A20: Commercial/Industrial | C20: m3 | D20: 0 | F20: 264 | G20: 392 | I20: 286 | J20: 416 | K20: 387 | L20: 327 | M20: 187 | N20: 192 | O20: 217 | P20: =SUM(D20:O20) -> 2668
A21: Total Volume Prepaid | C21: m3 | D21: =SUM(D17:D20) -> 2139 | E21: =SUM(E17:E20) -> 3686.9 | F21: =SUM(F17:F20) -> 2643 | G21: =SUM(G17:G20) -> 3019 | H21: =SUM(H17:H20) -> 3018.5 | I21: =SUM(I17:I20) -> 2256 | J21: =SUM(J17:J20) -> 2033 | K21: =SUM(K17:K20) -> 2438 | ... N21: =SUM(N17:N20) -> 2046 | O21: 1441 | P21: =SUM(P17:P20) -> 29130.4
A22: TOTAL REVENUE WATER | C22: m3 | D22: =D21+D15 -> 9738 | E22: =E21+E15 -> 10237.9 | F22: =F21+F15 -> 9048 | G22: =G21+G15 -> 9240 | H22: =H21+H15 -> 9672.5 | I22: =I21+I15 -> 8655 | J22: =J21+J15 -> 8958 | K22: =K21+K15 -> 9408 | ... N22: =N21+N15 -> 7647 | O22: 6146 | P22: =P21+P15 -> 105279.4
A24: Non-Revenue Water (NRW) | B24: Volume | C24: m3 | D24: =D9-D22 -> 2099 | E24: =E9-E22 -> 1630.1 | F24: =F9-F22 -> 2450 | G24: =G9-G22 -> 2180 | H24: =H9-H22 -> 1887.5 | I24: =I9-I22 -> 2596 | J24: =J9-J22 -> 2781 | K24: =K9-K22 -> 2498 | ... N24: =N9-N22 -> 1119 | O24: 1737 | P24: =P9-P22 -> 23956.6
B25: Percentage | C25: % | D25: =D24/D9 -> 0.17732534 | E25: =E24/E9 -> 0.13735254 | F25: =F24/F9 -> 0.21308054 | G25: =G24/G9 -> 0.19089317 | H25: =H24/H9 -> 0.16327855 | I25: =I24/I9 -> 0.23073505 | J25: =J24/J9 -> 0.23690263 | K25: =K24/K9 -> 0.20981018 | ... N25: =N24/N9 -> 0.12765229 | O25: 0.22034758 | P25: =P24/P9 -> 0.18537095
A26: OPERATING EXPENSES
A27: Chemicals
A28: Chemical | B28: Rate(MK/kg)
A29: Chlorine | B29: 3525.29 | C29: kg | D29: 14 | E29: 12 | F29: 14 | G29: 14 | H29: 16 | I29: 18 | J29: 18 | K29: 16 | L29: 16 | M29: 16 | N29: 12 | O29: 12 | P29: =SUM(D29:O29) -> 178
C30: kg/mg litre | D30: =D29/(D9/1000) -> 1.1827321 | E30: =E29/(E9/1000) -> 1.0111223 | F30: =F29/(F9/1000) -> 1.2176031 | G30: =G29/(G9/1000) -> 1.2259194 | H30: =H29/(H9/1000) -> 1.384083 | I30: =I29/(I9/1000) -> 1.5998578 | J30: =J29/(J9/1000) -> 1.5333504 | K30: =K29/(K9/1000) -> 1.3438602 | L30: 1.4951874 | M30: 1.8167367 | N30: =N29/(N9/1000) -> 1.3689254 | O30: 1.5222631 | P30: =P29/(P9/1000) -> 1.3773252
A31: Aluminium sulphate | C31: kg | P31: =SUM(D31:O31) -> 0
B32: 1060.01 | C32: kg/mg litre | D32: =D31/(D9/1000) -> 0 | E32: =E31/(E9/1000) -> 0 | F32: =F31/(F9/1000) -> 0 | G32: =G31/(G9/1000) -> 0 | H32: =H31/(H9/1000) -> 0 | I32: =I31/(I9/1000) -> 0 | J32: =J31/(J9/1000) -> 0 | K32: =K31/(K9/1000) -> 0 | ... N32: =N31/(N9/1000) -> 0 | O32: 0 | P32: =P31/(P9/1000) -> 0
A33: Soda | C33: kg | P33: =SUM(D33:O33) -> 0
B34: 1228.29 | C34: kg/mg litre | D34: =D33/(D9/1000) -> 0 | E34: =E33/(E9/1000) -> 0 | F34: =F33/(F9/1000) -> 0 | G34: =G33/(G9/1000) -> 0 | H34: =H33/(H9/1000) -> 0 | I34: =I33/(I9/1000) -> 0 | J34: =J33/(J9/1000) -> 0 | K34: =K33/(K9/1000) -> 0 | ... N34: =N33/(N9/1000) -> 0 | O34: 0 | P34: =P33/(P9/1000) -> 0
A35: Algae floc | C35: litres
B36: 3726.73 | C36: litres/mg litre | E36: =E35/(E11/1000) -> 0
A37: Sud floc | C37: litres | G37: 0 | H37: 0 | I37: 0 | J37: 0 | K37: 0 | L37: 0 | M37: 0 | N37: 0 | O37: 0 | P37: =SUM(D37:O37) -> 0
B38: 3951.59 | C38: litres/mg litre | D38: =D37/(D13/1000) -> 0 | E38: =E37/(E13/1000) -> 0 | F38: =F37/(F13/1000) -> 0 | G38: =G37/(G9/1000) -> 0 | H38: =H37/(H9/1000) -> 0 | I38: =I37/(I9/1000) -> 0 | J38: =J37/(J9/1000) -> 0 | K38: =K37/(K9/1000) -> 0 | L38: =L37/(L9/1000) -> 0 | M38: =M37/(M9/1000) -> 0 | N38: =N37/(N9/1000) -> 0 | O38: 0 | P38: =P37/(P9/1000) -> 0
A39: Potasium permanganate | C39: kg | G39: 0 | H39: 0 | I39: 0 | J39: 0 | K39: 0 | L39: 0 | M39: 0 | N39: 0 | O39: 0 | P39: =SUM(D39:O39) -> 0
B40: 1950 | C40: kg/mg litre | D40: =D39/(D15/1000) -> 0 | E40: =E39/(E15/1000) -> 0 | F40: =F39/(F15/1000) -> 0 | G40: =G39/(G9/1000) -> 0 | H40: =H39/(H9/1000) -> 0 | I40: =I39/(I9/1000) -> 0 | J40: =J39/(J9/1000) -> 0 | K40: =K39/(K9/1000) -> 0 | L40: =L39/(L9/1000) -> 0 | M40: =M39/(M9/1000) -> 0 | N40: =N39/(N9/1000) -> 0 | O40: 0 | P40: =P39/(P9/1000) -> 0
A41: Cost of Chemicals | C41: Mk | D41: =(D29*$B29)+(D31*$B31)+(D33*$B33)+(D35*$B35)+(D37*$B37)+(D39*$B39) -> 49354.06 | E41: =(E29*$B29)+(E31*$B31)+(E33*$B33)+(E35*$B35)+(E37*$B37)+(E39*$B39) -> 42303.48 | F41: =(F29*$B29)+(F31*$B31)+(F33*$B33)+(F35*$B35)+(F37*$B37)+(F39*$B39) -> 49354.06 | G41: =(G29*$B29)+(G31*$B31)+(G33*$B33)+(G35*$B35)+(G37*$B37)+(G39*$B39) -> 49354.06 | H41: =(H29*$B29)+(H31*$B31)+(H33*$B33)+(H35*$B35)+(H37*$B37)+(H39*$B39) -> 56404.64 | I41: =(I29*$B29)+(I31*$B31)+(I33*$B33)+(I35*$B35)+(I37*$B37)+(I39*$B39) -> 63455.22 | J41: =(J29*$B29)+(J31*$B31)+(J33*$B33)+(J35*$B35)+(J37*$B37)+(J39*$B39) -> 63455.22 | K41: =(K29*$B29)+(K31*$B31)+(K33*$B33)+(K35*$B35)+(K37*$B37)+(K39*$B39) -> 56404.64 | ... N41: =(N29*$B29)+(N31*$B31)+(N33*$B33)+(N35*$B35)+(N37*$B37)+(N39*$B39) -> 42303.48 | O41: 42303.48 | P41: =SUM(D41:O41) -> 627501.62
A42: Cost/vol. Produced (chemicals) | C42: Mk/m3 | D42: =D41/D9 -> 4.1694737 | E42: =E41/E9 -> 3.5644995 | F42: =F41/F9 -> 4.2924039 | G42: =G41/G9 -> 4.3217215 | H42: =H41/H9 -> 4.8792941 | I42: =I41/I9 -> 5.6399627 | J42: =J41/J9 -> 5.4055047 | K42: =K41/K9 -> 4.7374971 | ... N42: =N41/N9 -> 4.825859 | O42: 5.3664189 | P42: =P41/P9 -> 4.8554708
A43: Power
...

Sheet Chikwawa
A1: SOUTHERN REGION WATER BOARD
A3: MONTHLY REPORTS - 2023/2024
A4: NGABU ZONE
A5: NGABU ZONE
A7: PARAMETERS | C7: UNITS | D7: APRIL | E7: MAY | F7: JUNE | G7: JULY | H7: AUGUST | I7: SEPTEMBER | J7: OCTOBER | K7: NOVEMBER | L7: DECEMBER | M7: JANUARY | N7: FEBRUARY | O7: MARCH | P7: TOTALS
A8: PRODUCTION
A9: Volume Produced | C9: m3 | D9: 28533 | E9: 29250 | F9: 28920 | G9: 28655 | H9: 28342 | I9: 28121 | J9: 27479 | K9: 27655 | L9: 28062 | M9: 27553 | N9: 28105 | O9: 27956 | P9: =SUM(D9:O9) -> 338631
A10: REVENUE WATER - POSTPAID
A11: Volume Billed Individuals | C11: m3 | D11: =2404+712+11700 -> 14816 | E11: =2270+680+12732 -> 15682 | F11: =2946+1017+15859 -> 19822 | G11: =2216+667+12448 -> 15331 | H11: =2254+631+12248 -> 15133 | I11: =2337+674+13201 -> 16212 | J11: =2520+806+14549 -> 17875 | K11: =2416+649+15198 -> 18263 | L11: 16641 | M11: =2214+712+13991 -> 16917 | N11: 17751 | O11: 17601 | P11: =SUM(D11:O11) -> 202044
A12: Volume Billed CWPs | C12: m3 | D12: 886 | E12: 858 | F12: 1034 | G12: 719 | H12: 864 | I12: 763 | J12: 803 | K12: 756 | L12: 692 | M12: 565 | N12: 786 | O12: 882 | P12: =SUM(D12:O12) -> 9608
A13: Volume Billed Institutions | C13: m3 | D13: 248 | E13: 282 | F13: 318 | G13: 281 | H13: 238 | I13: 217 | J13: 592 | K13: 632 | L13: 229 | M13: 206 | N13: 259 | O13: 271 | P13: =SUM(D13:O13) -> 3773
A14: Volume Billed Commercial/Industrial | C14: m3 | D14: 59 | E14: 63 | F14: 125 | G14: 78 | H14: 92 | I14: 88 | J14: 167 | K14: 210 | L14: 108 | M14: 107 | N14: 118 | O14: 84 | P14: =SUM(D14:O14) -> 1299
A15: Total Volume Billed Post Paid | C15: m3 | D15: =SUM(D11:D14) -> 16009 | E15: =SUM(E11:E14) -> 16885 | F15: =SUM(F11:F14) -> 21299 | G15: =SUM(G11:G14) -> 16409 | H15: =SUM(H11:H14) -> 16327 | I15: =SUM(I11:I14) -> 17280 | J15: =SUM(J11:J14) -> 19437 | K15: =SUM(K11:K14) -> 19861 | ... N15: =SUM(N11:N14) -> 18914 | O15: 18838 | P15: =SUM(P11:P14) -> 216724
A16: REVENUE WATER - PREPAID
A17: Individuals | C17: m3 | F17: 2252 | G17: 2215 | I17: 1757 | J17: 1692 | K17: 1493 | L17: 2119 | M17: 1560 | N17: 1142 | O17: 1001 | P17: =SUM(D17:O17) -> 15231
A18: CWPs | C18: m3 | P18: =SUM(D18:O18) -> 0
A19: Institutions | C19: m3 | D19: 6680 | E19: 7519 | F19: 2820 | G19: 2790 | H19: 6251 | I19: 2340 | J19: 2159 | K19: 220 | L19: 2321 | M19: 2401 | N19: 2466 | O19: 2285 | P19: =SUM(D19:O19) -> 40252
A20: Commercial/Industrial | C20: m3 | F20: 943 | G20: 950 | I20: 758 | J20: 697 | K20: 709 | L20: 811 | M20: 703 | N20: 755 | O20: 669 | P20: =SUM(D20:O20) -> 6995
A21: Total Volume Prepaid | C21: m3 | D21: =SUM(D17:D20) -> 6680 | E21: =SUM(E17:E20) -> 7519 | F21: =SUM(F17:F20) -> 6015 | G21: =SUM(G17:G20) -> 5955 | H21: =SUM(H17:H20) -> 6251 | I21: =SUM(I17:I20) -> 4855 | J21: =SUM(J17:J20) -> 4548 | K21: =SUM(K17:K20) -> 2422 | ... N21: =SUM(N17:N20) -> 4363 | O21: 3955 | P21: =SUM(P17:P20) -> 62478
A22: TOTAL REVENUE WATER | C22: m3 | D22: =D21+D15 -> 22689 | E22: =E21+E15 -> 24404 | F22: =F21+F15 -> 27314 | G22: =G21+G15 -> 22364 | H22: =H21+H15 -> 22578 | I22: =I21+I15 -> 22135 | J22: =J21+J15 -> 23985 | K22: =K21+K15 -> 22283 | ... N22: =N21+N15 -> 23277 | O22: 22793 | P22: =P21+P15 -> 279202
A24: Non-Revenue Water (NRW) | B24: Volume | C24: m3 | D24: =D9-D22 -> 5844 | E24: =E9-E22 -> 4846 | F24: =F9-F22 -> 1606 | G24: =G9-G22 -> 6291 | H24: =H9-H22 -> 5764 | I24: =I9-I22 -> 5986 | J24: =J9-J22 -> 3494 | K24: =K9-K22 -> 5372 | ... N24: =N9-N22 -> 4828 | O24: 5163 | P24: =P9-P22 -> 59429
B25: Percentage | C25: % | D25: =D24/D9 -> 0.20481548 | E25: =E24/E9 -> 0.16567521 | F25: =F24/F9 -> 0.055532503 | G25: =G24/G9 -> 0.21954284 | H25: =H24/H9 -> 0.20337309 | I25: =I24/I9 -> 0.21286583 | J25: =J24/J9 -> 0.12715164 | K25: =K24/K9 -> 0.19425059 | ... N25: =N24/N9 -> 0.17178438 | O25: 0.18468307 | P25: =P24/P9 -> 0.17549781
A26: OPERATING EXPENSES
A27: Chemicals
A28: Chemical | B28: Rate(MK/kg)
A29: Chlorine | B29: 3525.29 | C29: kg | D29: 30 | E29: 30 | F29: 30 | G29: 31 | H29: 31 | I29: 30 | J29: 31 | K29: 30 | L29: 31 | M29: 31 | N29: 29 | O29: 30 | P29: =SUM(D29:O29) -> 364
C30: kg/mg litre | D30: =D29/(D9/1000) -> 1.0514142 | E30: =E29/(E9/1000) -> 1.025641 | F30: =F29/(F9/1000) -> 1.0373444 | G30: =G29/(G9/1000) -> 1.0818356 | H30: =H29/(H9/1000) -> 1.0937831 | I30: =I29/(I9/1000) -> 1.0668184 | J30: =J29/(J9/1000) -> 1.1281342 | K30: =K29/(K9/1000) -> 1.0847948 | L30: 1.1046967 | M30: =M29/(M9/1000) -> 1.1251043 | N30: =N29/(N9/1000) -> 1.0318449 | O30: 1.0731149 | P30: =P29/(P9/1000) -> 1.0749164
A31: Aluminium sulphate | C31: kg | P31: =SUM(D31:O31) -> 0
B32: 1060.01 | C32: kg/mg litre | D32: =D31/(D9/1000) -> 0 | E32: =E31/(E9/1000) -> 0 | F32: =F31/(F9/1000) -> 0 | G32: =G31/(G9/1000) -> 0 | H32: =H31/(H9/1000) -> 0 | I32: =I31/(I9/1000) -> 0 | J32: =J31/(J9/1000) -> 0 | K32: =K31/(K9/1000) -> 0 | ... N32: =N31/(N9/1000) -> 0 | O32: 0 | P32: =P31/(P9/1000) -> 0
A33: Soda | C33: kg | P33: =SUM(D33:O33) -> 0
B34: 1228.29 | C34: kg/mg litre | D34: =D33/(D9/1000) -> 0 | E34: =E33/(E9/1000) -> 0 | F34: =F33/(F9/1000) -> 0 | G34: =G33/(G9/1000) -> 0 | H34: =H33/(H9/1000) -> 0 | I34: =I33/(I9/1000) -> 0 | J34: =J33/(J9/1000) -> 0 | K34: =K33/(K9/1000) -> 0 | ... N34: =N33/(N9/1000) -> 0 | O34: 0 | P34: =P33/(P9/1000) -> 0
A35: Algae floc | C35: litres
B36: 3726.73 | C36: litres/mg litre | D36: =D35/(D11/1000) -> 0 | F36: =F35/(F11/1000) -> 0
A37: Sud floc | C37: litres | H37: 0 | I37: 0 | J37: 0 | K37: 0 | L37: 0 | M37: 0 | N37: 0 | O37: 0 | P37: =SUM(D37:O37) -> 0
B38: 3951.59 | C38: litres/mg litre | D38: =D37/(D13/1000) -> 0 | E38: =E37/(E13/1000) -> 0 | F38: =F37/(F13/1000) -> 0 | G38: =G37/(G13/1000) -> 0 | H38: =H37/(H9/1000) -> 0 | I38: =I37/(I9/1000) -> 0 | J38: =J37/(J9/1000) -> 0 | K38: =K37/(K9/1000) -> 0 | L38: =L37/(L9/1000) -> 0 | M38: =M37/(M9/1000) -> 0 | N38: =N37/(N9/1000) -> 0 | O38: 0 | P38: =P37/(P9/1000) -> 0
A39: Potasium permanganate | C39: kg | H39: 0 | I39: 0 | J39: 0 | K39: 0 | L39: 0 | M39: 0 | N39: 0 | O39: 0 | P39: =SUM(D39:O39) -> 0
B40: 1950 | C40: kg/mg litre | D40: =D39/(D15/1000) -> 0 | E40: =E39/(E15/1000) -> 0 | F40: =F39/(F15/1000) -> 0 | G40: =G39/(G15/1000) -> 0 | H40: =H39/(H9/1000) -> 0 | I40: =I39/(I9/1000) -> 0 | J40: =J39/(J9/1000) -> 0 | K40: =K39/(K9/1000) -> 0 | L40: =L39/(L9/1000) -> 0 | M40: =M39/(M9/1000) -> 0 | N40: =N39/(N9/1000) -> 0 | O40: 0 | P40: =P39/(P9/1000) -> 0
A41: Cost of Chemicals | C41: Mk | D41: =(D29*$B29)+(D31*$B31)+(D33*$B33)+(D35*$B35)+(D37*$B37)+(D39*$B39) -> 105758.7 | E41: =(E29*$B29)+(E31*$B31)+(E33*$B33)+(E35*$B35)+(E37*$B37)+(E39*$B39) -> 105758.7 | F41: =(F29*$B29)+(F31*$B31)+(F33*$B33)+(F35*$B35)+(F37*$B37)+(F39*$B39) -> 105758.7 | G41: =(G29*$B29)+(G31*$B31)+(G33*$B33)+(G35*$B35)+(G37*$B37)+(G39*$B39) -> 109283.99 | H41: =(H29*$B29)+(H31*$B31)+(H33*$B33)+(H35*$B35)+(H37*$B37)+(H39*$B39) -> 109283.99 | I41: =(I29*$B29)+(I31*$B31)+(I33*$B33)+(I35*$B35)+(I37*$B37)+(I39*$B39) -> 105758.7 | J41: =(J29*$B29)+(J31*$B31)+(J33*$B33)+(J35*$B35)+(J37*$B37)+(J39*$B39) -> 109283.99 | K41: =(K29*$B29)+(K31*$B31)+(K33*$B33)+(K35*$B35)+(K37*$B37)+(K39*$B39) -> 105758.7 | ... N41: =(N29*$B29)+(N31*$B31)+(N33*$B33)+(N35*$B35)+(N37*$B37)+(N39*$B39) -> 102233.41 | O41: 105758.7 | P41: =SUM(D41:O41) -> 1283205.6
A42: Cost/vol. Produced (chemicals) | C42: Mk/m3 | D42: =D41/D9 -> 3.7065398 | E42: =E41/E9 -> 3.6156821 | F42: =F41/F9 -> 3.6569398 | G42: =G41/G9 -> 3.8137843 | H42: =H41/H9 -> 3.8559025 | I42: =I41/I9 -> 3.7608442 | J42: =J41/J9 -> 3.9770003 | K42: =K41/K9 -> 3.8242162 | ... N42: =N41/N9 -> 3.6375524 | O42: 3.7830412 | P42: =P41/P9 -> 3.7893919
A43: Power
...

Sheet Nchalo
A1: SOUTHERN REGION WATER BOARD
A3: MONTHLY REPORTS - 2023/2024
A4: NGABU ZONE
A5: NGABU ZONE
A7: PARAMETERS | C7: UNITS | D7: APRIL | E7: MAY | F7: JUNE | G7: JULY | H7: AUGUST | I7: SEPTEMBER | J7: OCTOBER | K7: NOVEMBER | L7: DECEMBER | M7: JANUARY | N7: FEBRUARY | O7: MARCH | P7: TOTALS
A8: PRODUCTION
A9: Volume Produced | C9: m3 | D9: 20645 | E9: 26000 | F9: 25006 | G9: 25832 | H9: 25158 | I9: 23447 | J9: 23417 | K9: 21185 | L9: 21185 | M9: 22587 | N9: 21686 | O9: 21393 | P9: =SUM(D9:O9) -> 277541
A10: REVENUE WATER - POSTPAID
A11: Volume Billed Individuals | C11: m3 | D11: =67+445+10456 -> 10968 | E11: =81+359+13256 -> 13696 | F11: =91+423+13471 -> 13985 | G11: =82+379+12695 -> 13156 | H11: =96+547+13603 -> 14246 | I11: =105+413+13937 -> 14455 | J11: 15986 | K11: =103+307+14615 -> 15025 | L11: 13022 | M11: 13549 | N11: =75+313+14476 -> 14864 | O11: 13763 | P11: =SUM(D11:O11) -> 166715
A12: Volume Billed CWPs | C12: m3 | D12: 655 | E12: 631 | F12: 754 | G12: 654 | H12: 762 | I12: 859 | J12: 637 | K12: 859 | L12: 750 | M12: 836 | N12: 772 | O12: 712 | P12: =SUM(D12:O12) -> 8881
A13: Volume Billed Institutions | C13: m3 | D13: 31 | E13: 24 | F13: 40 | G13: 113 | H13: 130 | I13: 124 | J13: 177 | K13: 75 | L13: 48 | M13: 38 | N13: 64 | O13: 84 | P13: =SUM(D13:O13) -> 948
A14: Volume Billed Commercial/Industrial | C14: m3 | D14: 225 | E14: 213 | F14: 212 | G14: 392 | H14: 194 | I14: 108 | J14: 602 | K14: 85 | L14: 71 | M14: 84 | N14: 108 | O14: 145 | P14: =SUM(D14:O14) -> 2439
A15: Total Volume Billed Post Paid | C15: m3 | D15: =SUM(D11:D14) -> 11879 | E15: =SUM(E11:E14) -> 14564 | F15: =SUM(F11:F14) -> 14991 | G15: =SUM(G11:G14) -> 14315 | H15: =SUM(H11:H14) -> 15332 | I15: =SUM(I11:I14) -> 15546 | J15: =SUM(J11:J14) -> 17402 | K15: =SUM(K11:K14) -> 16044 | ... N15: =SUM(N11:N14) -> 15808 | O15: 14704 | P15: =SUM(P11:P14) -> 178983
A16: REVENUE WATER - PREPAID
A17: Individuals | C17: m3 | P17: =SUM(D17:O17) -> 0
A18: CWPs | C18: m3 | P18: =SUM(D18:O18) -> 0
A19: Institutions | C19: m3 | D19: 2896 | E19: 2624.8 | F19: 2399 | G19: 2220.8 | H19: 3493.4 | I19: 2577.1 | K19: 2572.3 | L19: 2833.8 | M19: 2421.6 | N19: 3557.9 | O19: 2069.4 | P19: =SUM(D19:O19) -> 29666.1
A20: Commercial/Industrial | C20: m3 | P20: =SUM(D20:O20) -> 0
A21: Total Volume Prepaid | C21: m3 | D21: =SUM(D17:D20) -> 2896 | E21: =SUM(E17:E20) -> 2624.8 | F21: =SUM(F17:F20) -> 2399 | G21: =SUM(G17:G20) -> 2220.8 | H21: =SUM(H17:H20) -> 3493.4 | I21: =SUM(I17:I20) -> 2577.1 | J21: =SUM(J17:J20) -> 0 | K21: =SUM(K17:K20) -> 2572.3 | ... N21: =SUM(N17:N20) -> 3557.9 | O21: 2069.4 | P21: =SUM(P17:P20) -> 29666.1
A22: TOTAL REVENUE WATER | C22: m3 | D22: =D21+D15 -> 14775 | E22: =E21+E15 -> 17188.8 | F22: =F21+F15 -> 17390 | G22: =G21+G15 -> 16535.8 | H22: =H21+H15 -> 18825.4 | I22: =I21+I15 -> 18123.1 | J22: =J21+J15 -> 17402 | K22: =K21+K15 -> 18616.3 | ... N22: =N21+N15 -> 19365.9 | O22: 16773.4 | P22: =P21+P15 -> 208649.1
A24: Non-Revenue Water (NRW) | B24: Volume | C24: m3 | D24: =D9-D22 -> 5870 | E24: =E9-E22 -> 8811.2 | F24: =F9-F22 -> 7616 | G24: =G9-G22 -> 9296.2 | H24: =H9-H22 -> 6332.6 | I24: =I9-I22 -> 5323.9 | J24: =J9-J22 -> 6015 | K24: =K9-K22 -> 2568.7 | ... N24: =N9-N22 -> 2320.1 | O24: 4619.6 | P24: =P9-P22 -> 68891.9
B25: Percentage | C25: % | D25: =D24/D9 -> 0.28433035 | E25: =E24/E9 -> 0.33889231 | F25: =F24/F9 -> 0.3045669 | G25: =G24/G9 -> 0.35987148 | H25: =H24/H9 -> 0.25171317 | I25: =I24/I9 -> 0.22706103 | J25: =J24/J9 -> 0.25686467 | K25: =K24/K9 -> 0.12125089 | ... N25: =N24/N9 -> 0.10698607 | O25: 0.21593979 | P25: =P24/P9 -> 0.24822242
A26: OPERATING EXPENSES
A27: Chemicals
A28: Chemical | B28: Rate(MK/kg)
A29: Chlorine | B29: 3525.29 | C29: kg | D29: 18 | E29: 19 | F29: 16 | G29: 17 | H29: 18 | I29: 18 | J29: 20 | K29: 19 | L29: 20 | M29: 18 | N29: 18 | O29: 18 | P29: =SUM(D29:O29) -> 219
C30: kg/mg litre | D30: =D29/(D9/1000) -> 0.87188181 | E30: =E29/(E9/1000) -> 0.73076923 | F30: =F29/(F9/1000) -> 0.63984644 | G30: =G29/(G9/1000) -> 0.65809848 | H30: =H29/(H9/1000) -> 0.71547818 | I30: =I29/(I9/1000) -> 0.76768883 | J30: =J29/(J9/1000) -> 0.85408037 | K30: =K29/(K9/1000) -> 0.89686099 | L30: 0.9440642 | M30: =M29/(M9/1000) -> 0.79691858 | N30: =N29/(N9/1000) -> 0.83002859 | O30: 0.84139672 | P30: =P29/(P9/1000) -> 0.78907261
A31: Aluminium sulphate | C31: kg | P31: =SUM(D31:O31) -> 0
B32: 1060.01 | C32: kg/mg litre | D32: =D31/(D9/1000) -> 0 | E32: =E31/(E9/1000) -> 0 | F32: =F31/(F9/1000) -> 0 | G32: =G31/(G9/1000) -> 0 | H32: =H31/(H9/1000) -> 0 | I32: =I31/(I9/1000) -> 0 | J32: =J31/(J9/1000) -> 0 | K32: =K31/(K9/1000) -> 0 | ... N32: =N31/(N9/1000) -> 0 | O32: 0 | P32: =P31/(P9/1000) -> 0
A33: Soda | C33: kg | P33: =SUM(D33:O33) -> 0
B34: 1228.29 | C34: kg/mg litre | D34: =D33/(D9/1000) -> 0 | E34: =E33/(E9/1000) -> 0 | F34: =F33/(F9/1000) -> 0 | G34: =G33/(G9/1000) -> 0 | H34: =H33/(H9/1000) -> 0 | I34: =I33/(I9/1000) -> 0 | J34: =J33/(J9/1000) -> 0 | K34: =K33/(K9/1000) -> 0 | ... N34: =N33/(N9/1000) -> 0 | O34: 0 | P34: =P33/(P9/1000) -> 0
A35: Algae floc | C35: litres
B36: 3726.73 | C36: litres/mg litre | D36: =D35/(D11/1000) -> 0 | E36: =E35/(E11/1000) -> 0 | F36: =F35/(F11/1000) -> 0 | G36: =G35/(G11/1000) -> 0
A37: Sud floc | C37: litres | H37: 0 | I37: 0 | J37: 0 | K37: 0 | L37: 0 | M37: 0 | N37: 0 | O37: 0 | P37: =SUM(D37:O37) -> 0
B38: 3951.59 | C38: litres/mg litre | D38: =D37/(D13/1000) -> 0 | E38: =E37/(E13/1000) -> 0 | F38: =F37/(F13/1000) -> 0 | G38: =G37/(G13/1000) -> 0 | H38: =H37/(H9/1000) -> 0 | I38: =I37/(I9/1000) -> 0 | J38: =J37/(J9/1000) -> 0 | K38: =K37/(K9/1000) -> 0 | L38: =L37/(L9/1000) -> 0 | M38: =M37/(M9/1000) -> 0 | N38: =N37/(N9/1000) -> 0 | O38: 0 | P38: =P37/(P9/1000) -> 0
A39: Potasium permanganate | C39: kg | H39: 0 | I39: 0 | J39: 0 | K39: 0 | L39: 0 | M39: 0 | N39: 0 | O39: 0 | P39: =SUM(D39:O39) -> 0
B40: 1950 | C40: kg/mg litre | D40: =D39/(D15/1000) -> 0 | E40: =E39/(E15/1000) -> 0 | F40: =F39/(F15/1000) -> 0 | G40: =G39/(G15/1000) -> 0 | H40: =H39/(H9/1000) -> 0 | I40: =I39/(I9/1000) -> 0 | J40: =J39/(J9/1000) -> 0 | K40: =K39/(K9/1000) -> 0 | L40: =L39/(L9/1000) -> 0 | M40: =M39/(M9/1000) -> 0 | N40: =N39/(N9/1000) -> 0 | O40: 0 | P40: =P39/(P9/1000) -> 0
A41: Cost of Chemicals | C41: Mk | D41: =(D29*$B29)+(D31*$B31)+(D33*$B33)+(D35*$B35)+(D37*$B37)+(D39*$B39) -> 63455.22 | E41: =(E29*$B29)+(E31*$B31)+(E33*$B33)+(E35*$B35)+(E37*$B37)+(E39*$B39) -> 66980.51 | F41: =(F29*$B29)+(F31*$B31)+(F33*$B33)+(F35*$B35)+(F37*$B37)+(F39*$B39) -> 56404.64 | G41: =(G29*$B29)+(G31*$B31)+(G33*$B33)+(G35*$B35)+(G37*$B37)+(G39*$B39) -> 59929.93 | H41: =(H29*$B29)+(H31*$B31)+(H33*$B33)+(H35*$B35)+(H37*$B37)+(H39*$B39) -> 63455.22 | I41: =(I29*$B29)+(I31*$B31)+(I33*$B33)+(I35*$B35)+(I37*$B37)+(I39*$B39) -> 63455.22 | J41: =(J29*$B29)+(J31*$B31)+(J33*$B33)+(J35*$B35)+(J37*$B37)+(J39*$B39) -> 70505.8 | K41: =(K29*$B29)+(K31*$B31)+(K33*$B33)+(K35*$B35)+(K37*$B37)+(K39*$B39) -> 66980.51 | ... N41: =(N29*$B29)+(N31*$B31)+(N33*$B33)+(N35*$B35)+(N37*$B37)+(N39*$B39) -> 63455.22 | O41: 63455.22 | P41: =SUM(D41:O41) -> 772038.51
A42: Cost/vol. Produced (chemicals) | C42: Mk/m3 | D42: =D41/D9 -> 3.0736362 | E42: =E41/E9 -> 2.5761735 | F42: =F41/F9 -> 2.2556442 | G42: =G41/G9 -> 2.319988 | H42: =H41/H9 -> 2.5222681 | I42: =I41/I9 -> 2.7063258 | J42: =J41/J9 -> 3.010881 | K42: =K41/K9 -> 3.1616951 | ... N42: =N41/N9 -> 2.9260915 | O42: 2.9661674 | P42: =P41/P9 -> 2.7817098
A43: Power
...

Sheet Miseu Folo
A1: SOUTHERN REGION WATER BOARD
A3: MONTHLY REPORTS - 2023/2024
A4: NGABU ZONE
A5: NGABU ZONE
A7: PARAMETERS | C7: UNITS | D7: APRIL | E7: MAY | F7: JUNE | G7: JULY | H7: AUGUST | I7: SEPTEMBER | J7: OCTOBER | K7: NOVEMBER | L7: DECEMBER | M7: JANUARY | N7: FEBRUARY | O7: MARCH | P7: TOTALS
A8: PRODUCTION
A9: Volume Produced | C9: m3 | D9: 2733 | E9: 3230 | F9: 3544 | G9: 3667 | H9: 3528 | I9: 3745 | J9: 4649 | K9: 4358 | L9: 3994 | M9: 3907 | N9: 4049 | O9: 3002 | P9: =SUM(D9:O9) -> 44406
A10: REVENUE WATER - POSTPAID
A11: Volume Billed Individuals | C11: m3 | D11: 301 | E11: 346 | F11: 526 | G11: 507 | H11: 705 | I11: 1412 | J11: 1981 | K11: 1043 | L11: 1311 | M11: 1074 | N11: 1185 | O11: 1136 | P11: =SUM(D11:O11) -> 11527
A12: Volume Billed CWPs | C12: m3 | P12: =SUM(D12:O12) -> 0
A13: Volume Billed Institutions | C13: m3 | F13: 5 | G13: 1 | H13: 7 | I13: 5 | J13: 5 | K13: 6 | M13: 5 | N13: 11 | O13: 9 | P13: =SUM(D13:O13) -> 54
A14: Volume Billed Commercial/Industrial | C14: m3 | D14: 7 | E14: 10 | F14: 19 | G14: 13 | H14: 15 | I14: 21 | J14: 11 | K14: 12 | O14: 13 | P14: =SUM(D14:O14) -> 121
A15: Total Volume Billed Post Paid | C15: m3 | D15: =SUM(D11:D14) -> 308 | E15: =SUM(E11:E14) -> 356 | F15: =SUM(F11:F14) -> 550 | G15: =SUM(G11:G14) -> 521 | H15: =SUM(H11:H14) -> 727 | I15: =SUM(I11:I14) -> 1438 | J15: =SUM(J11:J14) -> 1997 | K15: =SUM(K11:K14) -> 1061 | ... N15: =SUM(N11:N14) -> 1196 | O15: 1158 | P15: =SUM(P11:P14) -> 11702
A16: REVENUE WATER - PREPAID
A17: Individuals | C17: m3 | J17: 2037.6 | P17: =SUM(D17:O17) -> 2037.6
A18: CWPs | C18: m3 | P18: =SUM(D18:O18) -> 0
A19: Institutions | C19: m3 | D19: 1916 | E19: 2159 | F19: 2460.2 | G19: 2629 | H19: 1925 | I19: 2075.2 | K19: 2565 | L19: 1945 | M19: 1876.9 | N19: 2196 | O19: 1643.2 | P19: =SUM(D19:O19) -> 23390.5
A20: Commercial/Industrial | C20: m3 | P20: =SUM(D20:O20) -> 0
A21: Total Volume Prepaid | C21: m3 | D21: =SUM(D17:D20) -> 1916 | E21: =SUM(E17:E20) -> 2159 | F21: =SUM(F17:F20) -> 2460.2 | G21: =SUM(G17:G20) -> 2629 | H21: =SUM(H17:H20) -> 1925 | I21: =SUM(I17:I20) -> 2075.2 | J21: =SUM(J17:J20) -> 2037.6 | K21: =SUM(K17:K20) -> 2565 | ... N21: =SUM(N17:N20) -> 2196 | O21: 1643.2 | P21: =SUM(P17:P20) -> 25428.1
A22: TOTAL REVENUE WATER | C22: m3 | D22: =D21+D15 -> 2224 | E22: =E21+E15 -> 2515 | F22: =F21+F15 -> 3010.2 | G22: =G21+G15 -> 3150 | H22: =H21+H15 -> 2652 | I22: =I21+I15 -> 3513.2 | J22: =J21+J15 -> 4034.6 | K22: =K21+K15 -> 3626 | ... N22: =N21+N15 -> 3392 | O22: 2801.2 | P22: =P21+P15 -> 37130.1
A24: Non-Revenue Water (NRW) | B24: Volume | C24: m3 | D24: =D9-D22 -> 509 | E24: =E9-E22 -> 715 | F24: =F9-F22 -> 533.8 | G24: =G9-G22 -> 517 | H24: =H9-H22 -> 876 | I24: =I9-I22 -> 231.8 | J24: =J9-J22 -> 614.4 | K24: =K9-K22 -> 732 | ... N24: =N9-N22 -> 657 | O24: 200.8 | P24: =P9-P22 -> 7275.9
B25: Percentage | C25: % | D25: =D24/D9 -> 0.18624222 | E25: =E24/E9 -> 0.22136223 | F25: =F24/F9 -> 0.15062077 | G25: =G24/G9 -> 0.14098718 | H25: =H24/H9 -> 0.24829932 | I25: =I24/I9 -> 0.061895861 | J25: =J24/J9 -> 0.13215745 | K25: =K24/K9 -> 0.16796696 | ... N25: =N24/N9 -> 0.16226229 | O25: 0.066888741 | P25: =P24/P9 -> 0.16384948
A26: OPERATING EXPENSES
A27: Chemicals
A28: Chemical | B28: Rate(MK/kg)
A29: Chlorine | B29: 3525.29 | C29: kg | D29: 6 | E29: 7 | F29: 7.5 | G29: 8.1 | H29: 8 | I29: 7.2 | J29: 7 | K29: 6.8 | L29: 6.7 | M29: 6 | N29: 7 | O29: 6 | P29: =SUM(D29:O29) -> 83.3
C30: kg/mg litre | D30: =D29/(D9/1000) -> 2.1953897 | E30: =E29/(E9/1000) -> 2.1671827 | F30: =F29/(F9/1000) -> 2.1162528 | G30: =G29/(G9/1000) -> 2.2088901 | H30: =H29/(H9/1000) -> 2.2675737 | I30: =I29/(I9/1000) -> 1.9225634 | J30: =J29/(J9/1000) -> 1.5057002 | K30: =K29/(K9/1000) -> 1.5603488 | L30: 1.6775163 | M30: =M29/(M9/1000) -> 1.5357051 | N30: =N29/(N9/1000) -> 1.7288219 | O30: 1.9986676 | P30: =P29/(P9/1000) -> 1.8758726
A31: Aluminium sulphate | C31: kg | P31: =SUM(D31:O31) -> 0
B32: 1060.01 | C32: kg/mg litre | D32: =D31/(D9/1000) -> 0 | E32: =E31/(E9/1000) -> 0 | F32: =F31/(F9/1000) -> 0 | G32: =G31/(G9/1000) -> 0 | H32: =H31/(H9/1000) -> 0 | I32: =I31/(I9/1000) -> 0 | J32: =J31/(J9/1000) -> 0 | K32: =K31/(K9/1000) -> 0 | ... N32: =N31/(N9/1000) -> 0 | O32: 0 | P32: =P31/(P9/1000) -> 0
A33: Soda | C33: kg | P33: =SUM(D33:O33) -> 0
B34: 1228.29 | C34: kg/mg litre | D34: =D33/(D9/1000) -> 0 | E34: =E33/(E9/1000) -> 0 | F34: =F33/(F9/1000) -> 0 | G34: =G33/(G9/1000) -> 0 | H34: =H33/(H9/1000) -> 0 | I34: =I33/(I9/1000) -> 0 | J34: =J33/(J9/1000) -> 0 | K34: =K33/(K9/1000) -> 0 | ... N34: =N33/(N9/1000) -> 0 | O34: 0 | P34: =P33/(P9/1000) -> 0
A35: Algae floc | C35: litres
B36: 3726.73 | C36: litres/mg litre | D36: =D35/(D11/1000) -> 0 | E36: =E35/(E11/1000) -> 0 | F36: =F35/(F11/1000) -> 0 | G36: =G35/(G11/1000) -> 0
A37: Sud floc | C37: litres | H37: 0 | I37: 0 | J37: 0 | K37: 0 | L37: 0 | M37: 0 | N37: 0 | O37: 0 | P37: =SUM(D37:O37) -> 0
B38: 3951.59 | C38: litres/mg litre | D38: =D37/(D9/1000) -> 0 | E38: =E37/(E9/1000) -> 0 | F38: =F37/(F9/1000) -> 0 | G38: =G37/(G9/1000) -> 0 | H38: =H37/(H9/1000) -> 0 | I38: =I37/(I9/1000) -> 0 | J38: =J37/(J9/1000) -> 0 | K38: =K37/(K9/1000) -> 0 | ... N38: =N37/(N9/1000) -> 0 | O38: 0 | P38: =P37/(P9/1000) -> 0
A39: Potasium permanganate | C39: kg | H39: 0 | I39: 0 | J39: 0 | K39: 0 | L39: 0 | M39: 0 | N39: 0 | O39: 0 | P39: =SUM(D39:O39) -> 0
B40: 1950 | C40: kg/mg litre | D40: =D39/(D15/1000) -> 0 | E40: =E39/(E15/1000) -> 0 | F40: =F39/(F15/1000) -> 0 | G40: =G39/(G15/1000) -> 0 | H40: =H39/(H9/1000) -> 0 | I40: =I39/(I9/1000) -> 0 | J40: =J39/(J9/1000) -> 0 | K40: =K39/(K9/1000) -> 0 | L40: =L39/(L9/1000) -> 0 | M40: =M39/(M9/1000) -> 0 | N40: =N39/(N9/1000) -> 0 | O40: 0 | P40: =P39/(P9/1000) -> 0
A41: Cost of Chemicals | C41: Mk | D41: =(D29*$B29)+(D31*$B31)+(D33*$B33)+(D35*$B35)+(D37*$B37)+(D39*$B39) -> 21151.74 | E41: =(E29*$B29)+(E31*$B31)+(E33*$B33)+(E35*$B35)+(E37*$B37)+(E39*$B39) -> 24677.03 | F41: =(F29*$B29)+(F31*$B31)+(F33*$B33)+(F35*$B35)+(F37*$B37)+(F39*$B39) -> 26439.675 | G41: =(G29*$B29)+(G31*$B31)+(G33*$B33)+(G35*$B35)+(G37*$B37)+(G39*$B39) -> 28554.849 | H41: =(H29*$B29)+(H31*$B31)+(H33*$B33)+(H35*$B35)+(H37*$B37)+(H39*$B39) -> 28202.32 | I41: =(I29*$B29)+(I31*$B31)+(I33*$B33)+(I35*$B35)+(I37*$B37)+(I39*$B39) -> 25382.088 | J41: =(J29*$B29)+(J31*$B31)+(J33*$B33)+(J35*$B35)+(J37*$B37)+(J39*$B39) -> 24677.03 | K41: =(K29*$B29)+(K31*$B31)+(K33*$B33)+(K35*$B35)+(K37*$B37)+(K39*$B39) -> 23971.972 | ... N41: =(N29*$B29)+(N31*$B31)+(N33*$B33)+(N35*$B35)+(N37*$B37)+(N39*$B39) -> 24677.03 | O41: 21151.74 | P41: =SUM(D41:O41) -> 293656.66
A42: Cost/vol. Produced (chemicals) | C42: Mk/m3 | D42: =D41/D9 -> 7.7393853 | E42: =E41/E9 -> 7.6399474 | F42: =F41/F9 -> 7.4604049 | G42: =G41/G9 -> 7.7869782 | H42: =H41/H9 -> 7.9938549 | I42: =I41/I9 -> 6.7775936 | J42: =J41/J9 -> 5.3080297 | K42: =K41/K9 -> 5.500682 | ... N42: =N41/N9 -> 6.0945987 | O42: 7.0458827 | P42: =P41/P9 -> 6.612995
A43: Power
...

Sheet Nsanje
A1: SOUTHERN REGION WATER BOARD
A3: MONTHLY REPORTS - 2023/2024
A4: NGABU ZONE
A5: NGABU ZONE
A7: PARAMETERS | C7: UNITS | D7: APRIL | E7: MAY | F7: JUNE | G7: JULY | H7: AUGUST | I7: SEPTEMBER | J7: OCTOBER | K7: NOVEMBER | L7: DECEMBER | M7: JANUARY | N7: FEBRUARY | O7: MARCH | P7: TOTALS
A8: PRODUCTION
A9: Volume Produced | C9: m3 | D9: 18570 | E9: 20529 | F9: 20853 | G9: 18219 | H9: 20280 | I9: 22536 | J9: 25036 | K9: 23371 | L9: 23363 | M9: 24108 | N9: 24662 | O9: 22838 | P9: =SUM(D9:O9) -> 264365
A10: REVENUE WATER - POSTPAID
A11: Volume Billed Individuals | C11: m3 | D11: =237+797+6208 -> 7242 | E11: =305+903+7326 -> 8534 | F11: =340+931+7700 -> 8971 | G11: =294+873+6753 -> 7920 | H11: =348+885+6990 -> 8223 | I11: =389+1057+8181 -> 9627 | J11: =449+1142+9131 -> 10722 | K11: =434+1101+8488 -> 10023 | L11: 10011 | M11: 10047 | N11: 10619 | O11: 9398 | P11: =SUM(D11:O11) -> 111337
A12: Volume Billed CWPs | C12: m3 | D12: 773 | E12: 806 | F12: 680 | G12: 518 | H12: 824 | I12: 733 | J12: 858 | K12: 794 | L12: 814 | M12: 757 | N12: 756 | O12: 672 | P12: =SUM(D12:O12) -> 8985
A13: Volume Billed Institutions | C13: m3 | D13: 94 | E13: 102 | F13: 133 | G13: 126 | H13: 161 | I13: 210 | J13: 68 | K13: 91 | L13: 91 | M13: 133 | N13: 133 | O13: 114 | P13: =SUM(D13:O13) -> 1456
A14: Volume Billed Commercial/Industrial | C14: m3 | D14: 6 | E14: 7 | F14: 8 | G14: 49 | H14: 162 | I14: 196 | J14: 211 | K14: 146 | L14: 5 | M14: 6 | N14: 123 | O14: 90 | P14: =SUM(D14:O14) -> 1009
A15: Total Volume Billed Post Paid | C15: m3 | D15: =SUM(D11:D14) -> 8115 | E15: =SUM(E11:E14) -> 9449 | F15: =SUM(F11:F14) -> 9792 | G15: =SUM(G11:G14) -> 8613 | H15: =SUM(H11:H14) -> 9370 | I15: =SUM(I11:I14) -> 10766 | J15: =SUM(J11:J14) -> 11859 | K15: =SUM(K11:K14) -> 11054 | ... N15: =SUM(N11:N14) -> 11631 | O15: 10274 | P15: =SUM(P11:P14) -> 122787
A16: REVENUE WATER - PREPAID
A17: Individuals | C17: m3 | F17: 4491 | G17: 3872 | I17: 4589 | J17: 5441 | K17: 4990 | L17: 4826 | M17: 5046 | N17: 4913 | O17: 4595 | P17: =SUM(D17:O17) -> 42763
A18: CWPs | C18: m3 | P18: =SUM(D18:O18) -> 0
A19: Institutions | C19: m3 | D19: 6199 | E19: 5929 | F19: 834 | G19: 723 | H19: 5688.3 | I19: 883 | J19: 889 | K19: 880 | L19: 1093 | M19: 1476 | N19: 1902 | O19: 1918 | P19: =SUM(D19:O19) -> 28414.3
A20: Commercial/Industrial | C20: m3 | F20: 529 | G20: 339 | I20: 554 | J20: 442 | K20: 331 | L20: 556 | M20: 415 | N20: 515 | O20: 270 | P20: =SUM(D20:O20) -> 3951
A21: Total Volume Prepaid | C21: m3 | D21: =SUM(D17:D20) -> 6199 | E21: =SUM(E17:E20) -> 5929 | F21: =SUM(F17:F20) -> 5854 | G21: =SUM(G17:G20) -> 4934 | H21: =SUM(H17:H20) -> 5688.3 | I21: =SUM(I17:I20) -> 6026 | J21: =SUM(J17:J20) -> 6772 | K21: =SUM(K17:K20) -> 6201 | ... N21: =SUM(N17:N20) -> 7330 | O21: 6783 | P21: =SUM(P17:P20) -> 75128.3
A22: TOTAL REVENUE WATER | C22: m3 | D22: =D21+D15 -> 14314 | E22: =E21+E15 -> 15378 | F22: =F21+F15 -> 15646 | G22: =G21+G15 -> 13547 | H22: =H21+H15 -> 15058.3 | I22: =I21+I15 -> 16792 | J22: =J21+J15 -> 18631 | K22: =K21+K15 -> 17255 | ... N22: =N21+N15 -> 18961 | O22: 17057 | P22: =P21+P15 -> 197915.3
A24: Non-Revenue Water (NRW) | B24: Volume | C24: m3 | D24: =D9-D22 -> 4256 | E24: =E9-E22 -> 5151 | F24: =F9-F22 -> 5207 | G24: =G9-G22 -> 4672 | H24: =H9-H22 -> 5221.7 | I24: =I9-I22 -> 5744 | J24: =J9-J22 -> 6405 | K24: =K9-K22 -> 6116 | ... N24: =N9-N22 -> 5701 | O24: 5781 | P24: =P9-P22 -> 66449.7
B25: Percentage | C25: % | D25: =D24/D9 -> 0.22918686 | E25: =E24/E9 -> 0.25091334 | F25: =F24/F9 -> 0.24970028 | G25: =G24/G9 -> 0.25643559 | H25: =H24/H9 -> 0.25748028 | I25: =I24/I9 -> 0.25488108 | J25: =J24/J9 -> 0.2558316 | K25: =K24/K9 -> 0.26169184 | ... N25: =N24/N9 -> 0.23116536 | O25: 0.25313075 | P25: =P24/P9 -> 0.25135589
A26: OPERATING EXPENSES
A27: Chemicals
A28: Chemical | B28: Rate(MK/kg)
A29: Chlorine | B29: 3525.29 | C29: kg | D29: 8.5 | E29: 11 | F29: 10.5 | G29: 12.25 | H29: 11.5 | I29: 13.75 | J29: 11.5 | K29: 11.25 | L29: 10 | M29: 15 | N29: 16 | O29: 18 | P29: =SUM(D29:O29) -> 149.25
C30: kg/mg litre | D30: =D29/(D9/1000) -> 0.45772752 | E30: =E29/(E9/1000) -> 0.53582737 | F30: =F29/(F9/1000) -> 0.50352467 | G30: =G29/(G9/1000) -> 0.67237499 | H30: =H29/(H9/1000) -> 0.56706114 | I30: =I29/(I9/1000) -> 0.6101349 | J30: =J29/(J9/1000) -> 0.45933855 | K30: =K29/(K9/1000) -> 0.4813658 | ... N30: =N29/(N9/1000) -> 0.64877139 | O30: 0.78816008 | P30: =P29/(P9/1000) -> 0.56456036
A31: Aluminium sulphate | C31: kg | P31: =SUM(D31:O31) -> 0
B32: 1060.01 | C32: kg/mg litre | D32: =D31/(D11/1000) -> 0 | E32: =E31/(E11/1000) -> 0 | F32: =F31/(F11/1000) -> 0 | G32: =G31/(G11/1000) -> 0 | H32: =H31/(H9/1000) -> 0 | I32: =I31/(I9/1000) -> 0 | J32: =J31/(J9/1000) -> 0 | K32: =K31/(K9/1000) -> 0 | L32: =L31/(L9/1000) -> 0 | M32: =M31/(M9/1000) -> 0 | N32: =N31/(N9/1000) -> 0 | O32: 0 | P32: =P31/(P9/1000) -> 0
A33: Soda | C33: kg | P33: =SUM(D33:O33) -> 0
B34: 1228.29 | C34: kg/mg litre | D34: =D33/(D9/1000) -> 0 | E34: =E33/(E9/1000) -> 0 | F34: =F33/(F9/1000) -> 0 | G34: =G33/(G9/1000) -> 0 | H34: =H33/(H9/1000) -> 0 | I34: =I33/(I9/1000) -> 0 | J34: =J33/(J9/1000) -> 0 | K34: =K33/(K9/1000) -> 0 | ... N34: =N33/(N9/1000) -> 0 | O34: 0 | P34: =P33/(P9/1000) -> 0
A35: Algae floc | C35: litres
B36: 3726.73 | C36: litres/mg litre
A37: Sud floc | C37: litres | H37: 0 | I37: 0 | J37: 0 | K37: 0 | L37: 0 | M37: 0 | N37: 0 | O37: 0 | P37: =SUM(D37:O37) -> 0
B38: 3951.59 | C38: litres/mg litre | D38: =D37/(D9/1000) -> 0 | E38: =E37/(E9/1000) -> 0 | F38: =F37/(F9/1000) -> 0 | G38: =G37/(G9/1000) -> 0 | H38: =H37/(H9/1000) -> 0 | I38: =I37/(I9/1000) -> 0 | J38: =J37/(J9/1000) -> 0 | K38: =K37/(K9/1000) -> 0 | ... N38: =N37/(N9/1000) -> 0 | O38: 0 | P38: =P37/(P9/1000) -> 0
A39: Potasium permanganate | C39: kg | H39: 0 | I39: 0 | J39: 0 | K39: 0 | L39: 0 | M39: 0 | N39: 0 | O39: 0 | P39: =SUM(D39:O39) -> 0
B40: 1950 | C40: kg/mg litre | D40: =D39/(D9/1000) -> 0 | E40: =E39/(E9/1000) -> 0 | F40: =F39/(F9/1000) -> 0 | G40: =G39/(G9/1000) -> 0 | H40: =H39/(H9/1000) -> 0 | I40: =I39/(I9/1000) -> 0 | J40: =J39/(J9/1000) -> 0 | K40: =K39/(K9/1000) -> 0 | ... N40: =N39/(N9/1000) -> 0 | O40: 0 | P40: =P39/(P9/1000) -> 0
A41: Cost of Chemicals | C41: Mk | D41: =(D29*$B29)+(D31*$B31)+(D33*$B33)+(D35*$B35)+(D37*$B37)+(D39*$B39) -> 29964.965 | E41: =(E29*$B29)+(E31*$B31)+(E33*$B33)+(E35*$B35)+(E37*$B37)+(E39*$B39) -> 38778.19 | F41: =(F29*$B29)+(F31*$B31)+(F33*$B33)+(F35*$B35)+(F37*$B37)+(F39*$B39) -> 37015.545 | G41: =(G29*$B29)+(G31*$B31)+(G33*$B33)+(G35*$B35)+(G37*$B37)+(G39*$B39) -> 43184.802 | H41: =(H29*$B29)+(H31*$B31)+(H33*$B33)+(H35*$B35)+(H37*$B37)+(H39*$B39) -> 40540.835 | I41: =(I29*$B29)+(I31*$B31)+(I33*$B33)+(I35*$B35)+(I37*$B37)+(I39*$B39) -> 48472.738 | J41: =(J29*$B29)+(J31*$B31)+(J33*$B33)+(J35*$B35)+(J37*$B37)+(J39*$B39) -> 40540.835 | K41: =(K29*$B29)+(K31*$B31)+(K33*$B33)+(K35*$B35)+(K37*$B37)+(K39*$B39) -> 39659.512 | ... N41: =(N29*$B29)+(N31*$B31)+(N33*$B33)+(N35*$B35)+(N37*$B37)+(N39*$B39) -> 56404.64 | O41: 63455.22 | P41: =SUM(D41:O41) -> 526149.53
A42: Cost/vol. Produced (chemicals) | C42: Mk/m3 | D42: =D41/D9 -> 1.6136222 | E42: =E41/E9 -> 1.8889469 | F42: =F41/F9 -> 1.7750705 | G42: =G41/G9 -> 2.3703168 | H42: =H41/H9 -> 1.999055 | I42: =I41/I9 -> 2.1509024 | J42: =J41/J9 -> 1.6193016 | K42: =K41/K9 -> 1.696954 | ... N42: =N41/N9 -> 2.2871073 | O42: 2.7784929 | P42: =P41/P9 -> 1.990239
A43: Power
...

Sheet Ngabu
A1: SOUTHERN REGION WATER BOARD
A3: MONTHLY REPORTS - 2023/2024
A4: NGABU ZONE
A5: NGABU ZONE
A7: PARAMETERS | C7: UNITS | D7: APRIL | E7: MAY | F7: JUNE | G7: JULY | H7: AUGUST | I7: SEPTEMBER | J7: OCTOBER | K7: NOVEMBER | L7: DECEMBER | M7: JANUARY | N7: FEBRUARY | O7: MARCH | P7: TOTALS
A8: PRODUCTION
A9: Volume Produced | C9: m3 | D9: 14129 | E9: 20254 | F9: 22284 | G9: 12150 | H9: 12141 | I9: 12988 | J9: 10612 | K9: 15053 | L9: 12734 | M9: 11668 | N9: 13056 | O9: 12109 | P9: =SUM(D9:O9) -> 169178
A10: REVENUE WATER - POSTPAID
A11: Volume Billed Individuals | C11: m3 | D11: =345+91+4282 -> 4718 | E11: =327+62+4453 -> 4842 | F11: =442+280+6466 -> 7188 | G11: =415+262+5649 -> 6326 | H11: =387+116+4874 -> 5377 | I11: =471+162+5354 -> 5987 | J11: 5422 | K11: =437+203+5921 -> 6561 | L11: 5951 | M11: =396+145+5155 -> 5696 | N11: 6285 | O11: 5843 | P11: =SUM(D11:O11) -> 70196
A12: Volume Billed CWPs | C12: m3 | D12: 902 | E12: 855 | F12: 1100 | G12: 1023 | H12: 1197 | I12: 1023 | J12: 915 | K12: 1371 | L12: 1207 | M12: 982 | N12: 1043 | O12: 895 | P12: =SUM(D12:O12) -> 12513
A13: Volume Billed Institutions | C13: m3 | D13: 93 | E13: 115 | F13: 638 | G13: 257 | H13: 88 | I13: 109 | J13: 156 | K13: 179 | L13: 202 | M13: 138 | N13: 162 | O13: 170 | P13: =SUM(D13:O13) -> 2307
A14: Volume Billed Commercial/Industrial | C14: m3 | D14: 9 | E14: 6 | F14: 60 | G14: 39 | H14: 45 | I14: 70 | J14: 103 | K14: 49 | L14: 67 | M14: 59 | N14: 90 | O14: 74 | P14: =SUM(D14:O14) -> 671
A15: Total Volume Billed Post Paid | C15: m3 | D15: =SUM(D11:D14) -> 5722 | E15: =SUM(E11:E14) -> 5818 | F15: =SUM(F11:F14) -> 8986 | G15: =SUM(G11:G14) -> 7645 | H15: =SUM(H11:H14) -> 6707 | I15: =SUM(I11:I14) -> 7189 | J15: =SUM(J11:J14) -> 6596 | K15: =SUM(K11:K14) -> 8160 | ... N15: =SUM(N11:N14) -> 7580 | O15: 6982 | P15: =SUM(P11:P14) -> 85687
A16: REVENUE WATER - PREPAID
A17: Individuals | C17: m3 | G17: 2164 | I17: 2415 | J17: 2248 | K17: 2900.2 | L17: 1506 | M17: 1375 | N17: 1684 | O17: 1494 | P17: =SUM(D17:O17) -> 15786.2 | Q17: =P17/14458% -> 109.18661
A18: CWPs | C18: m3 | P18: =SUM(D18:O18) -> 0 | Q18: =P18/14458% -> 0
A19: Institutions | C19: m3 | D19: 2868 | E19: 4163 | F19: 2634 | G19: 633 | H19: 4110 | I19: 659 | J19: 671 | K19: 855 | L19: 875 | M19: 582 | N19: 633 | O19: 754 | P19: =SUM(D19:O19) -> 19437 | Q19: =P19/14458% -> 134.43768
A20: Commercial/Industrial | C20: m3 | G20: 154 | I20: 70 | J20: 65 | K20: 103 | L20: 98 | M20: 33 | N20: 43 | O20: 51 | P20: =SUM(D20:O20) -> 617 | Q20: =P20/14458% -> 4.2675335
A21: Total Volume Prepaid | C21: m3 | D21: =SUM(D17:D20) -> 2868 | E21: =SUM(E17:E20) -> 4163 | F21: =SUM(F17:F20) -> 2634 | G21: =SUM(G17:G20) -> 2951 | H21: =SUM(H17:H20) -> 4110 | I21: =SUM(I17:I20) -> 3144 | J21: =SUM(J17:J20) -> 2984 | K21: =SUM(K17:K20) -> 3858.2 | ... N21: =SUM(N17:N20) -> 2360 | O21: 2299 | P21: =SUM(P17:P20) -> 35840.2 | Q21: =P21/14458% -> 247.89182
A22: TOTAL REVENUE WATER | C22: m3 | D22: =D21+D15 -> 8590 | E22: =E21+E15 -> 9981 | F22: =F21+F15 -> 11620 | G22: =G21+G15 -> 10596 | H22: =H21+H15 -> 10817 | I22: =I21+I15 -> 10333 | J22: =J21+J15 -> 9580 | K22: =K21+K15 -> 12018.2 | ... N22: =N21+N15 -> 9940 | O22: 9281 | P22: =P21+P15 -> 121527.2
A24: Non-Revenue Water (NRW) | B24: Volume | C24: m3 | D24: =D9-D22 -> 5539 | E24: =E9-E22 -> 10273 | F24: =F9-F22 -> 10664 | G24: =G9-G22 -> 1554 | H24: =H9-H22 -> 1324 | I24: =I9-I22 -> 2655 | J24: =J9-J22 -> 1032 | K24: =K9-K22 -> 3034.8 | ... N24: =N9-N22 -> 3116 | O24: 2828 | P24: =P9-P22 -> 47650.8
B25: Percentage | C25: % | D25: =D24/D9 -> 0.39203058 | E25: =E24/E9 -> 0.50720845 | F25: =F24/F9 -> 0.47854963 | G25: =G24/G9 -> 0.12790123 | H25: =H24/H9 -> 0.10905197 | I25: =I24/I9 -> 0.20441946 | J25: =J24/J9 -> 0.097248398 | K25: =K24/K9 -> 0.20160765 | ... N25: =N24/N9 -> 0.23866422 | O25: 0.2335453 | P25: =P24/P9 -> 0.28166074
A26: OPERATING EXPENSES
A27: Chemicals
A28: Chemical | B28: Rate(MK/kg)
A29: Chlorine | B29: 3525.29 | C29: kg | D29: 16 | E29: 21 | F29: 21 | G29: 18 | H29: 15 | I29: 18 | J29: 15 | K29: 18 | L29: 18 | M29: 15 | N29: 18 | O29: 15 | P29: =SUM(D29:O29) -> 208
C30: kg/mg litre | D30: =D29/(D9/1000) -> 1.1324227 | E30: =E29/(E9/1000) -> 1.0368322 | F30: =F29/(F9/1000) -> 0.94238018 | G30: =G29/(G9/1000) -> 1.4814815 | H30: =H29/(H9/1000) -> 1.2354831 | I30: =I29/(I9/1000) -> 1.3858947 | J30: =J29/(J9/1000) -> 1.4134942 | K30: =K29/(K9/1000) -> 1.1957749 | L30: 1.4135386 | M30: =M29/(M9/1000) -> 1.2855674 | N30: =N29/(N9/1000) -> 1.3786765 | O30: 1.238748 | P30: =P29/(P9/1000) -> 1.2294743
A31: Aluminium sulphate | C31: kg | P31: =SUM(D31:O31) -> 0
B32: 1060.01 | C32: kg/mg litre | D32: =D31/(D9/1000) -> 0 | E32: =E31/(E9/1000) -> 0 | F32: =F31/(F9/1000) -> 0 | G32: =G31/(G9/1000) -> 0 | H32: =H31/(H9/1000) -> 0 | I32: =I31/(I9/1000) -> 0 | J32: =J31/(J9/1000) -> 0 | K32: =K31/(K9/1000) -> 0 | ... N32: =N31/(N9/1000) -> 0 | O32: 0 | P32: =P31/(P9/1000) -> 0
A33: Soda | C33: kg | P33: =SUM(D33:O33) -> 0
B34: 1228.29 | C34: kg/mg litre | D34: =D33/(D9/1000) -> 0 | E34: =E33/(E9/1000) -> 0 | F34: =F33/(F9/1000) -> 0 | G34: =G33/(G9/1000) -> 0 | H34: =H33/(H9/1000) -> 0 | I34: =I33/(I9/1000) -> 0 | J34: =J33/(J9/1000) -> 0 | K34: =K33/(K9/1000) -> 0 | ... N34: =N33/(N9/1000) -> 0 | O34: 0 | P34: =P33/(P9/1000) -> 0
A35: Algae floc | C35: litres
B36: 3726.73 | C36: litres/mg litre
A37: Sud floc | C37: litres | H37: 0 | I37: 0 | J37: 0 | K37: 0 | L37: 0 | M37: 0 | N37: 0 | O37: 0 | P37: =SUM(D37:O37) -> 0
B38: 3951.59 | C38: litres/mg litre | D38: =D37/(D9/1000) -> 0 | E38: =E37/(E9/1000) -> 0 | F38: =F37/(F9/1000) -> 0 | G38: =G37/(G9/1000) -> 0 | H38: =H37/(H9/1000) -> 0 | I38: =I37/(I9/1000) -> 0 | J38: =J37/(J9/1000) -> 0 | K38: =K37/(K9/1000) -> 0 | ... N38: =N37/(N9/1000) -> 0 | O38: 0 | P38: =P37/(P9/1000) -> 0
A39: Potasium permanganate | C39: kg | H39: 0 | I39: 0 | J39: 0 | K39: 0 | L39: 0 | M39: 0 | N39: 0 | O39: 0 | P39: =SUM(D39:O39) -> 0
B40: 1950 | C40: kg/mg litre | D40: =D39/(D9/1000) -> 0 | E40: =E39/(E9/1000) -> 0 | F40: =F39/(F9/1000) -> 0 | G40: =G39/(G9/1000) -> 0 | H40: =H39/(H9/1000) -> 0 | I40: =I39/(I9/1000) -> 0 | J40: =J39/(J9/1000) -> 0 | K40: =K39/(K9/1000) -> 0 | ... N40: =N39/(N9/1000) -> 0 | O40: 0 | P40: =P39/(P9/1000) -> 0
A41: Cost of Chemicals | C41: Mk | D41: =(D29*$B29)+(D31*$B31)+(D33*$B33)+(D35*$B35)+(D37*$B37)+(D39*$B39) -> 56404.64 | E41: =(E29*$B29)+(E31*$B31)+(E33*$B33)+(E35*$B35)+(E37*$B37)+(E39*$B39) -> 74031.09 | F41: =(F29*$B29)+(F31*$B31)+(F33*$B33)+(F35*$B35)+(F37*$B37)+(F39*$B39) -> 74031.09 | G41: =(G29*$B29)+(G31*$B31)+(G33*$B33)+(G35*$B35)+(G37*$B37)+(G39*$B39) -> 63455.22 | H41: =(H29*$B29)+(H31*$B31)+(H33*$B33)+(H35*$B35)+(H37*$B37)+(H39*$B39) -> 52879.35 | I41: =(I29*$B29)+(I31*$B31)+(I33*$B33)+(I35*$B35)+(I37*$B37)+(I39*$B39) -> 63455.22 | J41: =(J29*$B29)+(J31*$B31)+(J33*$B33)+(J35*$B35)+(J37*$B37)+(J39*$B39) -> 52879.35 | K41: =(K29*$B29)+(K31*$B31)+(K33*$B33)+(K35*$B35)+(K37*$B37)+(K39*$B39) -> 63455.22 | ... N41: =(N29*$B29)+(N31*$B31)+(N33*$B33)+(N35*$B35)+(N37*$B37)+(N39*$B39) -> 63455.22 | O41: 52879.35 | P41: =SUM(D41:O41) -> 733260.32
A42: Cost/vol. Produced (chemicals) | C42: Mk/m3 | D42: =D41/D9 -> 3.9921183 | E42: =E41/E9 -> 3.6551343 | F42: =F41/F9 -> 3.3221634 | G42: =G41/G9 -> 5.2226519 | H42: =H41/H9 -> 4.3554361 | I42: =I41/I9 -> 4.8856806 | J42: =J41/J9 -> 4.9829768 | K42: =K41/K9 -> 4.2154534 | ... N42: =N41/N9 -> 4.8602344 | O42: 4.3669461 | P42: =P41/P9 -> 4.3342534
A43: Power
...

Sheet Zone Monthly
A1: SOUTHERN REGION WATER BOARD
A3: MONTHLY REPORTS - 2023/2024
A4: NGABU ZONE
A5: NGABU ZONE
A7: PARAMETERS | C7: UNITS | D7: APRIL | E7: MAY | F7: JUNE | G7: JULY | H7: AUGUST | I7: SEPTEMBER | J7: OCTOBER | K7: NOVEMBER | L7: DECEMBER | M7: JANUARY | N7: FEBRUARY | O7: MARCH | P7: TOTALS
A8: PRODUCTION
A9: Volume Produced | C9: m3 | D9: =Bangula!D9+Chikwawa!D9+Nchalo!D9+'Miseu Folo'!D9+Nsanje!D9+Ngabu!D9 -> 96447 | E9: =Bangula!E9+Chikwawa!E9+Nchalo!E9+'Miseu Folo'!E9+Nsanje!E9+Ngabu!E9 -> 111131 | F9: =Bangula!F9+Chikwawa!F9+Nchalo!F9+'Miseu Folo'!F9+Nsanje!F9+Ngabu!F9 -> 112105 | G9: =Bangula!G9+Chikwawa!G9+Nchalo!G9+'Miseu Folo'!G9+Nsanje!G9+Ngabu!G9 -> 99943 | H9: =Bangula!H9+Chikwawa!H9+Nchalo!H9+'Miseu Folo'!H9+Nsanje!H9+Ngabu!H9 -> 101009 | I9: =Bangula!I9+Chikwawa!I9+Nchalo!I9+'Miseu Folo'!I9+Nsanje!I9+Ngabu!I9 -> 102088 | J9: =Bangula!J9+Chikwawa!J9+Nchalo!J9+'Miseu Folo'!J9+Nsanje!J9+Ngabu!J9 -> 102932 | K9: =Bangula!K9+Chikwawa!K9+Nchalo!K9+'Miseu Folo'!K9+Nsanje!K9+Ngabu!K9 -> 103528 | ... O9: =Bangula!O9+Chikwawa!O9+Nchalo!O9+'Miseu Folo'!O9+Nsanje!O9+Ngabu!O9 -> 95181 | P9: =SUM(D9:O9) -> 1223357
A10: REVENUE WATER - POSTPAID
A11: Volume Billed Individuals | C11: m3 | D11: =Bangula!D11+Chikwawa!D11+'Miseu Folo'!D11+Nchalo!D11+Nsanje!D11+Ngabu!D11 -> 43319 | E11: =Bangula!E11+Chikwawa!E11+'Miseu Folo'!E11+Nchalo!E11+Nsanje!E11+Ngabu!E11 -> 47839 | F11: =Bangula!F11+Chikwawa!F11+'Miseu Folo'!F11+Nchalo!F11+Nsanje!F11+Ngabu!F11 -> 55229 | G11: =Bangula!G11+Chikwawa!G11+'Miseu Folo'!G11+Nchalo!G11+Nsanje!G11+Ngabu!G11 -> 47697 | H11: =Bangula!H11+Chikwawa!H11+'Miseu Folo'!H11+Nchalo!H11+Nsanje!H11+Ngabu!H11 -> 48503 | I11: =Bangula!I11+Chikwawa!I11+'Miseu Folo'!I11+Nchalo!I11+Nsanje!I11+Ngabu!I11 -> 52836 | J11: =Bangula!J11+Chikwawa!J11+'Miseu Folo'!J11+Nchalo!J11+Nsanje!J11+Ngabu!J11 -> 57587 | K11: =Bangula!K11+Chikwawa!K11+'Miseu Folo'!K11+Nchalo!K11+Nsanje!K11+Ngabu!K11 -> 56505 | ... O11: =Bangula!O11+Chikwawa!O11+'Miseu Folo'!O11+Nchalo!O11+Nsanje!O11+Ngabu!O11 -> 51483 | P11: =SUM(D11:O11) -> 620127
A12: Volume Billed CWPs | C12: m3 | D12: =Bangula!D12+Chikwawa!D12+'Miseu Folo'!D12+Nchalo!D12+Nsanje!D12+Ngabu!D12 -> 5469 | E12: =Bangula!E12+Chikwawa!E12+'Miseu Folo'!E12+Nchalo!E12+Nsanje!E12+Ngabu!E12 -> 4900 | F12: =Bangula!F12+Chikwawa!F12+'Miseu Folo'!F12+Nchalo!F12+Nsanje!F12+Ngabu!F12 -> 5165 | G12: =Bangula!G12+Chikwawa!G12+'Miseu Folo'!G12+Nchalo!G12+Nsanje!G12+Ngabu!G12 -> 4610 | H12: =Bangula!H12+Chikwawa!H12+'Miseu Folo'!H12+Nchalo!H12+Nsanje!H12+Ngabu!H12 -> 5429 | I12: =Bangula!I12+Chikwawa!I12+'Miseu Folo'!I12+Nchalo!I12+Nsanje!I12+Ngabu!I12 -> 4553 | J12: =Bangula!J12+Chikwawa!J12+'Miseu Folo'!J12+Nchalo!J12+Nsanje!J12+Ngabu!J12 -> 4504 | K12: =Bangula!K12+Chikwawa!K12+'Miseu Folo'!K12+Nchalo!K12+Nsanje!K12+Ngabu!K12 -> 5099 | ... O12: =Bangula!O12+Chikwawa!O12+'Miseu Folo'!O12+Nchalo!O12+Nsanje!O12+Ngabu!O12 -> 4091 | P12: =SUM(D12:O12) -> 57022
A13: Volume Billed Institutions | C13: m3 | D13: =Bangula!D13+Chikwawa!D13+'Miseu Folo'!D13+Nchalo!D13+Nsanje!D13+Ngabu!D13 -> 533 | E13: =Bangula!E13+Chikwawa!E13+'Miseu Folo'!E13+Nchalo!E13+Nsanje!E13+Ngabu!E13 -> 578 | F13: =Bangula!F13+Chikwawa!F13+'Miseu Folo'!F13+Nchalo!F13+Nsanje!F13+Ngabu!F13 -> 1192 | G13: =Bangula!G13+Chikwawa!G13+'Miseu Folo'!G13+Nchalo!G13+Nsanje!G13+Ngabu!G13 -> 845 | H13: =Bangula!H13+Chikwawa!H13+'Miseu Folo'!H13+Nchalo!H13+Nsanje!H13+Ngabu!H13 -> 677 | I13: =Bangula!I13+Chikwawa!I13+'Miseu Folo'!I13+Nchalo!I13+Nsanje!I13+Ngabu!I13 -> 720 | J13: =Bangula!J13+Chikwawa!J13+'Miseu Folo'!J13+Nchalo!J13+Nsanje!J13+Ngabu!J13 -> 1031 | K13: =Bangula!K13+Chikwawa!K13+'Miseu Folo'!K13+Nchalo!K13+Nsanje!K13+Ngabu!K13 -> 1044 | ... O13: =Bangula!O13+Chikwawa!O13+'Miseu Folo'!O13+Nchalo!O13+Nsanje!O13+Ngabu!O13 -> 681 | P13: =SUM(D13:O13) -> 9292
A14: Volume Billed Commercial/Industrial | C14: m3 | D14: =Bangula!D14+Chikwawa!D14+'Miseu Folo'!D14+Nchalo!D14+Nsanje!D14+Ngabu!D14 -> 311 | E14: =Bangula!E14+Chikwawa!E14+'Miseu Folo'!E14+Nchalo!E14+Nsanje!E14+Ngabu!E14 -> 306 | F14: =Bangula!F14+Chikwawa!F14+'Miseu Folo'!F14+Nchalo!F14+Nsanje!F14+Ngabu!F14 -> 437 | G14: =Bangula!G14+Chikwawa!G14+'Miseu Folo'!G14+Nchalo!G14+Nsanje!G14+Ngabu!G14 -> 572 | H14: =Bangula!H14+Chikwawa!H14+'Miseu Folo'!H14+Nchalo!H14+Nsanje!H14+Ngabu!H14 -> 508 | I14: =Bangula!I14+Chikwawa!I14+'Miseu Folo'!I14+Nchalo!I14+Nsanje!I14+Ngabu!I14 -> 509 | J14: =Bangula!J14+Chikwawa!J14+'Miseu Folo'!J14+Nchalo!J14+Nsanje!J14+Ngabu!J14 -> 1094 | K14: =Bangula!K14+Chikwawa!K14+'Miseu Folo'!K14+Nchalo!K14+Nsanje!K14+Ngabu!K14 -> 502 | ... O14: =Bangula!O14+Chikwawa!O14+'Miseu Folo'!O14+Nchalo!O14+Nsanje!O14+Ngabu!O14 -> 406 | P14: =SUM(D14:O14) -> 5591
A15: Total Volume Billed Post Paid | C15: m3 | D15: =SUM(D11:D14) -> 49632 | E15: =SUM(E11:E14) -> 53623 | F15: =SUM(F11:F14) -> 62023 | G15: =SUM(G11:G14) -> 53724 | H15: =SUM(H11:H14) -> 55117 | I15: =SUM(I11:I14) -> 58618 | J15: =SUM(J11:J14) -> 64216 | K15: =SUM(K11:K14) -> 63150 | ... P15: =SUM(P11:P14) -> 692032
A16: REVENUE WATER - PREPAID
A17: Individuals | C17: m3 | D17: =Bangula!D17+Chikwawa!D17+'Miseu Folo'!D17+Nchalo!D17+Nsanje!D17+Ngabu!D17 -> 0 | E17: =Bangula!E17+Chikwawa!E17+'Miseu Folo'!E17+Nchalo!E17+Nsanje!E17+Ngabu!E17 -> 0 | F17: =Bangula!F17+Chikwawa!F17+'Miseu Folo'!F17+Nchalo!F17+Nsanje!F17+Ngabu!F17 -> 8539 | G17: =Bangula!G17+Chikwawa!G17+'Miseu Folo'!G17+Nchalo!G17+Nsanje!G17+Ngabu!G17 -> 9897 | H17: =Bangula!H17+Chikwawa!H17+'Miseu Folo'!H17+Nchalo!H17+Nsanje!H17+Ngabu!H17 -> 0 | I17: =Bangula!I17+Chikwawa!I17+'Miseu Folo'!I17+Nchalo!I17+Nsanje!I17+Ngabu!I17 -> 10365 | J17: =Bangula!J17+Chikwawa!J17+'Miseu Folo'!J17+Nchalo!J17+Nsanje!J17+Ngabu!J17 -> 12452.6 | K17: =Bangula!K17+Chikwawa!K17+'Miseu Folo'!K17+Nchalo!K17+Nsanje!K17+Ngabu!K17 -> 10819.2 | ... O17: =Bangula!O17+Chikwawa!O17+'Miseu Folo'!O17+Nchalo!O17+Nsanje!O17+Ngabu!O17 -> 8134 | P17: =SUM(D17:O17) -> 89109.8
A18: CWPs | C18: m3 | D18: =Bangula!D18+Chikwawa!D18+'Miseu Folo'!D18+Nchalo!D18+Nsanje!D18+Ngabu!D18 -> 0 | E18: =Bangula!E18+Chikwawa!E18+'Miseu Folo'!E18+Nchalo!E18+Nsanje!E18+Ngabu!E18 -> 0 | F18: =Bangula!F18+Chikwawa!F18+'Miseu Folo'!F18+Nchalo!F18+Nsanje!F18+Ngabu!F18 -> 0 | G18: =Bangula!G18+Chikwawa!G18+'Miseu Folo'!G18+Nchalo!G18+Nsanje!G18+Ngabu!G18 -> 0 | H18: =Bangula!H18+Chikwawa!H18+'Miseu Folo'!H18+Nchalo!H18+Nsanje!H18+Ngabu!H18 -> 0 | I18: =Bangula!I18+Chikwawa!I18+'Miseu Folo'!I18+Nchalo!I18+Nsanje!I18+Ngabu!I18 -> 57 | J18: =Bangula!J18+Chikwawa!J18+'Miseu Folo'!J18+Nchalo!J18+Nsanje!J18+Ngabu!J18 -> 0 | K18: =Bangula!K18+Chikwawa!K18+'Miseu Folo'!K18+Nchalo!K18+Nsanje!K18+Ngabu!K18 -> 1 | ... O18: =Bangula!O18+Chikwawa!O18+'Miseu Folo'!O18+Nchalo!O18+Nsanje!O18+Ngabu!O18 -> 0 | P18: =SUM(D18:O18) -> 59
A19: Institutions | C19: m3 | D19: =Bangula!D19+Chikwawa!D19+'Miseu Folo'!D19+Nchalo!D19+Nsanje!D19+Ngabu!D19 -> 22698 | E19: =Bangula!E19+Chikwawa!E19+'Miseu Folo'!E19+Nchalo!E19+Nsanje!E19+Ngabu!E19 -> 26081.7 | F19: =Bangula!F19+Chikwawa!F19+'Miseu Folo'!F19+Nchalo!F19+Nsanje!F19+Ngabu!F19 -> 11730.2 | G19: =Bangula!G19+Chikwawa!G19+'Miseu Folo'!G19+Nchalo!G19+Nsanje!G19+Ngabu!G19 -> 9976.8 | H19: =Bangula!H19+Chikwawa!H19+'Miseu Folo'!H19+Nchalo!H19+Nsanje!H19+Ngabu!H19 -> 24486.2 | I19: =Bangula!I19+Chikwawa!I19+'Miseu Folo'!I19+Nchalo!I19+Nsanje!I19+Ngabu!I19 -> 8843.3 | J19: =Bangula!J19+Chikwawa!J19+'Miseu Folo'!J19+Nchalo!J19+Nsanje!J19+Ngabu!J19 -> 4302 | K19: =Bangula!K19+Chikwawa!K19+'Miseu Folo'!K19+Nchalo!K19+Nsanje!K19+Ngabu!K19 -> 7706.3 | ... O19: =Bangula!O19+Chikwawa!O19+'Miseu Folo'!O19+Nchalo!O19+Nsanje!O19+Ngabu!O19 -> 8849.6 | P19: =SUM(D19:O19) -> 154271.3
A20: Commercial/Industrial | C20: m3 | D20: =Bangula!D20+Chikwawa!D20+'Miseu Folo'!D20+Nchalo!D20+Nsanje!D20+Ngabu!D20 -> 0 | E20: =Bangula!E20+Chikwawa!E20+'Miseu Folo'!E20+Nchalo!E20+Nsanje!E20+Ngabu!E20 -> 0 | F20: =Bangula!F20+Chikwawa!F20+'Miseu Folo'!F20+Nchalo!F20+Nsanje!F20+Ngabu!F20 -> 1736 | G20: =Bangula!G20+Chikwawa!G20+'Miseu Folo'!G20+Nchalo!G20+Nsanje!G20+Ngabu!G20 -> 1835 | H20: =Bangula!H20+Chikwawa!H20+'Miseu Folo'!H20+Nchalo!H20+Nsanje!H20+Ngabu!H20 -> 0 | I20: =Bangula!I20+Chikwawa!I20+'Miseu Folo'!I20+Nchalo!I20+Nsanje!I20+Ngabu!I20 -> 1668 | J20: =Bangula!J20+Chikwawa!J20+'Miseu Folo'!J20+Nchalo!J20+Nsanje!J20+Ngabu!J20 -> 1620 | K20: =Bangula!K20+Chikwawa!K20+'Miseu Folo'!K20+Nchalo!K20+Nsanje!K20+Ngabu!K20 -> 1530 | ... O20: =Bangula!O20+Chikwawa!O20+'Miseu Folo'!O20+Nchalo!O20+Nsanje!O20+Ngabu!O20 -> 1207 | P20: =SUM(D20:O20) -> 14231
A21: Total Volume Prepaid | C21: m3 | D21: =SUM(D17:D20) -> 22698 | E21: =SUM(E17:E20) -> 26081.7 | F21: =SUM(F17:F20) -> 22005.2 | G21: =SUM(G17:G20) -> 21708.8 | H21: =SUM(H17:H20) -> 24486.2 | I21: =SUM(I17:I20) -> 20933.3 | J21: =SUM(J17:J20) -> 18374.6 | K21: =SUM(K17:K20) -> 20056.5 | ... P21: =SUM(P17:P20) -> 257671.1
A22: TOTAL REVENUE WATER | C22: m3 | D22: =D21+D15 -> 72330 | E22: =E21+E15 -> 79704.7 | F22: =F21+F15 -> 84028.2 | G22: =G21+G15 -> 75432.8 | H22: =H21+H15 -> 79603.2 | I22: =I21+I15 -> 79551.3 | J22: =J21+J15 -> 82590.6 | K22: =K21+K15 -> 83206.5 | ... P22: =P21+P15 -> 949703.1
A24: Non-Revenue Water (NRW) | B24: Volume | C24: m3 | D24: =D9-D22 -> 24117 | E24: =E9-E22 -> 31426.3 | F24: =F9-F22 -> 28076.8 | G24: =G9-G22 -> 24510.2 | H24: =H9-H22 -> 21405.8 | I24: =I9-I22 -> 22536.7 | J24: =J9-J22 -> 20341.4 | K24: =K9-K22 -> 20321.5 | ... P24: =P9-P22 -> 273653.9
B25: Percentage | C25: % | D25: =D24/D9 -> 0.25005443 | E25: =E24/E9 -> 0.28278608 | F25: =F24/F9 -> 0.25045092 | G25: =G24/G9 -> 0.24524179 | H25: =H24/H9 -> 0.21191973 | I25: =I24/I9 -> 0.22075758 | J25: =J24/J9 -> 0.19761979 | K25: =K24/K9 -> 0.19628989 | ... P25: =P24/P9 -> 0.22369096
A26: OPERATING EXPENSES
A27: Chemicals
A28: Chemical | B28: Rate(MK/kg)
A29: Chlorine | B29: 3525.29 | C29: kg | D29: =Bangula!D29+Chikwawa!D29+'Miseu Folo'!D29+Nchalo!D29+Nsanje!D29+Ngabu!D29 -> 92.5 | E29: =Bangula!E29+Chikwawa!E29+'Miseu Folo'!E29+Nchalo!E29+Nsanje!E29+Ngabu!E29 -> 100 | F29: =Bangula!F29+Chikwawa!F29+'Miseu Folo'!F29+Nchalo!F29+Nsanje!F29+Ngabu!F29 -> 99 | G29: =Bangula!G29+Chikwawa!G29+'Miseu Folo'!G29+Nchalo!G29+Nsanje!G29+Ngabu!G29 -> 100.35 | H29: =Bangula!H29+Chikwawa!H29+'Miseu Folo'!H29+Nchalo!H29+Nsanje!H29+Ngabu!H29 -> 99.5 | I29: =Bangula!I29+Chikwawa!I29+'Miseu Folo'!I29+Nchalo!I29+Nsanje!I29+Ngabu!I29 -> 104.95 | J29: =Bangula!J29+Chikwawa!J29+'Miseu Folo'!J29+Nchalo!J29+Nsanje!J29+Ngabu!J29 -> 102.5 | K29: =Bangula!K29+Chikwawa!K29+'Miseu Folo'!K29+Nchalo!K29+Nsanje!K29+Ngabu!K29 -> 101.05 | ... O29: =Bangula!O29+Chikwawa!O29+'Miseu Folo'!O29+Nchalo!O29+Nsanje!O29+Ngabu!O29 -> 99 | P29: =SUM(D29:O29) -> 1201.55
C30: kg/mg litre | D30: =D29/(D9/1000) -> 0.95907597 | E30: =E29/(E9/1000) -> 0.89983893 | F30: =F29/(F9/1000) -> 0.88310066 | G30: =G29/(G9/1000) -> 1.0040723 | H30: =H29/(H9/1000) -> 0.98506074 | I30: =I29/(I9/1000) -> 1.0280346 | J30: =J29/(J9/1000) -> 0.99580305 | K30: =K29/(K9/1000) -> 0.97606445 | ... P30: =P29/(P9/1000) -> 0.98217446
A31: Aluminium sulphate | C31: kg | D31: =Bangula!D31+Chikwawa!D31+'Miseu Folo'!D31+Nchalo!D31+Nsanje!D31+Ngabu!D31 -> 0 | E31: =Bangula!E31+Chikwawa!E31+'Miseu Folo'!E31+Nchalo!E31+Nsanje!E31+Ngabu!E31 -> 0 | F31: =Bangula!F31+Chikwawa!F31+'Miseu Folo'!F31+Nchalo!F31+Nsanje!F31+Ngabu!F31 -> 0 | G31: =Bangula!G31+Chikwawa!G31+'Miseu Folo'!G31+Nchalo!G31+Nsanje!G31+Ngabu!G31 -> 0 | H31: =Bangula!H31+Chikwawa!H31+'Miseu Folo'!H31+Nchalo!H31+Nsanje!H31+Ngabu!H31 -> 0 | I31: =Bangula!I31+Chikwawa!I31+'Miseu Folo'!I31+Nchalo!I31+Nsanje!I31+Ngabu!I31 -> 0 | J31: =Bangula!J31+Chikwawa!J31+'Miseu Folo'!J31+Nchalo!J31+Nsanje!J31+Ngabu!J31 -> 0 | K31: =Bangula!K31+Chikwawa!K31+'Miseu Folo'!K31+Nchalo!K31+Nsanje!K31+Ngabu!K31 -> 0 | ... O31: =Bangula!O31+Chikwawa!O31+'Miseu Folo'!O31+Nchalo!O31+Nsanje!O31+Ngabu!O31 -> 0 | P31: =SUM(D31:O31) -> 0
B32: 1060.01 | C32: kg/mg litre | D32: =D31/(D9/1000) -> 0 | E32: =E31/(E9/1000) -> 0 | F32: =F31/(F9/1000) -> 0 | G32: =G31/(G9/1000) -> 0 | H32: =H31/(H9/1000) -> 0 | I32: =I31/(I9/1000) -> 0 | J32: =J31/(J9/1000) -> 0 | K32: =K31/(K9/1000) -> 0 | ... P32: =P31/(P9/1000) -> 0
A33: Soda | C33: kg | D33: =Bangula!D33+Chikwawa!D33+'Miseu Folo'!D33+Nchalo!D33+Nsanje!D33+Ngabu!D33 -> 0 | E33: =Bangula!E33+Chikwawa!E33+'Miseu Folo'!E33+Nchalo!E33+Nsanje!E33+Ngabu!E33 -> 0 | F33: =Bangula!F33+Chikwawa!F33+'Miseu Folo'!F33+Nchalo!F33+Nsanje!F33+Ngabu!F33 -> 0 | G33: =Bangula!G33+Chikwawa!G33+'Miseu Folo'!G33+Nchalo!G33+Nsanje!G33+Ngabu!G33 -> 0 | H33: =Bangula!H33+Chikwawa!H33+'Miseu Folo'!H33+Nchalo!H33+Nsanje!H33+Ngabu!H33 -> 0 | I33: =Bangula!I33+Chikwawa!I33+'Miseu Folo'!I33+Nchalo!I33+Nsanje!I33+Ngabu!I33 -> 0 | J33: =Bangula!J33+Chikwawa!J33+'Miseu Folo'!J33+Nchalo!J33+Nsanje!J33+Ngabu!J33 -> 0 | K33: =Bangula!K33+Chikwawa!K33+'Miseu Folo'!K33+Nchalo!K33+Nsanje!K33+Ngabu!K33 -> 0 | ... O33: =Bangula!O33+Chikwawa!O33+'Miseu Folo'!O33+Nchalo!O33+Nsanje!O33+Ngabu!O33 -> 0 | P33: =SUM(D33:O33) -> 0
B34: 1228.29 | C34: kg/mg litre | D34: =D33/(D9/1000) -> 0 | E34: =E33/(E9/1000) -> 0 | F34: =F33/(F9/1000) -> 0 | G34: =G33/(G9/1000) -> 0 | H34: =H33/(H9/1000) -> 0 | I34: =I33/(I9/1000) -> 0 | J34: =J33/(J9/1000) -> 0 | K34: =K33/(K9/1000) -> 0 | ... P34: =P33/(P9/1000) -> 0
A35: Algae floc | C35: litres | D35: =Bangula!D35+Chikwawa!D35+'Miseu Folo'!D35+Nchalo!D35+Nsanje!D35+Ngabu!D35 -> 0 | E35: =Bangula!E35+Chikwawa!E35+'Miseu Folo'!E35+Nchalo!E35+Nsanje!E35+Ngabu!E35 -> 0 | F35: =Bangula!F35+Chikwawa!F35+'Miseu Folo'!F35+Nchalo!F35+Nsanje!F35+Ngabu!F35 -> 0 | G35: =Bangula!G35+Chikwawa!G35+'Miseu Folo'!G35+Nchalo!G35+Nsanje!G35+Ngabu!G35 -> 0 | H35: =Bangula!H35+Chikwawa!H35+'Miseu Folo'!H35+Nchalo!H35+Nsanje!H35+Ngabu!H35 -> 0 | I35: =Bangula!I35+Chikwawa!I35+'Miseu Folo'!I35+Nchalo!I35+Nsanje!I35+Ngabu!I35 -> 0 | J35: =Bangula!J35+Chikwawa!J35+'Miseu Folo'!J35+Nchalo!J35+Nsanje!J35+Ngabu!J35 -> 0 | K35: =Bangula!K35+Chikwawa!K35+'Miseu Folo'!K35+Nchalo!K35+Nsanje!K35+Ngabu!K35 -> 0 | ... O35: =Bangula!O35+Chikwawa!O35+'Miseu Folo'!O35+Nchalo!O35+Nsanje!O35+Ngabu!O35 -> 0
B36: 3726.73 | C36: litres/mg litre
A37: Sud floc | C37: litres | D37: =Bangula!D37+Chikwawa!D37+'Miseu Folo'!D37+Nchalo!D37+Nsanje!D37+Ngabu!D37 -> 0 | E37: =Bangula!E37+Chikwawa!E37+'Miseu Folo'!E37+Nchalo!E37+Nsanje!E37+Ngabu!E37 -> 0 | F37: =Bangula!F37+Chikwawa!F37+'Miseu Folo'!F37+Nchalo!F37+Nsanje!F37+Ngabu!F37 -> 0 | G37: =Bangula!G37+Chikwawa!G37+'Miseu Folo'!G37+Nchalo!G37+Nsanje!G37+Ngabu!G37 -> 0 | H37: =Bangula!H37+Chikwawa!H37+'Miseu Folo'!H37+Nchalo!H37+Nsanje!H37+Ngabu!H37 -> 0 | I37: =Bangula!I37+Chikwawa!I37+'Miseu Folo'!I37+Nchalo!I37+Nsanje!I37+Ngabu!I37 -> 0 | J37: =Bangula!J37+Chikwawa!J37+'Miseu Folo'!J37+Nchalo!J37+Nsanje!J37+Ngabu!J37 -> 0 | K37: =Bangula!K37+Chikwawa!K37+'Miseu Folo'!K37+Nchalo!K37+Nsanje!K37+Ngabu!K37 -> 0 | ... O37: =Bangula!O37+Chikwawa!O37+'Miseu Folo'!O37+Nchalo!O37+Nsanje!O37+Ngabu!O37 -> 0 | P37: =SUM(D37:O37) -> 0
B38: 3951.59 | C38: litres/mg litre | D38: =D37/(D9/1000) -> 0 | E38: =E37/(E9/1000) -> 0 | F38: =F37/(F9/1000) -> 0 | G38: =G37/(G9/1000) -> 0 | H38: =H37/(H9/1000) -> 0 | I38: =I37/(I9/1000) -> 0 | J38: =J37/(J9/1000) -> 0 | K38: =K37/(K9/1000) -> 0 | ... P38: =P37/(P9/1000) -> 0
